File: .vms
VAMAS Surface Chemical Analysis Standard Data Transfer Format 1988 May 4
Not Specified
Not Specified
Not Specified
Not Specified
2
Casa Info Follows CasaXPS Version 2.3.22PR1.0
0
NORM
REGULAR
0
1
Exp Variable
d
0
0
0
0
4
Scattered
MeasuredSpectrum
2002
2020
09
13
35
37
0
10
Casa Info Follows
0
0
0
0
none
Group: none
Analyzer Lens: none
Analyzer Slit: none
Scan Mode: none
XPS
0
Al
1486.61
0
0
0
56.5
180
FAT
0
1
0
0
0
0
0
0
Scattered

-1
kinetic energy
eV
1311.61
0.10000000000013642
2
counts
d
Transmission
d
pulse counting
1
1
0
0
0
0
2
ESCAPE DEPTH TYPE
d
0
MFP Exponent
d
0
1249.4567
1
5298.2334
5336.1006
5266.6
5298.6997
5312.6997
5256.301
5296.5
5267.033
5323.6
5337.2666
5361.8335
5269.6333
5319.433
5351.467
5276.7666
5320.8335
5280.533
5345.9
5332.533
5282.767
5350.1997
5307.467
5301.0
5344.433
5382.8003
5354.3667
5384.9
5358.6
5336.301
5383.2666
5397.6665
5336.2666
5318.067
5388.067
5358.533
5362.2666
5317.7334
5324.7666
5400.301
5396.567
5331.1333
5366.1
5353.033
5403.467
5402.467
5361.433
5367.699
5431.433
5391.6
5384.8003
5412.1333
5370.3667
5346.3667
5390.3003
5333.3667
5409.933
5423.6
5352.2334
5353.8667
5384.1665
5368.0
5404.2666
5350.6
5371.1665
5412.6665
5348.6997
5430.7666
5432.7666
5426.567
5420.1665
5397.6333
5434.2666
5467.0664
5505.8003
5453.4
5375.0
5406.5
5454.6333
5450.3003
5437.2666
5392.467
5338.6665
5378.9
5419.9
5507.3335
5475.5
5418.6997
5374.1
5397.933
5451.8667
5447.067
5436.6997
5380.567
5467.4336
5394.6665
5494.1997
5462.6997
5463.267
5471.5664
5527.6
5466.233
5465.8003
5466.233
5480.301
5550.1665
5484.267
5494.267
5418.8335
5418.533
5480.301
5469.9336
5459.7334
5431.7334
5477.267
5513.1
5526.3335
5588.0664
5550.9
5487.3003
5454.6333
5548.1333
5477.1665
5477.1
5564.1
5619.3003
5565.0
5562.967
5564.3335
5514.467
5574.5
5470.733
5555.9
5518.0
5568.267
5599.233
5535.767
5548.8667
5523.6333
5536.0
5580.4336
5512.8003
5511.3667
5540.533
5552.467
5540.3003
5583.533
5549.8667
5537.1
5548.0005
5489.267
5531.6333
5531.6665
5559.267
5612.9336
5563.8335
5566.767
5610.8003
5598.9
5621.1333
5575.8335
5524.6665
5551.233
5556.3003
5571.4336
5593.967
5544.6665
5499.467
5577.8335
5566.033
5621.433
5640.033
5620.8003
5590.0664
5564.6665
5592.8003
5604.233
5604.1997
5587.767
5542.1
5561.967
5631.233
5616.0664
5621.467
5612.8667
5591.033
5654.733
5685.4
5665.6997
5638.0664
5606.0664
5611.3335
5629.6
5612.9336
5676.9336
5674.1665
5690.1665
5668.9336
5718.1665
5692.3335
5662.6333
5645.267
5737.533
5694.3335
5614.5664
5629.8667
5627.6333
5671.767
5705.8003
5639.767
5743.3335
5714.0664
5608.6997
5695.8667
5690.767
5681.533
5688.033
5653.4
5671.6
5728.6997
5700.8335
5629.5
5724.6333
5716.0664
5727.1997
5700.8335
5783.4
5708.5664
5786.533
5712.6665
5699.967
5691.1665
5790.667
5717.033
5727.9336
5761.033
5773.433
5797.5
5699.233
5766.5
5734.3335
5746.5
5725.767
5734.867
5759.967
5811.8003
5770.467
5777.133
5771.767
5792.033
5787.8667
5765.9
5761.8335
5739.6333
5745.1665
5833.8667
5804.8335
5858.4336
5772.8003
5809.1665
5756.467
5795.4336
5841.467
5842.533
5775.4
5812.8667
5778.1997
5838.733
5805.233
5784.733
5822.6
5820.8667
5779.9
5870.733
5831.267
5829.1333
5846.1997
5755.9
5866.767
5839.8667
5817.6
5823.533
5808.1997
5810.3667
5846.767
5779.1665
5795.767
5847.4336
5916.4336
5850.767
5863.9336
5891.6997
5888.0
5905.233
5863.533
5922.9336
5900.033
5944.301
5927.033
5924.4336
5911.4336
5855.8335
5886.3667
5811.9
5862.767
5862.233
5884.767
5884.767
5907.033
5926.667
5894.233
5918.667
5954.0
5928.8667
5905.3667
5923.267
5865.967
5791.767
5868.5
5979.6665
5998.6997
5896.5
5906.6997
5918.0664
5866.8335
5939.8003
5960.267
5882.8335
5934.4336
5928.767
5889.533
5969.4336
5960.6
5963.8335
5993.3003
5952.5
5907.967
5908.3667
5908.5664
5910.1333
5870.467
5920.6333
5960.6
5943.233
5950.0664
5939.033
5962.967
6002.3335
6054.667
5946.1
5991.699
5993.233
5948.0005
5957.8335
5979.3667
5953.1665
5951.8335
5949.0
6021.9
5979.1665
5968.767
5955.033
5970.1665
6065.9
5969.1665
5997.0
6014.4336
6053.733
5997.233
6040.8667
6106.4336
6002.8003
6027.1665
5983.967
6047.1
6022.6997
5970.533
5986.5
6010.8667
6059.9
6060.5664
6048.0664
6025.967
6029.433
6109.9
6073.133
6034.8003
6070.9336
6080.967
6008.8335
6059.8335
6076.767
6102.267
6017.5664
6075.267
6128.3335
6038.1
6015.5
6036.733
6059.3335
6015.6665
6074.8667
6093.6665
6092.4336
6077.033
6133.3335
6130.6665
6147.3003
6118.0
6097.9336
6086.3667
6069.1997
6115.5
6090.4336
6120.3335
6135.467
6113.233
6092.6997
6133.767
6100.4
6104.0
6099.8003
6156.6665
6132.4336
6164.533
6098.3667
6137.4
6100.3335
6097.3003
6212.033
6206.6333
6124.6997
6144.6333
6133.267
6143.1
6118.1997
6166.033
6174.733
6165.267
6096.6665
6214.867
6186.6997
6160.3335
6155.8335
6164.6665
6190.733
6177.533
6184.033
6148.967
6205.533
6133.8667
6186.733
6165.533
6290.233
6172.9336
6185.9
6221.6997
6207.4
6206.6333
6243.1997
6238.1665
6215.1997
6213.033
6286.1333
6243.967
6227.9
6170.8335
6255.8667
6166.1333
6260.8003
6310.033
6189.6333
6176.3335
6182.1997
6234.6665
6177.467
6196.4336
6210.6
6256.8003
6248.3667
6242.033
6260.1665
6242.1
6203.6997
6196.533
6239.0
6266.9
6255.4336
6276.5664
6277.3003
6233.3003
6253.3003
6273.1
6338.0
6261.6
6286.6997
6361.3667
6265.267
6243.267
6326.4336
6344.033
6338.1333
6315.5664
6298.5
6426.767
6327.733
6324.8335
6352.967
6343.3667
6326.6
6379.0
6308.6333
6309.0664
6283.8003
6333.1997
6382.3667
6425.5
6397.033
6386.6665
6345.4336
6383.533
6345.6997
6394.6
6281.5
6416.5
6374.1665
6400.9336
6394.533
6451.9
6455.767
6442.6997
6486.4
6526.3667
6470.9
6406.233
6413.9
6382.533
6432.8335
6438.267
6529.3667
6497.533
6519.6
6442.9336
6470.1665
6432.5664
6491.5664
6470.733
6506.8667
6450.4
6460.6
6511.3003
6579.233
6529.133
6539.6665
6572.267
6529.4336
6553.9
6564.767
6537.4336
6571.4336
6565.1997
6572.0664
6513.767
6548.6665
6605.267
6602.267
6629.1997
6575.6
6591.233
6533.9336
6546.967
6529.6333
6560.6333
6568.9
6567.9336
6529.9336
6612.3667
6629.533
6633.767
6623.1
6668.8667
6653.5664
6641.1997
6676.5
6640.1997
6632.301
6703.1997
6637.6665
6655.033
6687.1665
6634.8003
6668.1665
6706.033
6654.3667
6681.133
6697.3667
6679.033
6698.8335
6657.033
6679.6
6683.967
6663.3667
6721.967
6755.033
6768.1006
6779.267
6737.1997
6760.6665
6700.5664
6763.8003
6704.1006
6725.3667
6720.733
6780.3667
6745.8003
6763.6997
6735.8335
6770.4336
6762.8003
6777.3667
6705.533
6737.1665
6686.6997
6799.4336
6726.6333
6709.4
6804.033
6741.0664
6730.733
6799.1333
6773.967
6730.6333
6685.767
6788.233
6868.8003
6843.6333
6880.5664
6811.5664
6837.6997
6808.4
6818.1
6810.4
6781.6997
6792.9
6773.0
6813.6665
6801.6333
6818.8335
6828.533
6761.8335
6745.6665
6733.8667
6733.967
6757.9336
6700.6
6686.1997
6710.267
6659.733
6595.267
6659.1333
6625.967
6636.1665
6555.733
6541.8667
6561.9
6525.6665
6521.6665
6554.3003
6577.8667
6605.0664
6544.8335
6553.767
6558.267
6589.6333
6610.9
6591.767
6683.267
6586.0664
6571.533
6557.1997
6529.333
6519.8994
6453.467
6496.6997
6478.1333
6416.033
6532.1
6504.967
6532.3335
6419.3335
6456.1333
6434.4
6478.1665
6480.267
6480.767
6490.1997
6464.8667
6499.3667
6414.4336
6475.3003
6408.4
6495.3003
6481.9
6546.233
6538.1665
6467.5
6488.967
6553.5
6564.0664
6613.0664
6656.967
6650.9336
6696.9
6702.967
6705.6333
6730.0664
6603.533
6645.5
6599.233
6554.567
6592.467
6626.1665
6519.5664
6589.433
6732.733
6715.467
6813.6665
6973.733
7097.8335
7157.1
7358.867
7411.4
7542.767
7587.1997
7611.6665
7615.5664
7657.4336
7623.233
7631.533
7746.0
7858.9336
7969.4
8136.4336
8265.866
8312.934
8228.8
8081.5
7818.9
7519.533
7143.6
6851.8003
6574.667
6396.8667
6211.767
6098.233
5972.5664
5931.6
5849.3667
5726.267
5725.5
5753.267
5801.4
5834.1333
5986.033
6134.0
6302.8003
6515.0664
6686.6997
6845.1
6914.733
6963.033
6988.3667
6929.133
6878.3335
6952.5
6942.867
7063.467
7162.8003
7331.9336
7483.3335
7550.467
7548.8667
7439.4
7136.267
6642.6665
6133.1
5572.533
5194.6665
4893.567
4687.3667
4511.1665
4376.3667
4257.6
4179.033
4191.8335
4219.0
4153.933
4177.2334
4161.567
4144.1333
4123.0
4156.8667
4164.933
4182.6665
4205.4
4188.467
4194.033
4187.7666
4221.033
4212.067
4218.3667
4247.9
4267.6333
4176.3003
4205.6333
4233.7334
4236.6997
4216.6
4191.8335
4163.8667
4140.8003
4138.1997
4109.3667
4069.8333
3986.8333
4004.2666
3937.5667
3893.0999
3935.1335
4004.3665
4066.4668
4009.8333
4040.4001
4059.2666
4114.967
4035.9333
4101.9
4168.8667
4163.6
4190.8667
4246.6333
4350.8003
4309.033
4312.6665
4385.6665
4447.2666
4452.2666
4479.6333
4503.8335
4562.1665
4525.1997
4536.8667
4593.4
4596.6997
4642.7334
4765.933
4955.3667
5043.1
5239.1665
5551.4
5852.1997
6423.3003
7040.4
7871.4336
8964.0
10450.033
12403.034
14944.966
18287.133
22321.967
27090.834
32507.1
37606.0
41208.0
41919.668
38897.0
33101.867
26214.0
19801.201
14790.934
11226.833
8877.434
7318.8335
6319.8335
5757.6333
5280.7334
4990.567
4698.1
4484.6997
4441.6665
4388.9
4342.2334
4363.2334
4477.067
4612.067
4864.933
5136.9
5634.1333
6238.6997
7135.467
8172.267
9691.767
11594.267
14231.333
17602.732
22010.701
27657.568
34205.0
41116.668
47745.0
51979.668
51749.668
46893.0
38442.0
28972.0
21038.799
14879.466
10632.399
7815.3667
5968.6333
4800.1665
4026.1335
3483.1667
3116.6768
2832.327
2611.78
2409.49
2282.1965
2169.2468
2095.14
1992.1766
1949.7599
1850.0166
1839.2666
1770.1967
1721.4067
1650.7467
1629.4567
1604.21
1576.5133
1509.71
1491.71
1473.3267
1488.4968
1439.1567
1410.2767
1374.9733
1392.2767
1377.48
1373.9266
1350.8234
1350.24
1362.3833
1336.48
1321.8634
1314.3434
1315.9534
1295.64
1302.6101
1279.65
1312.5433
1299.7433
1291.27
1286.63
1284.65
1304.0533
1278.9833
1271.7233
1278.7966
1279.6134
1249.4567
1270.63
1262.9933
1260.8766
1280.7333
1298.5499
1290.4933
1286.16
1280.91
1300.14
1301.7067
1325.14
1298.1934
1300.7833
1287.9401
1304.79
1330.0133
1341.72
1338.3766
1347.5
1383.06
1354.9333
1336.1766
1363.5167
1366.35
1373.6733
1376.1466
1343.9066
1388.9166
1356.85
1356.5033
1360.2034
1
Unscattered
MeasuredSpectrum
2002
2020
09
13
35
37
0
10
Casa Info Follows
0
0
0
0
none
Group: none
Analyzer Lens: none
Analyzer Slit: none
Scan Mode: none
XPS
0
Al
1486.61
0
0
0
56.5
180
FAT
0
1
0
0
0
0
0
0
Unscattered

-1
kinetic energy
eV
1311.61
0.10000000000013642
2
counts
d
Transmission
d
pulse counting
1
1
0
0
0
0
2
ESCAPE DEPTH TYPE
d
0
MFP Exponent
d
0
2752.585
1
9745.25
9848.05
9772.95
9773.4
9835.65
9820.05
9796.0
9829.25
9918.75
9892.55
9844.5
9885.2
9956.2
9906.8
9962.4
10025.55
10021.65
9946.0
9983.9
9947.25
9933.1
10077.7
9980.9
9910.2
9982.451
9935.9
9934.4
9965.05
9941.15
10020.7
9910.95
9954.2
10076.6
10012.45
9997.75
9956.85
9948.9
9940.05
9885.65
9980.3
9998.55
9987.05
9913.7
9913.45
9956.8
10023.8
10100.3
9997.75
10004.7
10151.5
10021.851
10097.6
9986.25
9994.65
10005.95
9973.35
9960.2
10050.0
10051.5
10043.95
10015.75
10035.0
10018.3
10009.8
10025.85
10014.8
9972.2
9839.0
9974.1
10071.8
10097.15
10092.25
10006.8
10146.5
10143.3
10023.95
10005.9
10129.05
10083.65
10215.85
10104.45
10068.8
10046.7
10119.95
10128.4
10080.6
9938.9
10009.85
10170.05
10110.9
10045.25
10083.9
10143.7
10082.8
10037.5
10021.9
10125.2
10052.7
10090.95
10120.45
10145.15
10009.9
10005.0
10191.85
10153.1
10149.8
10109.4
10195.95
10207.6
10164.55
10265.9
10162.3
10103.1
10184.8
10264.2
10193.3
10234.2
10333.05
10262.1
10341.55
10263.65
10322.65
10228.6
10279.7
10318.1
10350.25
10313.55
10357.8
10396.0
10328.2
10310.55
10385.65
10374.15
10248.05
10303.35
10348.55
10428.0
10275.95
10365.9
10474.9
10394.3
10364.9
10257.85
10246.35
10304.9
10224.55
10184.05
10293.9
10319.1
10237.7
10286.95
10296.65
10281.6
10241.25
10278.4
10310.35
10296.75
10380.1
10382.9
10263.3
10225.85
10252.8
10295.5
10364.1
10343.65
10264.65
10302.051
10382.75
10392.45
10476.5
10437.25
10321.15
10298.2
10315.4
10389.0
10447.65
10441.85
10399.55
10426.2
10449.1
10335.15
10435.8
10425.1
10424.2
10439.4
10387.35
10389.3
10370.8
10471.599
10518.05
10534.3
10495.7
10524.4
10428.65
10466.15
10465.15
10566.251
10580.45
10504.9
10513.7
10433.2
10517.6
10525.95
10434.55
10496.7
10561.45
10645.4
10465.85
10515.45
10634.7
10542.6
10574.6
10591.55
10484.5
10571.6
10594.85
10487.3
10600.3
10693.55
10615.9
10639.45
10641.549
10520.3
10597.75
10601.25
10643.65
10698.85
10635.65
10581.9
10608.25
10644.3
10587.1
10640.75
10617.7
10807.55
10803.45
10717.1
10730.1
10685.25
10693.1
10625.549
10637.6
10726.4
10670.9
10623.85
10591.95
10654.8
10727.55
10781.45
10801.1
10671.5
10635.05
10662.3
10811.5
10766.1
10799.75
10867.55
10789.55
10768.75
10789.15
10787.05
10791.45
10744.9
10849.25
10805.7
10763.4
10872.7
10794.3
10709.851
10758.95
10791.0
10784.75
10816.5
10789.2
10876.15
10859.95
11031.15
10844.9
10876.25
10919.55
10903.75
11027.65
10949.95
10885.1
10946.7
10908.95
10875.45
10941.55
10841.25
10898.8
10822.8
10880.201
10915.55
10884.1
10946.95
10897.549
10843.3
10873.45
11003.7
10896.65
10859.75
10989.6
10905.15
11010.15
11019.2
11001.749
10923.4
10929.45
10805.7
10862.451
10908.75
10896.85
10875.55
10867.9
10926.85
10930.5
10942.75
10868.2
10897.8
10956.95
10911.55
10895.2
10908.95
11014.95
11002.35
10973.75
11023.35
11002.05
10947.95
10928.75
11076.55
11071.4
11012.25
10917.95
11042.75
11033.2
11048.05
10918.15
10972.0
10925.1
10990.4
11062.2
11137.35
11131.2
11060.75
11069.55
11040.5
11023.55
11001.3
11081.1
11150.65
11125.9
11159.55
11092.75
11054.75
11072.0
11167.0
11161.55
11085.75
11117.6
11151.05
11061.8
11075.9
11078.6
11128.1
11209.65
11115.65
11051.75
11055.25
11021.8
11071.0
11081.4
11132.4
11070.3
11038.6
11029.95
11200.8
11123.05
11096.55
11256.95
11309.8
11195.35
11161.5
11146.85
11100.45
11125.5
11101.0
11260.95
11230.65
11267.55
11179.45
11063.1
11282.25
11226.6
11231.799
11278.2
11114.4
11228.8
11249.549
11230.051
11359.65
11200.0
11173.5
11278.0
11252.5
11392.7
11306.75
11222.6
11338.25
11337.1
11361.1
11387.4
11300.25
11301.75
11372.1
11369.349
11386.4
11325.4
11318.75
11265.549
11502.55
11471.0
11360.35
11352.05
11391.0
11339.4
11495.65
11425.05
11434.9
11467.05
11471.1
11393.45
11383.15
11380.05
11457.7
11413.8
11458.7
11477.15
11487.3
11486.5
11458.75
11485.6
11586.85
11509.15
11373.35
11394.85
11521.7
11556.8
11481.85
11556.65
11552.0
11528.55
11574.85
11599.6
11504.5
11578.1
11557.95
11560.75
11574.45
11554.5
11632.201
11560.15
11613.4
11746.9
11638.4
11639.25
11533.45
11603.3
11625.6
11602.1
11674.2
11687.5
11721.65
11741.4
11598.8
11731.05
11826.65
11770.6
11724.8
11706.6
11687.85
11797.45
11811.05
11861.15
11829.25
11874.8
11817.749
11804.45
11890.3
11797.95
11807.6
11809.05
11908.9
11983.7
11913.4
11830.45
11978.75
11916.95
11980.05
11944.401
11962.25
11945.85
11956.2
12024.401
12008.55
12059.75
12131.0
12142.75
12003.1
12045.85
12057.9
12052.7
12137.55
12180.0
12136.5
12223.3
12178.4
12253.1
12236.4
12320.05
12252.2
12267.35
12336.4
12328.75
12269.6
12335.25
12242.6
12355.35
12371.6
12382.8
12217.3
12250.35
12368.8
12455.65
12429.85
12398.25
12353.65
12441.85
12579.2
12531.15
12524.6
12460.75
12486.95
12534.6
12639.5
12567.0
12583.1
12570.9
12669.05
12582.35
12690.95
12599.15
12717.95
12642.6
12601.749
12688.05
12644.95
12672.0
12681.6
12717.8
12772.45
12878.2
12828.35
12738.15
12863.55
12808.9
12744.85
12858.6
12790.7
12733.25
12819.75
12791.75
12675.15
12693.15
12668.4
12877.5
12715.15
12790.55
12798.451
12706.55
12680.65
12783.3
12733.85
12769.1
12759.7
12881.1
12927.9
12782.5
12837.8
12907.15
12864.75
12930.65
12817.5
12774.45
12877.15
12979.5
12911.2
12956.75
13070.8
12960.7
13069.75
12988.9
12935.55
13119.0
13147.6
13127.0
12978.5
13110.9
13090.3
13159.1
13144.3
13114.85
13206.5
13133.0
13263.7
13091.95
13225.3
13272.75
13143.55
13277.6
13264.75
13228.8
13218.0
13354.6
13297.2
13368.6
13452.85
13387.4
13375.55
13444.85
13418.6
13360.3
13401.95
13428.0
13438.2
13388.25
13445.1
13549.95
13460.25
13480.8
13424.3
13550.0
13483.75
13482.6
13486.5
13486.75
13380.6
13350.55
13355.4
13312.9
13296.95
13361.35
13311.85
13345.1
13307.05
13296.201
13297.3
13215.65
13220.7
13118.9
13221.65
13299.45
13078.4
13257.0
13155.5
13175.8
13260.65
13168.15
13138.5
13043.3
12986.9
12997.3
12884.15
12851.75
12843.15
12866.4
12900.35
12831.4
12855.85
12747.45
12783.799
12790.6
12676.6
12683.6
12492.15
12526.65
12469.9
12518.651
12522.85
12503.55
12527.1
12522.7
12320.15
12395.8
12356.45
12376.85
12375.8
12355.1
12301.85
12273.25
12323.85
12393.3
12362.9
12365.0
12344.9
12348.0
12291.05
12287.35
12422.85
12320.5
12425.15
12436.0
12341.6
12369.949
12401.949
12351.2
12439.25
12380.4
12235.05
12296.2
12467.25
12430.5
12266.5
12257.8
12364.1
12349.75
12431.4
12400.05
12337.549
12335.6
12437.2
12477.45
12468.25
12506.05
12400.201
12240.35
12294.251
12467.05
12435.3
12445.85
12402.6
12432.4
12476.55
12437.25
12496.4
12594.0
12344.1
12522.0
12595.45
12651.0
12677.8
12497.25
12600.7
12649.3
12555.9
12560.1
12560.8
12625.549
12606.65
12607.65
12522.0
12581.851
12594.45
12629.25
12647.95
12591.2
12699.65
12567.25
12612.3
12497.35
12546.35
12551.3
12438.1
12441.15
12306.1
12441.55
12390.95
12281.349
12222.5
12136.35
12149.0
12126.95
12075.7
12068.35
12062.65
11924.85
11824.6
11822.25
11780.2
11765.25
11769.55
11780.45
11777.949
11808.9
11859.4
11988.85
11918.6
11932.6
11884.45
11990.9
11986.35
12004.05
12000.75
12160.201
12187.6
12119.85
12278.6
12135.9
12188.85
12112.25
12189.75
12014.25
12073.55
12084.1
12028.7
12072.401
12021.95
11909.851
11946.5
11823.85
11833.45
11777.15
11667.5
11549.85
11544.2
11589.851
11534.7
11599.15
11591.0
11703.75
11716.8
11828.4
11849.25
11916.45
12079.2
12098.25
12238.3
12460.3
12641.75
12613.75
12674.9
12928.35
13028.25
13115.1
13240.1
13328.5
13455.45
13509.851
13556.85
13460.2
13555.35
13692.7
13803.1
13957.2
14207.05
14693.25
15179.25
15928.65
16994.8
18186.75
19932.5
22101.75
24950.1
28758.35
33689.3
40271.3
48758.8
59982.5
73525.0
89855.0
108123.5
125826.5
138285.0
140879.0
130609.49
110910.0
86770.0
64967.5
48020.95
36166.35
28122.3
23089.05
19718.95
17569.4
16005.45
15058.75
14213.15
13564.25
13205.35
12912.0
13044.15
13044.35
13461.55
13953.6
14746.2
15883.35
17370.55
19381.45
22263.4
26055.15
31017.7
37632.6
46609.746
57896.0
72821.5
91825.49
113720.5
137771.02
159690.5
174491.5
174082.0
157119.0
128247.0
96554.5
68464.5
48029.1
33856.8
24514.5
18472.15
14648.65
11936.9
10169.55
8837.25
7957.2
7230.1
6603.05
6181.1
5736.8
5369.85
5199.7
4896.16
4718.735
4508.175
4355.075
4169.935
4031.145
3972.795
3788.1
3689.33
3643.955
3551.865
3415.09
3375.275
3346.97
3247.63
3211.63
3180.32
3152.455
3132.415
3076.565
3028.075
3012.415
3008.175
2909.62
2911.78
2916.75
2871.28
2878.735
2839.87
2806.595
2788.12
2752.585
2767.26
2780.06
2796.665
2769.9998
2768.085
2777.725
2763.135
2823.005
2842.41
2777.14
2777.155
2771.315
2783.975
2791.945
2752.945
2802.86
2795.46
2785.03
2807.605
2806.89
2826.705
2873.74
2878.995
2883.665
2907.64
2912.605
2949.665
2944.38
2970.61
2975.495
2996.595
3034.6
3018.865
3081.005
3046.445
3099.815
3180.405
3165.675
3102.81
1
Simulated
Spectrum
2002
2020
09
13
35
37
0
10
Casa Info Follows
0
0
0
0
none
Group: none
Analyzer Lens: none
Analyzer Slit: none
Scan Mode: none
XPS
0
Al
1486.61
0
0
0
56.5
180
FAT
0
1
0
0
0
0
0
0
Simulated

-1
kinetic energy
eV
1311.61
0.10000000000013642
2
counts
d
Transmission
d
pulse counting
1
1
0
0
0
0
2
ESCAPE DEPTH TYPE
d
0
MFP Exponent
d
0
2760.045175
1
6906.448093
6936.888494
6914.713615
6915.027552
6933.763822
6929.556052
6922.926178
6933.312062
6960.377583
6953.12269
6939.211113
6951.330413
6972.273339
6957.61081
6974.221307
6993.208742
6992.384251
6970.300443
6981.845164
6971.358217
6967.62712
7010.984267
6982.846003
6962.413965
6984.369459
6971.284176
6971.673892
6981.553075
6975.023285
6998.798336
6966.349837
6979.363064
7016.137915
6997.896925
6994.326985
6982.906557
6981.195661
6979.2495
6963.836064
6992.491285
6998.342199
6995.181748
6973.609858
6973.79815
6987.160569
7007.759531
7031.245568
7001.625478
7004.278638
7048.185246
7010.107603
7032.857553
7000.285399
7003.293398
7007.196237
6998.041055
6994.585714
7021.645004
7022.669071
7021.129688
7013.476611
7019.749786
7015.223091
7013.069636
7018.261162
7015.548519
7003.54623
6964.650331
7005.08786
7034.335949
7042.111054
7040.951021
7016.020283
7057.907351
7057.612586
7022.997773
7018.354601
7055.406891
7042.399669
7081.905663
7049.251214
7039.066735
7032.939744
7055.067898
7057.978535
7044.19797
7002.642344
7024.194098
7072.305512
7055.455065
7036.575516
7048.512304
7066.746975
7049.32925
7036.586345
7032.575691
7063.601576
7042.367407
7053.843903
7062.771586
7070.387594
7030.745807
7029.830184
7085.857769
7075.222322
7075.117772
7063.834798
7089.799242
7093.267597
7080.444273
7110.554788
7080.250098
7063.287681
7088.057233
7112.052615
7091.510819
7104.192358
7134.187645
7113.931403
7138.093447
7115.461731
7133.277519
7105.833181
7121.530322
7133.550771
7143.669341
7133.253489
7146.669453
7158.216083
7138.372352
7133.443872
7156.080785
7153.183239
7116.432835
7133.398234
7147.262172
7171.150112
7126.425361
7153.41064
7186.124511
7162.75192
7154.555197
7123.357257
7120.500115
7138.464535
7115.309288
7103.849686
7136.749222
7144.50376
7120.781651
7135.901339
7139.328383
7135.27197
7123.516233
7134.598274
7144.147413
7140.271467
7165.167778
7166.249122
7131.133946
7120.453087
7128.981132
7142.248854
7163.115174
7157.420441
7134.214077
7145.434723
7169.564453
7172.813043
7198.201856
7187.120239
7153.278225
7147.025927
7152.662117
7174.930314
7192.596842
7190.964642
7178.391167
7186.259228
7193.185357
7159.819608
7190.197188
7187.650351
7187.959876
7192.971802
7178.020259
7179.045395
7174.046266
7204.451493
7218.798427
7224.165361
7213.235826
7222.246143
7194.451579
7206.141988
7206.366246
7236.717788
7241.278527
7219.347429
7222.589931
7199.510883
7225.188855
7228.103772
7201.273767
7219.871075
7239.274766
7264.38384
7211.452184
7226.449018
7262.240831
7235.663844
7246.01075
7251.908582
7220.942816
7247.299198
7254.590738
7223.024865
7256.743223
7284.705321
7262.222864
7269.843187
7271.126786
7235.786585
7259.150751
7260.488611
7273.309515
7289.974793
7271.651782
7256.142627
7264.281944
7275.184467
7258.416008
7274.562551
7268.209144
7325.120076
7324.629891
7299.630597
7303.859806
7290.860512
7293.480394
7273.799979
7277.699417
7304.343634
7288.338808
7275.011878
7266.358082
7285.863965
7308.287411
7325.078068
7331.707514
7294.089997
7283.883481
7292.254512
7336.509026
7323.113416
7333.361619
7354.053705
7331.775592
7326.415788
7333.059196
7332.843892
7334.531959
7321.273924
7352.842941
7340.59733
7328.604932
7361.43723
7338.730902
7314.340765
7329.520934
7339.529847
7338.059584
7347.852833
7340.31613
7366.768318
7362.682278
7414.011624
7359.426829
7369.325918
7382.795093
7378.699165
7415.850532
7393.199612
7374.377191
7393.13133
7382.563631
7373.225457
7393.266793
7363.953261
7381.431477
7359.4487
7377.006018
7387.967509
7379.073474
7398.132363
7384.058543
7368.659501
7378.29838
7417.544933
7386.391748
7375.825681
7414.45412
7389.532456
7420.816142
7423.902509
7419.359514
7396.900925
7399.443486
7363.478289
7380.909664
7395.225705
7392.27508
7386.41082
7384.389353
7401.995117
7403.348195
7407.513424
7386.181236
7395.750827
7414.037084
7401.324921
7397.182885
7401.858687
7433.684321
7430.215548
7421.954908
7436.957248
7431.143908
7415.758453
7410.757061
7455.216634
7454.40118
7437.631736
7410.424184
7447.954333
7445.459792
7450.015426
7411.713815
7428.0472
7414.83977
7435.093201
7457.33005
7480.434375
7479.253705
7458.897327
7462.011221
7453.933414
7449.361206
7443.096666
7467.052389
7488.160055
7481.597604
7492.47162
7473.544248
7462.980212
7468.612378
7497.163543
7495.909068
7473.783948
7483.534789
7493.844446
7468.008206
7472.983145
7474.63779
7490.008739
7514.637728
7487.125122
7468.528645
7469.963299
7460.499339
7475.540326
7479.153933
7494.908768
7477.288938
7468.738985
7467.000018
7518.330123
7495.877214
7488.435636
7536.248788
7552.224191
7518.761246
7509.311437
7505.647866
7492.600635
7500.666979
7493.973832
7541.805849
7533.198088
7544.465142
7518.770497
7484.779614
7550.12963
7533.969945
7535.735703
7549.744003
7501.636698
7535.996415
7542.515748
7536.917124
7575.386895
7528.322822
7520.961102
7552.564268
7545.611239
7587.590249
7562.546577
7538.109107
7572.899655
7573.009536
7580.356954
7588.191383
7562.389725
7562.97292
7584.100027
7583.63928
7589.039436
7571.325078
7569.73036
7554.364579
7624.924016
7615.866562
7583.262585
7580.871959
7592.435733
7577.176367
7623.467545
7602.575858
7605.574465
7615.29814
7616.795223
7594.089923
7591.2513
7590.46279
7613.518331
7600.478984
7613.620662
7618.832885
7621.563306
7621.081692
7612.636261
7620.357429
7650.157659
7627.090257
7586.969795
7593.515067
7631.23306
7641.685262
7619.433403
7641.429017
7639.84311
7632.755912
7646.51652
7654.13269
7626.443958
7648.783996
7643.262951
7644.358432
7648.550514
7642.739991
7665.852372
7644.591913
7660.395779
7699.95636
7667.9262
7668.434576
7637.496336
7658.650892
7665.701183
7659.075293
7680.625722
7684.704344
7695.017736
7701.145435
7659.164324
7698.443715
7726.714738
7710.008829
7696.375888
7690.992942
7685.512169
7718.091621
7722.272241
7737.264544
7727.909175
7741.388887
7724.400766
7720.340761
7745.642879
7718.16853
7720.91386
7721.268638
7750.849685
7773.144706
7752.618397
7728.447605
7772.749279
7754.698602
7773.506734
7763.006551
7768.329966
7763.476128
7766.490401
7786.580472
7781.749629
7796.80757
7817.871439
7821.344983
7779.932344
7792.465698
7795.861753
7794.120196
7818.97903
7831.145429
7817.680174
7842.633102
7828.462938
7849.704226
7843.992419
7868.203227
7847.761995
7852.083615
7872.485009
7870.207528
7852.636022
7871.910309
7844.12814
7877.020375
7881.291588
7884.185413
7834.944271
7844.686612
7879.863004
7905.822846
7898.564861
7889.670048
7876.859791
7903.167922
7943.775221
7929.291827
7927.037863
7907.848927
7915.470276
7929.73563
7961.389873
7940.964417
7947.108399
7944.964138
7975.387482
7950.854097
7983.94714
7957.492966
7993.232446
7971.31949
7959.565192
7985.537276
7973.339427
7982.11118
7985.933717
7997.815227
8015.188582
8047.565043
8033.741963
8008.07267
8046.622181
8032.308983
8015.527634
8051.438075
8033.348586
8018.069383
8045.171178
8038.172522
8004.777873
8011.107529
8004.728631
8067.792275
8021.306689
8045.841697
8050.851458
8026.369684
8021.04717
8053.142904
8039.565715
8050.641749
8048.196801
8084.224705
8097.956193
8054.747948
8071.16744
8091.938484
8079.544891
8098.837036
8064.651981
8051.176001
8081.494424
8112.904346
8095.16102
8112.393478
8150.910376
8123.72305
8161.646042
8142.784865
8130.624379
8186.445943
8194.120189
8185.48949
8138.190526
8174.156027
8165.375441
8183.84392
8178.366769
8169.220255
8196.183105
8173.809745
8210.764161
8156.419854
8190.499016
8197.428369
8150.900447
8181.889838
8169.576314
8151.210438
8141.549198
8177.034441
8156.519911
8175.39615
8199.025414
8178.928888
8175.026332
8195.381719
8187.867209
8171.753469
8186.665994
8198.718245
8207.759753
8200.125276
8224.380201
8262.110145
8240.539947
8249.201096
8232.228048
8266.505677
8241.851985
8235.430224
8230.60452
8225.663353
8190.459314
8178.742843
8177.62802
8161.896863
8152.579398
8164.934604
8141.115597
8139.519861
8115.145978
8098.154864
8085.18725
8049.236614
8041.153037
8003.813529
8029.267392
8049.158329
7981.944228
8034.132814
8004.074767
8010.480733
8036.124109
8009.227
8000.955043
7973.38848
7957.539237
7961.784294
7929.805479
7922.092741
7921.694522
7930.953577
7943.677146
7926.340986
7937.195906
7909.372747
7925.274504
7933.484653
7907.143272
7917.902914
7871.003604
7891.837241
7886.080603
7911.601879
7923.551605
7927.743359
7943.364831
7948.958272
7893.704538
7918.461755
7906.740156
7910.378786
7905.52863
7893.150365
7870.231367
7854.955254
7865.107997
7884.787264
7881.106508
7895.683092
7914.532548
7952.43714
7984.207366
8040.145699
8139.76086
8163.949162
8237.377708
8265.686714
8242.726741
8236.174721
8214.246717
8158.109081
8141.878902
8088.30496
8018.928242
8020.076176
8060.697141
8045.46153
8000.516653
8015.596287
8086.77592
8151.480036
8277.758639
8402.363741
8541.521051
8707.028512
8890.346024
9020.307794
9084.778608
9110.594645
9055.912423
8973.74444
8972.450206
9046.534499
9111.237249
9237.980639
9383.961129
9559.725564
9710.347398
9766.316147
9750.366105
9634.982124
9322.065574
9076.97827
8783.100704
8498.593893
8238.325397
7955.664374
7796.698871
7659.949567
7516.955611
7433.095658
7370.215687
7340.496983
7296.66597
7272.30254
7244.313068
7292.268737
7368.381929
7497.651503
7665.737226
7842.862144
8078.574767
8224.06322
8374.88087
8413.230556
8436.507797
8405.469289
8333.735168
8326.427455
8332.484968
8480.054654
8623.291965
8772.497868
8917.660833
8983.082007
8956.087207
8767.943724
8426.498464
7995.719748
7526.313171
7040.202901
6629.783272
6329.948232
6096.765204
5936.018939
5828.750469
5756.633354
5702.806978
5673.648788
5660.129415
5676.692832
5638.844481
5629.492301
5604.555162
5627.745147
5620.026111
5620.554075
5616.264344
5661.371357
5668.390305
5648.083086
5695.534459
5654.209424
5671.18427
5649.993938
5674.476515
5623.905015
5642.646395
5646.642193
5630.701415
5643.597128
5627.997893
5593.454725
5602.238941
5563.116867
5562.484182
5541.717675
5504.588598
5464.587102
5457.349998
5465.028786
5442.695733
5455.699991
5447.155125
5474.420489
5472.269207
5499.577394
5500.423949
5515.469594
5559.232942
5560.760696
5598.415202
5660.688759
5711.361498
5700.374459
5716.066807
5788.942042
5816.610473
5840.74202
5876.500863
5901.680327
5938.452439
5953.862805
5967.207501
5938.163306
5966.110521
6006.75093
6039.581683
6085.482257
6159.812789
6304.156316
6448.371805
6670.412418
6985.973805
7338.511467
7854.954665
8496.940436
9340.29665
10468.148452
11928.591294
13878.028263
16391.821076
19715.998228
23726.821837
28562.874643
33972.531545
39214.262238
42902.62925
43669.695429
40627.417293
34792.640318
27642.946203
21185.649574
16166.574659
12655.595278
10273.190449
8782.497939
7784.382499
7147.760588
6684.576736
6404.205417
6153.778105
5961.608188
5855.328512
5768.463595
5807.619768
5807.696029
5931.275832
6077.023716
6311.785601
6648.592261
7089.073351
7684.657207
8538.221533
9661.240385
11131.014473
13090.167675
15748.949358
19091.620209
23512.132239
29140.579532
35625.260116
42748.343384
49240.288351
53623.944068
53502.693141
48478.77444
39927.748184
30541.366684
22221.93365
16169.565242
11972.140391
9205.218796
7415.645936
6283.231189
5480.084631
4956.642179
4562.04977
4301.401404
4086.053081
3900.337367
3775.367217
3643.778161
3535.09871
3484.706199
3394.807905
3342.261545
3279.901988
3234.560837
3179.730455
3138.627813
3121.349302
3066.65128
3037.401768
3023.966381
2996.695399
2956.190103
2944.401474
2936.02187
2906.603729
2895.94508
2886.675532
2878.426245
2872.494482
2855.956819
2841.598998
2836.964486
2835.712225
2806.526612
2807.169796
2808.645242
2795.181841
2797.393298
2785.886097
2776.034438
2770.566191
2760.045175
2764.394959
2768.189429
2773.110814
2765.21688
2764.653174
2767.511778
2763.194096
2780.929295
2786.679997
2767.35241
2767.36038
2765.634205
2769.387267
2771.751237
2760.204067
2774.990947
2772.802745
2769.717208
2776.406761
2776.198486
2782.070686
2796.004587
2797.56454
2798.951176
2806.055376
2807.529442
2818.509112
2816.947368
2824.719567
2826.169941
2832.422685
2843.682288
2839.025603
2857.433234
2847.201231
2863.011448
2886.883519
2882.524569
2863.909423
1
loss_function
LossFunction
2002
2020
09
13
35
37
0
10
Casa Info Follows
0
0
0
0
none
Group: none
Analyzer Lens: none
Analyzer Slit: none
Scan Mode: none
XPS
0
Al
1486.61
0
0
0
56.5
180
FAT
0
1
0
0
0
0
0
0
loss_function

-1
kinetic energy
eV
0.0
0.1
2
counts
d
Transmission
d
pulse counting
1
1
0
0
0
0
2
ESCAPE DEPTH TYPE
d
0
MFP Exponent
d
0
0.0
0.0
0.0
0.0
0.0
0.0
0.0
0.0
0.0
0.0
2e-06
1.1e-05
5.1e-05
0.000192
0.000564
0.001287
0.002287
0.003165
0.003412
0.002864
0.001873
0.000956
0.000395
0.000211
0.001821
0.1611
0.061658
0.055438
0.079366
0.017423
0.043717
0.045208
0.05299
0.023115
0.029165
0.031901
0.02914
0.025037
0.0231
0.023027
0.023434
0.023755
0.023941
0.023999
0.023872
0.023492
0.022846
0.021995
0.021052
0.02013
0.019315
0.018647
0.018122
0.017708
0.017364
0.017049
0.016731
0.016392
0.016024
0.015624
0.015197
0.01475
0.014289
0.013822
0.013354
0.012892
0.012439
0.012
0.011575
0.011167
0.010778
0.010406
0.010053
0.009718
0.0094
0.0091
0.008815
0.008546
0.008291
0.00805
0.007822
0.007606
0.007401
0.007207
0.007022
0.006847
0.00668
0.006521
0.00637
0.006225
0.006087
0.005955
0.005829
0.005708
0.005592
0.00548
0.005373
0.005271
0.005172
0.005076
0.004984
0.004896
0.00481
0.004728
0.004648
0.00457
0.004495
0.004423
0.004353
0.004284
0.004218
0.004154
0.004091
0.00403
0.003971
0.003914
0.003858
0.003803
0.00375
0.003698
0.003647
0.003598
0.00355
0.003503
0.003457
0.003412
0.003368
0.003325
0.003283
0.003241
0.003201
0.003161
0.003123
0.003085
0.003048
0.003011
0.002976
0.002941
0.002906
0.002872
0.002839
0.002807
0.002775
0.002744
0.002713
0.002683
0.002653
0.002624
0.002595
0.002567
0.002539
0.002512
0.002485
0.002458
0.002432
0.002407
0.002381
0.002357
0.002332
0.002308
0.002284
0.002261
0.002238
0.002215
0.002193
0.002171
0.002149
0.002128
0.002107
0.002086
0.002066
0.002045
0.002026
0.002006
0.001987
0.001967
0.001949
0.00193
0.001912
0.001894
0.001876
0.001858
0.001841
0.001824
0.001807
0.00179
0.001773
0.001757
0.001741
0.001725
0.001709
0.001694
0.001678
0.001663
0.001648
0.001634
0.001619
0.001605
0.00159
0.001576
0.001562
0.001549
0.001535
0.001522
0.001508
0.001495
0.001482
0.001469
0.001457
0.001444
0.001432
0.00142
0.001407
0.001395
0.001384
0.001372
0.00136
0.001349
0.001338
0.001326
0.001315
0.001304
0.001293
0.001283
0.001272
0.001262
0.001251
0.001241
0.001231
0.001221
0.001211
0.001201
0.001191
0.001182
0.001172
0.001163
0.001153
0.001144
0.001135
0.001126
0.001117
0.001108
0.001099
0.001091
0.001082
0.001074
0.001065
0.001057
0.001049
0.00104
0.001032
0.001024
0.001016
0.001008
0.001001
0.000993
0.000985
0.000978
0.00097
0.000963
0.000956
0.000948
0.000941
0.000934
0.000927
0.00092
0.000913
0.000906
0.000899
0.000893
0.000886
0.000879
0.000873
0.000866
0.00086
0.000854
0.000847
0.000841
0.000835
0.000829
0.000823
0.000817
0.000811
0.000805
0.000799
0.000793
0.000788
0.000782
0.000776
0.000771
0.000765
0.00076
0.000754
0.000749
0.000744
0.000738
0.000733
0.000728
0.000723
0.000718
0.000713
0.000708
0.000703
0.000698
0.000693
0.000688
0.000683
0.000679
0.000674
0.000669
0.000665
0.00066
0.000655
0.000651
0.000646
0.000642
0.000638
0.000633
0.000629
0.000625
0.00062
0.000616
0.000612
0.000608
0.000604
0.0006
0.000596
0.000592
0.000588
0.000584
0.00058
0.000576
0.000572
0.000569
0.000565
0.000561
0.000557
0.000554
0.00055
0.000547
0.000543
0.000539
0.000536
0.000532
0.000529
0.000525
0.000522
0.000519
0.000515
0.000512
0.000509
0.000505
0.000502
0.000499
0.000496
0.000493
0.00049
0.000486
0.000483
0.00048
0.000477
0.000474
0.000471
0.000468
0.000465
0.000462
0.00046
0.000457
0.000454
0.000451
0.000448
0.000445
0.000443
0.00044
0.000437
0.000434
0.000432
0.000429
0.000427
0.000424
0.000421
0.000419
0.000416
0.000414
0.000411
0.000409
0.000406
0.000404
0.000401
0.000399
0.000396
0.000394
0.000392
0.000389
0.000387
0.000385
0.000382
0.00038
0.000378
0.000376
0.000373
0.000371
0.000369
0.000367
0.000365
0.000363
0.00036
0.000358
0.000356
0.000354
0.000352
0.00035
0.000348
0.000346
0.000344
0.000342
0.00034
0.000338
0.000336
0.000334
0.000332
0.00033
0.000329
0.000327
0.000325
0.000323
0.000321
0.000319
0.000317
0.000316
0.000314
0.000312
0.00031
0.000309
0.000307
0.000305
0.000303
0.000302
0.0003
0.000298
0.000297
0.000295
0.000293
0.000292
0.00029
0.000289
0.000287
0.000285
0.000284
0.000282
0.000281
0.000279
0.000278
0.000276
0.000275
0.000273
0.000272
0.00027
0.000269
0.000267
0.000266
0.000265
0.000263
0.000262
0.00026
0.000259
0.000258
0.000256
0.000255
0.000253
0.000252
0.000251
0.000249
0.000248
0.000247
0.000245
0.000244
0.000243
0.000242
0.00024
0.000239
0.000238
0.000237
0.000235
0.000234
0.000233
0.000232
0.000231
0.000229
0.000228
0.000227
0.000226
0.000225
0.000224
0.000222
0.000221
0.00022
0.000219
0.000218
0.000217
0.000216
0.000215
0.000213
0.000212
0.000211
0.00021
0.000209
0.000208
0.000207
0.000206
0.000205
0.000204
0.000203
0.000202
0.000201
0.0002
0.000199
0.000198
0.000197
0.000196
0.000195
0.000194
0.000193
0.000192
0.000191
0.00019
0.000189
0.000188
0.000188
0.000187
0.000186
0.000185
0.000184
0.000183
0.000182
0.000181
0.00018
0.00018
0.000179
0.000178
0.000177
0.000176
0.000175
0.000174
0.000174
0.000173
0.000172
0.000171
0.00017
0.00017
0.000169
0.000168
0.000167
0.000166
0.000166
0.000165
0.000164
0.000163
0.000162
0.000162
0.000161
0.00016
0.000159
0.000159
0.000158
0.000157
0.000157
0.000156
0.000155
0.000154
0.000154
0.000153
0.000152
0.000152
0.000151
0.00015
0.000149
0.000149
0.000148
0.000147
0.000147
0.000146
0.000145
0.000145
0.000144
0.000143
0.000143
0.000142
0.000142
0.000141
0.00014
0.00014
0.000139
0.000138
0.000138
0.000137
0.000137
0.000136
0.000135
0.000135
0.000134
0.000134
0.000133
0.000132
0.000132
0.000131
0.000131
0.00013
0.00013
0.000129
0.000128
0.000128
0.000127
0.000127
0.000126
0.000126
0.000125
0.000125
0.000124
0.000123
0.000123
0.000122
0.000122
0.000121
0.000121
0.00012
0.00012
0.000119
0.000119
0.000118
0.000118
0.000117
0.000117
0.000116
0.000116
0.000115
0.000115
0.000114
0.000114
0.000113
0.000113
0.000112
0.000112
0.000111
0.000111
0.000111
0.00011
0.00011
0.000109
0.000109
0.000108
0.000108
0.000107
0.000107
0.000106
0.000106
0.000106
0.000105
0.000105
0.000104
0.000104
0.000103
0.000103
0.000103
0.000102
0.000102
0.000101
0.000101
0.000101
0.0001
0.0001
9.9e-05
9.9e-05
9.9e-05
9.8e-05
9.8e-05
9.7e-05
9.7e-05
9.7e-05
9.6e-05
9.6e-05
9.5e-05
9.5e-05
9.5e-05
9.4e-05
9.4e-05
9.4e-05
9.3e-05
9.3e-05
9.2e-05
9.2e-05
9.2e-05
9.1e-05
9.1e-05
9.1e-05
9e-05
9e-05
9e-05
8.9e-05
8.9e-05
8.9e-05
8.8e-05
8.8e-05
8.7e-05
8.7e-05
8.7e-05
8.6e-05
8.6e-05
8.6e-05
8.5e-05
8.5e-05
8.5e-05
8.4e-05
8.4e-05
8.4e-05
8.4e-05
8.3e-05
8.3e-05
8.3e-05
8.2e-05
8.2e-05
8.2e-05
8.1e-05
8.1e-05
8.1e-05
8e-05
8e-05
8e-05
7.9e-05
7.9e-05
7.9e-05
7.9e-05
7.8e-05
7.8e-05
7.8e-05
7.7e-05
7.7e-05
7.7e-05
7.7e-05
7.6e-05
7.6e-05
7.6e-05
7.5e-05
7.5e-05
7.5e-05
7.5e-05
7.4e-05
7.4e-05
7.4e-05
7.3e-05
7.3e-05
7.3e-05
7.3e-05
7.2e-05
7.2e-05
7.2e-05
7.2e-05
7.1e-05
7.1e-05
7.1e-05
7.1e-05
7e-05
7e-05
7e-05
7e-05
6.9e-05
6.9e-05
6.9e-05
6.9e-05
6.8e-05
6.8e-05
6.8e-05
6.8e-05
6.7e-05
6.7e-05
6.7e-05
6.7e-05
6.6e-05
6.6e-05
6.6e-05
6.6e-05
6.5e-05
6.5e-05
6.5e-05
6.5e-05
6.5e-05
6.4e-05
6.4e-05
6.4e-05
6.4e-05
6.3e-05
6.3e-05
6.3e-05
6.3e-05
6.2e-05
6.2e-05
6.2e-05
6.2e-05
6.2e-05
6.1e-05
6.1e-05
6.1e-05
6.1e-05
6.1e-05
6e-05
6e-05
6e-05
6e-05
6e-05
5.9e-05
5.9e-05
5.9e-05
5.9e-05
5.8e-05
5.8e-05
5.8e-05
5.8e-05
5.8e-05
5.7e-05
5.7e-05
5.7e-05
5.7e-05
5.7e-05
5.7e-05
5.6e-05
5.6e-05
5.6e-05
5.6e-05
5.6e-05
5.5e-05
5.5e-05
5.5e-05
5.5e-05
5.5e-05
5.4e-05
5.4e-05
5.4e-05
5.4e-05
5.4e-05
5.4e-05
5.3e-05
5.3e-05
5.3e-05
5.3e-05
5.3e-05
5.2e-05
5.2e-05
5.2e-05
5.2e-05
5.2e-05
5.2e-05
5.1e-05
5.1e-05
5.1e-05
5.1e-05
5.1e-05
5.1e-05
5e-05
5e-05
5e-05
5e-05
5e-05
5e-05
4.9e-05
4.9e-05
4.9e-05
4.9e-05
4.9e-05
4.9e-05
4.9e-05
4.8e-05
4.8e-05
4.8e-05
4.8e-05
4.8e-05
4.8e-05
4.7e-05
4.7e-05
4.7e-05
4.7e-05
4.7e-05
4.7e-05
4.7e-05
4.6e-05
4.6e-05
4.6e-05
4.6e-05
4.6e-05
4.6e-05
4.5e-05
4.5e-05
4.5e-05
4.5e-05
4.5e-05
4.5e-05
4.5e-05
4.4e-05
4.4e-05
4.4e-05
4.4e-05
4.4e-05
4.4e-05
4.4e-05
4.4e-05
4.3e-05
4.3e-05
4.3e-05
4.3e-05
4.3e-05
4.3e-05
4.3e-05
4.2e-05
4.2e-05
4.2e-05
4.2e-05
4.2e-05
4.2e-05
4.2e-05
4.2e-05
4.1e-05
4.1e-05
4.1e-05
4.1e-05
4.1e-05
4.1e-05
4.1e-05
4.1e-05
4e-05
4e-05
4e-05
4e-05
4e-05
4e-05
4e-05
4e-05
3.9e-05
3.9e-05
3.9e-05
3.9e-05
3.9e-05
3.9e-05
3.9e-05
3.9e-05
3.8e-05
3.8e-05
3.8e-05
3.8e-05
3.8e-05
3.8e-05
3.8e-05
3.8e-05
3.8e-05
3.7e-05
3.7e-05
3.7e-05
3.7e-05
3.7e-05
3.7e-05
3.7e-05
3.7e-05
3.7e-05
3.6e-05
3.6e-05
3.6e-05
3.6e-05
3.6e-05
3.6e-05
3.6e-05
3.6e-05
3.6e-05
3.6e-05
3.5e-05
3.5e-05
3.5e-05
3.5e-05
3.5e-05
3.5e-05
3.5e-05
3.5e-05
3.5e-05
3.4e-05
3.4e-05
3.4e-05
3.4e-05
3.4e-05
3.4e-05
3.4e-05
3.4e-05
3.4e-05
3.4e-05
3.4e-05
3.3e-05
3.3e-05
3.3e-05
3.3e-05
3.3e-05
3.3e-05
3.3e-05
3.3e-05
3.3e-05
3.3e-05
3.2e-05
3.2e-05
3.2e-05
3.2e-05
3.2e-05
3.2e-05
3.2e-05
3.2e-05
3.2e-05
3.2e-05
3.2e-05
3.1e-05
3.1e-05
3.1e-05
3.1e-05
3.1e-05
3.1e-05
3.1e-05
3.1e-05
3.1e-05
3.1e-05
3.1e-05
3.1e-05
3e-05
3e-05
3e-05
3e-05
3e-05
3e-05
3e-05
3e-05
3e-05
3e-05
3e-05
2.9e-05
2.9e-05
2.9e-05
2.9e-05
2.9e-05
2.9e-05
2.9e-05
2.9e-05
2.9e-05
2.9e-05
2.9e-05
2.9e-05
2.9e-05
2.8e-05
2.8e-05
2.8e-05
2.8e-05
2.8e-05
2.8e-05
2.8e-05
2.8e-05
2.8e-05
2.8e-05
2.8e-05
2.8e-05
2.8e-05
2.7e-05
2.7e-05
2.7e-05
2.7e-05
2.7e-05
2.7e-05
2.7e-05
2.7e-05
2.7e-05
2.7e-05
2.7e-05
2.7e-05
2.7e-05
2.7e-05
2.6e-05
2.6e-05
2.6e-05
2.6e-05
2.6e-05
2.6e-05
2.6e-05
2.6e-05
2.6e-05
2.6e-05
2.6e-05
2.6e-05
2.6e-05
2.6e-05
2.5e-05
2.5e-05
2.5e-05
2.5e-05
2.5e-05
2.5e-05
2.5e-05
2.5e-05
2.5e-05
2.5e-05
2.5e-05
2.5e-05
2.5e-05
2.5e-05
2.5e-05
2.5e-05
2.4e-05
2.4e-05
2.4e-05
2.4e-05
2.4e-05
2.4e-05
2.4e-05
2.4e-05
2.4e-05
2.4e-05
2.4e-05
2.4e-05
2.4e-05
2.4e-05
2.4e-05
2.4e-05
2.3e-05
2.3e-05
2.3e-05
2.3e-05
2.3e-05
2.3e-05
2.3e-05
2.3e-05
2.3e-05
2.3e-05
2.3e-05
2.3e-05
2.3e-05
2.3e-05
2.3e-05
2.3e-05
2.3e-05
2.2e-05
2.2e-05
2.2e-05
2.2e-05
2.2e-05
2.2e-05
2.2e-05
2.2e-05
2.2e-05
2.2e-05
2.2e-05
2.2e-05
2.2e-05
2.2e-05
2.2e-05
2.2e-05
2.2e-05
2.2e-05
2.1e-05
2.1e-05
2.1e-05
2.1e-05
2.1e-05
2.1e-05
2.1e-05
2.1e-05
2.1e-05
2.1e-05
2.1e-05
2.1e-05
2.1e-05
2.1e-05
2.1e-05
2.1e-05
2.1e-05
2.1e-05
2.1e-05
2e-05
2e-05
2e-05
2e-05
2e-05
2e-05
2e-05
2e-05
2e-05
2e-05
2e-05
2e-05
2e-05
2e-05
2e-05
2e-05
2e-05
2e-05
2e-05
2e-05
1.9e-05
1.9e-05
1.9e-05
1.9e-05
1.9e-05
1.9e-05
1.9e-05
1.9e-05
1.9e-05
1.9e-05
1.9e-05
1.9e-05
1.9e-05
1.9e-05
1.9e-05
1.9e-05
1.9e-05
1.9e-05
1.9e-05
1.9e-05
1.9e-05
1.9e-05
1.8e-05
1.8e-05
1.8e-05
1.8e-05
1.8e-05
1.8e-05
1.8e-05
1.8e-05
1.8e-05
1.8e-05
1.8e-05
1.8e-05
1.8e-05
1.8e-05
1.8e-05
1.8e-05
1.8e-05
1.8e-05
1.8e-05
1.8e-05
1.8e-05
1.8e-05
1.8e-05
1.8e-05
1.7e-05
1.7e-05
1.7e-05
1.7e-05
1.7e-05
1.7e-05
1.7e-05
1.7e-05
1.7e-05
1.7e-05
1.7e-05
1.7e-05
1.7e-05
1.7e-05
1.7e-05
1.7e-05
1.7e-05
1.7e-05
1.7e-05
1.7e-05
1.7e-05
1.7e-05
1.7e-05
1.7e-05
1.7e-05
1.6e-05
1.6e-05
1.6e-05
1.6e-05
1.6e-05
1.6e-05
1.6e-05
1.6e-05
1.6e-05
1.6e-05
1.6e-05
1.6e-05
1.6e-05
1.6e-05
1.6e-05
1.6e-05
1.6e-05
1.6e-05
1.6e-05
1.6e-05
1.6e-05
1.6e-05
1.6e-05
1.6e-05
1.6e-05
1.6e-05
1.6e-05
1.5e-05
1.5e-05
1.5e-05
1.5e-05
1.5e-05
1.5e-05
1.5e-05
1.5e-05
1.5e-05
1.5e-05
1.5e-05
1.5e-05
1.5e-05
1.5e-05
1.5e-05
1.5e-05
1.5e-05
1.5e-05
1.5e-05
1.5e-05
1.5e-05
1.5e-05
1.5e-05
1.5e-05
1.5e-05
1.5e-05
1.5e-05
1.5e-05
1.5e-05
1.5e-05
1.4e-05
1.4e-05
1.4e-05
1.4e-05
1.4e-05
1.4e-05
1.4e-05
1.4e-05
1.4e-05
1.4e-05
1.4e-05
1.4e-05
1.4e-05
1.4e-05
1.4e-05
1.4e-05
1.4e-05
1.4e-05
1.4e-05
1.4e-05
1.4e-05
1.4e-05
1.4e-05
1.4e-05
1.4e-05
1.4e-05
1.4e-05
1.4e-05
1.4e-05
1.4e-05
1.4e-05
1.4e-05
1.4e-05
1.3e-05
1.3e-05
1.3e-05
1.3e-05
1.3e-05
1.3e-05
1.3e-05
1.3e-05
1.3e-05
1.3e-05
1.3e-05
1.3e-05
1.3e-05
1.3e-05
1.3e-05
1.3e-05
1.3e-05
1.3e-05
1.3e-05
1.3e-05
1.3e-05
1.3e-05
1.3e-05
1.3e-05
1.3e-05
1.3e-05
1.3e-05
1.3e-05
1.3e-05
1.3e-05
1.3e-05
1.3e-05
1.3e-05
1.3e-05
1.3e-05
1.3e-05
1.2e-05
1.2e-05
1.2e-05
1.2e-05
1.2e-05
1.2e-05
1.2e-05
1.2e-05
1
end of experiment