File: .vms
VAMAS Surface Chemical Analysis Standard Data Transfer Format 1988 May 4
Not Specified
Not Specified
Not Specified
Not Specified
2
Casa Info Follows CasaXPS Version 2.3.22PR1.0
0
NORM
REGULAR
0
1
Exp Variable
d
0
0
0
0
1
loss_function
LossFunction
2025
2020
08
14
15
01
0
10
Casa Info Follows
0
0
0
0
none
Group: none
Analyzer Lens: none
Analyzer Slit: none
Scan Mode: none
XPS
0
Al
1486.61
0
0
0
56.5
180
FAT
0
1
0
0
0
0
0
0
loss_function

-1
kinetic energy
eV
0.0
0.1
2
counts
d
Transmission
d
pulse counting
1
1
0
0
0
0
2
ESCAPE DEPTH TYPE
d
0
MFP Exponent
d
0
1
0.0
1
0.0
1
0.0
1
0.0
1
0.0
1
0.0
1
0.0
1
0.0
1
0.0
1
0.0
1
0.0
1
0.0
1
0.0
1
0.0
1
0.0
1
0.0
1
0.0
1
0.0
1
0.0
1
0.0
1
0.0
1
0.0
1
0.0
1
0.0
1
0.0
1
0.0
1
0.0
1
0.0
1
0.0
1
0.0
1
0.0
1
0.0
1
0.0
1
0.0
1
0.0
1
0.0
1
0.0
1
0.0
1
0.0
1
0.0
1
0.0
1
0.0
1
0.0
1
0.0
1
0.0
1
0.0
1
0.0
1
0.0
1
0.0
1
0.0
1
0.0
1
0.0
1
0.0
1
0.0
1
0.0
1
0.0
1
0.0
1
0.0
1
0.0
1
0.0
1
0.0
1
0.0
1
0.0
1
0.0
1
0.0
1
0.0
1
0.0
1
0.0
1
0.0
1
0.0
1
0.0
1
0.0
1
0.0
1
0.0
1
0.0
1
0.0
1
0.0
1
0.0
1
0.0
1
0.0
1
0.0
1
0.0
1
0.0
1
0.0
1
0.0
1
0.0
1
0.0
1
0.0
1
0.0
1
0.0
1
0.0
1
0.0
1
0.0
1
0.0
1
0.0
1
0.0
1
0.0
1
0.0
1
0.0
1
0.0
1
0.0
1
0.0
1
0.0
1
0.0
1
0.0
1
0.0
1
0.0
1
0.0
1
0.0
1
0.0
1
0.0
1
0.0
1
0.0
1
0.0
1
0.0
1
0.0
1
0.0
1
0.0
1
0.0
1
0.0
1
0.0
1
0.0
1
0.0
1
0.0
1
0.0
1
0.0
1
0.0
1
0.0
1
0.0
1
0.0
1
0.0
1
0.0
1
0.0
1
0.0
1
0.0
1
0.0
1
0.0
1
0.0
1
0.0
1
0.0
1
0.0
1
0.0
1
0.0
1
0.0
1
0.0
1
0.0
1
0.0
1
0.0
1
0.0
1
0.0
1
0.0
1
0.0
1
0.0
1
0.0
1
0.0
1
0.0
1
0.0
1
0.0
1
0.0
1
0.0
1
0.0
1
0.0
1
0.0
1
0.0
1
0.0
1
0.0
1
0.0
1
0.0
1
0.0
1
0.0
1
0.0
1
0.0
1
0.0
1
0.0
1
0.0
1
0.0
1
0.0
1
0.0
1
0.0
1
0.0
1
0.0
1
0.0
1
0.0
1
0.0
1
0.0
1
0.0
1
0.0
1
0.0
1
0.0
1
0.0
1
0.0
1
0.0
1
0.0
1
0.0
1
0.0
1
0.0
1
0.0
1
0.0
1
0.0
1
0.0
1
0.0
1
0.0
1
0.0
1
0.0
1
0.0
1
0.0
1
0.0
1
0.0
1
0.0
1
0.0
1
0.0
1
0.0
1
0.0
1
0.0
1
0.0
1
0.0
1
0.0
1
0.0
1
0.0
1
0.0
1
0.0
1
0.0
1
0.0
1
0.0
1
0.0
1
0.0
1
0.0
1
0.0
1
0.0
1
0.0
1
0.0
1
0.0
1
0.0
1
0.0
1
0.0
1
0.0
1
0.0
1
0.0
1
0.0
1
0.0
1
0.0
1
0.0
1
0.0
1
0.0
1
0.0
1
0.0
1
0.0
1
0.0
1
0.0
1
0.0
1
0.0
1
0.0
1
0.0
1
0.0
1
0.0
1
0.0
1
0.0
1
0.0
1
0.0
1
0.0
1
0.0
1
0.0
1
0.0
1
0.0
1
0.0
1
0.0
1
0.0
1
0.0
1
0.0
1
0.0
1
0.0
1
0.0
1
0.0
1
0.0
1
0.0
1
0.0
1
0.0
1
0.0
1
0.0
1
0.0
1
0.0
1
0.0
1
0.0
1
0.0
1
0.0
1
0.0
1
0.0
1
0.0
1
0.0
1
0.0
1
0.0
1
0.0
1
0.0
1
0.0
1
0.0
1
0.0
1
0.0
1
0.0
1
0.0
1
0.0
1
0.0
1
0.0
1
0.0
1
0.0
1
0.0
1
0.0
1
0.0
1
0.0
1
0.0
1
0.0
1
0.0
1
0.0
1
0.0
1
0.0
1
0.0
1
0.0
1
0.0
1
0.0
1
0.0
1
0.0
1
0.0
1
0.0
1
0.0
1
0.0
1
0.0
1
0.0
1
0.0
1
0.0
1
0.0
1
0.0
1
0.0
1
0.0
1
0.0
1
0.0
1
0.0
1
0.0
1
0.0
1
0.0
1
0.0
1
0.0
1
0.0
1
0.0
1
0.0
1
0.0
1
0.0
1
0.0
1
0.0
1
0.0
1
0.0
1
0.0
1
0.0
1
0.0
1
0.0
1
0.0
1
0.0
1
0.0
1
0.0
1
0.0
1
0.0
1
0.0
1
0.0
1
0.0
1
0.0
1
0.0
1
0.0
1
0.0
1
0.0
1
0.0
1
0.0
1
0.0
1
0.0
1
0.0
1
0.0
1
0.0
1
0.0
1
0.0
1
0.0
1
0.0
1
0.0
1
0.0
1
0.0
1
0.0
1
0.0
1
0.0
1
0.0
1
0.0
1
0.0
1
0.0
1
0.0
1
0.0
1
0.0
1
0.0
1
0.0
1
0.0
1
0.0
1
0.0
1
0.0
1
0.0
1
0.0
1
0.0
1
0.0
1
0.0
1
0.0
1
0.0
1
0.0
1
0.0
1
0.0
1
0.0
1
0.0
1
0.0
1
0.0
1
0.0
1
0.0
1
0.0
1
0.0
1
0.0
1
0.0
1
0.0
1
0.0
1
0.0
1
0.0
1
0.0
1
0.0
1
0.0
1
0.0
1
0.0
1
0.0
1
0.0
1
0.0
1
0.0
1
0.0
1
0.0
1
0.0
1
0.0
1
0.0
1
0.0
1
0.0
1
0.0
1
0.0
1
0.0
1
0.0
1
0.0
1
0.0
1
0.0
1
0.0
1
0.0
1
0.0
1
0.0
1
0.0
1
0.0
1
0.0
1
0.0
1
0.0
1
0.0
1
0.0
1
0.0
1
0.0
1
0.0
1
0.0
1
0.0
1
0.0
1
0.0
1
0.0
1
0.0
1
0.0
1
0.0
1
0.0
1
0.0
1
0.0
1
0.0
1
0.0
1
0.0
1
0.0
1
0.0
1
0.0
1
0.0
1
0.0
1
0.0
1
0.0
1
0.0
1
0.0
1
0.0
1
0.0
1
0.0
1
0.0
1
0.0
1
0.0
1
0.0
1
0.0
1
0.0
1
0.0
1
0.0
1
0.0
1
0.0
1
0.0
1
0.0
1
0.0
1
0.0
1
0.0
1
0.0
1
0.0
1
0.0
1
0.0
1
0.0
1
0.0
1
0.0
1
0.0
1
0.0
1
0.0
1
0.0
1
0.0
1
0.0
1
0.0
1
0.0
1
0.0
1
0.0
1
0.0
1
0.0
1
0.0
1
0.0
1
0.0
1
0.0
1
0.0
1
0.0
1
0.0
1
0.0
1
0.0
1
0.0
1
0.0
1
0.0
1
0.0
1
0.0
1
0.0
1
0.0
1
0.0
1
0.0
1
0.0
1
0.0
1
0.0
1
0.0
1
0.0
1
0.0
1
0.0
1
0.0
1
0.0
1
0.0
1
0.0
1
0.0
1
0.0
1
0.0
1
0.0
1
0.0
1
0.0
1
0.0
1
0.0
1
0.0
1
0.0
1
0.0
1
0.0
1
0.0
1
0.0
1
0.0
1
0.0
1
0.0
1
0.0
1
0.0
1
0.0
1
0.0
1
0.0
1
0.0
1
0.0
1
0.0
1
0.0
1
0.0
1
0.0
1
0.0
1
0.0
1
0.0
1
0.0
1
0.0
1
0.0
1
0.0
1
0.0
1
0.0
1
0.0
1
0.0
1
0.0
1
0.0
1
0.0
1
0.0
1
0.0
1
0.0
1
0.0
1
0.0
1
0.0
1
0.0
1
0.0
1
0.0
1
0.0
1
0.0
1
0.0
1
0.0
1
0.0
1
0.0
1
0.0
1
0.0
1
0.0
1
0.0
1
0.0
1
0.0
1
0.0
1
0.0
1
0.0
1
0.0
1
0.0
1
0.0
1
0.0
1
0.0
1
0.0
1
0.0
1
0.0
1
0.0
1
0.0
1
0.0
1
0.0
1
0.0
1
0.0
1
0.0
1
0.0
1
0.0
1
0.0
1
0.0
1
0.0
1
0.0
1
0.0
1
0.0
1
0.0
1
0.0
1
0.0
1
0.0
1
0.0
1
0.0
1
0.0
1
0.0
1
0.0
1
0.0
1
0.0
1
0.0
1
0.0
1
0.0
1
0.0
1
0.0
1
0.0
1
0.0
1
0.0
1
0.0
1
0.0
1
0.0
1
0.0
1
0.0
1
0.0
1
0.0
1
0.0
1
0.0
1
0.0
1
0.0
1
0.0
1
0.0
1
0.0
1
0.0
1
0.0
1
0.0
1
0.0
1
0.0
1
0.0
1
0.0
1
0.0
1
0.0
1
0.0
1
0.0
1
0.0
1
0.0
1
0.0
1
0.0
1
0.0
1
0.0
1
0.0
1
0.0
1
0.0
1
0.0
1
0.0
1
0.0
1
0.0
1
0.0
1
0.0
1
0.0
1
0.0
1
0.0
1
0.0
1
0.0
1
0.0
1
0.0
1
0.0
1
0.0
1
0.0
1
0.0
1
end of experiment