File: data/N2/Au, Ag, Cu in N2.vms
VAMAS Surface Chemical Analysis Standard Data Transfer Format 1988 May 4
Not Specified
Not Specified
Not Specified
Not Specified
14
Casa Info Follows CasaXPS Version 2.3.24rev1.0F
0
Created by SpecsLab Prodigy, Version 4.63.4-r87993
SourceAnalyserAngle: 56.500000 d
CasaRowLabel:Ag in 2 mbar N2
CasaRowLabel:Ag in vacuum
CasaRowLabel:Cu in vacuum
CasaRowLabel:Cu in 2mbar N2
CasaRowLabel:Cu in vacuum
CasaRowLabel:Cu in 2mbar N2
CasaRowLabel:Au in 2mbar N2
CasaRowLabel:Au in vacuum
CasaRowLabel:Au in 2mbar N2
CasaRowLabel:Au in vacuum
NORM
REGULAR
12
1
Exp Variable
d
0
0
0
0
32
Survey
Ag in 2 mbar N2
2020
3
10
5
10
21
0
14
Casa Info Follows
0
0
0
0
File = E:/OwnCloud/XPS lab/EX340_CEC356_effect of lens modes.sle
Group = Ag in 2 mbar N2 , #Treatments: , #Temp: RT , #Pressure:2 mbar, #Gas1:N2, #Gas2:, #Gas Ratio:, #Comments:
First of group = 0
Analyzer lens = LargeArea:1.5kV
Analyzer slit = 4:7x20c\C:mesh
Scan mode = FixedAnalyzerTransmission
Kinetic energy start = 286.61
C:\Users\Mark\ownCloud\Muelheim Group\Projects\Gas phase background\EX340_CEC356_effect of lens modes.vms
Sum of 29 spectra in column containing 29 scans
XPS
1
Al
1486.61
0
0
0
54.5
180
FAT
20
1
4.156
0
0
0
0
0
Survey

-1
kinetic energy
eV
286.61
0.5
2
counts
d
Transmission
d
pulse counting
2.9
1
0
0
0
0
2
ESCAPE DEPTH TYPE
d
0
MFP Exponent
d
0
2.24647
3519.82
3585.63
3571.51
3658.85
3631.8
3667.99
3693.04
3628.27
3616.05
3681.8
3543.32
3736.58
3630.77
3636.88
3763.14
3746.89
3643.41
3677.35
3640.22
3739.26
3701.56
3782.21
3685.02
3725.14
3675.9
3677.43
3662.85
3598.39
3708.14
3686.07
3780.17
3741.7
3817.35
3764.04
3743.64
3842.08
3859.7
3923.01
3921.76
3877.53
3863.92
4069.72
3865.51
3954.24
3985.07
3919.08
3970.06
4026.68
4022.31
4068.62
3985.19
4134.53
3986.66
3887.35
4026.51
3947.84
4029.91
3964.6
3916.35
3920.79
3943.55
3990.86
3951.92
4114.1
4487.05
4651.04
4391.48
4216.63
4006.56
3920.45
4185.45
4297.48
3861.8
3502.06
3436.62
3470.06
3620.42
3652.47
3595.82
3699.99
3749.95
3794.02
3544.29
3463.75
3437.86
3337.73
3475.68
3337.43
3299.5
3484.35
3448.22
3434.04
3399.25
3458.76
3487.05
3470.16
3518.84
3429.3
3557.01
3490.11
3568.37
3587.9
3596.8
3659.34
3581.1
3592.11
3610.23
3605.57
3696.69
3645.9
3774.45
3747.21
3703.23
3699.39
3771.34
3764.34
3752.41
3694.45
3822.85
3834.58
3883.39
3855.92
3978.5
3843.38
3913.3
3928.73
4057.9
3984.72
3944.34
4005.95
3996.47
3976.35
4033.15
4065.85
4089.12
4233.82
4134.6
4028.59
4166.07
4214.39
4171.53
4118.81
4180.54
4232.3
4192.24
4184.43
4238.93
4137
4354.28
4262.59
4285.72
4327.49
4294.01
4358.79
4394.22
4382.16
4401.36
4383.34
4485.24
4401.47
4436.49
4454.39
4609.99
4387.89
4563.28
4545.44
4544.5
4620.38
4640.86
4597.57
4598.76
4608.43
4751.51
4770.69
4801.52
4741.07
4806.39
4751
4741.86
4784.15
4857.69
4909.16
4947.17
4843.97
4768.88
5054.14
4990.47
4994.3
5025.43
5076.79
5064.97
5083.73
5022.91
5038.4
5009.27
5149.95
5130.12
5074.51
5186.03
5238.06
5160.12
5239.92
5150.83
5213.11
5365.41
5241.29
5347.1
5204.24
5228.19
5391.05
5275.43
5271.08
5452.66
5436.46
5433.69
5524.16
5487.83
5453.95
5435.71
5499.67
5373.97
5559.35
5629.06
5528.71
5590.47
5535.95
5587.21
5710.78
5678.64
5636.95
5749.99
5611.42
5676.24
5834.76
5702.79
5698.66
5705.65
5756.84
5779.35
5813.59
5721.74
5769.7
5861.79
5995.88
5995.73
5891.67
5872.22
5980.72
5950.65
6067.35
5999.05
6033.13
6140.45
6112.28
6113.81
6158.27
6098.29
6155.37
6270.07
6129.82
6220.63
6102.42
6300.16
6188.23
6242.71
6302.93
6305.13
6291.26
6296.27
6445.98
6365.72
6313.7
6452.92
6405.03
6559.86
6509.56
6526.63
6578.78
6525.35
6513.73
6660.74
6496.49
6692.28
6661.73
6661.23
6780.85
6622.58
6808.71
6772.47
6804.86
6813.47
6751.13
6851.66
6846.29
6987.28
6953.32
6830.97
6929.72
6992.45
6954
6932.99
7039.36
7140.72
7074.83
7133.45
7060.1
7133.2
7103.07
7094.43
7190.01
7221.92
7306.72
7369.31
7294.64
7190.77
7321.29
7425.38
7393.77
7314.59
7406.76
7436.64
7396.2
7582.52
7478.85
7503.55
7601.2
7472.81
7527.22
7486.46
7696.87
7573.99
7738.4
7682.38
7766.79
7744.92
7909.02
7755.24
7851.41
7783.24
7931.04
7825.58
7871.76
7917.19
7937.76
8025.52
8046.7
8053.53
8023.13
8119.71
8079
8294.23
8210.93
8138.75
8134.77
8233.27
8221.12
8483.43
8221.45
8315.27
8274.88
8398.26
8306.77
8439.74
8409.07
8476.79
8431.48
8604.83
8511.17
8718.28
8619.33
8631.6
8541.47
8731.96
8649.26
8714.83
8750.38
8786.39
8767.81
8896.33
8803.45
8861.75
8848.7
8827.86
8910.64
9026.8
8870.98
8946.33
8923.84
9089.93
9058.98
9096.84
9100.89
9111.08
9228.32
9244.83
9285.36
9180.08
9310.27
9347.97
9306.36
9253.34
9470.18
9333.26
9567.39
9349.64
9402.63
9590.69
9420.37
9413.51
9549.49
9564.05
9717.24
9668.59
9538.49
9547.78
9676.42
9701.5
9750.92
9835.98
9889.8
9855.25
9926.87
9792.34
9897.92
9987.64
9995.05
10127.4
10104.5
10043.6
10058.6
10116.4
10006.4
9998.58
10194
10159.9
10177.1
10325.8
10340.1
10278.9
10295.1
10405.9
10504.7
10410.5
10421.5
10428.1
10574.3
10629.7
10703.4
10779.6
10639.3
10665.7
10624.5
10686.2
10828.7
10666.4
10826.1
10700.4
10882
10887.3
10779.9
10859.1
11053.7
10759.4
10906.7
10994.5
10894.5
11019.4
11199.7
11141.1
11006.8
11153.3
10817.3
10997.6
11069.2
11142.3
11095.1
11269.2
11439
11448.2
11638.6
11720.2
11600.4
11568.1
11400.1
11376.2
11264.3
11271.1
11300.6
11249.4
11236.7
11031.9
11211
11023.8
11133.2
11218.5
11271.5
11068.9
11223.6
11115.5
11330.2
11312
11336.2
11333.5
11217.5
11586.3
11410.4
11429
11368
11569.9
11462.6
11409.8
11542.4
11560.4
11600.6
11564.2
11537.8
11725.9
11748.4
11868.5
11722.3
11770.5
11669.2
11789.8
11821.6
11975.4
11993.2
11779.4
11998.9
11899.9
12114
12059
12144.1
12130.7
12284.9
12223.4
12235.5
12287.5
12257.3
12306.8
12285.6
12282.9
12345.1
12519.8
12332.8
12364.7
12297.6
12400.6
12458.7
12450
12591
12622.2
12682.4
12599.7
12608.4
12815.3
12741.9
12758.5
12770.2
12783.1
12797.4
12758.8
12813.1
12837.6
12952.8
12889.3
12900.7
12867.4
13030.3
13034.3
13097.2
13112.2
13235.6
13267.3
13315.8
13153.1
13225.3
13275.7
13283.6
13468.5
13500.7
13502.9
13527.7
13708.6
13301.7
13010.6
13119.4
12960.1
12839.1
12810.6
12815.4
12968.7
13165.3
13419.9
13900.1
15118.9
17142.6
16736.2
14751.4
13527.8
13170.6
12552.2
12594.1
12467.1
12298.6
12243.8
12388.6
12186.4
12293.4
12518.8
12541.3
12501.2
12951.8
12728.8
12899.4
12208.8
11713.2
11176.6
11135.7
11142.1
11131.1
11193.6
11421.9
11842.3
12326.6
13621.9
16408.8
20102.3
18294.8
13982.5
11898.1
10908.9
10508.5
10176.5
9875.49
9845.81
9750.46
9774.37
9769.73
9722.35
9608.56
9547.28
9588.77
9606.02
9653.33
9704.04
9615.99
9788.47
9666.07
9723.84
9885.34
9946.34
9728.76
9835.28
9782.4
9809.66
9854.46
9969.89
9954.73
9777.88
9823.74
9918.63
9964.02
10020.6
10050.1
10023
10065.8
10097
10240.2
10364.6
10263.9
10109.6
10132.4
10148.9
10049.2
10158
10096.7
10258.2
10332.7
10217
10189.1
10220.4
10353
10306.3
10331.5
10427.1
10544.9
10337.2
10465.4
10359.4
10545.8
10493.6
10533.8
10667.8
10535.9
10519.4
10609.3
10673
10809.8
10585.3
10732.9
10835.2
10830.4
10908.1
10764.8
10970
10824.6
10957.4
10986.3
10981.2
11174.4
10901.2
11247
11130
11205.4
11070.8
11047.9
11292.5
11197.5
11279.8
11280.4
11244.9
11325.9
11594.9
11507.8
11311.2
11458.3
11539.8
11537.7
11547.5
11708.3
11719.8
11603.7
11627.3
11738.2
11609.3
11847.2
11830.3
11738.1
11835.8
12047.1
11936.7
11852.2
11995
11866.9
12068.2
12028.1
12108.7
12028.3
12060.3
12117.8
12055.8
12270.5
12238.8
12243.2
12026.8
12149.2
12198.6
12184.5
12241.6
12382.1
12319.2
12477.2
12387.3
12626.8
12755.8
12364
12483.6
12449.7
12557.7
12652.5
12494.4
12673.6
12647.2
12563
12686.7
12973.2
12909.2
13198.6
13264.2
12990.7
13163.5
13077.5
12574.8
12654.2
12709.2
12686
12556
12662.6
12687
12670.5
12759.3
12934
13072.4
17422.8
21330.6
13133.6
13020.1
13158.6
13192.5
13316.3
13350.8
13211.4
13145.8
13191.8
13224
13287.1
13192.4
13209.1
13282.8
13293.8
13028.1
14535.4
15731.1
12159.3
11264.4
11495.6
11154.7
13179.3
14230.3
9133.64
7411.77
7968.86
8092.37
8007.34
11899.8
54775.6
12406.3
6892
6214.54
6047.88
12154.9
74108.7
13269.3
3286.38
2536.41
2240.17
2156
2086.45
2065.81
1980.79
2029.9
1946.96
1936.65
2011.57
1944.26
1934.32
1966.85
2003.49
1970.35
1966.95
2002.73
1992.87
1948.94
2115.2
1940.81
1973.31
1985.42
1992.04
1967.41
1903.66
2005.95
1982.67
2019
1957.71
2003.38
2080.39
2029.81
2063.69
2080.52
2090.74
2080.61
2025.98
2158.54
2122.05
2052.34
2117.68
2016.75
2105.41
2113.11
2103.39
2105.37
2082.59
2077.07
2197.28
2120.65
2185.22
2115.18
2094.83
2129.48
2077.04
2109.91
2075.72
2096.32
2206.34
2077.55
2161.84
2170.51
2147.64
2279.56
2196.59
2186.59
2247.55
2198.34
2160.16
2125.22
2139.88
2161.43
2181.99
2197.65
2213.28
2170.36
2297.77
2309.51
2365.31
2741.78
3013.21
2250.22
2212.82
2171.19
2179.43
2229.86
2215.71
2161.7
2189.67
2163.95
2201.53
2232.89
2228.17
2217.44
2172.05
2230.43
2246.21
2316.66
2215.39
2238.15
2241.65
2284.85
2264.63
2244.88
2299.7
2249.77
2270.63
2276.46
2220.99
2259.31
2241.16
2317.64
2236.09
2312
2298.89
2314.97
2321.39
2328.91
2339.55
2250.88
2380.55
2378.63
2470.39
2432.05
2416.7
2250.19
2395.38
2442.25
2315.54
2428.52
2396.23
2386.31
2374.79
2350.15
2415.31
2396.85
2434.31
2461.98
2461.44
2477.7
2452.4
2362.67
2450.7
2517.79
2466.74
2431.35
2457.89
2431.41
2468.82
2553.73
2505.26
2510.74
2459.32
2512.08
2509.39
2539.14
2513.5
2498.05
2508.47
2537.26
2502.4
2498.42
2607.57
2521.27
2535.89
2578.54
2551.57
2554.41
2530.55
2593.39
2521
2491.26
2560.7
2575.01
2582.01
2628.87
2574.92
2604.44
2555.86
2629.63
2621.58
2663.49
2686.67
2640.78
2732.57
2717.47
2774.93
2706.01
2694.43
2795.03
2650.33
2733.43
2679.03
2737.75
2747.59
2751.95
2812.79
2737.26
2737.67
2796.31
2865.65
2870.05
2908.23
2945.86
2924.7
2811.67
2724.43
2787.83
2779.82
2780.41
2872.34
2810.93
2841.41
2849.77
2877.23
2910.97
2882.52
2778.1
2856.42
2887.17
2916.41
2934.86
2843.89
2948.13
2860.26
2860.51
2916.51
2938.98
2897.32
2966.61
2916.88
2933.51
2891.75
2931.08
2956.36
2948.28
2971.63
2974.2
2937.64
2911.62
3003.93
3046.47
3038.36
3066.1
2987.55
3031.14
3033.9
2974.13
3092.62
3019.04
3137.21
3087.42
3044.98
3123.14
3196.51
3050.69
3053.46
3025.89
3013.15
3009.41
3074.26
3052.87
3157.15
3128.88
3227.19
3393.12
3522.2
3708.78
3704.42
3374.6
3171.51
3063.63
2963.83
2915.78
2902.79
2939.98
2922.81
2924.32
2897.44
2866.13
2932.84
2958.47
2977.11
2830.73
2936.37
2940.27
3010.86
2949.85
2949.29
2788.18
2933.59
2847.67
2872.16
2785.4
2845.47
2796.02
2776.35
2918.04
3002.28
3062.64
3238.2
3383.77
3334.49
3363.23
3461.23
3533.13
3520.43
3393.33
3154.37
2914.83
2520.54
2264.95
1932.19
1892.1
1705.33
1604.98
1563.2
1551.37
1610.22
1441.76
1519.7
1518.41
1404.18
1461.08
1472.75
1406.89
1468.98
1427.42
1456.64
1544.33
1533.14
1619.54
1594.04
1537.33
1523.66
1492.17
1487.5
1460.48
1504.98
1530.44
1552.43
1518.83
1526.74
1634.71
1787.18
1729.29
1678.99
1394.15
993.282
954.906
1260.75
919.439
863.414
908.512
869.536
935.717
1091.59
3114.18
5980.33
6639.15
6718.72
1027.86
400.255
356.107
269.763
2.24647
AgMNN
Ag in 2 mbar N2
2020
3
10
4
53
59
0
14
Casa Info Follows
0
0
0
0
File = E:/OwnCloud/XPS lab/EX340_CEC356_effect of lens modes.sle
Group = Ag in 2 mbar N2 , #Treatments: , #Temp: RT , #Pressure:2 mbar, #Gas1:N2, #Gas2:, #Gas Ratio:, #Comments:
First of group = 1
Analyzer lens = LargeArea:1.5kV
Analyzer slit = 4:7x20c\C:mesh
Scan mode = FixedAnalyzerTransmission
Kinetic energy start = 266.61
C:\Users\Mark\ownCloud\Muelheim Group\Projects\Gas phase background\EX340_CEC356_effect of lens modes.vms
Sum of 29 spectra in column containing 29 scans
XPS
1
Al
1486.61
0
0
0
54.5
180
FAT
20
1
4.156
0
0
0
0
0
AgMNN

-1
kinetic energy
eV
266.61
0.1
2
counts
d
Transmission
d
pulse counting
2.9
1
0
0
0
0
2
ESCAPE DEPTH TYPE
d
0
MFP Exponent
d
0
96.942
4.42285
3350.49
3318.85
3357.36
3339.37
3410.27
3472.37
3333.44
3361.55
3425.92
3339.26
3364.19
3323.05
3328.36
3355.93
3319.27
3281.91
3324.22
3299.2
3286.46
3372.45
3385.28
3338.23
3420.72
3381.5
3396.85
3470.48
3401.94
3385.8
3367.76
3374.41
3387.39
3327.76
3332.34
3352
3307.68
3369.64
3458.93
3372.81
3335.47
3374.71
3297.83
3374.99
3422.52
3453.54
3422.65
3384.48
3406.01
3385.91
3283.67
3413.56
3316.97
3363.31
3368.3
3303.27
3329.24
3444.17
3361.24
3384.21
3341.31
3462.42
3428.55
3381.51
3402.9
3448.15
3371.02
3320.21
3405.45
3356.4
3408.25
3473.14
3374.03
3354.73
3312.25
3377.9
3467.01
3351.66
3300.46
3355.36
3314.04
3452.11
3490.61
3270.26
3392.7
3333.53
3358.02
3332.64
3350.39
3355.73
3358.18
3387.9
3352.11
3474.6
3477.26
3441.39
3465.03
3582.82
3460.25
3383.25
3407.8
3388.21
3447.36
3443.42
3467.17
3487.25
3468.3
3337.14
3394.9
3472.35
3491.02
3440.82
3497.51
3421.94
3400.84
3451.76
3486.82
3389.82
3370.71
3408
3384.26
3451.01
3486.36
3510.57
3460.65
3490.48
3518.2
3486.43
3395.78
3471.23
3583.37
3584.12
3486.31
3498.49
3483.76
3456.89
3434.47
3443.91
3468.5
3592.57
3545.67
3492.29
3529.55
3482.91
3478.28
3460.62
3468.66
3506.32
3518.15
3428.01
3518.6
3538.22
3545.3
3566.21
3562.07
3549.72
3445.77
3504.89
3514.73
3512.45
3562.25
3528.47
3518.64
3566.39
3610.8
3574.98
3471.7
3586.77
3520.4
3465.39
3445.76
3467.56
3523.28
3610.18
3546.61
3536.41
3512.85
3563.86
3652.49
3511.4
3531.78
3579.88
3587.58
3595.54
3478.38
3536.04
3557
3502.93
3607.04
3609.47
3478.24
3545.95
3519.89
3560.46
3558.95
3510.68
3551.92
3588.77
3522.13
3542.61
3662.69
3571.88
3605
3543.84
3587.88
3618.25
3580.23
3518.94
3519.3
3546.04
3557.58
3610.13
3587.32
3637.35
3690.11
3666.1
3686.51
3585.22
3504.79
3533.2
3652.62
3670.96
3676.87
3679.66
3630.63
3537.98
3638.39
3545.87
3629.84
3624.66
3659.09
3676.62
3584.08
3557.01
3555.55
3466.41
3534.26
3650.11
3609.24
3603.09
3668.74
3613.27
3534.98
3613.89
3554.21
3531.05
3606.06
3581.75
3597.92
3679.89
3655.26
3569.25
3534.46
3660.56
3663.34
3670.65
3597.22
3550
3610.76
3581.74
3611.77
3714.36
3610.61
3611.19
3620.3
3602.42
3687.1
3596.03
3589.15
3579.76
3599.14
3680.05
3690.32
3605.38
3661.73
3683.5
3661.67
3698.71
3648.32
3721.04
3665.84
3632.01
3573.46
3644.93
3664.9
3641.77
3672.14
3602.67
3615.7
3665.54
3572.89
3552.3
3538.27
3600.31
3703.93
3596.27
3681.98
3624.18
3670.84
3523.9
3571.91
3588.82
3568.47
3676.55
3678.17
3680.17
3567.2
3627.12
3648.48
3732.81
3811.89
3675.75
3751.31
3736.83
3654.95
3607.91
3693.81
3675.22
3633.94
3720.03
3668.7
3602.77
3636.72
3668.39
3726.06
3754.09
3708.31
3673.1
3664.14
3670.24
3708.96
3593.86
3592.82
3633.58
3574.56
3639.35
3661.74
3689.57
3680.31
3692.39
3642.88
3675.48
3709.82
3702.77
3760.83
3719.88
3705.2
3673.42
3641.79
3781.64
3768.94
3672.55
3637.23
3767.08
3775.09
3758.97
3627.27
3730.26
3704.82
3665.84
3715.06
3768.58
3632.58
3667.35
3630.92
3582.81
3640.03
3640.54
3756.47
3684.19
3670.62
3701.17
3724.22
3717.1
3729.29
3703.39
3756.51
3745.6
3734.15
3776.76
3763.55
3653.15
3661.71
3652.12
3694.27
3715.92
3655.66
3825.9
3688.46
3651.02
3765.16
3715.51
3738.18
3697.03
3713.68
3637.64
3626.61
3721.99
3721.43
3599.92
3701.19
3657.18
3666.88
3674.07
3741.12
3696.09
3662.07
3643.61
3716.98
3586.99
3716.1
3700.4
3646.74
3671.42
3659.68
3640.79
3558.88
3677.07
3731.81
3709.8
3712.52
3673.52
3664.21
3680.41
3712.5
3713.69
3704.02
3656.38
3645.21
3567.25
3627.66
3565.66
3641.42
3732.58
3782.79
3625.99
3613.98
3590.07
3575.6
3675.25
3701.69
3761.68
3639.31
3680.32
3670.39
3672
3585.95
3607.19
3679.14
3758.71
3699.09
3622.96
3711.08
3749.42
3650.8
3750.16
3692.28
3666.42
3679.42
3611.32
3767.16
3666.65
3682.66
3637.52
3729.15
3755.54
3648.34
3669.81
3723.06
3774.19
3724.96
3671.34
3701.05
3783.39
3692.64
3630.87
3778.91
3680.63
3728.11
3746.21
3696.12
3711.23
3730.49
3655.32
3666.43
3641.01
3657.99
3656.17
3836.63
3654.91
3687.97
3702.15
3705.79
3712.94
3670.93
3797.57
3756.57
3807.49
3747.63
3668.11
3702.07
3672.71
3729.08
3719.62
3685.65
3624.02
3681.04
3698.39
3782.32
3670.25
3810.24
3726.74
3741.81
3801.22
3763.7
3797.46
3782.5
3739.58
3795.38
3810.31
3788.76
3843.39
3672.88
3723.52
3724.45
3704.17
3840.99
3754.78
3757.62
3734.58
3746.65
3836.84
3842.01
3754.46
3794.53
3777.17
3712.38
3872.03
3861.47
3769.82
3693.78
3814.66
3796.74
3790.99
3765.57
3796.72
3845.12
3786.79
3743.02
3758.86
3860
3814.95
3811.87
3795.23
3771.14
3833.33
3866.06
3798.53
3722.98
3746.8
3749.31
3825.32
3811.53
3878.9
3864.92
3824.81
3835.88
3851.76
3735.92
3780.02
3782.35
3773.7
3923.72
3856.41
3783.28
3899.95
3894.11
3865.11
3874.1
3768.29
3757.92
3928.56
3972.68
3855.04
3839.64
3856.71
3747.82
3851.99
3808.55
3839.31
3788.61
3880.17
3840.15
3830.99
3885.71
3880.79
3924.01
3886.89
3895.65
3944.91
3955.56
3912.66
3936
3905.08
3857.67
3891.9
3987.89
3885.07
3881.31
3819.61
3890.77
3857.97
3862.33
3855.25
3885.35
3852.83
3880.6
3849.58
3908.14
3915.06
3875.01
3913.95
3963.15
3950.42
3953.64
3889.15
3924.36
3844.78
3922.55
3977.24
3932.64
3903.79
3994.56
3911.44
3938.42
3942
3937.45
3995.22
3912.92
3920.09
3864.32
3893.37
3838.76
3868.69
4000.57
3945.61
3978.21
4004.54
3924.07
3929.36
3982.16
3979.48
3912.13
3938.81
3989.32
3878.34
3958.3
3908.02
4007.79
4003.32
4055.42
3928.47
3926.15
3976.47
3900.8
3924.78
3981.02
3861.73
3964.74
3866.08
3917.05
3891.49
4040.56
3930.16
3886.8
4000.33
4026.76
3949.21
4004.01
3949.21
3953.57
3959.96
4063.93
3940.86
3989.38
4065.8
4044.19
3937.12
4003.24
4049.64
3951.11
4006.72
3963.18
4031.31
4046.23
3983.75
4079.24
4039.69
4061.05
4001.02
4080.35
4134.91
4078.88
4014
4016.21
4069.81
4022.52
3937.51
4058.67
4143.97
4126.96
4062.42
4110.8
4018.94
4078.19
4099.12
4130.13
4156.84
4129.67
4162.44
4156.98
4163.26
4143.02
4144.81
4127.67
4118.28
4093
4041.03
4099.29
4049.87
4031.53
4155.16
4120.66
4043.62
3891.7
3934.38
4035.9
4067.57
4016.07
4008.08
3998.95
3975.84
4010.78
4110.38
4026.9
3947.32
4079.55
4091.14
3998.61
4085.64
4021.41
3840.69
3927.77
3941.55
3960.85
4058.95
3967.1
3963.16
3974.49
3923.12
3955.29
3956.34
3925.35
3921.12
4022.94
3937.36
4066.89
4029.34
4039.77
3963.78
3892.85
4016.74
4027.57
4069.47
3856.88
3973.56
4087.85
3856.47
4023.31
3989.09
4048.46
4041.55
3988.16
4048.52
3988.63
3937.33
3933.87
4027.17
4017.64
3894.35
4011.6
3885.42
3950.34
3990.28
3947.4
3891.81
3980.7
3888.84
3875.34
3939.24
3916.39
3884.43
3933.49
4026.14
3949.63
3963.7
3950.4
3924.57
3958.78
3951.29
3907.06
3861.46
3886.71
3884.57
3931.35
3891.21
3892.09
3873.7
3915.95
4015.28
3908.1
3973.21
3991.51
3944.94
4008.91
4046
3969.46
3895.18
3914.5
3940.35
3918.43
3869.46
3942.24
3965.58
3967.53
4034.27
4076.7
4041.92
4097.26
4034.43
4174.59
4060.11
4129.59
4207.36
4128.67
4204.43
4291.53
4425.5
4518.54
4606.12
4667.71
4799.35
4764.87
4846.42
4809.11
4751.94
4761.39
4592.17
4658.26
4729.72
4644.25
4604.85
4545.44
4524.96
4505.82
4458.8
4482.07
4452.61
4544.35
4495.44
4455.8
4352.57
4376.77
4389.66
4372.67
4270.31
4290.24
4078.37
4160.43
4097.85
4140.38
4156.56
4183.88
4107.29
4165.85
4041.65
4028.47
4070.7
3995.45
4075.68
4005.23
3956.5
3892.18
3952.69
3951.08
3950.76
3979.16
3915.9
3850.37
3888.79
4017.45
4051.86
3937.32
4024.89
3943.3
4015.48
4095.54
4096.78
4170.55
4221.34
4285.58
4402.19
4389.33
4401.15
4433.13
4461.11
4464.88
4317.92
4129.82
4150.6
4085.97
4046.72
4008.29
3903.6
3878.53
3863.07
3793.98
3784.76
3795.27
3836.56
3709.75
3690.86
3657.4
3633.36
3584.91
3597.67
3488.3
3542.1
3498.59
3477.95
3490.92
3434.17
3468.23
3568.42
3507.93
3596.65
3537.43
3525.77
3526.44
3471.35
3509.62
3526.47
3445.53
3548.81
3575.99
3573.92
3516.28
3430.49
3477.37
3523
3517.09
3541.73
3532.49
3622.42
3568.21
3545.89
3602.3
3604.58
3589.41
3597.92
3484.39
3502.95
3548.11
3556.1
3540.63
3618
3653.72
3655.23
3699.19
3698.69
3759.55
3708.59
3786.04
3648.3
3554.13
3628.93
3673.95
3537.05
3526.75
3556.22
3609.93
3613.13
3617.39
3637.67
3669.17
3710.7
3764.22
3768.53
3699.23
3748.47
3746.02
3836.3
3832.15
3740.96
3716.78
3772.54
3866.33
3860.3
3796.61
3770.08
3702.28
3744.56
3739.93
3767.79
3772.52
3759.72
3719.89
3774.79
3783.99
3735.43
3720.16
3797.69
3758.84
3633.23
3597.94
3612.48
3568.49
3548.22
3506.82
3400.68
3504.81
3491.95
3499.1
3413.27
3356.18
3383.82
3390.39
3431.13
3426.41
3465.49
3368.98
3494.85
3524.03
3561.56
3538.67
3511.48
3596.73
3529.38
3386.82
3395.82
3414.41
3447.96
3422.32
3458.03
3354.02
3351.3
3365.2
3398.67
3308.76
3345.05
3367.1
3343.18
3356.54
3335.56
3364.62
3338.45
3322.61
3314.55
3390.19
3386.92
3372.24
3401.44
3465.56
3465.75
3431.82
3438.46
3342.7
3399.34
3375.37
3390.23
3355
3371.55
3383.55
3392.76
3407.92
3430.67
3368.58
3396.59
3374.54
3424.88
3339.37
3450.04
3411.53
3472.83
3413.92
3413.04
3449.32
3377.94
3346.65
3378.5
3407.95
3364.87
3376.66
3509.9
3392.96
3391.58
3388.5
3300.62
3355.2
3459.84
3410.7
3391.78
3460.28
3480.14
3466.66
3421.1
3476.63
3445.53
3424.1
3447.81
3415.47
3454.79
3414.34
3411.44
3389.57
3344.73
3430.07
3443.62
3324.63
3419.29
3476.97
3450.27
3522.61
3519.73
3509.47
3541.49
3546.98
3539.91
3462.5
3400.68
3416.71
3487.05
3474
3485.7
3532.14
3502.02
3509.97
3402.99
3364.42
3472.59
3437.94
3464.56
3494.06
3477.2
3428.01
3437.73
3548.53
3511.39
3539.97
3448.26
3441.72
3433.14
3483.86
3527.59
3501.07
3504.48
3518.59
3438.51
3479.61
3571.7
3505.23
3506.22
3535.56
3500.09
3498.6
3499.58
3437.4
3413.91
3434.9
3536.7
3522.05
3536.75
3459.61
3453.65
3538.29
3540.97
3537.26
3568.98
3531.3
3457.46
3550.59
3543.32
3676.05
3492.81
3516.25
3576.39
3488.01
3476.3
3585.98
3581.61
3545.08
3530.24
3465.31
4.42285
Ag3p
Ag in 2 mbar N2
2020
3
10
5
0
13
0
14
Casa Info Follows
0
0
0
0
File = E:/OwnCloud/XPS lab/EX340_CEC356_effect of lens modes.sle
Group = Ag in 2 mbar N2 , #Treatments: , #Temp: RT , #Pressure:2 mbar, #Gas1:N2, #Gas2:, #Gas Ratio:, #Comments:
First of group = 0
Analyzer lens = LargeArea:1.5kV
Analyzer slit = 4:7x20c\C:mesh
Scan mode = FixedAnalyzerTransmission
Kinetic energy start = 686.61
C:\Users\Mark\ownCloud\Muelheim Group\Projects\Gas phase background\EX340_CEC356_effect of lens modes.vms
Sum of 28 spectra in column containing 28 scans
XPS
1
Al
1486.61
0
0
0
54.5
180
FAT
20
1
4.156
0
0
0
0
0
Ag
3p
-1
kinetic energy
eV
686.61
0.1
2
counts
d
Transmission
d
pulse counting
2.8
1
0
0
0
0
2
ESCAPE DEPTH TYPE
d
0
MFP Exponent
d
0
3.31097
8849.62
3.31
9015.21
3.30879
8991.87
3.30758
9102.98
3.30637
9047.51
3.30516
9073.95
3.30396
9018.15
3.30275
9158.69
3.30155
9028.87
3.30035
9090.48
3.29915
9107.35
3.29795
9110.97
3.29675
9198.92
3.29555
9063.1
3.29436
9334.39
3.29316
9305.77
3.29197
9223.69
3.29078
9076.29
3.28959
9245.1
3.2884
9390.69
3.28721
9195.6
3.28603
9259.57
3.28484
9241.67
3.28366
9248.41
3.28248
9402.33
3.28129
9367.49
3.28011
9204.92
3.27894
9369.58
3.27776
9347.7
3.27658
9262.16
3.27541
9303.11
3.27423
9442.92
3.27306
9413.19
3.27189
9472.95
3.27072
9360.75
3.26955
9457.22
3.26838
9477.91
3.26722
9491.1
3.26605
9428.07
3.26489
9343.56
3.26373
9555.69
3.26257
9418.39
3.26141
9409.16
3.26025
9533.22
3.25909
9459.65
3.25793
9625.06
3.25678
9668.04
3.25563
9647.85
3.25447
9615.45
3.25332
9544.11
3.25217
9684.86
3.25102
9702.01
3.24988
9611.44
3.24873
9717.85
3.24758
9656.4
3.24644
9760.01
3.2453
9706.63
3.24416
9724.34
3.24302
9797.85
3.24188
9864.79
3.24074
9763.12
3.2396
9767.9
3.23847
9863.54
3.23733
9558.33
3.2362
10015.5
3.23507
9993.84
3.23394
9671.47
3.23281
9957.85
3.23168
9815.17
3.23055
9838.87
3.22942
10072.9
3.2283
9905.2
3.22718
9821.57
3.22605
9830.68
3.22493
9962.89
3.22381
10045.1
3.22269
9936.13
3.22158
10045.3
3.22046
9912.55
3.21934
10059.9
3.21823
10011.7
3.21712
10094.3
3.216
10035
3.21489
10050.9
3.21378
9992.33
3.21267
10100.1
3.21157
10212
3.21046
10105.6
3.20936
10170
3.20825
10071.2
3.20715
10131.8
3.20605
10085.7
3.20495
10176.1
3.20385
10388
3.20275
10132.1
3.20165
10384.9
3.20055
10290.1
3.19946
10363.2
3.19837
10356.9
3.19727
10345.7
3.19618
10286.8
3.19509
10236.9
3.194
10301.5
3.19291
10136
3.19183
10284.2
3.19074
10247.9
3.18966
10312.7
3.18857
10292.2
3.18749
10328.8
3.18641
10396.2
3.18533
10536.8
3.18425
10523.8
3.18317
10388
3.18209
10525.1
3.18102
10480.6
3.17994
10485.1
3.17887
10393
3.17779
10255.1
3.17672
10492.4
3.17565
10573.8
3.17458
10471
3.17351
10542.8
3.17245
10576.2
3.17138
10602.6
3.17031
10588.1
3.16925
10641.2
3.16819
10568.8
3.16712
10797.9
3.16606
10478.8
3.165
10657.8
3.16394
10810.3
3.16289
10653.1
3.16183
10610.2
3.16077
10641.1
3.15972
10674.8
3.15867
10625.8
3.15761
10790.4
3.15656
10567.7
3.15551
10787.4
3.15446
10677.3
3.15341
10752.9
3.15237
10652.2
3.15132
10641
3.15027
10603.1
3.14923
10675.1
3.14819
10742.9
3.14714
10555.5
3.1461
10755.7
3.14506
10726.2
3.14402
10764.9
3.14299
10735.9
3.14195
10781.9
3.14091
10863.1
3.13988
10781
3.13884
10795.5
3.13781
10998.8
3.13678
10996
3.13575
11085.8
3.13472
11222.9
3.13369
10930.7
3.13266
11119.3
3.13164
11082.6
3.13061
11169.1
3.12959
11250.2
3.12856
11109.7
3.12754
11092.1
3.12652
11131.6
3.1255
11030.3
3.12448
11034.4
3.12346
10997.8
3.12244
10973
3.12142
11054.6
3.12041
10711
3.11939
10831.8
3.11838
10961.3
3.11737
10713.4
3.11635
10919.6
3.11534
10772.3
3.11433
10722
3.11332
10848.4
3.11232
10815
3.11131
10741.3
3.1103
10767.6
3.1093
10768.5
3.10829
10769.3
3.10729
10595
3.10629
10838.2
3.10529
10819.2
3.10429
10704
3.10329
10696.9
3.10229
10650.3
3.10129
10898.4
3.1003
10739
3.0993
10706.4
3.09831
10771.3
3.09731
10823.9
3.09632
10806.7
3.09533
10621.4
3.09434
10779.7
3.09335
10763.7
3.09236
10911.9
3.09137
10768.3
3.09039
10850.8
3.0894
10878.8
3.08842
10754
3.08743
10840.3
3.08645
10836.8
3.08547
10725.7
3.08449
10919.6
3.08351
11130.9
3.08253
11084.8
3.08155
11041.7
3.08057
11263.6
3.0796
10885
3.07862
11028.8
3.07765
11047
3.07667
11023.5
3.0757
11006.9
3.07473
10907.7
3.07376
10969.3
3.07279
11100.7
3.07182
10994.1
3.07085
10995.3
3.06988
11185.5
3.06892
11098.8
3.06795
11215.5
3.06699
11240.1
3.06602
11299.6
3.06506
11328.4
3.0641
11138.2
3.06314
11239.4
3.06218
11135.5
3.06122
11112.2
3.06026
11480.5
3.0593
11356.2
3.05835
11276.1
3.05739
11235.3
3.05644
11383.2
3.05548
11145
3.05453
11392.4
3.05358
11503.7
3.05263
11312.1
3.05168
11381.2
3.05073
11485.7
3.04978
11494.4
3.04883
11284.1
3.04788
11484.3
3.04694
11433.4
3.04599
11519.4
3.04505
11456
3.04411
11491.5
3.04317
11515.4
3.04222
11625
3.04128
11574.3
3.04034
11702.6
3.03941
11536.2
3.03847
11564.6
3.03753
11644.1
3.03659
11630.3
3.03566
11492.9
3.03472
11479.2
3.03379
11546
3.03286
11579.6
3.03193
11633.6
3.031
11563.9
3.03007
11602.8
3.02914
11602.4
3.02821
11742.9
3.02728
11597.3
3.02635
11722.2
3.02543
11438.6
3.0245
11867.1
3.02358
11735.1
3.02266
11655
3.02173
11884.1
3.02081
11679.3
3.01989
11827.7
3.01897
11892.8
3.01805
11780.2
3.01713
11986.9
3.01622
11980.8
3.0153
11900.6
3.01438
11871.6
3.01347
11884.9
3.01256
11813
3.01164
11947.9
3.01073
11836.4
3.00982
12063.7
3.00891
11901.6
3.008
11971.9
3.00709
11874.4
3.00618
11980.7
3.00527
12002.1
3.00437
11998.7
3.00346
12086.5
3.00256
12004.8
3.00165
12075.5
3.00075
12169.3
2.99985
12150
2.99894
12163.3
2.99804
12078.8
2.99714
12214.4
2.99624
12126.3
2.99535
12142.2
2.99445
12056.6
2.99355
12161.9
2.99266
12181.5
2.99176
12373.5
2.99087
12235.4
2.98997
12199.6
2.98908
12328.7
2.98819
12173.7
2.9873
12241.9
2.98641
12297.6
2.98552
12300.4
2.98463
12299.9
2.98374
12321.3
2.98285
12401.2
2.98197
12356.6
2.98108
12248.3
2.98019
12349.4
2.97931
12251.2
2.97843
12416.8
2.97754
12518.7
2.97666
12480
2.97578
12377.6
2.9749
12397.5
2.97402
12448.6
2.97314
12423.1
2.97227
12552.4
2.97139
12596.5
2.97051
12471.9
2.96964
12474.4
2.96876
12516.9
2.96789
12666.7
2.96702
12630.1
2.96614
12465.2
2.96527
12518
2.9644
12697
2.96353
12643.3
2.96266
12696.2
2.96179
12720.4
2.96092
12580.3
2.96006
12818.6
2.95919
12684.4
2.95833
12665.8
2.95746
12804
2.9566
12769.4
2.95573
12691.5
2.95487
12776
2.95401
12773.8
2.95315
12747.6
2.95229
12989
2.95143
12935.3
2.95057
12772.1
2.94971
12897
2.94885
12869.3
2.948
12816.6
2.94714
12944.8
2.94629
13049.8
2.94543
13005.9
2.94458
12883.4
2.94373
13167.2
2.94287
13113.9
2.94202
13147.5
2.94117
13063.6
2.94032
13089.1
2.93947
12935.9
2.93863
12569.1
2.93778
12460.7
2.93693
12335.7
2.93608
12608
2.93524
12455.2
2.93439
12516.4
2.93355
12487.7
2.93271
12259.5
2.93187
12509
2.93102
12343.7
2.93018
12463.9
2.92934
12302.3
2.9285
12442.4
2.92766
12550.3
2.92683
12631.1
2.92599
12766.7
2.92515
12805.9
2.92432
12967.1
2.92348
13284.1
2.92265
13762.7
2.92181
14139.5
2.92098
14778.1
2.92015
15990.3
2.91931
16825.8
2.91848
16605.1
2.91765
15676.7
2.91682
14528.9
2.91599
13723.9
2.91517
13257.3
2.91434
12879.9
2.91351
12753.2
2.91269
12448.7
2.91186
12530.6
2.91104
12242.1
2.91021
12208.6
2.90939
12178.1
2.90857
12087.6
2.90774
12176.5
2.90692
12093
2.9061
11964.9
2.90528
11981.6
2.90446
11862.7
2.90364
11859.1
2.90283
11840.4
2.90201
12014.9
2.90119
11977
2.90038
12069.1
2.89956
12195.2
2.89875
11958.7
2.89794
12034
2.89712
12019
2.89631
12269.7
2.8955
12195.6
2.89469
12194.3
2.89388
12222.1
2.89307
12419.1
2.89226
12364.2
2.89145
12510
2.89064
12598.9
2.88984
12235.1
2.88903
12182.7
2.88823
11723.5
2.88742
11344.9
2.88662
11217.6
2.88581
11023.5
2.88501
10825.9
2.88421
10910.9
2.88341
10812.5
2.88261
10771.9
2.88181
10757.4
2.88101
10754.3
2.88021
10916.6
2.87941
10910.8
2.87861
10870.7
2.87782
10901.7
2.87702
11082.8
2.87622
11180.4
2.87543
11580.1
2.87464
11678.2
2.87384
12046.1
2.87305
12769.4
2.87226
13574.9
2.87147
15047.2
2.87067
16485.7
2.86988
18389.8
2.86909
19475
2.86831
18705.3
2.86752
16544.5
2.86673
14552.6
2.86594
12999.9
2.86516
11965
2.86437
11280.8
2.86359
10673
2.8628
10335.1
2.86202
10206
2.86124
10066.1
2.86045
9827.57
2.85967
9718.06
2.85889
9482.82
2.85811
9429.29
2.85733
9505.77
2.85655
9463.9
2.85577
9463.11
2.85499
9399.74
2.85422
9408.31
2.85344
9272.55
2.85266
9271.9
2.85189
9325.28
2.85111
9300.29
2.85034
9512.97
2.84957
9365.15
2.84879
9177.68
2.84802
9363.06
2.84725
9384.84
2.84648
9153.71
2.84571
9336.23
2.84494
9440.42
2.84417
9209.49
2.8434
9309.5
2.84263
9448.24
2.84187
9348.57
2.8411
9400.29
2.84033
9369.39
2.83957
9142.83
2.8388
9301.98
2.83804
9310.23
2.83727
9292.41
2.83651
9364.37
2.83575
9374.71
2.83499
9274.16
2.83423
9458.06
2.83347
9341.94
2.83271
9478.33
2.83195
9412.63
2.83119
9400.83
2.83043
9389.1
2.82967
9491.13
2.82892
9473.53
2.82816
9473.51
2.8274
9365.65
2.82665
9331.51
2.82589
9583.85
2.82514
9381.1
2.82439
9564.88
2.82364
9464.68
2.82288
9587.57
2.82213
9513.25
2.82138
9432.6
2.82063
9307.98
2.81988
9587.37
2.81913
9467.1
2.81838
9566.16
2.81764
9546.77
2.81689
9503.7
2.81614
9659.7
2.8154
9677.1
2.81465
9609.1
2.81391
9668
2.81316
9559.38
2.81242
9692.43
2.81168
9639.78
2.81093
9553.92
2.81019
9608.61
2.80945
9703.61
2.80871
9749.19
2.80797
9720.06
2.80723
9995.18
2.80649
9913.43
2.80575
9859.1
2.80501
9977.53
2.80428
10021.6
2.80354
9912.51
2.8028
9726.42
2.80207
9845.52
2.80133
9816.78
2.8006
10064.4
2.79987
9722.08
2.79913
9818.78
2.7984
9789.62
2.79767
9816.57
2.79694
9871.71
2.79621
9817.91
2.79548
9690.02
2.79475
9693.55
2.79402
9726.06
2.79329
9958.6
2.79256
9893.66
2.79183
9904.56
2.79111
9947.53
2.79038
9931.65
2.78965
9838.12
2.78893
9983.33
2.7882
9935.89
2.78748
9892.56
2.78676
10000.1
2.78603
9917.71
2.78531
9924.39
2.78459
9997.06
2.78387
10023.8
2.78315
10030.6
2.78243
10041.8
2.78171
10063.1
2.78099
10089.8
2.78027
9980.97
2.77955
9908.66
2.77884
10116.1
2.77812
10108.7
2.7774
10183.7
2.77669
10017.9
2.77597
10204.7
2.77526
10126.7
2.77454
10209.1
2.77383
10144
2.77312
10301
2.7724
10116.6
2.77169
10072.3
2.77098
10173.8
2.77027
10165
2.76956
10120.7
2.76885
10362.3
2.76814
10418.7
2.76743
10280.9
2.76673
10447.4
2.76602
10248.9
2.76531
10519.7
2.7646
10272.2
2.7639
10339.3
2.76319
10348.8
2.76249
10476.3
2.76178
10485.1
2.76108
10501
2.76038
10473.1
2.75968
2.75953
Ag3d
Ag in 2 mbar N2
2020
3
10
5
2
22
0
14
Casa Info Follows
0
0
0
0
File = E:/OwnCloud/XPS lab/EX340_CEC356_effect of lens modes.sle
Group = Ag in 2 mbar N2 , #Treatments: , #Temp: RT , #Pressure:2 mbar, #Gas1:N2, #Gas2:, #Gas Ratio:, #Comments:
First of group = 0
Analyzer lens = LargeArea:1.5kV
Analyzer slit = 4:7x20c\C:mesh
Scan mode = FixedAnalyzerTransmission
Kinetic energy start = 1036.61
C:\Users\Mark\ownCloud\Muelheim Group\Projects\Gas phase background\EX340_CEC356_effect of lens modes.vms
Sum of 29 spectra in column containing 29 scans
XPS
1
Al
1486.61
0
0
0
54.5
180
FAT
20
1
4.156
0
0
0
0
0
Ag
3d
-1
kinetic energy
eV
1036.61
0.1
2
counts
d
Transmission
d
pulse counting
2.9
1
0
0
0
0
2
ESCAPE DEPTH TYPE
d
0
MFP Exponent
d
0
49.741
2.57029
12038.4
12008.5
12222.6
12048
12112.6
12048.3
12082.4
12200
12013.8
11949.1
12147.8
12105.8
12144.2
12140.6
12285.8
12274.2
12214
12058.9
12188.6
12247.7
12121.7
12207.5
12080.6
12208.8
12370.5
11982.2
12031
12206.8
12090
12231.2
12299.7
12252.7
12130.5
12162.6
12217.9
12316.4
12150.5
12110.5
12163.7
12322.5
12171
12134.6
12207
12233.3
12188.1
12154.9
12412.6
12362.8
12251.9
12191.9
12179.7
12132.4
12146
12224.5
12267.6
12279
12283.2
12424.3
12255.3
12313.7
12263.5
12199.3
12143.7
12361.7
12250.3
12430.4
12403.2
12291.5
12386.8
12294.7
12332.4
12362.9
12379.6
12255.2
12259.1
12267.7
12200.1
12276.6
12255.8
12109.3
12293.2
12411.2
12418
12423.5
12351.9
12195.9
12317.7
12375.9
12318.9
12377.7
12404.5
12327.2
12246.2
12327.4
12458.7
12405.4
12361.4
12391.2
12362.5
12276
12456.1
12416.3
12350.4
12390
12487.1
12609.9
12303
12310.9
12293.6
12347.1
12447.5
12335.6
12342.5
12385.3
12482.8
12437
12487.7
12235.8
12440.1
12634.4
12580.8
12534.2
12480.8
12315.3
12331.3
12452.7
12494.7
12265.4
12290.6
12546.9
12640.1
12560.7
12580.8
12513.2
12456.7
12464.3
12490.9
12453.4
12334.2
12376.7
12353.8
12402.3
12469.8
12487
12669.2
12561.3
12624.7
12698.6
12532.7
12431
12467.3
12357.5
12618.7
12532.7
12406.5
12583.1
12627.5
12526.3
12498.7
12641
12645.1
12431.9
12554.8
12515.8
12593.4
12587.1
12532.6
12609.7
12410.5
12559.4
12406.5
12353.6
12477.1
12464.7
12441.3
12434.1
12487.8
12487.4
12342
12390.4
12583.2
12633.1
12572.2
12764.2
12556.2
12661.1
12663.3
12640.7
12683.9
12717.3
12755.4
12711.1
12718.3
12822.9
12881.7
12823.1
12856.2
12739.3
12742.1
12624.8
12585.6
12599.3
12544.2
12547
12713.4
12860.1
12639.8
12591.1
12922.7
12777.4
12742.5
12861.7
12769
12846.3
12805.2
12701.3
12610.5
12792.1
12686.7
12552.5
12667.7
12514.2
12524.7
12539.9
12599.5
12552.7
12638.3
12557.9
12612.4
12470.8
12634.8
12655.6
12482.1
12547.3
12591.4
12572.4
12585.7
12545.7
12643.7
12708.2
12620.1
12614.3
12732.9
12811.9
12756.6
12723.9
12600.5
12836.7
12744.7
12698.1
12808.5
12893.5
12807.8
12887.7
12694
12852.5
12712.2
12908.7
12702
12880.9
12828
12888.1
12793.8
12780.7
12984.7
12951.1
13045.8
13117.5
13208.3
13076.2
12983.2
13097.9
13143.5
13353.8
13119.2
13341.3
13227.7
13470
13483.3
13400.2
13568.7
13501.5
13481.4
13376
13408.5
13251.3
13232
13185.1
13096.9
13104.3
13076.1
13181.1
13033.1
13058.8
13095.1
12934.6
13080.3
13189.1
13230.9
13299.5
13275.1
13371.6
13322.1
13160.1
13107.3
13028.2
13221.7
13335.5
13176.9
13403.7
13458.2
13483.5
13541.2
13652.5
13500.6
13169.3
12933.8
12887.8
12734.6
12605
12553.1
12560.1
12399.2
12477.1
12540.7
12497
12367.5
12374.1
12778.5
12592
12464
12511.4
12553.4
12740.5
12552.8
12560.5
12588
12531.4
12640.1
12761.4
12718.6
12696.7
12742.1
12793.1
12776.8
12848.7
12711.4
12741.9
12870
12940.7
12756.7
12815.6
12787.4
12916.7
12648.7
12604.7
12610
12607.7
12696.2
12690.3
12615.8
12587.1
12570.2
12487
12578.3
12612
12565.5
12640.8
12615.4
12647.4
12509.2
12647.8
12820.9
12660.6
12675.8
12413.9
12538.7
12635.4
12573.9
12669.6
12757.1
12766.9
12691.1
12486.9
12627.2
12635.9
12660.3
12619.3
12661.3
12719.6
12913.1
12662.8
12594
12693.2
12684.3
12796
12842.5
12767.3
12738.5
12548.5
12576.6
12768.3
12722.6
12720.9
12655.8
12806.2
12628.1
12708.4
12665.8
12787.3
12868.2
12842.2
12753.4
12802.2
12793.8
12769.9
12914.7
12844.2
12994
12828
12857.1
12726.8
12861.8
12860.7
13043.6
13038.7
13081.1
13064
13048.1
13286.1
13596.9
13899.8
14148.3
14685.3
15631.3
16934.7
18189.6
20189.1
22885.2
25546.6
27858.5
29536.6
29326.9
27598.3
24400.7
20497.5
17259.3
15175
14153.6
13720
13530.7
13581.7
13322.3
13221.4
13102.5
13001.4
13344.7
13203
13173.5
12988.2
13057.6
13096.9
13032.9
13115.8
13041.3
13049.1
12877.8
12876.9
12859.5
13065.3
13094.1
13004.7
12894.8
12867.5
12935.4
13045.3
13063.1
13244.5
13025.9
13062.5
13193.7
13258.4
13116.5
13246.1
13101.2
13105.6
13163.8
13364
13158.5
13189.4
13275.2
13093.2
13202.7
13271.4
13219.7
13261.9
13091
13317.6
13396.6
13379
13399.2
13333.4
13307.1
13128.9
13053.5
13164.3
13348.4
13358.8
13318.9
13244.3
13316.7
13347.5
13347.5
13187.1
13395.8
13303.6
13203.7
13313
13103.9
13127.5
12980.7
13324.4
13179.2
13348.9
13191.5
13179.1
13107.5
13015.8
12966.3
12917.5
13267.6
13089.6
13155.6
13144.4
13036.2
12854.5
13031.2
13178.6
13165.4
13063
13100.8
13275.6
13090.1
13131.8
13236.7
13164.3
13123.2
13139.1
13234.7
13247.1
13227.3
13344.7
13135.1
13239.2
13317.3
13388.6
13298.3
13477.3
13280.4
13406.8
13396.9
13327.7
13238.8
13137.5
13113.3
13204.1
13373.7
13196.3
13174.1
13297.2
13395.6
13218.4
13117.8
13207.6
13292.9
13305.9
13273.1
13229.9
13249.9
13505.5
13320.8
13137.9
13279.5
13459
13477.4
13410.6
13378.6
13482.2
13332.1
13265.9
13257.2
13199.9
13407.1
13342.3
13458.1
13512.2
13358.1
13422.4
13349.3
13205.7
13249.3
13158.3
13144.6
13019.3
12649.5
12595.5
12966.2
12926
13138.2
13203.8
13538.3
13706.7
13899
14277.9
14524.4
14755.1
14900.1
14783.5
14768.9
14757.1
14606.4
14596.9
14717.7
15097.6
15378.1
15705
16185.8
16143.5
15937.3
15700.5
15105.3
14407.5
13577.1
12951.4
12452.6
12141.1
11842.9
11670.6
11487.7
11434.9
11347.1
11381.5
11353.6
11256.7
11252.9
11172.6
11147.3
11181.1
11336.3
11353.2
11256.8
11334.1
11374.9
11425.6
11327.3
11346.1
11676.2
11667.5
11559.2
11297.5
11465.1
11559.5
11335.8
11070.8
11001.4
11020.7
11088.1
11169.7
11049.5
11275.2
11587.3
12041.4
12510.6
12905.1
13181.1
13575.8
13699.7
13665.7
13484
13262.7
13297.3
13116
13333.3
13522.9
13888.2
14236.8
14616.3
14777.7
15016.8
14460.2
13400.3
12306.8
11025.2
10101.8
9304.58
8571.07
8366
8071.04
7743.46
7686.93
7618.52
7531.31
7467.37
7386.12
7420.52
7250.77
7263.44
7330.52
7380.03
7467.6
7385.83
7540.66
7594.94
7717.21
7736.7
7885.02
8041.54
8244.11
8289.08
8423.25
8593.34
8555.85
8482.39
8401.94
8157.79
8166.03
8060.12
7845
7978.87
7925.87
7729.62
7735.5
7840.79
7864.36
8006.29
7970.12
8177.44
8263.92
8350.51
8614.38
8829.34
9091.04
9286.46
9830.34
10473.9
11275.6
12361
14013.4
15853.6
18687.9
22214.9
26759.3
32597.2
40048.8
49033.7
58264.9
67017.6
71106
68142.5
58599.5
45267.4
32036.8
22272.5
16077.8
12567.6
10206.8
8800.58
7886.65
7421.08
7055.35
6883.38
6654.66
6651.15
6528.67
6562.1
6714.9
6780.16
6935.69
7034.14
6992.41
6929.56
6914.11
6812.38
6642.83
6332.8
6205.92
6047.83
5942.92
5823.8
5677.04
5601.52
5621.89
5723.32
5939.29
6091.54
6125.32
6238.4
6385.45
6646.78
6965.39
7365.58
7782.48
8222.05
9001.81
10033.7
11228.6
12913.6
15131.8
17875.3
22028.4
27150.4
34031.1
42493.4
53137.4
65713.7
79114.4
91353.2
97231.5
94282.9
80434.8
61111.5
41929.7
27581.9
18730.1
13359.4
10168.4
7983.29
6471.25
5738.91
5051
4577.4
4128.55
3907.86
3699.72
3478.93
3341.44
3275.38
3224.65
3077.22
2895.67
2814.11
2769.77
2733.23
2667.32
2642.17
2536.38
2469.97
2484.22
2411.57
2407.58
2370.04
2353.39
2320.28
2302.53
2285.46
2333.16
2256.18
2173.74
2156.15
2157.99
2180.42
2100.17
2135.6
2101.47
2071.18
2125.13
2153.24
2157.11
2082.33
2114.73
2175.63
2134.1
2095.87
2150.49
2070.11
2081.21
2074.42
2008.95
2018.44
1993.99
1989.52
2042.66
2049.56
2009.83
2041.42
2038.09
2041.85
2009.36
2039.48
1977.58
1962.31
2010.49
2014.55
2065.33
2108.93
2033.8
2047.38
2041.65
1964.91
1973.13
2009.71
1998.3
1963.67
2020.3
2012.62
2015.72
1952.76
1957.84
1965.07
1997.41
1934.11
1960.65
2005.87
1985.44
1994.17
2005.07
1999
2000.51
2052.32
2048.83
1983.52
2006.48
1998.73
2059.71
1975.82
2034.25
1943.31
2016.05
1976.51
2015.42
2002.04
2005.68
1994.85
1948.38
1959.8
1944.13
1911.41
1945.8
1971.96
1961.13
1967.58
1989.46
2003.94
1967.2
1983.68
1949.52
2011.33
1986.19
1928.78
1968.91
1984.49
2018.13
1987.1
1975.76
2023.59
2011.84
1967.5
1986.74
1999.66
1943.6
1896.02
1900.69
1953.25
1935.81
1968.95
1958.42
1970.82
1959.11
1984.86
1983.74
1983.81
1997.23
1929.59
1921.32
1978.46
2015.57
2038.18
1978.95
2021.07
2007.64
2023.24
1945.72
1942.04
1929.89
1981.58
1983.03
1953.04
2002.96
2039.26
2016.1
1953.37
1976.72
1953.26
1966.29
1944.21
1959.13
1982.3
1955.98
1887.27
1918.73
1922.45
2.57029
Ag4d
Ag in 2 mbar N2
2020
3
10
5
5
22
0
14
Casa Info Follows
0
0
0
0
File = E:/OwnCloud/XPS lab/EX340_CEC356_effect of lens modes.sle
[...]
3.24873
4423.46
3.24758
4382.1
3.24644
4178.54
3.2453
4239.58
3.24416
4342.51
3.24302
4246.14
3.24188
4273.06
3.24074
4289.67
3.2396
4154.39
3.23847
4307.69
3.23733
4252.9
3.2362
4346.69
3.23507
4309.89
3.23394
4402.18
3.23281
4345.16
3.23168
4369.24
3.23055
4348.81
3.22942
4544.18
3.2283
4605.04
3.22718
4625.6
3.22605
4548.95
3.22493
4721.9
3.22381
4577.74
3.22269
4614.78
3.22158
4608.31
3.22046
4559.74
3.21934
4612.26
3.21823
4284.17
3.21712
4429.38
3.216
4415.59
3.21489
4480.68
3.21378
4155.08
3.21267
4030.96
3.21157
4134.34
3.21046
4223.71
3.20936
4095.98
3.20825
3906.03
3.20715
3997.08
3.20605
4066.73
3.20495
4104.96
3.20385
4140.29
3.20275
3927.71
3.20165
3947.12
3.20055
4088.83
3.19946
3980.82
3.19837
3836.11
3.19727
3853.49
3.19618
4030.66
3.19509
4077.12
3.194
3860.77
3.19291
4003.41
3.19183
3904.15
3.19074
3929.67
3.18966
3786.98
3.18857
3829.08
3.18749
3692.18
3.18641
3924.76
3.18533
4042.23
3.18425
3922.19
3.18317
3914.24
3.18209
3819.78
3.18102
4065.61
3.17994
3829.73
3.17887
3830.43
3.17779
3859.53
3.17672
3873.51
3.17565
4054.48
3.17458
3712.84
3.17351
3764.38
3.17245
3984.12
3.17138
3840.04
3.17031
3933.34
3.16925
3937.14
3.16819
4022.12
3.16712
3965.19
3.16606
3860.74
3.165
3954.88
3.16394
4026.61
3.16289
4035.12
3.16183
3957.62
3.16077
3955.71
3.15972
4075.28
3.15867
4094.83
3.15761
3942.57
3.15656
4034.3
3.15551
3998.21
3.15446
3935.01
3.15341
3907.68
3.15237
3936.25
3.15132
3779
3.15027
4134.13
3.14923
4087.05
3.14819
3888.35
3.14714
4235.93
3.1461
3838.5
3.14506
3936.35
3.14402
3917.68
3.14299
4014.09
3.14195
4100.39
3.14091
4110.77
3.13988
3996.44
3.13884
4238.18
3.13781
3978.11
3.13678
3820.62
3.13575
3908.61
3.13472
4064.88
3.13369
3894.14
3.13266
3925.27
3.13164
4063.29
3.13061
3908.39
3.12959
4196.17
3.12856
3958.72
3.12754
4172.96
3.12652
4039.38
3.1255
3979.58
3.12448
4020.06
3.12346
3940.22
3.12244
4087.16
3.12142
4159.48
3.12041
4092.37
3.11939
4165.75
3.11838
4054.3
3.11737
4006.74
3.11635
4097.75
3.11534
4188.24
3.11433
4110.41
3.11332
3908.15
3.11232
4149.78
3.11131
4079.78
3.1103
3994.36
3.1093
4161.42
3.10829
4029.45
3.10729
4083.77
3.10629
4193.15
3.10529
4201.62
3.10429
3999.06
3.10329
4241.18
3.10229
3940.87
3.10129
4168.04
3.1003
4225.49
3.0993
4042.11
3.09831
4164.41
3.09731
4281.68
3.09632
4207.93
3.09533
4171.46
3.09434
4153.06
3.09335
4271.13
3.09236
4167.08
3.09137
4123.1
3.09039
4210.99
3.0894
4205.27
3.08842
4042.11
3.08743
4121.73
3.08645
4249.82
3.08547
4479.98
3.08449
4165.02
3.08351
4509.13
3.08253
4060.02
3.08155
4140.88
3.08057
4254.91
3.0796
4027.01
3.07862
4029.59
3.07765
4266.65
3.07667
4140.48
3.0757
4189.88
3.07473
4253.46
3.07376
4315.81
3.07279
4195.54
3.07182
4367.95
3.07085
4338.23
3.06988
4298.79
3.06892
4358.23
3.06795
4364.74
3.06699
4605.43
3.06602
4323.5
3.06506
4398.94
3.0641
4169.57
3.06314
4187.77
3.06218
4429.05
3.06122
4336.91
3.06026
4257.05
3.0593
4479.06
3.05835
4230.36
3.05739
4332.44
3.05644
4273.3
3.05548
4329.74
3.05453
4205.36
3.05358
4323.06
3.05263
4279.44
3.05168
4132.8
3.05073
4637.94
3.04978
4168.57
3.04883
4307.58
3.04788
4267.47
3.04694
4442.65
3.04599
4484.21
3.04505
4380.25
3.04411
4273.67
3.04317
4338.78
3.04222
4333.27
3.04128
4284.15
3.04034
4357.61
3.03941
4395.36
3.03847
4467.19
3.03753
4451.51
3.03659
4443.41
3.03566
4530.6
3.03472
4345.38
3.03379
4342.84
3.03286
4321.09
3.03193
4470.33
3.031
4481.85
3.03007
4420.36
3.02914
4330.86
3.02821
4709.45
3.02728
4256.12
3.02635
4413.99
3.02543
4490.84
3.0245
4421.88
3.02358
4386.12
3.02266
4282.74
3.02173
4554.95
3.02081
4590.15
3.01989
4663.24
3.01897
4385.63
3.01805
4336.9
3.01713
4554.97
3.01622
4549.02
3.0153
4464.37
3.01438
4359.42
3.01347
4440.85
3.01256
4354.77
3.01164
4423.69
3.01073
4576.91
3.00982
4407.31
3.00891
4467.11
3.008
4454
3.00709
4499.09
3.00618
4325.07
3.00527
4353.55
3.00437
4281.02
3.00346
4319.19
3.00256
4502.25
3.00165
4334.91
3.00075
4223.16
2.99985
4349.21
2.99894
4118.36
2.99804
4237.11
2.99714
4280.15
2.99624
4474.39
2.99535
4472.02
2.99445
4474.66
2.99355
4515.49
2.99266
4586.42
2.99176
4454.75
2.99087
4685.28
2.98997
4778.61
2.98908
4981.83
2.98819
4866.46
2.9873
5280.69
2.98641
4941.21
2.98552
5156.34
2.98463
5411.17
2.98374
5258.7
2.98285
5206.13
2.98197
5043.66
2.98108
4763.3
2.98019
4501.34
2.97931
4376.57
2.97843
4397.42
2.97754
4284.86
2.97666
4199.71
2.97578
3913.86
2.9749
4099.61
2.97402
4127.67
2.97314
3843.44
2.97227
3878.8
2.97139
3946.28
2.97051
3960.96
2.96964
3809.24
2.96876
3650.33
2.96789
3646.22
2.96702
3725.82
2.96614
3992.73
2.96527
3657.14
2.9644
3799.96
2.96353
3774.99
2.96266
3529.42
2.96179
3768.56
2.96092
3822.41
2.96006
3823.06
2.95919
3712.82
2.95833
3805.78
2.95746
3468.24
2.9566
3558.21
2.95573
3740.78
2.95487
3563.15
2.95401
3619.72
2.95315
3798.99
2.95229
3678.06
2.95143
3712.94
2.95057
3817.61
2.94971
3695.38
2.94885
3592.94
2.948
3781.11
2.94714
3446.47
2.94629
3643.52
2.94543
3556.18
2.94458
3784.52
2.94373
3845.87
2.94287
3788.2
2.94202
3573.63
2.94117
4067.55
2.94032
3840.76
2.93947
3705.87
2.93863
3617.16
2.93778
3825.15
2.93693
3747.72
2.93608
3905.29
2.93524
3598.54
2.93439
3832.58
2.93355
3765.81
2.93271
3841.52
2.93187
3662.92
2.93102
3725.11
2.93018
3847.08
2.92934
3718.74
2.9285
3793.88
2.92766
3751.4
2.92683
3821.71
2.92599
3882.2
2.92515
3649.37
2.92432
3850.62
2.92348
3878.55
2.92265
3821.96
2.92181
3719.16
2.92098
3798.73
2.92015
3732.78
2.91931
3814.6
2.91848
3897.21
2.91765
3983.49
2.91682
3885.94
2.91599
3880.67
2.91517
4080.48
2.91434
3797.76
2.91351
3999.21
2.91269
3750.24
2.91186
3921.24
2.91104
3926.01
2.91021
3976.95
2.90939
3883.47
2.90857
3695.35
2.90774
3992.9
2.90692
4038.43
2.9061
4051.32
2.90528
4000.28
2.90446
3855.7
2.90364
3979.1
2.90283
4034.96
2.90201
3922.48
2.90119
4132.57
2.90038
3830.72
2.89956
4028.54
2.89875
3805.12
2.89794
3840.77
2.89712
4027.17
2.89631
3784.94
2.8955
4075.17
2.89469
3951.06
2.89388
3861.71
2.89307
4067.62
2.89226
4066.39
2.89145
4137.01
2.89064
3775
2.88984
4228.54
2.88903
3891.33
2.88823
4301.69
2.88742
4311.39
2.88662
4098.96
2.88581
4210.67
2.88501
4080.84
2.88421
4034.47
2.88341
4260.34
2.88261
4046.67
2.88181
4041.15
2.88101
3980.88
2.88021
4236.66
2.87941
4082.99
2.87861
3937.87
2.87782
4141.99
2.87702
4098.27
2.87622
4164.79
2.87543
4040.16
2.87464
4072.77
2.87384
4061.63
2.87305
4100.04
2.87226
4026.89
2.87147
4097.38
2.87067
4247.72
2.86988
4208.6
2.86909
4096.72
2.86831
3876.48
2.86752
4098.69
2.86673
3899.53
2.86594
4128.51
2.86516
4100.64
2.86437
4087
2.86359
3949.9
2.8628
3770.24
2.86202
4239.81
2.86124
4069.52
2.86045
4073.37
2.85967
3952.05
2.85889
4181.67
2.85811
3944.02
2.85733
4153.2
2.85655
4078.42
2.85577
4046.67
2.85499
4116.66
2.85422
4062.57
2.85344
4324.33
2.85266
3937.51
2.85189
4333.44
2.85111
4302.2
2.85034
4226.49
2.84957
4404.12
2.84879
4179
2.84802
4040.9
2.84725
3996.55
2.84648
3737.04
2.84571
3612.17
2.84494
3427.23
2.84417
3615.04
2.8434
3149.39
2.84263
3244.38
2.84187
3343.31
2.8411
2865.49
2.84033
3268.71
2.83957
3089.97
2.8388
3120.38
2.83804
2933.43
2.83727
3016.23
2.83651
3281.07
2.83575
3605.06
2.83499
3524.4
2.83423
3920.08
2.83347
4165.32
2.83271
4429.7
2.83195
4944.53
2.83119
5435.01
2.83043
6323.54
2.82967
7022.42
2.82892
7629.95
2.82816
7777.13
2.8274
8052.27
2.82665
7672.96
2.82589
6814.5
2.82514
6348.4
2.82439
5271.04
2.82364
4408.25
2.82288
3603.11
2.82213
3091.62
2.82138
3011.3
2.82063
2480.32
2.81988
2034.11
2.81913
2029.75
2.81838
1867.56
2.81764
1374.62
2.81689
1440.04
2.81614
1069.72
2.8154
1100.06
2.81465
1089.36
2.81391
992.823
2.81316
866.148
2.81242
790.635
2.81168
808.686
2.81093
547.8
2.81019
852.179
2.80945
618.922
2.80871
729.53
2.80797
797.204
2.80723
776.243
2.80649
907.95
2.80575
592.024
2.80501
909.765
2.80428
591.074
2.80354
577.453
2.8028
451.1
2.80207
500.618
2.80133
342.805
2.8006
405.064
2.79987
532.593
2.79913
601.995
2.7984
316.069
2.79767
368.816
2.79694
428.636
2.79621
132.73
2.79548
110.099
2.79475
362.042
2.79402
387.861
2.79329
465.656
2.79256
182.827
2.79183
480.276
2.79111
388.202
2.79038
99.4057
2.78965
297.288
2.78893
413.75
2.7882
176.191
2.78748
176.813
2.78676
386.915
2.78603
5.89776
2.78531
256.663
2.78459
236.01
2.78387
330.539
2.78315
78.8524
2.78243
65.3492
2.78171
357.03
2.78099
151.696
2.78027
271.647
2.77955
146.284
2.77884
167.007
2.77812
-39.1828
2.7774
74.3146
2.77669
279
2.77597
296.474
2.77526
214.536
2.77454
161.888
2.77383
277.83
2.77312
158.463
2.7724
104.487
2.77169
-13.9985
2.77098
162.709
2.77027
3.80819
2.76956
33.2009
2.76885
154.987
2.76814
251.167
2.76743
-29.7576
2.76673
-108.688
2.76602
123.578
2.76531
230.14
2.7646
133.099
2.7639
75.5546
2.76319
351.708
2.76249
137.76
2.76178
349.41
2.76108
-39.5398
2.76038
0
2.75968
2.75953
Au4p - background subtracted
Au in vacuum
2020
3
8
7
33
12
0
16
Casa Info Follows
0
0
0
0
File = E:/OwnCloud/XPS lab/EX340_CEC356_effect of lens modes.sle
Group = Au in vacuum , #Treatments: , #Temp: RT , #Pressure:, #Gas1:, #Gas2:, #Gas Ratio:, #Comments:
First of group = 0
Analyzer lens = LargeArea:1.5kV
Analyzer slit = 4:7x20c\C:mesh
Scan mode = FixedAnalyzerTransmission
Kinetic energy start = 656.61
C:\Users\Mark\ownCloud\Muelheim Group\Projects\Gas phase background\EX340_CEC356_effect of lens modes.vms
Sum of 20 spectra in column containing 20 scans
CasaXP6_Ag in vacuum_Au in vacuum , #Treatments: , #Temp: RT , #Pressure:, #Gas1:, #Gas2:, #Gas Ratio:, #Comments:.vms
c:\users\mark\owncloud\muelheim group\projects\gas phase background\ex340_cec356_au n2 largearea.vms
XPS
1e+037
Al
1486.61
0
0
0
54.5
180
FAT
20
1
4.156
0
0
0
0
0
Au
4p
-1
kinetic energy
eV
656.61
0.1
2
counts
d
Transmission
d
pulse counting
2
1
0
0
0
0
2
ESCAPE DEPTH TYPE
d
0
MFP Exponent
d
0
3.38623
7624.95
3.3852
7885.68
3.3839
7496.52
3.38261
8100.75
3.38131
7876.09
3.38002
8107.32
3.37873
8074.76
3.37745
7967.19
3.37616
7704.93
3.37487
7871.37
3.37359
7875.3
3.37231
8201.94
3.37103
8140.37
3.36975
8100.71
3.36847
7923.65
3.36719
8058.88
3.36592
7804.72
3.36464
8023.76
3.36337
7984.9
3.3621
8012.34
3.36083
7856.47
3.35956
8176.91
3.3583
8025.95
3.35703
7882.39
3.35577
8235.03
3.35451
8053.57
3.35325
8171.01
3.35199
7821.65
3.35073
7846.89
3.34947
7942.73
3.34822
7762.48
3.34697
7918.22
3.34571
8074.06
3.34446
8143.71
3.34321
7872.35
3.34196
8044.99
3.34072
8510.14
3.33947
7874.18
3.33823
7925.93
3.33699
8014.88
3.33575
8073.33
3.33451
7823.17
3.33327
8033.82
3.33203
8158.07
3.3308
8172.12
3.32956
7952.97
3.32833
8043.22
3.3271
8214.87
3.32587
8378.03
3.32464
7941.78
3.32341
8179.34
3.32219
8229.49
3.32096
8415.95
3.31974
8234.1
3.31852
8233.96
3.3173
8299.52
3.31608
8275.98
3.31486
8427.84
3.31364
8260.2
3.31243
8334.76
3.31121
8277.72
3.31
8246.89
3.30879
8319.25
3.30758
8324.31
3.30637
8351.28
3.30516
8220.05
3.30396
8184.92
3.30275
8379.99
3.30155
8207.36
3.30035
8171.33
3.29915
8432.2
3.29795
8272.37
3.29675
8384.65
3.29555
8379.22
3.29436
8374.5
3.29316
8105.78
3.29197
8404.06
3.29078
8511.14
3.28959
8504.62
3.2884
8467.8
3.28721
8192.98
3.28603
8570.17
3.28484
8481.96
3.28366
8302.34
3.28248
8651.53
3.28129
8420.92
3.28011
8441.91
3.27894
8498.31
3.27776
8586.6
3.27658
8667.6
3.27541
8424.79
3.27423
8484.09
3.27306
8527.09
3.27189
8317.69
3.27072
8533.79
3.26955
8658.4
3.26838
8572.9
3.26722
8568.11
3.26605
8505.72
3.26489
8448.92
3.26373
8617.64
3.26257
8759.95
3.26141
8453.56
3.26025
8396.58
3.25909
8509.6
3.25793
8431.21
3.25678
8786.43
3.25563
8619.26
3.25447
8713.48
3.25332
8741.91
3.25217
8592.93
3.25102
8566.96
3.24988
8675.89
3.24873
8855.52
3.24758
8646.76
3.24644
8758.49
3.2453
8870.53
3.24416
9006.67
3.24302
8937.31
3.24188
9063.85
3.24074
8934.9
3.2396
9022.74
3.23847
8944.89
3.23733
9372.54
3.2362
9458.69
3.23507
9629.85
3.23394
9544.9
3.23281
9802.86
3.23168
10204.6
3.23055
10254.8
3.22942
10655.5
3.2283
10980.2
3.22718
10862
3.22605
10984.2
3.22493
11397.2
3.22381
11475.5
3.22269
11547.2
3.22158
11344.5
3.22046
11136
3.21934
10925.5
3.21823
10632.3
3.21712
10317.5
3.216
9957.18
3.21489
9906.83
3.21378
9499.97
3.21267
8925.71
3.21157
9053.84
3.21046
8686.86
3.20936
8381.18
3.20825
8553.09
3.20715
8312.1
3.20605
7949.8
3.20495
8174.58
3.20385
8132.06
3.20275
8006.73
3.20165
7876.29
3.20055
7687.94
3.19946
7876.08
3.19837
7763.51
3.19727
7251.03
3.19618
7627.63
3.19509
7720.42
3.194
7299.1
3.19291
7479.17
3.19183
7628.52
3.19074
7563.46
3.18966
7650.88
3.18857
7379.09
3.18749
7322.98
3.18641
7380.65
3.18533
7303.41
3.18425
7516.25
3.18317
7481.78
3.18209
7296.18
3.18102
7294.87
3.17994
7244.54
3.17887
7260.38
3.17779
7158.91
3.17672
7254.72
3.17565
7353.61
3.17458
7241.17
3.17351
7286.01
3.17245
7125.94
3.17138
7126.53
3.17031
7301.81
3.16925
7111.36
3.16819
7210.99
3.16712
7272.89
3.16606
7428.46
3.165
7201.62
3.16394
7213.34
3.16289
7455.94
3.16183
7262.71
3.16077
7101.96
3.15972
7243.07
3.15867
7326.86
3.15761
7219.12
3.15656
7153.95
3.15551
7236.55
3.15446
7316.12
3.15341
7197.06
3.15237
7077.26
3.15132
7517.04
3.15027
7503.78
3.14923
7037.49
3.14819
7361.37
3.14714
7355.71
3.1461
7082.22
3.14506
7300.7
3.14402
7433.94
3.14299
7214.95
3.14195
7302.81
3.14091
7471.25
3.13988
7537.04
3.13884
7207.3
3.13781
7342.62
3.13678
7237.21
3.13575
7424.45
3.13472
7154.05
3.13369
7274.42
3.13266
7223.34
3.13164
7297.93
3.13061
7325.37
3.12959
7274.47
3.12856
7363.93
3.12754
7135.65
3.12652
7468.82
3.1255
7393.36
3.12448
7308.64
3.12346
7516.99
3.12244
7412.68
3.12142
7580.84
3.12041
7499.14
3.11939
7016.1
3.11838
7330.62
3.11737
7407.08
3.11635
7439.2
3.11534
7299.17
3.11433
7447.2
3.11332
7326.37
3.11232
7559.5
3.11131
7173.17
3.1103
7459.79
3.1093
6973.87
3.10829
7418.69
3.10729
7411.96
3.10629
7403.48
3.10529
7333.64
3.10429
7499.85
3.10329
7354.11
3.10229
7679.11
3.10129
7343.46
3.1003
7267.96
3.0993
7525.69
3.09831
7445.28
3.09731
7576.1
3.09632
7686.97
3.09533
7535.78
3.09434
7604.04
3.09335
7287.03
3.09236
7162.77
3.09137
7406.05
3.09039
7579.47
3.0894
7476.04
3.08842
7351.35
3.08743
7573
3.08645
7482.9
3.08547
7453.84
3.08449
7588.03
3.08351
7351.07
3.08253
7177.45
3.08155
7300.69
3.08057
7483.56
3.0796
7668.99
3.07862
7858.27
3.07765
7611.3
3.07667
7700.67
3.0757
7597
3.07473
7518.58
3.07376
7524.81
3.07279
7626.89
3.07182
7360.53
3.07085
7822.02
3.06988
7625.86
3.06892
7678.46
3.06795
7805.81
3.06699
7459.92
3.06602
7729.38
3.06506
7545.9
3.0641
7685.78
3.06314
7798.72
3.06218
7555.31
3.06122
7490.86
3.06026
7691.67
3.0593
7816.94
3.05835
7439.07
3.05739
7522.26
3.05644
7616.92
3.05548
8052.73
3.05453
7879.11
3.05358
7783.55
3.05263
7692.45
3.05168
7553.52
3.05073
7790.15
3.04978
7961.05
3.04883
7690.31
3.04788
7855.64
3.04694
7706.93
3.04599
7848.89
3.04505
7630.82
3.04411
7773.92
3.04317
7743.38
3.04222
7772.92
3.04128
7736.72
3.04034
7895.9
3.03941
7637.44
3.03847
7797.26
3.03753
8033.35
3.03659
7946.41
3.03566
7875.44
3.03472
7778.45
3.03379
7789.93
3.03286
8171.98
3.03193
8060.91
3.031
7613.12
3.03007
7915.5
3.02914
7950.76
3.02821
7889.89
3.02728
7833.61
3.02635
8050.7
3.02543
8073.77
3.0245
8240.51
3.02358
8028.44
3.02266
7783.85
3.02173
7947.74
3.02081
8201.41
3.01989
7902.36
3.01897
8010.4
3.01805
7920.92
3.01713
7933.32
3.01622
8029.8
3.0153
8013.27
3.01438
7783.73
3.01347
7920.76
3.01256
8139.49
3.01164
8048.3
3.01073
7861.2
3.00982
8300.79
3.00891
7837.26
3.008
7989.13
3.00709
8336.48
3.00618
7869.02
3.00527
8059.75
3.00437
8105.68
3.00346
8271.69
3.00256
8325.8
3.00165
8216.7
3.00075
8559.29
2.99985
8421.07
2.99894
8601.45
2.99804
8789.73
2.99714
8822.7
2.99624
9153.06
2.99535
8982.12
2.99445
9519.28
2.99355
9535.23
2.99266
9660.38
2.99176
9871.43
2.99087
10693
2.98997
10863.3
2.98908
11173.8
2.98819
11800.5
2.9873
12021.8
2.98641
12292.5
2.98552
12201.7
2.98463
12218.9
2.98374
12042.4
2.98285
11358
2.98197
10967.5
2.98108
10474.9
2.98019
10148.5
2.97931
9780.91
2.97843
9174.4
2.97754
8898.19
2.97666
8212.39
2.97578
8328.09
2.9749
7798.31
2.97402
7769.33
2.97314
7495.16
2.97227
7209.5
2.97139
7021.75
2.97051
7073.81
2.96964
6936.87
2.96876
7209.75
2.96789
7058.83
2.96702
6878.11
2.96614
6578.5
2.96527
6697.6
2.9644
6699.3
2.96353
6675.81
2.96266
6418.42
2.96179
6546.53
2.96092
6605.14
2.96006
6516.06
2.95919
6411.28
2.95833
6253.3
2.95746
6454.12
2.9566
6336.73
2.95573
6117.55
2.95487
6496.77
2.95401
6322.08
2.95315
6437.7
2.95229
6480.91
2.95143
6445.81
2.95057
5968.61
2.94971
6206.11
2.94885
6077.4
2.948
6085.39
2.94714
6037.47
2.94629
6391.04
2.94543
6434.11
2.94458
6278.26
2.94373
6395.21
2.94287
6075.15
2.94202
6270.08
2.94117
6339.1
2.94032
6471.51
2.93947
6104.31
2.93863
6373.9
2.93778
6219.38
2.93693
6201.64
2.93608
6465.89
2.93524
6128.12
2.93439
6310.94
2.93355
6292.45
2.93271
6412.34
2.93187
6087.02
2.93102
6389.47
2.93018
6229.41
2.92934
6458.34
2.9285
6332.44
2.92766
6385.03
2.92683
6088
2.92599
6365.84
2.92515
6360.87
2.92432
5997.97
2.92348
6332.56
2.92265
6176.82
2.92181
6176.56
2.92098
6056.08
2.92015
6144.57
2.91931
6361.84
2.91848
6160.69
2.91765
6329.6
2.91682
6164.2
2.91599
6291.46
2.91517
6126
2.91434
6478.42
2.91351
6089.7
2.91269
6593.56
2.91186
6258.99
2.91104
6294.58
2.91021
6123.25
2.90939
6418.49
2.90857
6537.49
2.90774
6284.17
2.90692
6358.91
2.9061
6508.62
2.90528
6464.89
2.90446
6391.33
2.90364
6334.04
2.90283
6853.61
2.90201
6450.15
2.90119
6681.85
2.90038
6436.81
2.89956
6531.04
2.89875
6578.23
2.89794
6710.88
2.89712
6727.89
2.89631
6784.66
2.8955
6402.39
2.89469
6508.28
2.89388
6521.64
2.89307
6608.84
2.89226
6678.31
2.89145
6675.74
2.89064
6836.62
2.88984
6807.26
2.88903
7002.85
2.88823
6618.5
2.88742
7109
2.88662
6866.16
2.88581
7004.27
2.88501
6673.03
2.88421
6741.85
2.88341
6815.52
2.88261
7135.54
2.88181
6761.11
2.88101
7024.23
2.88021
7216.9
2.87941
7001.22
2.87861
7096.39
2.87782
7220.71
2.87702
7289.77
2.87622
6840.48
2.87543
7068.94
2.87464
6980.45
2.87384
7157.2
2.87305
7190.69
2.87226
7050.03
2.87147
7180.61
2.87067
7116.94
2.86988
6767.31
2.86909
6928.52
2.86831
7249.07
2.86752
7354.06
2.86673
7439.2
2.86594
7325.77
2.86516
7059.49
2.86437
7034.84
2.86359
7166.03
2.8628
6948.87
2.86202
7298.94
2.86124
7092.96
2.86045
7204.02
2.85967
7096.82
2.85889
7034.37
2.85811
7256.66
2.85733
7170.59
2.85655
7083.27
2.85577
6922.99
2.85499
7165.55
2.85422
7175.77
2.85344
7104.93
2.85266
7049.73
2.85189
7072.08
2.85111
7373.78
2.85034
7070.53
2.84957
7359.73
2.84879
7260.28
2.84802
7277.07
2.84725
7220.72
2.84648
7551.32
2.84571
7654.86
2.84494
7260.46
2.84417
7608.51
2.8434
7696.22
2.84263
7517.27
2.84187
8015.98
2.8411
7853.45
2.84033
8127.76
2.83957
8214.14
2.8388
8431.76
2.83804
8911.85
2.83727
9216.79
2.83651
9362.18
2.83575
10165.2
2.83499
11001.8
2.83423
11676.7
2.83347
12661.9
2.83271
14147.4
2.83195
15920.7
2.83119
17891.4
2.83043
20260.7
2.82967
22765.4
2.82892
25132.2
2.82816
26667.3
2.8274
26316.8
2.82665
25080.8
2.82589
22740.5
2.82514
19213.4
2.82439
16498.3
2.82364
13925
2.82288
11671.7
2.82213
9980.17
2.82138
8520.8
2.82063
6982.89
2.81988
6418.75
2.81913
5848.88
2.81838
4583.67
2.81764
4179.63
2.81689
4024.96
2.81614
3844.46
2.8154
3512.13
2.81465
2956.37
2.81391
2553.99
2.81316
2395.57
2.81242
2211.52
2.81168
2066.05
2.81093
1792.44
2.81019
1751.81
2.80945
1909.96
2.80871
1996.28
2.80797
1920.77
2.80723
2113.34
2.80649
2013.18
2.80575
1663.4
2.80501
1168.19
2.80428
1016.06
2.80354
879.212
2.8028
864.738
2.80207
897.743
2.80133
867.026
2.8006
640.487
2.79987
684.329
2.79913
673.25
2.7984
776.852
2.79767
735.035
2.79694
795.399
2.79621
732.745
2.79548
535.773
2.79475
457.484
2.79402
530.678
2.79329
470.656
2.79256
486.018
2.79183
546.965
2.79111
556.597
2.79038
602.315
2.78965
564.118
2.78893
392.608
2.7882
472.885
2.78748
106.65
2.78676
460.003
2.78603
622.943
2.78531
455.373
2.78459
348.292
2.78387
315.401
2.78315
315
2.78243
180.09
2.78171
400.271
2.78099
333.644
2.78027
285.109
2.77955
31.6666
2.77884
261.917
2.77812
187.261
2.7774
283.199
2.77669
285.332
2.77597
99.2597
2.77526
214.883
2.77454
581.402
2.77383
230.117
2.77312
153.029
2.7724
230.838
2.77169
1.54529
2.77098
57.6506
2.77027
186.255
2.76956
115.558
2.76885
0
2.76814
0
2.76743
0
2.76673
0
2.76602
0
2.76531
0
2.7646
0
2.7639
0
2.76319
0
2.76249
0
2.76178
0
2.76108
0
2.76038
0
2.75968
2.75953
end of experiment