File: data/He/Au, Ag, Cu in He.vms
VAMAS Surface Chemical Analysis Standard Data Transfer Format 1988 May 4
Not Specified
Not Specified
Not Specified
Not Specified
13
Casa Info Follows CasaXPS Version 2.3.24rev1.0W
0
Created by SpecsLab Prodigy, Version 4.63.4-r87993
SourceAnalyserAngle: 56.500000 d
CasaRowLabel:1. Ag in vacuum
CasaRowLabel:1. Ag in 4 mbar He
CasaRowLabel:2. Au in 4 mbar He
CasaRowLabel:2. Au in vacuum
CasaRowLabel:3. Cu in 4mbar He
CasaRowLabel:3. Cu in vacuum
CasaRowLabel:4. Au in 23 mbar He
CasaRowLabel:4. Au in vacuum
CasaRowLabel:4. Au in 12 mbar He
NORM
REGULAR
12
1
Exp Variable
d
0
0
0
0
31
AgMNN
1. Ag in vacuum
2020
3
6
16
4
13
0
13
Casa Info Follows
0
0
0
0
EX340_CEC356_effect of lens modes.sle
Group = Ag in vacuum
First of group = 0
Analyzer lens = AngleResolvedMode22:1.5kV
Analyzer slit = 4:7x20c\C:mesh
Scan mode = FixedAnalyzerTransmission
Kinetic energy start = 266.61
Sum of 9 spectra in column containing 10 scans
XPS
0
Al
1486.61
0
0
0
54.5
180
FAT
20
1
4.156
0
0
0
0
0
AgMNN

-1
kinetic energy
eV
266.61
0.1
2
counts
d
Transmission
d
pulse counting
1
1
0
0
0
0
2
ESCAPE DEPTH TYPE
d
0
MFP Exponent
d
0
798.328
4.42285
9044.64
8941.33
8974.57
9026.14
8971.95
9139.2
9027.27
8964.53
9003.94
8990.66
8840.12
8772.4
8825.88
8880.63
8828.48
8975.28
8935.48
8751.08
8890.44
8779.79
8878.05
8761.77
8672.38
8591.76
8753.95
8691.81
8758.3
8831.57
8747.43
8557.86
8629.9
8621.64
8554.91
8649.42
8503.73
8612.18
8476.03
8643.01
8563.55
8554.34
8568.62
8604.92
8607.47
8498.77
8594.09
8543.27
8423.14
8501.94
8409.66
8584.28
8433.36
8393.72
8470.77
8506.99
8528.34
8351.64
8480.32
8377.83
8352.72
8451.57
8460
8439.62
8520.2
8547.17
8386.52
8467.07
8557.41
8435.9
8342.11
8409.17
8368.93
8506.42
8440.51
8417.01
8379.14
8460
8441.8
8350.58
8357.16
8429.99
8454.04
8348.04
8458.02
8542.85
8378.22
8344.34
8393.19
8433.55
8512.91
8529.21
8503
8544.02
8400.31
8221.62
8390.61
8485.37
8511.5
8524.12
8455.05
8389.94
8537.26
8505.3
8398.65
8418.61
8368.16
8399.95
8493.27
8421.3
8490.21
8538
8514.63
8388.36
8428.31
8428.83
8488.77
8477.06
8605.83
8453.32
8635.16
8605.46
8617.82
8482.85
8674.89
8575.41
8567.73
8504.11
8464.53
8582.39
8496.89
8490.05
8594.17
8579.47
8607.19
8643.14
8722.09
8560.9
8459.4
8513.69
8650.54
8570.72
8541.42
8695.68
8589.69
8569.44
8625.14
8581.41
8608.41
8608.03
8599.97
8706.89
8671.69
8656.77
8568.94
8602.95
8693.37
8723.61
8727.82
8693.6
8696.43
8790.83
8876.82
8801.51
8837.08
8820.23
8775.21
8789.21
8848.7
8754.42
8853.38
8654.38
8795.88
8915.03
8962.49
8937.97
8952.26
8801.4
8968.62
8903.88
8986.3
8909.3
8968.15
8989.7
8855.86
8860.67
9096.75
9042.16
8830.13
8918.12
9004.45
9069.85
9138.07
9123.86
9163.4
9045.23
9034.72
8990.56
9039.56
9068.35
9230.47
9203.52
9235.02
9333.37
9215.42
9124.42
9143.7
9142.54
9148.71
9233.06
9261.2
9233.3
9115.91
9132.97
9311.46
9321.11
9211.97
9166.8
9271.01
9264.5
9373.1
9225.26
9244.54
9509.62
9449.89
9479.76
9370.47
9344.71
9346.72
9449.98
9546.37
9570.38
9483.97
9406.44
9429.91
9382.19
9505.21
9565.7
9498.71
9386.47
9305.34
9425.42
9538.3
9632.86
9385.88
9370.69
9558.35
9436.39
9545.42
9522.92
9542.68
9502.7
9528.42
9647.88
9499.91
9524.74
9477.58
9405.34
9422.05
9506.98
9499.12
9504.66
9529.97
9626.14
9508.19
9544.41
9513.99
9481.62
9460.59
9562.4
9654.87
9597.42
9569.36
9490.48
9524.16
9526.38
9500.36
9643.39
9767.83
9720.96
9769.75
9595.89
9528.04
9532.34
9482.91
9662.75
9652.97
9558.65
9485.3
9640.37
9634.96
9672.69
9516.81
9561.82
9593.34
9624.35
9432.49
9442.94
9477.26
9499.08
9431.09
9460.27
9442.21
9355.93
9371.39
9498.35
9335.6
9437.59
9436.82
9331.02
9363.98
9489.15
9501.58
9420.16
9507.74
9333.65
9314.25
9394.02
9376.8
9458.12
9437.01
9275.62
9351.9
9353.48
9290.88
9220.18
9191.25
9126.68
9140.84
9219.82
9157.36
9294.17
9277.35
9180.75
9222.5
9210.62
9242.72
9074.13
9133.16
9173.99
9227.14
9201.9
9252.28
9237.04
9239.14
9168.36
9194.92
9077.08
8909.66
8923.63
8881.9
9086.78
9049.89
8994.29
8948.6
8903.8
8921.37
8897.5
8835.38
8850.69
8858.84
8671.51
8703.19
8597.03
8608.18
8375.38
8546.49
8484.98
8500.08
8469.38
8567.95
8576.98
8533.4
8516.32
8417.57
8207.34
8258.96
8191
8259.64
8237.71
8155.93
8180.59
7999.18
8046.94
8195.18
8067.45
8086.04
7969.46
7965
8041.15
8021.65
7835.5
8048.44
7981.81
7898.48
7842.58
7656.15
7720.89
7737.94
7712.51
7741.28
7759.01
7664.72
7527.46
7539.94
7589.81
7601.6
7492.86
7566.32
7522.77
7433.17
7337.01
7372.74
7269.01
7366.94
7452.18
7252.27
7343.79
7457.63
7188.69
7054.84
7093.1
7082.26
7142.11
7035.4
7026.05
7055.74
7039.54
6871.65
6935.84
6893.12
6968.3
6985.47
6973.28
6840.76
6909.27
6753.67
6823.03
6845.4
6831.89
6935.17
6817.83
6753.67
6754.92
6791.51
6709.26
6751.82
6750.62
6711.33
6644.05
6558.97
6626.76
6639.29
6562.34
6647.75
6523.3
6472.45
6566.5
6480.55
6553.88
6528.83
6561.55
6536.25
6589.14
6484.61
6547.3
6487.28
6536.61
6524.02
6456.32
6335.11
6429.14
6494.57
6253.93
6400.05
6387.03
6348.13
6462.86
6393.71
6450.37
6395.38
6370.87
6420.22
6419.33
6406.26
6343.59
6320.29
6362.65
6381.9
6405.11
6305.02
6306.06
6451.21
6246.75
6304.58
6371.76
6322.4
6265.29
6316.22
6330.07
6337.37
6386.45
6328.11
6361.49
6194.49
6279.31
6327.14
6226.49
6247.44
6254.34
6231.65
6322.09
6287.67
6177.53
6221.02
6272.09
6185.94
6270.4
6256.4
6266.13
6279.86
6272.43
6167.41
6334.3
6411.07
6378.37
6379.98
6359.37
6261.83
6333.91
6273.81
6372.67
6280.21
6269.35
6204.94
6274.93
6398.23
6235.2
6211.91
6270.45
6176.23
6191.92
6285.43
6354.8
6374.89
6339
6310.78
6389.19
6329.92
6273.99
6178.25
6089.65
6408.41
6298.14
6384.65
6201.93
6325.67
6254.63
6348.57
6229.83
6187.23
6223.12
6426.11
6320.88
6326.33
6444.3
6388.4
6324.7
6280.28
6269.74
6301.03
6452
6351.4
6319.67
6398.81
6249.48
6327.67
6376.7
6426.24
6189.04
6356.05
6313.75
6342.32
6387.89
6374.45
6262.01
6376.36
6303.33
6445.38
6379.3
6375.25
6374.1
6422.14
6427.45
6307.22
6363.81
6379.37
6272.24
6393.85
6346.56
6418.96
6421.22
6430.66
6428.81
6406.29
6407.09
6406.51
6421.65
6469.03
6449.91
6428.19
6509.97
6507.56
6439.68
6453.7
6550.72
6574.22
6534.8
6364.89
6331.86
6449.25
6498.4
6464.91
6534.55
6370.57
6471.35
6517.24
6575.89
6472.09
6394.92
6386.1
6484.29
6627.1
6520.84
6308.31
6496.02
6690.87
6618.73
6510.96
6442.66
6497.5
6542.77
6522.19
6550.96
6634.42
6446.17
6502.38
6571.8
6455.51
6600.56
6446.59
6533.83
6561.57
6626.55
6485.47
6483.95
6515.98
6515.26
6539.08
6576.95
6553.6
6612.82
6582.63
6553.12
6750.18
6576.43
6571.92
6688.56
6557.47
6620.75
6696.6
6739.54
6594.48
6597.08
6728.72
6657.14
6686.41
6626.08
6574.06
6607.08
6600.18
6605.09
6571.32
6651.62
6578
6669.85
6606.86
6613.07
6669.99
6607.63
6640.36
6730.68
6632.61
6710.99
6706.4
6749.54
6676.31
6795.78
6742.23
6716.33
6714.36
6735.48
6658.26
6849.58
6788.15
6812.55
6763.65
6736.61
6745.27
6816.34
6827.36
6794.44
6685.03
6771.18
6810.06
6783.25
6813.11
6714.74
6765.44
6736.32
6753.17
6805.31
6850.58
6885.18
6855.02
6892.22
6927.65
6891.92
6772.05
6788.26
6836.84
6945.83
6898.27
6823.11
6773.33
6923.31
7033.02
7001.98
7032.16
7045.94
6906.48
6867.8
7054.88
6856.14
6975.6
7064.46
7019.13
7098.64
7058.2
6931.86
6969.27
6989.85
6906.42
6951.88
7078.03
7064.7
7096.98
7193.31
7220.59
7140.47
7305.76
7135.66
7313.08
7293.85
7255.83
7320.77
7319.36
7337
7366.04
7327.35
7370.27
7287.76
7363.38
7397.06
7390.53
7473.29
7488.68
7444.89
7499.89
7662.6
7675.02
7822.23
7747.78
7701.77
7676.68
7768.26
7553.04
7531.98
7633.65
7863.58
7980.74
7800.05
7724.2
7838.18
7866.37
7896.5
7999.13
8034.48
7950.06
8007.88
8126.85
8120.82
8172.12
8269.96
8327.81
8295.71
8349.19
8291.62
8358.25
8436.6
8489.95
8563.93
8524.89
8784.31
8761.05
8840.05
8902.24
9041.61
9180.03
9405.48
9436.03
9639.42
9575.46
9660.59
9631.09
9689.37
9642.05
9679.93
9551.78
9681.94
9607.4
9688.86
9661.25
9732.96
9749.94
9795.89
9657.82
9756.45
9878.57
10010.5
10092.7
10265.1
10408.9
10588
10752.9
11097.4
11601.8
12167.9
12742.3
13363.9
14191.2
14945.3
15517.1
15807.4
16112.7
16156
15708.5
15362.2
15081.4
14695.2
14531.5
14378.2
14331.2
14291.7
13982.9
13649.3
13552.5
13616.9
13465.2
13378.7
13321.8
13357
13166.4
12873.8
12561.2
12080.4
11906.5
11630
11338.2
11189.1
10919.5
10811.4
10813.7
10643.8
10385.2
10206.2
10153.2
9907.13
9714.56
9766.62
9547.82
9302.53
9232.72
9303.05
9199
9196.77
9221.63
9129.09
9158.65
8961.97
8986.05
9206.64
9196.92
9165.97
9432.26
9506.52
9722
10120.3
10548.6
11331.6
11882.3
12387.4
12932.8
13347.1
13579.6
13633.8
13482.9
12971.1
12112.8
11559.3
11069.2
10535.2
10024.2
9600.02
9415.93
9244.75
8948.08
8917.8
8657.04
8502.25
8176.61
7751.34
7545.75
7368.78
7074.89
6804.7
6551.63
6368.03
6127.21
6148.1
6171.58
6084.14
5970.53
5859.23
5855.8
5973.38
5798.92
5719.51
5756.91
5707.85
5733.23
5614.9
5691.69
5632.39
5571.36
5685.34
5543.74
5628.96
5585.16
5494.26
5464.75
5417.86
5408.65
5487.36
5329.06
5417.31
5354.45
5463.9
5318.32
5259.26
5253.29
5209.58
5149.06
5127.03
5154.99
5163.87
5035.67
5017.11
4996.22
5045.01
4998.85
5102.86
5048.76
5013.66
4937.1
4957.06
4962.97
4943.41
4805.47
4865.49
4816.1
4779.31
4823.53
4727.36
4767.61
4690.59
4628.74
4704.96
4695
4702.76
4677.25
4655.31
4555.98
4577.93
4506.88
4613.04
4583.19
4568.47
4667.16
4641.3
4630.07
4579.95
4512.43
4499.32
4565.24
4563.3
4486.9
4548.22
4650.18
4501.17
4524.3
4538.62
4514.89
4567.68
4461.38
4493.75
4451.21
4492.48
4420.57
4476.81
4469.78
4424.37
4494.95
4555.1
4485.98
4467.59
4341.37
4349.65
4370.71
4437.22
4489.59
4444.7
4405.17
4383.04
4448.64
4431.11
4486.18
4388
4409.12
4386.9
4428.26
4500.58
4448.38
4489.09
4390.2
4468.89
4453.18
4393
4396.77
4332.79
4274.12
4382.52
4404.16
4387.28
4395.7
4420.74
4312
4370.98
4377.65
4309.19
4318.76
4364.81
4440.02
4360.88
4293.92
4310.28
4332.35
4406.43
4279.09
4327.71
4287.76
4418.7
4397.79
4405.56
4306.1
4369.62
4409.03
4321.5
4373.64
4365.19
4336.25
4327.79
4225.64
4294.3
4379.32
4315.28
4383.32
4227.13
4255.52
4262.08
4325.21
4293.49
4299.92
4304.52
4323.1
4357.75
4319.35
4291
4369.56
4358.57
4384.28
4364.52
4398
4404.87
4391.03
4279.8
4235.46
4282.39
4243.24
4306.91
4265.83
4301.54
4270.4
4269.79
4398.46
4388.14
4315.22
4239.99
4326.7
4429.09
4338.08
4451.43
4477.9
4285.34
4320.18
4278.23
4316.09
4410.39
4314.68
4408.62
4393.01
4238.98
4311.42
4329.88
4272.61
4324.72
4218.21
4290.68
4318.35
4267.58
4339.78
4402.08
4402.28
4294.02
4265.32
4304.24
4295.27
4358.8
4350.76
4365.13
4296.8
4258.42
4342.24
4408.85
4385.91
4330.43
4448.85
4447.45
4369.63
4338.78
4385.68
4436.11
4374.29
4354.85
4416.09
4418.59
4348.9
4318.71
4373.73
4315.57
4331.25
4271.78
4273.53
4373.8
4365.24
4283.65
4255.42
4341.64
4365.78
4419.6
4356.84
4358.67
4353.01
4342.57
4318.83
4339.32
4408.92
4345.8
4308.67
4328.25
4424.6
4382
4353.75
4.42285
Ag3p
1. Ag in vacuum
2020
3
6
16
22
8
0
14
Casa Info Follows
0
0
0
0
File = E:/OwnCloud/XPS lab/EX340_CEC356_effect of lens modes.sle
Group = Ag in vacuum , #Treatments: , #Temp: RT , #Pressure: vacuum, #Gas1:, #Gas2:, #Gas Ratio:, #Comments:
First of group = 0
Analyzer lens = AngleResolvedMode22:1.5kV
Analyzer slit = 4:7x20c\C:mesh
Scan mode = FixedAnalyzerTransmission
Kinetic energy start = 686.61
C:\Users\Mark\ownCloud\Muelheim Group\Projects\Gas phase background\EX340_CEC356_effect of lens modes.vms
Sum of 9 spectra in column containing 10 scans
XPS
0
Al
1486.61
0
0
0
54.5
180
FAT
20
1
4.156
0
0
0
0
0
Ag3p

-1
kinetic energy
eV
686.61
0.1
2
counts
d
Transmission
d
pulse counting
1
1
0
0
0
0
2
ESCAPE DEPTH TYPE
d
0
MFP Exponent
d
0
3.31097
7096.11
3.31
6989.29
3.30879
7106.1
3.30758
7095.45
3.30637
7126.95
3.30516
7111.71
3.30396
6993.2
3.30275
7017.02
3.30155
7005.63
3.30035
7155.75
3.29915
7078.51
3.29795
7214.27
3.29675
7079.26
3.29555
7147.41
3.29436
7001.64
3.29316
7057.33
3.29197
7180.86
3.29078
7203.62
3.28959
7206.91
3.2884
7171.3
3.28721
7085.3
3.28603
7056.24
3.28484
7229.94
3.28366
7082.64
3.28248
7300.81
3.28129
7143.14
3.28011
7269.64
3.27894
7097.57
3.27776
7339.16
3.27658
7234.78
3.27541
7146.89
3.27423
7345.23
3.27306
7208.89
3.27189
7321.36
3.27072
7428.48
3.26955
7368.3
3.26838
7197.72
3.26722
7282.48
3.26605
7395.39
3.26489
7210.52
3.26373
7485.55
3.26257
7220.64
3.26141
7473.46
3.26025
7279.22
3.25909
7454.22
3.25793
7343.55
3.25678
7322.21
3.25563
7392.15
3.25447
7385
3.25332
7429.55
3.25217
7390.17
3.25102
7356.01
3.24988
7519.93
3.24873
7505.45
3.24758
7488.22
3.24644
7438.47
3.2453
7548.74
3.24416
7511.17
3.24302
7468.76
3.24188
7544.02
3.24074
7450.69
3.2396
7590.8
3.23847
7500.17
3.23733
7520.65
3.2362
7611.65
3.23507
7422.48
3.23394
7692.39
3.23281
7545.73
3.23168
7633.31
3.23055
7612.21
3.22942
7697.36
3.2283
7569.65
3.22718
7688.82
3.22605
7666.64
3.22493
7680.32
3.22381
7735.2
3.22269
7661.51
3.22158
7626.09
3.22046
7557.2
3.21934
7725.96
3.21823
7755.42
3.21712
7660.03
3.216
7737.66
3.21489
7799.02
3.21378
7813.79
3.21267
7754.42
3.21157
7696.67
3.21046
7774.18
3.20936
7789.63
3.20825
7837.36
3.20715
7914.78
3.20605
7698.13
3.20495
7853.83
3.20385
7710.43
3.20275
7931.62
3.20165
7981.05
3.20055
7857.71
3.19946
7919.57
3.19837
7930.29
3.19727
7853.64
3.19618
7936.95
3.19509
8000.97
3.194
8155.63
3.19291
8049.24
3.19183
8025.15
3.19074
8003.78
3.18966
8011.25
3.18857
8086.11
3.18749
8037.56
3.18641
8133.76
3.18533
8073.07
3.18425
8081.74
3.18317
8087.35
3.18209
8167.74
3.18102
8049.52
3.17994
8108
3.17887
8153.61
3.17779
8118.5
3.17672
8207.45
3.17565
8196.62
3.17458
8272.38
3.17351
8139.56
3.17245
8108.72
3.17138
8397.53
3.17031
8229.34
3.16925
8197.15
3.16819
8075.83
3.16712
8384.71
3.16606
8227.36
3.165
8228.27
3.16394
8217.84
3.16289
8254.67
3.16183
8250.72
3.16077
8212.99
3.15972
8354.73
3.15867
8264.49
3.15761
8358.53
3.15656
8371.95
3.15551
8419.6
3.15446
8405.71
3.15341
8399.16
3.15237
8381.59
3.15132
8698.74
3.15027
8554.22
3.14923
8692.65
3.14819
8775.03
3.14714
8700
3.1461
8675.46
3.14506
8751.97
3.14402
8793.18
3.14299
8725.26
3.14195
8902.15
3.14091
8980.53
3.13988
9129.69
3.13884
9136.62
3.13781
9211.24
3.13678
9462.13
3.13575
9389.32
3.13472
9572.55
3.13369
9678.63
3.13266
9678.13
3.13164
9698.99
3.13061
9747.77
3.12959
9744.04
3.12856
9654.9
3.12754
9521.55
3.12652
9351.93
3.1255
9413.2
3.12448
9210.71
3.12346
9129.93
3.12244
8874.67
3.12142
8882.03
3.12041
8857.13
3.11939
8783.04
3.11838
8649.47
3.11737
8507.87
3.11635
8602.24
3.11534
8517.14
3.11433
8370.07
3.11332
8527.28
3.11232
8441.98
3.11131
8294.71
3.1103
8408.82
3.1093
8226.71
3.10829
8190.93
3.10729
8352.96
3.10629
8199.44
3.10529
8134.07
3.10429
8254.15
3.10329
8299.76
3.10229
8195.41
3.10129
8226.04
3.1003
8127.37
3.0993
8354.73
3.09831
8210.96
3.09731
8224.34
3.09632
8271.38
3.09533
8197.46
3.09434
8186.19
3.09335
8282.4
3.09236
8230.13
3.09137
8202.29
3.09039
8210.67
3.0894
8128.16
3.08842
8105.49
3.08743
8213.96
3.08645
8191.83
3.08547
8279.57
3.08449
8137.86
3.08351
8358.71
3.08253
8109.43
3.08155
8246.14
3.08057
8154.74
3.0796
8319.4
3.07862
8328.49
3.07765
8254.72
3.07667
8218.62
3.0757
8264.17
3.07473
8193.84
3.07376
8406.22
3.07279
8330.63
3.07182
8298.26
3.07085
8359.67
3.06988
8265.44
3.06892
8489.16
3.06795
8374.16
3.06699
8279.14
3.06602
8365.05
3.06506
8345.23
3.0641
8364.18
3.06314
8502.35
3.06218
8455.12
3.06122
8347.88
3.06026
8331.16
3.0593
8530.96
3.05835
8432.78
3.05739
8375.96
3.05644
8339.93
3.05548
8558.2
3.05453
8321.95
3.05358
8372.11
3.05263
8527.68
3.05168
8405.68
3.05073
8455.42
3.04978
8567.01
3.04883
8567.34
3.04788
8588.64
3.04694
8489.97
3.04599
8750.63
3.04505
8510.8
3.04411
8450.17
3.04317
8566.75
3.04222
8564.62
3.04128
8569.38
3.04034
8576
3.03941
8355.31
3.03847
8711.95
3.03753
8528.63
3.03659
8664.04
3.03566
8610.01
3.03472
8378.25
3.03379
8758.85
3.03286
8815.64
3.03193
8718.89
3.031
8711.73
3.03007
8737.62
3.02914
8699.47
3.02821
8708.15
3.02728
8677.6
3.02635
8695.97
3.02543
8622.44
3.0245
8669.82
3.02358
8730.21
3.02266
8673.58
3.02173
8813.03
3.02081
8687.67
3.01989
8697.74
3.01897
8885.07
3.01805
8844.51
3.01713
8912.69
3.01622
8738.51
3.0153
8849.52
3.01438
8730.46
3.01347
8815.89
3.01256
8907.69
3.01164
8781.11
3.01073
8727.11
3.00982
8938.41
3.00891
9053.56
3.008
8951.21
3.00709
8959.85
3.00618
8739.14
3.00527
8894.91
3.00437
8974.39
3.00346
9018.19
3.00256
8909.99
3.00165
8998.26
3.00075
8831.68
2.99985
8972.07
2.99894
8914.7
2.99804
8914.55
2.99714
8881.02
2.99624
9027.17
2.99535
8803.13
2.99445
8921.57
2.99355
8939.56
2.99266
9038.88
2.99176
9048.31
2.99087
8977.14
2.98997
8996.54
2.98908
9057.78
2.98819
8980.39
2.9873
9004.96
2.98641
9032.87
2.98552
9128.04
2.98463
9055.37
2.98374
9063.93
2.98285
9073.67
2.98197
9146.99
2.98108
9070.73
2.98019
9248.31
2.97931
9041.9
2.97843
9172.86
2.97754
9220.41
2.97666
9208.49
2.97578
9242.13
2.9749
9161.51
2.97402
9186.41
2.97314
9250.64
2.97227
9162.57
2.97139
9171.02
2.97051
9467.93
2.96964
9306.19
2.96876
9302.42
2.96789
9355.08
2.96702
9302.85
2.96614
9325.94
2.96527
9308.05
2.9644
9313.34
2.96353
9394.34
2.96266
9364.93
2.96179
9573.43
2.96092
9355.12
2.96006
9624.28
2.95919
9510.7
2.95833
9407.04
2.95746
9423.09
2.9566
9542.26
2.95573
9556.56
2.95487
9536.44
2.95401
9413.27
2.95315
9621.68
2.95229
9513.17
2.95143
9581.77
2.95057
9598.24
2.94971
9682.7
2.94885
9613.07
2.948
9613.04
2.94714
9535.29
2.94629
9546.41
2.94543
9621.6
2.94458
9592.9
2.94373
9460.33
2.94287
9596.86
2.94202
9695.62
2.94117
9649.84
2.94032
9708.73
2.93947
9535.04
2.93863
9737.34
2.93778
9805.22
2.93693
9676.93
2.93608
9860.66
2.93524
9812.98
2.93439
9844.25
2.93355
9993.59
2.93271
9889.42
2.93187
9960.05
2.93102
10055.9
2.93018
10119
2.92934
10272.6
2.9285
10265.6
2.92766
10442.4
2.92683
10310.2
2.92599
10693
2.92515
10817.3
2.92432
11132.3
2.92348
11449.3
2.92265
12130.5
2.92181
12902.7
2.92098
14529.6
2.92015
16325.8
2.91931
17960.3
2.91848
18495.5
2.91765
16754.4
2.91682
14752.1
2.91599
12884.9
2.91517
11657.1
2.91434
11130.8
2.91351
10409.6
2.91269
10291.8
2.91186
9795.73
2.91104
9669.1
2.91021
9395.6
2.90939
9371.38
2.90857
9431.46
2.90774
9302.03
2.90692
9378.3
2.9061
9202.86
2.90528
9265.15
2.90446
9207.05
2.90364
9271.01
2.90283
9033.66
2.90201
9299.47
2.90119
9157.72
2.90038
9009.6
2.89956
9177.66
2.89875
9275.04
2.89794
9288.1
2.89712
9178.69
2.89631
9088.56
2.8955
9243.12
2.89469
9131.71
2.89388
8993.51
2.89307
9066.25
2.89226
9078.64
2.89145
9124.44
2.89064
9140.92
2.88984
9112.51
2.88903
9095.93
2.88823
9202.19
2.88742
9040.98
2.88662
9044.03
2.88581
9232.16
2.88501
9111.64
2.88421
9316.15
2.88341
9313.94
2.88261
9532.69
2.88181
9582.64
2.88101
9490.87
2.88021
9865.53
2.87941
9744.36
2.87861
9948.15
2.87782
9948.53
2.87702
10127.6
2.87622
10498.8
2.87543
11049.7
2.87464
11359.3
2.87384
11956.9
2.87305
13005.4
2.87226
14092.7
2.87147
16350.2
2.87067
19612.7
2.86988
23407.6
2.86909
25855.6
2.86831
24926.2
2.86752
21394.9
2.86673
17142.4
2.86594
14041.1
2.86516
12104.5
2.86437
10584.1
2.86359
9565.6
2.8628
8850.65
2.86202
8341.13
2.86124
7957.83
2.86045
7799.96
2.85967
7376.99
2.85889
7327.52
2.85811
7133.77
2.85733
7076.88
2.85655
6968.93
2.85577
6878.8
2.85499
6596.2
2.85422
6840.7
2.85344
6658.71
2.85266
6582.86
2.85189
6659.26
2.85111
6674.69
2.85034
6519.32
2.84957
6734.11
2.84879
6601.93
2.84802
6528.02
2.84725
6565.14
2.84648
6613.98
2.84571
6639
2.84494
6542.41
2.84417
6476.8
2.8434
6581.7
2.84263
6505.62
2.84187
6413.71
2.8411
6309.84
2.84033
6501.12
2.83957
6424.51
2.8388
6511.81
2.83804
6447.56
2.83727
6523.88
2.83651
6491.47
2.83575
6455.01
2.83499
6588.27
2.83423
6399.63
2.83347
6385.52
2.83271
6340.2
2.83195
6650.52
2.83119
6491.64
2.83043
6413.92
2.82967
6453.64
2.82892
6483.54
2.82816
6485.62
2.8274
6438.44
2.82665
6408.15
2.82589
6504.52
2.82514
6333.07
2.82439
6514.8
2.82364
6433.1
2.82288
6466.15
2.82213
6500.2
2.82138
6454.42
2.82063
6476.63
2.81988
6496.01
2.81913
6464.89
2.81838
6530.26
2.81764
6460.58
2.81689
6540.88
2.81614
6574.14
2.8154
6392.98
2.81465
6586.64
2.81391
6544.81
2.81316
6467.77
2.81242
6471.15
2.81168
6478.24
2.81093
6489.2
2.81019
6610.54
2.80945
6578.95
2.80871
6701.18
2.80797
6636.29
2.80723
6735.41
2.80649
6630.44
2.80575
6894.69
2.80501
6804.89
2.80428
6873.96
2.80354
6517.07
2.8028
6553.44
2.80207
6374.18
2.80133
6620.37
2.8006
6590.86
2.79987
6572.94
2.79913
6631.46
2.7984
6496.64
2.79767
6593.85
2.79694
6563.05
2.79621
6552.17
2.79548
6680.28
2.79475
6668.08
2.79402
6594.66
2.79329
6620.6
2.79256
6683.4
2.79183
6561.81
2.79111
6609.99
2.79038
6563.57
2.78965
6654.44
2.78893
6575.09
2.7882
6541.05
2.78748
6680.86
2.78676
6568.44
2.78603
6559.26
2.78531
6656.64
2.78459
6742.76
2.78387
6521.58
2.78315
6796.65
2.78243
6646.5
2.78171
6758.53
2.78099
6741.84
2.78027
6657.55
2.77955
6744.1
2.77884
6715.72
2.77812
6742.36
2.7774
6836.34
2.77669
6696.94
2.77597
6663.97
2.77526
6801.49
2.77454
6601.06
2.77383
6782.96
2.77312
6702.81
2.7724
6778.3
2.77169
6745.26
2.77098
6689.48
2.77027
6644.07
2.76956
6803.9
2.76885
6615.13
2.76814
6714.81
2.76743
6843.73
2.76673
6784.4
2.76602
6803.15
2.76531
6866.13
2.7646
6789.89
2.7639
6718.53
2.76319
6781.87
2.76249
6821.05
2.76178
6920.68
2.76108
6776.94
2.76038
6762.96
2.75968
2.75953
Ag3d
1. Ag in vacuum
2020
3
6
16
39
12
0
13
Casa Info Follows
0
0
0
0
EX340_CEC356_effect of lens modes.sle
Group = Ag in vacuum
First of group = 0
Analyzer lens = AngleResolvedMode22:1.5kV
Analyzer slit = 4:7x20c\C:mesh
Scan mode = FixedAnalyzerTransmission
Kinetic energy start = 1036.61
Sum of 9 spectra in column containing 10 scans
XPS
0
Al
1486.61
0
0
0
54.5
180
FAT
20
1
4.156
0
0
0
0
0
Ag3d

-1
kinetic energy
eV
1036.61
0.1
2
counts
d
Transmission
d
pulse counting
1
1
0
0
0
0
2
ESCAPE DEPTH TYPE
d
0
MFP Exponent
d
0
203.475
2.57029
7550.33
7524.33
7561.45
7468.94
7521.72
7380.55
7557.73
7427.09
7357.28
7505.29
7535.48
7378.91
7574.84
7573.37
7388.35
7431.96
7487.44
7435.91
7494.92
7471.49
7513.07
7463.02
7486.65
7577.33
7477.28
7481.62
7488.93
7517.83
7564.08
7527.95
7491.64
7510.11
7637.17
7702.92
7563.49
7532.57
7575.38
7492.33
7475.71
7320.74
7485.58
7539.34
7593.44
7501.05
7513.78
7531.48
7548.63
7506.52
7399.83
7503.73
7406.77
7618.05
7450.23
7548.87
7638.73
7486.15
7498.71
7486.84
7575.41
7544.12
7549.54
7487.2
7454.97
7388.86
7533.4
7409.43
7488.15
7526.9
7518.78
7474.75
7505.28
7514.5
7422.04
7568.79
7473.13
7608.38
7419.19
7460.57
7386.02
7394.61
7489.14
7582.32
7596.41
7550.49
7497
7532.09
7651.95
7609.13
7570.24
7620.26
7537.45
7527.11
7594.86
7581
7571.02
7599.53
7603.53
7586.23
7611.08
7531.48
7567.04
7648.06
7462.02
7508.68
7597.86
7596
7556
7586.52
7569.38
7631.53
7488.43
7535.14
7633.15
7571.98
7548.48
7514.77
7528.64
7647.3
7545.78
7569.82
7478.62
7423.57
7440.67
7623.69
7576.15
7622.58
7738.82
7617.72
7505.57
7439.41
7536.56
7498.9
7514.04
7555.59
7538.83
7643.28
7553.58
7492.36
7458.28
7544.03
7561.09
7612.53
7545.28
7475.85
7549.56
7556.29
7655.93
7510.34
7636.78
7565.02
7495.96
7463.73
7403.81
7551.41
7621.51
7485.8
7489.85
7541.28
7560.75
7518.13
7472.24
7515.75
7476.02
7552.67
7475.96
7413.16
7481.16
7450.42
7542.99
7575.73
7582.17
7525.62
7541.67
7582.16
7508.38
7581.27
7528.9
7577.55
7579.91
7583.6
7557.34
7555.5
7699.12
7575.43
7504.91
7450.21
7602.27
7779.64
7649.55
7670.95
7600.07
7664.18
7680
7635.65
7483.36
7551.89
7617.61
7741.13
7615.85
7596.49
7662.54
7565.26
7622.91
7593.72
7587.88
7635.83
7643.21
7645.28
7731.44
7623.48
7579.36
7578.47
7473.24
7545.27
7552.9
7648.95
7672.3
7623.31
7605.77
7621.51
7707.78
7643.66
7586.72
7688.08
7673.05
7737.23
7541.3
7533.5
7697.83
7671.09
7805.41
7653.16
7593.62
7646.61
7657.64
7569.18
7542.53
7684.82
7638.33
7590.94
7674.93
7734.49
7654.55
7729.16
7592.92
7625.79
7558.64
7588.04
7707.69
7628.35
7642.93
7787.13
7682.74
7666.61
7590.38
7814.39
7868.14
7664.88
7607.26
7720.64
7679.23
7770.78
7651.3
7669.57
7731.26
7774.79
7666.08
7747.18
7745.99
7687.46
7755.15
7789.08
7724.08
7703.2
7651.8
7689.63
7855.76
7912.54
7753.81
7695
7649.45
7621.01
7675
7831.37
7853.38
7808.62
7778.37
7675.01
7691.67
7777.05
7720.31
7811.66
7819.09
7727.62
7698.16
7780.85
7745.72
7656.95
7612.61
7682.95
7592.43
7629.26
7618.13
7627.03
7680.31
7695.22
7821.65
7593.65
7626.37
7663.08
7629.01
7640.27
7654.73
7693
7751.26
7669.85
7629.23
7661.63
7720.46
7620.04
7657.92
7651.82
7715.37
7718.56
7605.36
7716.56
7727.35
7545.97
7643.75
7798.61
7598.45
7659.19
7757.08
7638.31
7733.85
7602.22
7746.59
7667.11
7627.95
7655.54
7713.04
7831.69
7738.13
7625.18
7691.46
7629
7601.42
7606
7823.21
7835.58
7745.59
7821.71
7832.15
7770
7871.61
7681.6
7682.4
7751.47
7730.67
7613.29
7682.92
7750.56
7690.19
7726.78
7836.42
7776.85
7808.69
7850.22
7725.77
7720.69
7788.87
7884.04
7789.73
7774.81
7824.04
7816.1
7819.23
7721.75
7921.15
7777.21
7960.22
7820.27
7788.61
7780.91
7851.41
7820.99
7815.07
7837.69
7799.79
7785.4
7818.05
7886.19
7755.26
7886.55
7898.82
7893.34
7911.67
7889.58
7879.08
7942.15
7942.98
7898.77
7841.06
7908.48
7853.42
7940.75
7977.24
8008.38
7890.55
8073.06
8054.52
8026.02
7900.11
7989.8
8077.44
8060.57
8038.8
7987.43
8115.08
7970.81
7944.58
8070.12
7944.78
7924.64
8037.73
8039.54
8044.6
8085.47
8062.91
8011.27
8103.01
8069.95
8156.31
8073.07
8089.66
8195
8089.74
8153.22
8077.11
8106.63
8142.59
8171.88
8195.39
8098.36
8158.7
8040.65
8194.26
8161.41
8166.95
8224.34
8098.12
8280.45
8349.79
8374.88
8233.13
8178.14
8250.43
8156.03
8284.58
8193.22
8301.77
8231.18
8147.43
8146.37
8214.81
8390.45
8402.16
8323.41
8254.77
8365.65
8229.29
8464.92
8253.23
8387.98
8453.38
8254.03
8286.22
8387.56
8381.29
8499.68
8432.03
8523.92
8551.52
8413.04
8554.97
8553.91
8483.46
8723.7
8643.1
8586.18
8537.29
8380.75
8605.22
8538.23
8612.4
8650.69
8740.32
8781.84
8780.2
8774.44
8883.85
8704.38
8745.68
8795.91
8775.55
8842.04
8852.45
8702.6
8799.03
8871.9
8787.44
8746.5
8783.72
8773.47
8838.56
8919.71
8845.45
8728
8776.76
8860.8
8769.23
8685.12
8809.54
8821.62
8768.09
8759.74
8800.42
8752.7
8793.08
8730.99
8681.83
8749.16
8648.21
8566.71
8667.96
8707.63
8639.34
8762.15
8702.76
8662.29
8663.65
8532.91
8702.12
8731.91
8562.86
8688.48
8707.91
8711.78
8915.89
9045.22
9003.76
9019.16
9087.74
9010.51
9098.37
9187.21
9131.87
9094.56
9246.69
9279.23
9234.82
9184.53
9200.49
9226.37
9148.44
9261.78
9176.3
9184.58
9116.02
9222.41
9240.52
9186.83
9214.4
9056.83
9181.27
9180.01
9168.05
9202.83
9197.83
9082.91
9222.32
9173.45
9175.19
9174.71
9033.36
9036.55
9183.92
8994.77
8920.49
8915.44
8995.53
9073.31
9237.37
9143.67
8990.73
9058.49
8948.28
8818.38
8909.01
8878.48
8869.33
8889.78
8993.6
8886.4
8807.15
8932.92
8918.71
8834.49
8800.49
8739.75
8947.12
8795.57
8745.33
8929.72
8946.21
8832.16
8799.73
8926.96
8843.14
8994.54
8913.32
8941.17
8999.93
9053.78
9045.59
8892.27
8878.77
9055.86
9016.9
8999.24
9076.07
9128.62
9220.66
9014.41
8915.33
8933.85
9091.81
8941.83
9009.53
8875.39
8850.38
8828.14
8837.21
8844.34
8829.3
8810.59
8792.16
8683.88
8734.49
8867.54
8673.3
8686.48
8605.09
8723
8748.95
8703.68
8606.07
8756.18
8842.91
8708.23
8659.12
8769.41
8739.37
8761.15
8804.29
8791.73
9042.34
8937.66
9059.13
9049.44
8961.51
9065.21
9087.98
9102.32
9158.97
9108.51
9075.52
9230.32
9127.44
9159.05
9185.64
9064.18
9157.08
9153.84
9225.95
9229.65
9235.65
9077.26
8988.15
9136.78
8911.39
8820.32
8931.03
8814.04
8627.12
8791.18
8802.21
8720.98
8785.6
8646.4
8548.94
8664.31
8512.94
8504.01
8589.93
8612.47
8591.05
8581.64
8759.99
8710.29
8931.42
8879.24
8978.66
9210.62
9348.86
9492.13
9687.36
9878.45
10376.9
10618.4
10688.3
10430.9
10173.2
9829.09
9507.67
9105.88
8832.02
8870.53
8896.85
8888.31
8842.52
8918.54
9142.76
9145.35
9268.69
9450.17
9806.75
9913.12
10161.2
10388.1
10653.5
10935.8
11254.3
11585.5
12087.7
12637.9
13338.6
14458.7
15631.6
17405.3
20369.3
24532.3
31289.3
40993.3
53961.4
71105.8
88762.8
101539
104345
96857.7
81078
61264.7
42657.7
28906.9
20470.2
15598.4
12791.1
11021.6
9957.68
9360.28
8764.2
8450.79
8345.61
8138.35
8243.98
8389.1
8584.38
8874.36
8963.29
9075.16
9374.92
9023.68
8562.01
7951.88
7354.89
6825.13
6293.74
6078.98
5751.61
5619.6
5570.87
5625.02
5802.09
5936.81
6024.86
6311.06
6415.16
6713.96
6969.69
7284.93
7611.28
8167.75
8847.34
9237.85
10114.1
11130.8
11988.7
13601.3
15590.8
18422.3
22698
29182
38217.5
52058.9
71093.2
95420.5
120453
138671
142665
133041
111188
83143.3
56230.8
35865.7
23437.2
16201.2
11992.9
9263.05
7579.4
6375.8
5423.45
4769.51
4210.75
3837.44
3543.31
3298.87
3082.19
2981.66
2836.32
2619.81
2503.04
2467.85
2322
2169.85
2128.21
2142.7
1999.53
1956.8
1881.73
1826.3
1807.89
1770.81
1731.52
1679.54
1707.18
1640.61
1599.43
1546.38
1504.97
1552.71
1563.19
1524
1540.31
1448.34
1396.08
1413.31
1352.14
1391.36
1391.82
1412.32
1376.15
1345.82
1357.31
1378.1
1360.29
1340.82
1321.28
1322.22
1389.52
1349.85
1314.62
1263.58
1269.37
1245.47
1233.53
1236.91
1214.65
1240.66
1230.7
1247.49
1233.94
1236.07
1243.94
1215.19
1220.18
1195.76
1223.83
1198.02
1181.67
1189.58
1209.05
1181.63
1217.55
1188.76
1216.24
1160.45
1165.06
1178.33
1162.82
1221.55
1226.06
1191.17
1225.83
1181.27
1221.98
1134.77
1197.23
1183.25
1198.35
1116.84
1190.71
1184.04
1163.33
1138.83
1152.98
1198.73
1191.18
1182.31
1114.11
1208.23
1153.93
1160.77
1164.15
1144.06
1145.9
1153.42
1087.48
1166.98
1171.91
1170.9
1137.65
1176.45
1126.24
1142.37
1139.05
1143.63
1198.19
1147.57
1119.09
1165.62
1204.9
1183.51
1151.24
1165.81
1158.45
1137.86
1185.16
1180.31
1167.16
1140.64
1111.94
1145.25
1133.17
1172.21
1137.59
1147.24
1159.77
1126.4
1128.03
1120.68
1160.94
1193.04
1157.57
1096.28
1136.63
1122.43
1152.33
1176.39
1134.03
1127.77
1189.04
1172.64
1161.2
1164.24
1153.27
1093.85
1159.12
1168.77
1118.91
1163.71
1173.26
1165.67
1148.64
1151.12
1106.39
1137.93
1143.7
1174.56
1171.49
1148.3
1148.01
2.57029
Ag4d
1. Ag in vacuum
2020
3
6
16
49
48
0
13
Casa Info Follows
0
0
0
0
EX340_CEC356_effect of lens modes.sle
Group = Ag in vacuum
First of group = 0
Analyzer lens = AngleResolvedMode22:1.5kV
Analyzer slit = 4:7x20c\C:mesh
Scan mode = FixedAnalyzerTransmission
Kinetic energy start = 1346.61
Sum of 9 spectra in column containing 10 scans
XPS
0
Al
1486.61
0
0
0
54.5
180
FAT
20
1
4.156
0
0
0
0
0
Ag4d

-1
kinetic energy
eV
1346.61
0.1
2
counts
d
Transmission
d
pulse counting
1
1
0
0
0
0
2
ESCAPE DEPTH TYPE
d
0
MFP Exponent
d
0
0.0383
2.24496
1603.49
1585.07
1619.01
1593.77
1612.08
1629.72
1639.4
1596.64
1584.55
1583.4
1568.39
1572.19
1570.39
1558.68
1541.32
1560.48
1562.34
1554.76
1558.19
1569.3
1600.35
1582.26
1572.68
1575.42
1607.31
1592.81
1496.78
1545.9
1575.13
1593.15
1589.75
1654.54
1601.1
1645.35
1586.98
1613.68
1652.5
1605.4
1580.83
1597.7
1600.69
1635.26
1598.39
1587.51
1545.49
1595.75
1640.25
1640.24
1697.39
1657.83
1577.38
1629.03
1584.86
1626.32
1565.33
1560.64
1622.25
1585.76
1600.05
1624.37
1566.38
1641.21
1656.52
1633.7
1643.44
1607.99
1649.45
1620.6
1664.59
1578.11
1701.12
1644.13
1647.06
1656.11
1605.74
1584.09
1639.08
1650.05
1642.52
1590.85
1554.53
1599.46
1608.56
1634.66
1615.79
1662.86
1639.5
1627.37
1633.49
1577.61
1639.84
1608.34
1626.28
1634.43
1594.93
1677.84
1592.26
1577.06
1612.65
1605.2
1674.31
1596.18
1680.05
1626.14
1535.22
1620.41
1599.01
1633.21
1687.31
1636.26
1614.77
1665.69
1688.39
1624.97
1679.75
1620.9
1634.39
1636.51
1596.87
1649.03
1618.7
1627.85
1646.41
1658.89
1630.05
1569.98
1657.93
1626.1
1644.27
1651.26
1591.96
1589.91
1629.96
1708.4
1638.48
1612.55
1657.82
1700.47
1660.31
1654.8
1676.83
1624.61
1610.95
1659.76
1633.22
1649.45
1670.54
1663.83
1646.33
1660.2
1658.86
1641.34
1683.54
1681.69
1685.01
1593.98
1659.04
1683.34
1634.57
1653.08
1642.02
1690.75
1685.02
1673.11
1652.97
1687.89
1652.58
1688.1
1712.76
1683.9
1613.85
1666.1
1645.62
1620.96
1590.08
1605.32
1677.75
1635.36
1696.68
1687.08
1690.58
1645.93
1693.46
1693.06
1691.7
1657.45
1665.63
1718.37
1704.74
1641.19
1605.88
1650.89
1711.39
1624.59
1567.98
1662.65
1654.98
1674.03
1700.3
1622.54
1593.29
1610.84
1601.83
1645.44
1640.96
1616.78
1680.59
1621.2
1673.74
1707.35
1701.89
1673.97
1703.08
1677.34
1615.93
1677.28
1638.16
1615.41
1678.94
1666.22
1668.46
1657.11
1663.51
1663.68
1675.24
1709
1711.05
1584.41
1681.7
1696.22
1647.15
1610.28
1672.2
1683.35
1661.43
1732.44
1698.67
1718.25
1689.7
1705.85
1665.55
1654.27
1670.55
1691.79
1692.88
1709.03
1693.68
1709.51
1720.72
1671.59
1674.88
1646.06
1631.38
1678.45
1653.07
1682.98
1667.54
1691.97
1719.74
1636.53
1703.66
1704.71
1684.05
1683.63
1694.3
1741.18
1776.13
1683.23
1640.95
1631.87
1687.92
1680.15
1750.3
1674
1642.33
1680.91
1734.64
1703.25
1706.88
1689.34
1703.57
1692.25
1656.31
1706.98
1675.49
1739.5
1781.86
1721.06
1710.22
1741.18
1740.89
1700.87
1725.37
1754.63
1757.33
1805.52
1751.18
1666.36
1731.31
1697.06
1729.34
1692.28
1731.71
1738.53
1788.25
1754.18
1752.43
1748.94
1734.46
1701.84
1759.14
1767.17
1747.06
1745.11
1748.77
1696.04
1713.21
1697.03
1774.99
1756.55
1740.3
1755.61
1741.25
1741.43
1708.09
1718.37
1743.27
1757.36
1748.26
1768.19
1721.08
1730.77
1719.99
1721.02
1795.76
1780.18
1776.31
1706.6
1742.81
1775.85
1867.82
1763.34
1760.24
1751.83
1725.93
1800.54
1747.86
1782.38
1795.06
1750.39
1753.8
1848.63
1824.78
1881.11
1864.12
1827.8
1827.71
1884.87
1863.36
1868.23
1846.48
1775.99
1854.52
1840.52
1868.9
1812.19
1837.4
1830.58
1843.66
1855.26
1838.07
1809.44
1871.34
1878.6
1952.92
1989.42
1933.22
1904.9
1875.65
1885.6
1839.56
1865.2
1900.08
1924.32
1990.56
1968.15
1960.4
1874.99
1916.19
1934.01
1963.37
1985.11
1944.47
1999.76
1983.73
2025.64
2039.06
2064.84
2088.91
2062.54
2091.5
2114.15
2062.44
2098.6
2070.03
2072.82
2160.15
2148.99
2218.74
2218.78
2208.51
2213.79
2267.72
2320.43
2352.62
2415.52
2458.6
2433.26
2459.78
2415.64
2381.9
2464.01
2476.87
2525.37
2502.8
2496.76
2577.29
2580.8
2619.42
2612.35
2517.12
2567.3
2580.95
2519.47
2486.86
2544.95
2461.34
2498.52
2536.18
2488.22
2407.96
2389.41
2402.28
2389.36
2297.97
2365.22
2308.97
2220.76
2178.32
2230.85
2152.74
2102.71
2125.94
2096.15
2076.26
2051.68
2010.08
2015.53
2017.35
1930.01
1922.79
1894.4
1944.51
1967.49
1915.96
1840.46
1838.2
1785.93
1810.58
1829.93
1810.36
1754.3
1830.32
1815.54
1789.79
1727.96
1706.01
1758.77
1753.28
1812.01
1758.88
1665.43
1671.28
1717.34
1686.95
1685.81
1691.44
1666.46
1748.3
1732.9
1688.88
1711.43
1678.85
1688.73
1675.15
1659.74
1599.21
1692.97
1687.44
1703.02
1686.55
1674.38
1652.89
1647.52
1725.42
1743.1
1638.42
1635.68
1636.32
1651.26
1752.52
1690.05
1638.69
1607.69
1672.71
1606.88
1635.59
1615.78
1734.81
1713.64
1702.5
1670.02
1721.81
1671
1722.14
1698.53
1653.67
1604.78
1634.75
1636.65
1569.12
1651.73
1648.27
1723.53
1632.09
1628.11
1670.59
1641.17
1617.98
1629.07
1639.52
1710.8
1613.14
1665
1664.76
1653.47
1603.56
1686.28
1697.63
1626.37
1654.61
1618.86
1654.25
1635.12
1659.36
1658.24
1667.99
1655.71
1656.19
1654.61
1666.59
1648.76
1697.32
1688.27
1643.58
1671.95
1716.1
1697.66
1597.88
1675.02
1612.75
1602.21
1666.28
1656.68
1607.19
1644.28
1643.67
1659.63
1595.3
1645.39
1691.47
1638.72
1627.57
1637.02
1671.06
1670.84
1677.01
1725.55
1780.4
1749.15
1675.39
1677.22
1668.89
1660.09
1654.47
1614.79
1671.33
1646.16
1641.78
1637.92
1660.01
1674.63
1691.71
1726.31
1704.92
1696.13
1729.49
1675.18
1658.64
1779.32
1713.24
1619.9
1668.31
1751.52
1770.77
1737.44
1678.21
1691.3
1626.29
1695.44
1704.22
1705.28
1672.46
1708.55
1724.17
1677.24
1735.88
1771.77
1770.3
1665.58
1661.29
1681.6
1723.57
1698.21
1684.32
1734.31
1713.04
1741.2
1724.77
1729.02
1753.5
1747.26
1692.86
1727.54
1701.45
1729.14
1751.68
1759.89
1767.29
1709.59
1776.31
1763.07
1725.39
1762.51
1745.75
1784.26
1790.65
1760.04
1841.27
1757.88
1798.5
1897.28
1814.34
1788.39
1771.05
1852.66
1815.18
1776.9
1794.64
1813.61
1754.76
1797.25
1743.93
1822.73
1921.47
1812.69
1795.18
1843.4
1823.11
1820.72
1795.55
1814.88
1802.47
1871.15
1795.62
1888.47
1926.74
1890.28
1889.41
1864.92
1861.5
1869.46
1860.7
1910.77
1905.22
1874.48
1917.89
1911.58
1912.27
1977.11
1901.77
1935.54
1931.6
1970.83
1997.22
1974.35
1967.31
1986.13
2004.05
2007.24
1998.39
2007.08
2027.63
2058.65
2052.94
2036.88
2045.34
2129.05
2134.83
2155.17
2152.84
2109.78
2153.64
2227.22
2205.51
2251.94
2216.65
2253.54
2233.24
2230.25
2271.43
2377.79
2331.37
2298.81
2356.82
2352.06
2387.76
2404.41
2445.89
2444.52
2471.67
2493.49
2487.12
2538.75
2533.93
2565.05
2507.76
2554.58
2569.39
2656.41
2607.4
2653.64
2602.32
2644.09
2627.16
2645.91
2694.32
2706.24
2653.51
2739.69
2634.49
2670.04
2776.76
2758.7
2741.77
2748.65
2763.43
2745.63
2762.64
2794.4
2816.06
2831.03
2763.99
2768.35
2836.8
2798.45
2839.87
2810.9
2742.58
2819.49
2815.42
2861.05
2886.06
2931.17
2864.71
2857.61
2844.72
2852.77
2883.52
2836.3
2920.45
2986.09
2956.13
2934.26
2955.07
2890.84
2934.05
2901.66
2981.33
3003.19
2917.53
2910.91
2944.93
2973.24
2943.72
2954
2957.33
2977.48
3044.55
2985.74
2952.81
2977.89
3019.01
3039.5
3054.36
2957.64
2891.46
3001.88
3034.78
2991.99
3016.96
2968.59
2961.05
3033.31
3068.95
2980.21
2955.72
2919.5
2895.08
2873.39
2780.65
2755.33
2856.67
2750.08
2712.66
2705.9
2723.92
2669.29
2610.43
2542.78
2553.47
2543.72
2510.21
2476.75
2452.77
2321.12
2314.28
2237.81
2222.74
2171.04
2148.15
2053.66
2006.24
2089.63
1971.31
1954.11
1955.46
1918.95
1876.8
1841.25
1824.97
1761.36
1733.03
1700.29
1762.51
1704.5
1687.88
1586.91
1526.29
1519.43
1548.93
1494.28
1449
1429.63
1443.66
1417.18
1456.98
1355.12
1334.71
1321.06
1335.05
1335.68
1281.17
1277.05
1202.41
1245.49
1253.56
1209.74
1148.25
1190.29
1218.81
1180.43
1154.49
1145.27
1107.84
990.132
1041.46
1071
1030.33
1036.41
1040.19
1032.73
984.954
975.066
983.378
1030.27
1036.23
1007.46
1025.92
973.821
958.153
937.711
927.6
955.793
935.578
902.002
880.052
902.612
882.308
881.689
902.537
871.264
882.299
842.035
851.544
814.122
850.663
880.193
859.291
837.064
837.995
843.887
796.966
788.43
836.771
832.909
814.766
826.76
820.265
799.159
803.568
798.933
781.542
843.887
811.192
783.397
772.502
780.915
791.454
800.959
765.379
804.971
784.934
790.839
791.855
795.886
802.298
755.26
783.176
816.784
785.58
757.173
749.908
755.58
777.685
764.411
793.354
745.302
730.126
786.872
762.987
781.874
779.141
785.297
786.697
755.282
765.546
750.497
753.391
795.784
805.02
795.086
765.55
761.146
758.719
770.388
765.993
770.787
797.405
767.903
797.963
751.587
744.14
756.914
750.626
759.274
756.817
736.078
743.01
781.588
818.135
799.662
735.066
765.322
749.417
741.17
788.081
794.28
781.958
785.747
734.361
756.71
759.236
785.852
795.611
734.668
739.497
781.444
786.926
799.121
765.921
741.324
729.307
756.24
742.174
740.604
739.003
786.375
773.429
742.991
747.539
789.099
755.758
769.418
751.795
780.182
789.591
730.599
768.888
793.251
724.39
741.851
788.619
815.509
770.162
728.325
736.715
720.443
752.851
744.591
776.039
793.193
766.225
740.976
758.695
778.446
800.591
787.713
769.676
779.428
775.933
761.118
724.011
782.936
761.457
764.064
794.816
791.703
784.468
802.236
798.961
792.209
778.181
769.32
796.469
761.025
802.247
783.325
795.961
844.081
799.366
824.798
787.487
783.767
778.209
778.333
782.283
812.79
779.283
820.03
785.059
817.957
828.468
827.724
819.039
813.784
872.897
825.578
827.358
796.832
828.367
834.772
869.029
860.476
840.136
827.396
814.288
804.798
776.696
817.942
826.752
851.139
827.456
836.645
781.308
785.834
778.214
812.394
815.417
801.136
811.753
772.59
788.202
758.269
768.668
826.33
788.011
775.581
776.902
759.005
740.083
818.084
789.549
774.468
776.498
756.583
767.549
772.995
762.55
810.663
780.709
778.502
786.125
807.967
780.57
818.311
790.781
762.384
776.346
798.818
816.341
798.27
752.66
797.632
788.141
803.813
824.823
826.696
791.624
808.502
784.541
750.773
790.882
811.47
821.139
823.306
828.188
839.355
836.913
828.071
800.28
809.829
843.544
842.33
840.564
841.659
827.195
832.777
809.23
818.234
828.648
827.959
827.965
823.884
811.154
764.973
802.317
756.708
790.216
803.663
829.075
786.992
807.095
780.563
808.211
803.079
769.292
796.873
811.724
783.505
757.237
766.238
806.898
783.914
791.081
806.594
784.048
778.346
748.894
805.272
775.349
767.608
797.264
793.484
791.103
780.465
765.208
802.043
839.059
787.264
836.184
812.069
818.342
792.106
808.6
807.628
793.062
838.708
865.766
828.223
827.126
856.676
834.946
809.178
809.759
821.855
850.955
839.691
864.77
854.241
810.451
835.728
818.132
826.459
829.509
829.546
842.157
864.203
858.757
903.115
882.812
854.955
908.667
883.003
892.63
862.599
898.844
942.705
934.094
906.377
908.102
909.091
875.975
908.521
892.971
954.752
919.263
964.373
944.372
907.313
905.793
835.245
904.03
871.265
914.116
886.839
857.555
876.789
952.878
910.391
870.607
891.617
918.071
912.383
845.694
845.614
851.47
884.105
903.204
929.073
895.321
934.899
937.454
[...]
49.2753
49.5845
49.5278
49.9171
50.1614
49.7014
50.2005
49.9588
49.8102
49.6109
49.9813
50.2331
50.9842
50.5123
50.5238
50.4996
50.4428
50.2762
51.0723
51.535
51.1077
51.1052
51.4677
51.9203
51.5745
51.9224
51.7908
52.2434
52.0117
52.351
52.5564
52.7195
52.7062
52.8222
53.4237
52.8956
53.2802
52.6867
52.9234
53.0886
53.6285
54.1405
55.7394
54.9943
54.1911
53.7659
52.8963
51.6106
50.244
49.1606
49.1049
48.8033
48.9576
49.3313
50.0393
51.2755
54.3441
57.6011
61.9678
67.6728
73.11
77.0668
78.4577
77.1892
72.9296
68.2712
63.6363
59.41
55.6193
53.1529
50.4892
49.3079
47.7108
46.7918
46.3656
45.652
45.7979
46.3578
47.2167
46.8638
47.2743
46.4413
44.8336
42.8975
41.2143
39.4475
38.5162
37.444
37.1937
37.3628
37.8468
39.1832
41.3135
44.4523
49.0281
55.0603
62.3964
68.905
74.7468
75.0671
72.3271
66.8494
60.517
54.4119
48.5156
44.1357
40.3893
37.9943
36.1691
34.5581
33.545
33.4023
32.8269
31.8929
31.5729
31.3188
30.7209
31.0499
31.5606
31.1658
30.7824
30.5582
30.4949
30.2979
30.5332
30.4616
30.3749
30.1641
30.3534
30.447
30.2233
29.8008
29.6123
29.8573
30.0751
30.4874
30.246
29.9572
30.21
30.2361
30.0161
30.0919
30.0959
29.7763
29.6136
29.903
30.1366
29.9731
29.8928
30.336
30.0287
29.7465
29.6577
29.9037
29.6144
29.5647
29.8655
29.6033
29.7191
29.6741
29.8049
29.7105
30.042
29.5759
29.6991
30.1199
29.5242
29.1245
29.5508
29.4129
29.5024
29.5494
29.4856
29.3173
29.2718
29.3809
29.0731
28.8484
28.8584
28.5206
28.9997
28.9681
29.1755
28.4488
28.1255
28.3519
28.4503
27.9793
27.7012
28.0224
27.6338
27.8012
27.8418
27.307
27.336
27.5382
27.4294
27.5786
27.8154
28.2107
28.2291
28.2876
28.35
28.0621
27.8962
28.5492
28.014
27.9581
28.3346
28.0434
27.914
27.7879
28.2347
28.4472
28.0659
27.5694
27.7906
27.8333
27.71
27.8578
27.3615
26.9495
26.7749
26.7549
26.8737
26.7179
26.8545
27.0411
26.7163
26.6898
26.7191
26.9774
27.1216
26.9034
27.0302
27.5463
27.7467
27.7103
27.7174
28.0116
28.2296
28.4636
28.8029
28.5632
29.1865
29.5494
29.5325
29.6413
29.8181
29.7958
30.0795
29.4973
30.1138
30.0304
29.8525
30.0618
31.1568
31.4662
32.7315
33.3562
34.7715
36.8784
39.2715
41.9727
46.0072
51.3505
59.1653
71.1898
88.1024
111.777
145.279
186.809
229.035
263.31
276.091
264.386
234.665
194.689
155.761
122.178
94.0743
72.7445
58.3061
48.5344
42.3795
37.6993
34.3887
31.8271
30.401
29.6844
28.7809
28.0647
27.982
27.9994
28.6816
29.5925
30.752
32.3313
34.491
36.9861
40.4316
45.8411
53.0144
63.5366
79.3783
103.063
137.419
185.706
241.456
295.189
333.678
344.793
321.31
276.676
222.813
171.658
129.737
94.5855
70.0193
51.9876
40.7595
32.7645
27.4326
24.509
21.7684
19.4094
18.177
17.6576
16.6656
15.8069
15.4991
14.8511
14.0103
13.7705
13.0553
13.1734
12.7902
12.4192
12.4043
12.1526
11.9235
11.7188
11.6307
11.2473
11.3651
11.1199
10.7573
11.0939
10.9858
10.8359
10.9605
10.67
10.6207
10.7946
10.4805
10.3826
10.3839
10.3189
10.6331
10.3356
10.309
10.18
10.0049
9.99947
10.0681
9.96645
10.0065
10.4727
10.5375
9.86097
9.92173
10.0613
9.75373
9.92203
9.98433
10.1005
10.0689
10.1051
9.90375
9.96877
10.1067
10.1119
9.78418
9.88371
10.0235
9.84477
9.68971
9.96264
9.94681
10.1155
10.0822
9.97524
10.1096
10.1051
9.9842
10.0853
10.1452
10.004
10.1521
10.1984
10.4324
10.4623
10.0249
10.1304
2.30555
Au4f
4. Au in vacuum
2020
8
29
1
53
9
0
12
Casa Info Follows
0
0
0
0
EX440_S718_Au in 23 mbar He.sle

Group = Au in vacuum

First of group = 1

Analyzer lens = AngleResolvedMode22:1.5kV

Analyzer slit = 4:7x20c\C:mesh

Scan mode = FixedAnalyzerTransmission

Kinetic energy start = 1311.61

XPS
0
Al
1486.61
0
0
0
54.5
180
FAT
20
1
4.156
0
0
0
0
0
Au4f

-1
kinetic energy
eV
1311.61
0.1
2
counts
d
Transmission
d
pulse counting
1
1
0
0
0
0
2
ESCAPE DEPTH TYPE
d
2
MFP Exponent
d
0
13.5918
2.30555
235.314
232.628
237.647
231.031
230.906
242.07
237.202
232.779
231.974
236.825
234.179
235.972
235.085
241.248
237.091
230.886
233.954
239.035
235.208
233.527
237.852
238.382
232.451
233.08
232.618
238.45
241.266
233.36
232.797
238.467
235.238
237.489
237.424
240.719
231.892
239.717
238.224
234.947
238.343
238.102
235.074
239.717
237.945
232.645
238.345
236.61
239.644
237.711
239.348
240.813
238.732
236.121
238.554
235.384
237.621
243.051
243.285
239.104
242.67
241.485
239.647
240.04
239.523
236.983
238.012
240.042
240.858
244.109
234.587
237.609
239.566
236.398
232.271
239.26
240.206
239.127
240.91
238.101
239.777
238.636
240.59
237.081
241.25
238.925
239.359
233.61
240.127
235.578
239.253
239.718
234.097
234.563
241.026
243.672
240.231
237.265
239.68
240.802
239.689
242.003
242.697
239.647
238.853
240.631
241.361
242.227
239.525
239.47
241.449
240.909
239.353
236.152
240.716
240.594
241.872
237.759
240.24
241.959
241.479
245.942
238.081
239.389
243.146
241.292
238.036
239.903
239.752
240.552
246.923
242.424
240.68
245.008
241.194
241.61
243.948
239.137
242.904
245.713
246.895
243.399
243.139
245.109
242.43
244.28
239.526
243.205
238.447
240.968
240.807
241.666
244.477
245.002
245.471
242.782
238.794
244.269
239.573
237.504
241.792
245.057
242.21
244.182
244.13
243.925
245.016
248.727
243.259
248.067
244.947
244.61
245.268
246.345
250.461
242.783
243.942
246.192
246.535
252.163
249.791
244.683
245.537
243.175
248.583
250.619
248.616
243.893
253.5
246.711
245.483
250.787
243.688
244.264
246.382
245.425
245.199
247.847
250.611
246.715
248.775
244.504
248.631
249.346
249.104
248.903
253.145
241.808
245.884
253.618
249.388
248.925
249.029
249.868
248.863
251.749
254.403
247.257
251.154
252.652
247.578
247.257
253.863
254.675
249.932
248.489
254.837
248.183
248.194
252
252.393
250.99
251.396
250.031
251.473
248.898
245.545
248.996
251.806
247.714
251.223
249.759
252.405
251.782
250.726
247.674
254.924
253.534
248.817
247.113
251.218
253.895
256.244
255.758
251.786
255.553
255.65
256.241
250.006
255.139
253.732
254.833
256.452
257.063
248.738
249.32
255.685
251.055
251.412
253.629
255.838
257.268
260.173
253.699
257.753
251.219
249.875
248.842
253.071
250.155
252.117
252.14
254.997
249.619
250.069
249.135
250.523
252.417
251.45
254.414
258.602
254.556
253.565
253.556
253.055
250.322
251.946
248.029
261.868
263.556
252.754
253.66
254.53
258.108
256.415
254.154
256.889
255.462
252.783
253.123
257.433
255.663
254.15
255.388
259.435
257.406
256.126
254.166
253.865
256.379
257.807
257.716
254.745
254.215
258.095
257.675
258.386
255.969
257.161
254.294
256.539
255.226
258.23
253.047
255.042
257.765
256.757
259.489
257.577
258.712
260.147
257.491
252.419
256.454
258.009
255.309
257.847
259.025
258.674
256.817
260.793
256.12
259.272
262.116
257.681
257.635
261.551
256.228
256.749
259.293
261.402
263.064
260.336
259.864
257.371
262.01
265.334
266.92
264.46
260.384
258.482
260.65
259.876
259.76
260.694
259.698
263.078
263.982
263.338
258.126
262.184
264.947
260.243
255.621
260.073
259.744
260.879
261.308
261.155
263.12
265.749
256.927
260.786
261.669
261.437
264.495
261.908
264.804
259.711
258.768
260.952
263.786
265.119
260.098
267.133
264.682
263.854
262.501
265.102
265.312
266.87
265.904
267.221
265.8
263.018
264.528
264.476
266.14
264.619
265.046
264.28
260.804
266.44
266.81
264.458
266.991
264.5
271.377
271.311
270.659
260.509
267.968
267.69
263.478
264.377
263.96
262.252
266.297
267.554
264.51
263.608
267.016
270.07
266.159
267.012
273.578
267.423
260.28
266.593
268.753
272.143
268.472
265.703
272.192
270.104
268.124
264.983
267.596
268.81
271.757
268.478
268.626
268.764
264.499
269.295
264.717
262.575
265.232
267.92
273.268
272.565
268.95
270.373
264.981
274.675
275.728
270.447
267.369
273.243
271.2
266.784
270.775
273.861
272.49
272.492
271.943
275.435
275.41
274.684
279.118
277.089
274.966
276.938
275.213
272.718
274.622
272.216
275.964
272.965
274.455
275.015
275.669
274.644
273.725
271.71
273.806
275.44
281.5
278.471
279.448
275.635
277.669
283.09
277.327
270.871
280.373
282.922
280.569
282.21
282.617
284.689
287.221
280.645
286.423
280.702
282.57
287.631
285.956
283.703
287.369
288.152
285.051
285.695
289.706
288.313
286.498
283.421
283.1
282.444
285.447
289.541
291.446
289.18
286.977
289.248
285.319
292.93
283.24
284.577
283.89
286.126
286.541
287.238
289.207
286.03
292.767
287.186
281.626
285.872
287.359
287.818
291.396
290.844
289.611
291.846
290.298
286.946
287.905
286.427
286.523
290.456
287.53
292.754
294.061
293.98
288.716
291.31
287.209
289.227
294.279
288.781
291.044
296.553
296.097
293.664
294.361
287.624
294.644
293.437
293.299
285.569
297.559
294.853
293.678
290.228
292.641
292.924
295.61
297.047
298.77
298.197
288.604
297.669
294.496
293.679
299.108
295.328
295.18
292.471
294.009
296.119
299.68
297.138
297.395
302.112
299.198
301.293
300.381
295.702
301.616
303.292
298.147
299.832
302.422
299.879
302.965
298.855
303.863
305.407
299.28
296.723
296.879
301.329
312.03
305.751
306.972
298.889
304.613
310.031
303.875
304.232
304.65
298.455
299.929
304.635
300.154
296.332
304.141
295.566
302.383
303.539
299.391
301.465
297.41
304.504
299.585
291.888
299.26
295.228
297.865
300.959
296.014
297.243
292.627
297.941
298.895
295.028
291.915
296.222
292.337
291.946
291.853
294.224
290.708
289.349
284.259
280.428
284.506
287.33
286.847
290.57
287.49
286.693
287.414
281.084
279.653
279.958
279.453
276.672
277.184
277.316
279.959
275.832
274.493
275.324
274.019
272.875
273.613
276.627
277.098
271.485
272.587
267.269
273.095
272.143
268.971
269.859
269.944
275.797
274.078
272.85
271.46
274.171
276.299
273.851
274.985
272.253
267.467
270.83
268.397
267.743
267.762
269.709
266.523
272.71
271.871
270.778
271.562
273.161
267.358
270.91
275.528
274.289
265.882
269.607
269.789
270.059
265.998
260.05
268.739
276.926
268.236
271.797
269.888
272.907
273.104
272.941
269.596
269.396
269.596
267.487
269.399
270.734
266.334
267.442
265.126
261.487
268.513
270.853
271.672
266.992
266.052
263.918
269.447
272.078
266.381
263.629
268.224
270.453
268.406
262.407
263.399
260.491
261.361
266.592
263.244
262.816
264.11
258.588
256.746
260.446
258.124
257.892
252.684
255.469
253.789
254.752
250.795
247.996
248.237
247.73
246.639
250.004
247.17
243.425
244.299
249.622
250.236
249.461
248.19
246.528
249.368
254.791
254.662
250.649
251.016
256.962
253.241
255.668
252.301
256.083
254.306
249.528
246.494
249.244
251.336
253.422
249.598
245.427
247.387
248.937
243.204
240.3
239.4
246.923
248.047
235.084
238.873
236.431
241.188
244.832
244.651
243.02
245.017
244.09
247.732
250.45
250.486
259.136
255.692
253.82
261.814
267.115
264.873
266.634
269.408
268.672
272.534
273.416
273.5
273.748
272.344
272.533
277.5
279.807
284.293
294.419
305.263
311.961
329.8
344.024
367.722
406.595
451.001
502.578
589.539
701.973
884.516
1151.11
1500.11
1939.46
2372.01
2716.59
2858.79
2741.77
2429.2
2018.54
1608.53
1258.59
965.068
747.169
593.283
488.784
410.676
356.657
322.595
295.47
283.873
269.715
261.335
254.44
260.914
260.043
266.519
269.995
283.421
296.727
316.475
346.502
388.734
439.514
512.281
622.208
794.384
1048.9
1403.77
1899.93
2487.04
3084.37
3490.04
3585.06
3352.02
2858.76
2314.01
1803.38
1348.42
993.074
713.613
528.825
403.345
316.521
255.319
215.847
184.8
167.926
153.639
138.392
131.38
124.538
115.422
109.894
108.962
101.802
95.0627
94.2617
92.7633
90.3872
86.6656
82.1419
81.0183
77.271
77.5596
78.6864
79.3328
74.988
75.0947
73.6913
71.3481
71.2612
70.282
67.6085
68.9285
68.2198
67.2728
68.1847
70.1051
68.9728
67.7823
64.7837
62.8318
63.0616
65.4407
64.0155
64.068
64.3415
65.6102
63.5404
67.6464
64.2968
64.1119
63.0481
64.6281
65.1075
64.4529
64.4781
65.274
66.329
66.7056
65.9798
66.9355
66.3745
65.9921
64.6096
67.2132
66.5986
68.7213
67.5231
69.5311
71.0952
69.5023
69.5279
70.41
68.5493
71.6914
72.46
73.168
71.492
71.4212
71.6543
71.427
74.7203
75.9226
75.3477
2.30555
Au4f
4. Au in 12 mbar He
2020
8
30
15
30
28
0
12
Casa Info Follows
0
0
0
0
EX440_S718_Au in 20 mbar He.sle
Group = Au in 12 mbar He
First of group = 0
Analyzer lens = AngleResolvedMode22:1.5kV
Analyzer slit = 4:7x20c\C:mesh
Scan mode = FixedAnalyzerTransmission
Kinetic energy start = 1311.61
XPS
0
Al
1486.61
0
0
0
54.5
180
FAT
20
1
4.156
0
0
0
0
0
Au4f

-1
kinetic energy
eV
1311.61
0.1
2
counts
d
Transmission
d
pulse counting
1
1
0
0
0
0
2
ESCAPE DEPTH TYPE
d
0
MFP Exponent
d
0
47.1432
2.30555
235.482
233.418
242.201
232.233
232.154
234.903
228.366
233.316
236.012
244.459
242.249
237.67
237.489
240.009
236.093
232.935
236.309
240.638
237.492
239.509
232.909
233.673
236.733
237.117
235.847
238.055
232.623
233.521
236.73
235.919
231.765
238.246
239.334
233.163
239.709
231.946
229.595
238.232
242.096
241.674
245.581
243.516
242.295
234.444
237.8
229.508
231.842
237.447
239.809
233.872
236.318
241.117
239.982
237.656
242.827
240.701
234.489
232.14
231.988
239.745
233.664
237.474
240.948
237.759
233.969
231.834
232.957
229.462
236.796
232.969
235.735
244.289
240.298
235.757
235.694
237.4
232.654
228.925
239.273
237.223
243.981
244.031
242.309
239.33
237.415
234.314
235.673
243.615
238.96
232.929
234.79
241.223
245.809
241.751
235.302
236.361
237.509
237.549
238.573
231.746
238.965
239.027
239.682
231.935
237.444
238.913
240.031
242.24
241.393
235.285
239.373
240.195
239.923
244.92
244.11
240.544
243.937
236.562
236.792
244.553
245.349
240.365
239.739
244.112
237.972
236.953
241.363
240.056
237.733
246.091
247.324
237.069
230.976
232.662
241.16
237.959
242.809
242.86
240.378
241.208
247.666
245.664
244.302
239.049
241.868
236.217
245.683
241.677
237.108
235.001
236.912
240.429
244.702
234.165
236.281
240.113
246.381
245.35
248.625
248.317
238.589
241.392
240.718
235.876
238.924
237.365
249.024
242.926
242.077
231.833
237.124
239.864
246.985
243.803
245.481
247.342
247.353
243.083
243.98
245.62
243.045
247.515
246.465
247.094
246.253
246.14
249.448
239.631
241.913
242.246
249.647
246.197
238.437
243.948
240.874
246.386
240.723
245.453
254.04
249.297
241.486
246.212
244.124
245.274
250.961
250.758
248.677
246.819
243.502
247.809
244.457
250.866
241.94
247.424
256.628
253.13
244.934
244.847
249.969
242.869
242.333
236.373
241.124
246.853
250.268
247.209
248.646
247.785
246.351
241.881
244.485
247.439
250.405
250.291
249.674
247.712
245.932
246.948
250.364
243.612
242.289
242.403
248.425
246.131
246.894
250.343
251.93
254.221
253.573
254.002
241.679
247.895
254.032
248.886
246.304
249.099
251.825
252.371
246.579
242.814
255.694
250.217
251.077
251.398
249.202
245.229
253.109
253.292
248.41
249.796
250.739
248.012
252.84
250.164
249.5
252.338
250.556
254.346
251.846
250.697
254.032
249.713
251.976
254.527
260.037
258.176
253.294
250.836
240.851
254.972
264.151
255.085
252.385
255.219
252.618
257.879
252.948
250.376
249.637
251.574
254.172
251.924
252.953
252.173
251.829
247.993
254.145
251.813
258.988
256.073
256.444
251.475
250
250.138
249.325
250.637
252.847
258.107
246.929
254.288
251.952
249.204
256.51
256.314
254.216
254.162
252.988
250.523
257.378
257.251
262.062
258.115
259.401
254.453
253.211
250.536
253.964
252.313
254.063
254.431
251.962
258.207
255.857
258.69
254.782
251.89
253.842
254.52
254.422
258.531
255.984
256.833
255.647
260.37
259.297
256.729
253.918
253.415
257.888
258.599
258.097
258.446
256.057
253.336
257.585
253.464
254.788
253.973
257.371
250.878
256.087
251.183
251.984
266.207
262.883
256.416
254.217
250.952
253.541
249.775
260.303
254.75
256.378
257.248
256.123
252.503
256.178
265.527
260.521
254.59
255.416
262.304
256.689
257.496
253.857
255.707
254.853
257.768
252.783
250.992
255.882
255.372
259.029
260.338
267.983
258.574
258.237
257.739
255.557
251.143
256.284
259.169
259.076
256.286
261.035
262.185
260.247
257.101
260.599
262.864
261.783
255.411
255.587
255.667
260.522
256.717
255.548
260.142
261.676
260.915
258.295
268.293
260.188
261.732
254.08
254.419
261.168
260.883
261.582
256.705
256.827
256.73
265.068
265.345
263.607
256.304
258.217
264.208
259.848
259.722
257.853
259.702
255.554
266.5
260.652
263.884
257.733
264.03
263.49
262.303
257.878
256.809
261.837
268.241
260.516
262.721
261.128
258.208
258.42
259.142
255.621
257.735
255.958
261.282
258.975
260.713
258.265
255.981
259.931
263.359
259.423
262.756
267.313
263.2
264.415
268.999
260.539
260.109
265.102
264.265
259.707
251.493
257.559
261.179
262.148
261.393
264.895
263.222
267.538
259.661
265.152
264.927
268.45
259.654
260.022
254.953
262.955
261.961
265.587
263.62
265.144
267.467
264.904
267.704
271.464
266.399
265.046
268.889
265.199
259.281
266.331
272.851
270.657
266.745
265.906
263.253
269.729
266.733
270.229
267.465
271.281
269.103
271.726
269.069
269.204
268.084
274.297
263.832
266.541
267.882
271.716
274.01
276.589
265.746
279.554
269.579
274.447
270.458
276.549
276.484
273.927
273.302
274.663
268.507
269.536
273.312
276.675
278.833
278.425
278.56
282.15
281.287
276.152
278.752
276.551
280.256
274.166
272.142
277.136
272.277
278.16
279.496
277.077
275.546
283.942
282.185
273.823
273.2
274.956
268.278
275.811
287.075
280.825
274.169
288.024
278.182
286.081
282.932
281.031
280.717
282.362
284.199
282.316
282.611
283.784
280.405
280.358
284.111
282.978
285.882
295.243
285.843
286.825
285.498
292.608
288.458
292.599
286.062
293.043
287.419
287.35
296.904
287.181
290.55
287.838
295.642
296.209
299.509
289.456
294.659
296.455
298.448
296.871
293.784
292.306
289.205
291.822
298.895
299.142
288.712
291.002
294.204
295.16
299.525
304.129
311.671
301.288
307.434
305.489
312.034
316.758
316.718
308.845
296.036
291.716
288.466
280.794
281.84
290.866
283.1
284.4
289.459
295.353
303.05
319.769
336.374
351.831
372.413
392.19
396.729
384.189
372.704
356.821
341.543
321.963
303.882
296.208
288.431
281.766
272.293
271.181
270.311
266.333
271.566
272.65
271.214
277.688
278.713
270.437
261.342
249.12
251.468
244.423
232.967
233.286
233.488
230.575
238.328
242.202
253.34
270.794
280.713
301.759
319.754
349.185
373.808
370.872
355.37
338.167
313.721
296.631
274.386
254.533
242.133
235.411
232.755
230.566
216.754
220.143
213.523
208.297
216.871
210.651
210.175
211.018
208.617
209.412
213.284
211.627
208.69
202.326
207.134
206.514
207.561
207.033
202.282
202.889
206.119
206.212
204.567
202.817
205.215
209.316
206.242
205.052
206.052
203.459
206.535
202.637
208.297
203.38
205.77
204.04
206.001
203.909
206.965
202.241
202.212
207.989
206.967
207.203
206.186
204.037
202.137
203.009
203.581
204.756
204.742
203.979
201.765
210.346
202.964
204.29
200.094
202.049
206.477
203.201
205.159
207.858
199.955
201.404
205.551
201.58
204.556
201.489
195.67
197.905
196.779
194.04
197.101
192.267
190.72
191.325
192.674
189.54
186.858
190.126
191.582
188.937
188.893
189.14
185.331
183.533
192.174
196.655
192.352
190.817
189.714
193.168
194.07
194.753
198.118
199.161
195.126
194.884
194.181
194.417
190.178
196.96
190.633
197.016
193.395
194.801
189.363
190.479
192.615
184.889
187.716
183.939
187.151
182.422
180.995
181.676
180.655
184.292
183.962
184.746
185.108
182.875
183.449
187.756
187.069
190.725
194.656
191.788
188.94
189.727
194.446
194.047
203.137
199.915
204.278
201.26
202.321
205.237
205.606
204.727
206.568
204.337
202.085
209.918
205.362
207.209
212.531
220.409
227.172
230.696
245.93
265.599
276.173
295.705
322.278
373.171
428.737
513.423
633.553
823.541
1074.19
1381.91
1700.59
1949.9
2046.26
1978.59
1754.61
1450.61
1160.86
886.333
683.064
540.376
425.559
348.83
301.025
273.053
243.226
220.183
215.77
207.103
197.021
195.993
191.784
193.992
200.807
205.439
210.672
223.847
249.592
260.622
277.676
328.814
381.269
463.468
582.279
747.063
1027.75
1370.88
1787.79
2210.48
2482.76
2548.44
2391.46
2057.89
1676.77
1267.69
955.445
702.65
508.294
372
283.419
232.802
191.168
162.874
148.054
133.195
119.106
113.391
106.464
101.356
93.7629
91.9011
89.6766
85.3188
79.7128
78.7724
78.1512
77.7029
76.0021
73.1001
69.4544
71.87
68.3093
68.7569
70.8353
66.4897
63.4911
66.2855
67.2371
61.7049
64.2681
66.1497
63.092
66.6021
64.3394
62.262
63.5593
59.4865
60.3822
57.572
59.2501
61.6686
61.289
57.757
62.1805
60.1935
59.5753
57.101
59.2948
61.2409
59.1669
59.2367
59.371
58.1361
57.4183
58.9978
58.5243
57.569
56.2589
56.872
59.1744
59.5877
58.7662
59.7888
60.5901
58.9409
60.0325
63.2155
61.867
58.5453
58.7619
58.5798
59.5637
59.9141
59.1672
63.4068
65.1188
61.7841
61.4152
61.4819
60.5221
64.4212
62.755
63.4707
2.30555
end of experiment