File: data/H2/Au, Ag, Cu in H2.vms
VAMAS Surface Chemical Analysis Standard Data Transfer Format 1988 May 4
Not Specified
Not Specified
Not Specified
Not Specified
10
Casa Info Follows CasaXPS Version 2.3.24rev1.0F
0
Created by SpecsLab Prodigy, Version 4.64.1-r88350
SourceAnalyserAngle: 56.500000 d
CasaRowLabel:Ag in 2 mbar H2
CasaRowLabel:Ag in vac
CasaRowLabel:Au in 2 mbar H2
CasaRowLabel:Au in vacuum
CasaRowLabel:Cu in 2mbar H2
CasaRowLabel:Cu in vacuum
NORM
REGULAR
5
1
Exp Variable
d
0
0
0
0
28
AgMNN
Ag in 2 mbar H2
2020
3
13
12
52
42
0
14
Casa Info Follows
0
0
0
0
File = C:/Users/Mark/ownCloud/Muelheim Group/Projects/Gas phase background/EX340_CEC356_effect of lens modes.sle
Group = Ag in 2 mbar H2 , #Treatments: , #Temp: RT , #Pressure:2, #Gas1:H2, #Gas2:, #Gas Ratio:, #Comments:
First of group = 1
Analyzer lens = AngleResolvedMode22:1.5kV
Analyzer slit = 4:7x20c\C:mesh
Scan mode = FixedAnalyzerTransmission
Kinetic energy start = 266.61
C:\Users\Mark\ownCloud\Muelheim Group\Projects\Gas phase background\EX340_CEC356_effect of lens modes.vms
Sum of 19 spectra in column containing 19 scans
XPS
1
Al
1486.61
0
0
0
54.5
180
FAT
20
1
4.156
0
0
0
0
0
AgMNN

-1
kinetic energy
eV
266.61
0.1
2
counts
d
Transmission
d
pulse counting
1.9
1
0
0
0
0
2
ESCAPE DEPTH TYPE
d
0
MFP Exponent
d
0
242.827
4.42285
8738.9
8708.05
8605.98
8781.86
8748.33
8524.32
8577.32
8769.03
8608.8
8689.01
8609.03
8605.87
8502.53
8521.18
8660.55
8478.6
8659.33
8654.77
8619.47
8447.25
8511.47
8475.31
8453.03
8518.53
8572.89
8558.58
8355.59
8308.67
8533.19
8411.61
8380
8462.17
8587.53
8406.72
8514.26
8499.43
8491.73
8467.82
8409.57
8363.73
8393.07
8363.27
8381.26
8498.73
8394.56
8376.81
8502.56
8410.69
8279.35
8291.65
8366.91
8465.02
8424.68
8410.26
8381.94
8453.2
8483.96
8318.41
8439.75
8436.64
8262.52
8441.26
8262.88
8372
8511.91
8432.95
8359.44
8349.38
8351.67
8450.13
8386.38
8298.46
8404.69
8416.81
8467.99
8606.88
8466.99
8367.07
8491.77
8320.97
8316.07
8546.53
8440.42
8436.6
8380.69
8421.78
8371.81
8267.74
8412.8
8441.83
8376.65
8356.07
8229.76
8460.09
8444.49
8392.64
8380.73
8396.46
8365.5
8420.44
8502.08
8420.68
8580.89
8477.55
8454.48
8347.77
8376.84
8372.19
8217.96
8346.39
8466.49
8471.79
8510.81
8353.43
8322.76
8375.91
8396.3
8459.01
8266.28
8313.26
8472.51
8468.09
8431.07
8386.41
8470.06
8390.36
8323.25
8326.93
8376.63
8354.88
8301.05
8309.4
8384.5
8448.33
8405.18
8408.74
8477.12
8498.58
8488.7
8517.95
8398.65
8570.21
8497.07
8485.95
8444.22
8395.28
8554.93
8583.12
8445.94
8425.33
8336.17
8429.27
8450.82
8467.41
8487.19
8446.2
8507.06
8401.6
8213.46
8398.27
8393.81
8381.07
8447.17
8446.93
8484.31
8406.28
8520.08
8397.66
8425.32
8360.12
8518.22
8513.55
8475.71
8478.42
8605.72
8565.2
8425.79
8340.62
8388.94
8316.41
8303.3
8437.42
8364.53
8506.78
8482.87
8411.28
8226.06
8322.23
8559.08
8470.31
8413.47
8397.26
8481.68
8419.14
8444.39
8494.45
8505.77
8591.73
8416.81
8469.65
8445.23
8473.35
8444
8486.28
8376.7
8357.42
8485.51
8369.52
8416.44
8395.81
8375.1
8435.91
8452.78
8426.08
8380.7
8374.9
8480.59
8498.09
8384.34
8434.12
8607.53
8545.36
8376.17
8502.3
8418.87
8491.28
8462.57
8521.4
8451.13
8526.65
8455.66
8462.42
8515.1
8618.99
8432.05
8365.33
8495.54
8486.48
8527.12
8506.56
8421
8378.99
8422.99
8362.31
8363.28
8335.9
8473.71
8356.89
8379.81
8456.72
8495.94
8486.45
8426.58
8333.28
8469.72
8483.58
8461.6
8314.24
8368.47
8475.36
8411.84
8398.98
8364.3
8302.93
8302.16
8275.32
8272.36
8331.3
8265.94
8310.73
8360.9
8221.97
8301.55
8344.13
8362.26
8397.92
8234.4
8304.51
8351.81
8283.42
8227.56
8345.02
8365.2
8312.14
8468.53
8332.37
8274.66
8118.07
8185.89
8317.52
8402.45
8348.07
8191.74
8207.64
8246.83
8223.87
8172.8
8193.79
8189.03
8232.71
8159.06
8066.93
8130.37
8148.9
8294.33
8273.54
8175.28
8161.76
8298.26
8170.85
8194.64
8093.72
8055.22
8188.03
8133.84
8090.75
8130.28
8211.87
8139.93
8113.16
7937.01
8176.65
8161.35
8243.31
8260.37
8173.53
8089.44
8105.73
8282.03
8166.89
8114.68
8062.38
8108.26
8084.65
8043.56
8116.22
8180.04
8154.19
8092.48
8104.56
8119.84
8156.85
8089.23
7964.17
8078.1
8082.56
8083.96
8082.56
7950.26
7870.12
8008.88
8002.85
7934.54
7946.86
8021.29
8075.84
8006.12
7934.82
7951.11
7873.43
7944.74
7872.68
7955.35
7802.49
7878.59
7952.08
7908.46
7853.52
7897.39
7980.72
7853.28
7825.49
7752.6
7814.98
7703.94
7742.55
7755.72
7756.86
7700.1
7834.02
7759.79
7709.63
7627.33
7531.72
7653.61
7611.86
7474.52
7612.39
7648.79
7670.8
7676.3
7525.82
7622.06
7636.75
7559.23
7541.99
7634.12
7519.56
7626.6
7413.82
7520.19
7595.43
7536.52
7490.03
7493.89
7470.59
7519.96
7398.81
7412.47
7367.9
7480.71
7405.69
7431.33
7480.99
7435.51
7373.73
7302.96
7353.37
7386.04
7379.54
7286.34
7347.06
7231.62
7202.08
7171.7
7241.54
7436.31
7379.15
7284.21
7215.09
7223.44
7112.27
7111.41
7267.47
7173.57
7190.28
7242.01
7231.22
7098.85
7142.38
7223.19
7131.96
7205
7152.47
7119.23
7206.42
7185.09
7220.12
7213.93
7003.09
7164.83
7171
7231.14
7058.1
7148.7
7144.76
7109.77
7123.58
7151.77
7045.6
7145.95
7377.17
7270.75
7180.1
7228.34
7171.09
7206.09
7232.87
7149.53
7049.93
7219.72
7127.43
7210.37
7155.19
7106.56
7228.31
7113.39
7295.61
7141.81
7071.33
7190.83
7152.47
7160.01
7148.26
7083.96
7116.95
7057.42
7136.99
7083.52
6962.21
7067.98
7014.92
7059.48
7192.7
7287.71
7240.96
7195.51
7088.13
7009.84
7075.98
7005.71
7152.06
7075.93
7151.52
7119.61
7061.82
7079.35
7107.58
7089.94
7213.28
7189.89
7060.34
7156.75
7188.01
7130.81
7147.16
7212.04
7293.23
7241.29
7291.19
7278.53
7103.65
7181.22
7264.41
7194.97
7084.49
7133.04
7187.59
7270.13
7229.24
7259.7
7108.33
7078.84
7190.73
7242.45
7171.82
7186.69
7182.11
7145.67
7089.93
7153.4
7231.23
7219.05
7155.91
7288.71
7338.94
7161.43
7224.17
7279.79
7136.1
7122.4
7122.23
7256.87
7298
7238.16
7165.03
7112.57
7361.95
7177.31
7171.38
7269.99
7202.73
7036.08
7187.31
7191.24
7253.55
7343.13
7216.26
7195.48
7194.51
7215.26
7341.8
7332.76
7342.61
7232.18
7248.1
7399.32
7442.29
7368.6
7462.14
7426.23
7365.61
7330.28
7302.7
7448.92
7237.52
7266.22
7335
7272.71
7172.06
7192.42
7333.61
7442.46
7398.52
7285.26
7332.22
7389.73
7463.99
7379.81
7424.42
7334.94
7371.65
7444.71
7324.44
7441.9
7374.3
7472.17
7433.06
7439
7402.78
7467.77
7376.6
7415.97
7472.93
7315.54
7300.84
7333.88
7266.53
7330.28
7424.26
7388.9
7432.95
7415.36
7484.25
7452.27
7288.18
7357.77
7380.19
7389.12
7443.84
7440.69
7552.44
7508.07
7430.21
7409.04
7462.72
7549.36
7497.67
7479.92
7403.73
7447.01
7462.96
7453.79
7552.93
7523.29
7488.59
7662.38
7629.74
7541.38
7549.49
7528.79
7506.47
7572.77
7674.79
7540.84
7546.01
7649.07
7615.55
7570.95
7548.46
7478.44
7584.66
7558.69
7579.11
7548.33
7559.62
7600.46
7603.31
7565.67
7732.2
7700.9
7734.82
7604.71
7578.85
7644.87
7583.16
7621.25
7694.19
7718.87
7577.9
7601.03
7613.57
7732.98
7720.44
7540.64
7624.51
7663.94
7709.13
7796.98
7822.34
7775.08
7859.27
7725.99
7663.5
7750.6
7687.62
7662.12
7819.99
7817.75
7675.28
7739.95
7692.8
7828.41
7662.8
7864.76
7794.55
7901.95
7888.26
7890.78
7775.55
7847.74
7840.61
7831.23
7826.81
7918.45
7954.28
8014.16
7901.07
7957.11
7877.96
7959.26
8012.66
8114.24
8082.1
8086.45
8133.58
8014.74
8007.45
8034.23
8031.93
8019.73
8153.75
7958.4
7921.06
7979.64
8133.35
7845.79
7945.81
7913.72
7797.99
7906.14
7857.5
7827.61
7770.18
7750.17
7708.68
7758.35
7628.19
7501.31
7663.42
7663.53
7559.59
7554.44
7559.37
7527.49
7591.28
7683.12
7564.06
7560.33
7447.65
7481
7356.52
7412.57
7404.43
7358.43
7379.69
7316.84
7383.92
7358.77
7361.5
7365.05
7383.75
7482.3
7424
7397.37
7590.26
7429.65
7450.9
7575.6
7500.33
7568.04
7453.61
7510.12
7494.62
7577.82
7567.61
7559.79
7550.31
7606.02
7632.85
7486.89
7470.68
7419.63
7470.07
7391.6
7529.45
7427.84
7358.81
7262.65
7271.96
7344.55
7392.42
7483.39
7339.74
7390.1
7414.66
7427.08
7369.8
7412.43
7340.58
7457.79
7553.11
7435.05
7366.2
7636.15
7651.5
7528.8
7564.79
7718.27
7622.12
7622.38
7760.35
7793.04
7876.6
7815.93
7712.02
7668.68
7704.8
7724.13
7743.11
7690.1
7855.49
7779.06
7739.35
7737.96
7741.47
7886.46
7896.86
8018.52
7968.79
8226.66
8201.53
8287.2
8473.9
8810.47
9090.49
9486.98
9759.88
10051.9
10484.5
10890
10937.5
10926.5
10821.9
10878.5
10626.4
10456.3
10279.4
10141.1
10034.9
9942.12
9757.07
9683.49
9605.59
9765.8
9684.02
9663.83
9535.42
9483.11
9388.27
9332.42
9243.85
9287.33
9070.05
8900.18
8624.55
8581.09
8385.58
8261.53
8145.39
8164.06
8112.41
8089.12
7852.93
7906.99
7779.25
7832.85
7671.35
7576.35
7545.04
7477.1
7595.51
7514.94
7420.98
7433.98
7481.07
7473.48
7429.37
7332.63
7415.4
7353.16
7613.06
7581.96
7654.51
7830.58
8032.04
8285.95
8641.66
9029.07
9303.15
9567.48
9793.54
9737.62
9575.48
9700.46
9333.5
9097.11
8736.55
8356.65
7962.38
7841.64
7780.62
7561.09
7479.98
7332.3
7262.36
7154.98
7147.46
7037.68
6734.89
6579.69
6518.81
6428.28
6336.94
6240.38
6047.81
6028.1
5936.63
5850.53
5837.23
5794.12
5923.75
5797.08
5721.14
5825.63
5835.5
5665.64
5606.88
5800.03
5812.07
5780.32
5658.46
5676.88
5641.83
5652.42
5563.77
5668.92
5647.14
5618.37
5580.2
5561.57
5460.31
5516.74
5630.3
5559.91
5521.1
5499.65
5502.73
5542.65
5470.93
5453.7
5498.23
5441.93
5376.61
5495.14
5406.66
5294.49
5402.26
5409.49
5276.57
5336.07
5288.64
5375.72
5345.12
5364.98
5339.24
5304.4
5222.5
5158.04
5221.77
5322.68
5249.63
5247.93
5252.72
5227.57
5257.45
5280.86
5240.58
5217.88
5295.9
5293.2
5110.85
5143.83
5191.58
5214.37
5165.74
5079.17
5217.35
5203.65
5153.39
5076.1
5114.37
5228.91
5211.1
5216.4
5221.23
5184.49
5100.52
5149.37
5250.02
5150.01
5169.77
5222.17
5199.98
5059.99
5058.76
5099.64
5170.44
5064.4
5164.51
5247.82
5078.07
5162.91
5150.26
5108.13
4956.67
5195.83
5146.15
5160.15
5132.06
5131.16
5170.21
5157.27
5095.63
5152.08
5145.9
5121.33
5080.64
5239.98
5130.79
5181.88
5118.25
5125.92
5099.87
5090.68
5148.99
5075.43
5206.81
5170.86
5113.07
5164.44
5089.16
5087.95
5147.93
5168.27
5112.04
5073.49
5123.99
5127.15
5062.21
5179.12
5134.96
5086.72
5093.84
5039.83
4995.88
5035.07
5193.22
5175.69
5145.6
5127
5204.49
5176.89
5114.03
5116.41
5053.15
5122.46
5036.66
5137.68
5151.62
5096.5
5139.66
5120
5035.1
5159.84
5160.47
5122.23
5114.37
5041.89
5110.85
5227.16
5123.82
5075.43
5134.04
5104.85
5191.95
5210.91
5221.83
5250.68
5095.05
5154.7
5052.12
5189.34
5179.67
5216.13
5236.92
5207.34
5165.47
5181.92
5116.67
5294.11
5237.61
5104.55
5109.33
5200.78
5101.55
5110.95
5155.87
5137.7
5213.12
5191.44
5195.17
5217.2
5138.44
5145.68
5186.8
5204.9
5169.5
5176.89
5066.56
5041.01
5200.66
5274.6
5243.5
5262.39
5225.4
5227.17
5232.84
5116.17
5118.93
5163.8
5243.79
5185.96
5240.77
5202.69
5252.24
5167.15
5224.72
5224.17
5109.08
5242.09
5262.82
5199.76
5321.78
5261.92
5103.74
5253.62
5253.3
5188.66
5278.65
5215.85
5231.11
5265.05
5271.66
5269.78
5180.63
5231.6
5129.21
5203.95
5233.65
5233.71
5186.04
5258.64
5300.3
5300.57
5202.72
5200.47
5280.27
5285.28
5253.94
5183.16
5250.23
5231.1
5284.21
5284.09
5303.32
5278.72
5253.96
5310.95
5217.63
5270.83
4.42285
Ag3p
Ag in 2 mbar H2
2020
3
13
12
58
57
0
14
Casa Info Follows
0
0
0
0
File = C:/Users/Mark/ownCloud/Muelheim Group/Projects/Gas phase background/EX340_CEC356_effect of lens modes.sle
Group = Ag in 2 mbar H2 , #Treatments: , #Temp: RT , #Pressure:2, #Gas1:H2, #Gas2:, #Gas Ratio:, #Comments:
First of group = 0
Analyzer lens = AngleResolvedMode22:1.5kV
Analyzer slit = 4:7x20c\C:mesh
Scan mode = FixedAnalyzerTransmission
Kinetic energy start = 686.61
C:\Users\Mark\ownCloud\Muelheim Group\Projects\Gas phase background\EX340_CEC356_effect of lens modes.vms
Sum of 18 spectra in column containing 18 scans
XPS
1
Al
1486.61
0
0
0
54.5
180
FAT
20
1
4.156
0
0
0
0
0
Ag
3p
-1
kinetic energy
eV
686.61
0.1
2
counts
d
Transmission
d
pulse counting
1.8
1
0
0
0
0
2
ESCAPE DEPTH TYPE
d
0
MFP Exponent
d
0
3.31097
9542.9
3.31
9606.72
3.30879
9563.74
3.30758
9588.06
3.30637
9539.59
3.30516
9556.49
3.30396
9524.97
3.30275
9649.07
3.30155
9894.54
3.30035
9775.55
3.29915
9480.18
3.29795
9599.13
3.29675
9677.16
3.29555
9879.16
3.29436
9759.95
3.29316
9795.58
3.29197
9869.02
3.29078
9763.52
3.28959
9765.42
3.2884
9921.7
3.28721
9817.24
3.28603
9799.23
3.28484
9690.69
3.28366
9794.89
3.28248
9795.17
3.28129
9896.36
3.28011
9873.85
3.27894
9781.41
3.27776
9876.77
3.27658
9827.38
3.27541
9905.78
3.27423
9929.72
3.27306
9957.98
3.27189
9960.57
3.27072
10067.8
3.26955
10025.2
3.26838
10008.2
3.26722
10007.5
3.26605
10106.3
3.26489
9977.22
3.26373
10136.3
3.26257
10216
3.26141
10168.2
3.26025
10234.5
3.25909
10192.7
3.25793
10220.5
3.25678
10199.7
3.25563
10249.5
3.25447
10155.9
3.25332
10183.9
3.25217
10358.4
3.25102
10347.3
3.24988
10185.1
3.24873
10198.6
3.24758
10298.2
3.24644
10346.6
3.2453
10236.9
3.24416
10220.7
3.24302
10330.9
3.24188
10420.5
3.24074
10211.7
3.2396
10310.9
3.23847
10416.7
3.23733
10443
3.2362
10398.6
3.23507
10539.3
3.23394
10455
3.23281
10435.8
3.23168
10446.6
3.23055
10436.2
3.22942
10399.5
3.2283
10616.9
3.22718
10619
3.22605
10491.3
3.22493
10417.5
3.22381
10627.8
3.22269
10644.9
3.22158
10452.4
3.22046
10578.3
3.21934
10642.4
3.21823
10707.6
3.21712
10711.3
3.216
10685.1
3.21489
10804.7
3.21378
10712.5
3.21267
10667.3
3.21157
10709.6
3.21046
10742.6
3.20936
10876.1
3.20825
10966.8
3.20715
10696.3
3.20605
10848.5
3.20495
11009.3
3.20385
10918.3
3.20275
10790.3
3.20165
10861.8
3.20055
10976.2
3.19946
10920
3.19837
10944.3
3.19727
11097.5
3.19618
11066.2
3.19509
10788.3
3.194
11120.3
3.19291
11122
3.19183
11165.2
3.19074
10987.3
3.18966
10995
3.18857
11152.2
3.18749
11217.4
3.18641
11089.5
3.18533
11091.4
3.18425
11301.4
3.18317
11263
3.18209
11013.9
3.18102
11240.9
3.17994
11253.4
3.17887
11143.7
3.17779
11303.1
3.17672
11493.9
3.17565
11264.8
3.17458
11407
3.17351
11409.8
3.17245
11554.3
3.17138
11457.6
3.17031
11383.8
3.16925
11503
3.16819
11627.3
3.16712
11389.4
3.16606
11558.6
3.165
11592.3
3.16394
11528.1
3.16289
11387.8
3.16183
11557.7
3.16077
11431.8
3.15972
11464.7
3.15867
11840.3
3.15761
11691.2
3.15656
11581.7
3.15551
11646.1
3.15446
11663
3.15341
11602.2
3.15237
11591.2
3.15132
11620.8
3.15027
11630.2
3.14923
11603
3.14819
11688.1
3.14714
11719.2
3.1461
11783
3.14506
11701.1
3.14402
11661.1
3.14299
11894.8
3.14195
11955.4
3.14091
11881.5
3.13988
12010.4
3.13884
12069.3
3.13781
12283.4
3.13678
12290.9
3.13575
12139.5
3.13472
12422.6
3.13369
12469.6
3.13266
12549.8
3.13164
12551.2
3.13061
12506.8
3.12959
12542.1
3.12856
12411.1
3.12754
12446.6
3.12652
12340.9
3.1255
12269.7
3.12448
12179.5
3.12346
12150.2
3.12244
11888.7
3.12142
11982.6
3.12041
11910
3.11939
11945.3
3.11838
11794.2
3.11737
11777
3.11635
11708.4
3.11534
11469.3
3.11433
11562
3.11332
11570.3
3.11232
11464.1
3.11131
11427.3
3.1103
11533.3
3.1093
11432.5
3.10829
11519.8
3.10729
11528.6
3.10629
11601.6
3.10529
11488.2
3.10429
11454.9
3.10329
11556.2
3.10229
11480.1
3.10129
11467.6
3.1003
11355.3
3.0993
11397.5
3.09831
11564.1
3.09731
11347.3
3.09632
11414.2
3.09533
11437.5
3.09434
11412.1
3.09335
11421.3
3.09236
11582.2
3.09137
11364.1
3.09039
11512.1
3.0894
11669
3.08842
11525.9
3.08743
11576.8
3.08645
11313.9
3.08547
11496.4
3.08449
11495.1
3.08351
11539.5
3.08253
11591.2
3.08155
11589.9
3.08057
11640.2
3.0796
11607.9
3.07862
11619.8
3.07765
11640.9
3.07667
11695.3
3.0757
11576.7
3.07473
11799
3.07376
11527.4
3.07279
11790.5
3.07182
11767.5
3.07085
11863.7
3.06988
11866.2
3.06892
11629.8
3.06795
11718.2
3.06699
11921.4
3.06602
11808.9
3.06506
11745.4
3.0641
11784.9
3.06314
11993.9
3.06218
11851.7
3.06122
11778.2
3.06026
11788.9
3.0593
11826.3
3.05835
11880.4
3.05739
11970.1
3.05644
11764.1
3.05548
11855.5
3.05453
11929.4
3.05358
11805.7
3.05263
11965.2
3.05168
11822.7
3.05073
12137.4
3.04978
11919.6
3.04883
11961
3.04788
12071.9
3.04694
11992.1
3.04599
11949.7
3.04505
11993.5
3.04411
11986.7
3.04317
12093.8
3.04222
11975.6
3.04128
12057.7
3.04034
12193.2
3.03941
12061.9
3.03847
11997.3
3.03753
12073.7
3.03659
12019.6
3.03566
12230.7
3.03472
12217.9
3.03379
12180.9
3.03286
12244.5
3.03193
12173.6
3.031
12170.7
3.03007
12285.6
3.02914
12049.8
3.02821
12121.1
3.02728
12259.6
3.02635
12063.9
3.02543
12368.1
3.0245
12318.7
3.02358
12536.9
3.02266
12279.5
3.02173
12377.4
3.02081
12473.4
3.01989
12354.8
3.01897
12718.2
3.01805
12603.3
3.01713
12423.2
3.01622
12471.8
3.0153
12521.7
3.01438
12477.7
3.01347
12537.4
3.01256
12568.6
3.01164
12608
3.01073
12506.3
3.00982
12520.4
3.00891
12579.9
3.008
12714.6
3.00709
12584.9
3.00618
12799.6
3.00527
12734.5
3.00437
12666.7
3.00346
12652.9
3.00256
12640.2
3.00165
12969.8
3.00075
12796.7
2.99985
12573
2.99894
12627.1
2.99804
12732.8
2.99714
12964.4
2.99624
12899.5
2.99535
12642.2
2.99445
12923.5
2.99355
12897.3
2.99266
12773.5
2.99176
12855.6
2.99087
13022.7
2.98997
13030.6
2.98908
12983.1
2.98819
12941.7
2.9873
13002.1
2.98641
13010.6
2.98552
13081.4
2.98463
13092.4
2.98374
12905
2.98285
12983.2
2.98197
13103.9
2.98108
13136.5
2.98019
13024.6
2.97931
13085.1
2.97843
13207.2
2.97754
13142.5
2.97666
13176.8
2.97578
13105.7
2.9749
13288.5
2.97402
13112.1
2.97314
13220.6
2.97227
13164
2.97139
13383.8
2.97051
13442.7
2.96964
13251.9
2.96876
13530.4
2.96789
13530.3
2.96702
13399.3
2.96614
13544.3
2.96527
13532.9
2.9644
13556.8
2.96353
13482.4
2.96266
13708.2
2.96179
13679.3
2.96092
13547.8
2.96006
13476.8
2.95919
13695.9
2.95833
13715.7
2.95746
13691.7
2.9566
13744.5
2.95573
13822.5
2.95487
13744.9
2.95401
13703.1
2.95315
13765.8
2.95229
13782.7
2.95143
13790.1
2.95057
13912.9
2.94971
13920.6
2.94885
13994.1
2.948
13962.9
2.94714
14052.5
2.94629
14271
2.94543
14157.9
2.94458
14150.9
2.94373
14270.9
2.94287
14201.7
2.94202
14342.6
2.94117
14474.5
2.94032
14616.3
2.93947
14496.9
2.93863
14219.2
2.93778
14057.2
2.93693
13795.7
2.93608
13774.7
2.93524
13692.7
2.93439
13636.9
2.93355
13659
2.93271
13843.2
2.93187
13736.1
2.93102
13694.6
2.93018
13964.3
2.92934
13727.9
2.9285
13921.2
2.92766
13972.2
2.92683
14027.3
2.92599
14200.7
2.92515
14363.4
2.92432
14739.6
2.92348
14973.8
2.92265
15636.8
2.92181
16471.7
2.92098
17693.4
2.92015
19628.2
2.91931
21109.3
2.91848
21343.1
2.91765
20109.9
2.91682
17994.9
2.91599
16425.6
2.91517
15374.8
2.91434
14702.6
2.91351
14062.5
2.91269
13852.4
2.91186
13697.6
2.91104
13541.4
2.91021
13543.9
2.90939
13459.1
2.90857
13290
2.90774
13307.8
2.90692
13163.3
2.9061
13125.3
2.90528
13084.3
2.90446
13092.9
2.90364
13106.7
2.90283
13168
2.90201
13123
2.90119
13285
2.90038
13345
2.89956
13438.5
2.89875
13451.5
2.89794
13493.4
2.89712
13499.8
2.89631
13502.3
2.8955
13566.7
2.89469
13726.4
2.89388
13547
2.89307
13612.3
2.89226
13718.6
2.89145
13932.5
2.89064
14173.5
2.88984
14082.1
2.88903
14052.1
2.88823
13907.8
2.88742
13521.3
2.88662
13138
2.88581
12701.7
2.88501
12311.8
2.88421
12266.6
2.88341
12139.5
2.88261
12165.2
2.88181
12110.1
2.88101
12137.4
2.88021
12168.4
2.87941
12364.4
2.87861
12208.8
2.87782
12405.3
2.87702
12673.8
2.87622
12837.2
2.87543
13025.3
2.87464
13729.1
2.87384
14300.8
2.87305
15180.7
2.87226
16417.6
2.87147
18567.4
2.87067
21354.2
2.86988
24822
2.86909
27142.4
2.86831
26270.3
2.86752
23035.6
2.86673
19259.3
2.86594
16345.1
2.86516
14340.1
2.86437
13010
2.86359
11984.6
2.8628
11469.1
2.86202
10954.2
2.86124
10709.6
2.86045
10401.1
2.85967
10176
2.85889
10148.1
2.85811
9904.79
2.85733
9639.76
2.85655
9843.26
2.85577
9657.81
2.85499
9581.24
2.85422
9442.82
2.85344
9483.97
2.85266
9506.43
2.85189
9470.98
2.85111
9528.55
2.85034
9400.37
2.84957
9203.16
2.84879
9313.86
2.84802
9482.05
2.84725
9435.37
2.84648
9301.88
2.84571
9316.79
2.84494
9466.76
2.84417
9350.83
2.8434
9138.87
2.84263
9295.23
2.84187
9223.32
2.8411
9427.4
2.84033
9347.69
2.83957
9251.29
2.8388
9341.97
2.83804
9429.44
2.83727
9299.57
2.83651
9341.84
2.83575
9331.44
2.83499
9513.61
2.83423
9380.22
2.83347
9334.35
2.83271
9350.85
2.83195
9362.37
2.83119
9247.73
2.83043
9369.72
2.82967
9529.69
2.82892
9265.85
2.82816
9363.64
2.8274
9343.06
2.82665
9490.57
2.82589
9447.03
2.82514
9457.26
2.82439
9309.59
2.82364
9363.13
2.82288
9398.23
2.82213
9472.04
2.82138
9334.61
2.82063
9414.36
2.81988
9294.21
2.81913
9469.19
2.81838
9398.87
2.81764
9363.74
2.81689
9431.29
2.81614
9411.5
2.8154
9387.18
2.81465
9275.45
2.81391
9482.94
2.81316
9557.64
2.81242
9546.28
2.81168
9434.89
2.81093
9517.68
2.81019
9599.56
2.80945
9738.17
2.80871
9867.42
2.80797
9917.53
2.80723
10094.6
2.80649
10250.9
2.80575
9881.09
2.80501
9784.29
2.80428
9634.56
2.80354
9577.78
2.8028
9536.39
2.80207
9567.13
2.80133
9603.62
2.8006
9488.21
2.79987
9640.31
2.79913
9561.64
2.7984
9480.35
2.79767
9524.83
2.79694
9573.32
2.79621
9659.4
2.79548
9493.25
2.79475
9482.83
2.79402
9516.81
2.79329
9692.86
2.79256
9606.69
2.79183
9525.4
2.79111
9733.62
2.79038
9662.11
2.78965
9687.1
2.78893
9523.78
2.7882
9638.19
2.78748
9683.79
2.78676
9716.39
2.78603
9688.35
2.78531
9730.83
2.78459
9708.25
2.78387
9727.89
2.78315
9632.05
2.78243
9555.15
2.78171
9714.82
2.78099
9675
2.78027
9618.23
2.77955
9708.84
2.77884
9820.01
2.77812
9872.98
2.7774
9793.35
2.77669
9646.19
2.77597
9770.53
2.77526
9925.95
2.77454
9736.32
2.77383
9787.11
2.77312
9883.25
2.7724
9832.79
2.77169
9858.17
2.77098
9924.39
2.77027
9882.31
2.76956
9951.23
2.76885
9827.67
2.76814
9846.33
2.76743
9881.55
2.76673
9987.66
2.76602
9993.13
2.76531
9920.95
2.7646
10067.7
2.7639
9894.86
2.76319
9935.29
2.76249
9878.05
2.76178
9961.04
2.76108
9932.43
2.76038
9900.78
2.75968
2.75953
Ag3d
Ag in 2 mbar H2
2020
3
13
13
1
6
0
14
Casa Info Follows
0
0
0
0
File = C:/Users/Mark/ownCloud/Muelheim Group/Projects/Gas phase background/EX340_CEC356_effect of lens modes.sle
Group = Ag in 2 mbar H2 , #Treatments: , #Temp: RT , #Pressure:2, #Gas1:H2, #Gas2:, #Gas Ratio:, #Comments:
First of group = 0
Analyzer lens = AngleResolvedMode22:1.5kV
Analyzer slit = 4:7x20c\C:mesh
Scan mode = FixedAnalyzerTransmission
Kinetic energy start = 1036.61
C:\Users\Mark\ownCloud\Muelheim Group\Projects\Gas phase background\EX340_CEC356_effect of lens modes.vms
Sum of 19 spectra in column containing 19 scans
XPS
1
Al
1486.61
0
0
0
54.5
180
FAT
20
1
4.156
0
0
0
0
0
Ag
3d
-1
kinetic energy
eV
1036.61
0.1
2
counts
d
Transmission
d
pulse counting
1.9
1
0
0
0
0
2
ESCAPE DEPTH TYPE
d
0
MFP Exponent
d
0
75.3769
2.57029
11561.9
11584.5
11635.6
11655.9
11670.5
11669.8
11560.4
11550.4
11480.7
11711.4
11701.4
11479
11542.4
11616.9
11689.5
11534
11425.4
11676.2
11671.3
11622
11621.7
11504.8
11645.6
11723.8
11882.8
11626
11682.8
11747.4
11587.1
11600.4
11650.8
11596.5
11576.8
11553.6
11702.5
11621.7
11648.2
11654.5
11586.8
11818.6
11772.1
11697.9
11583.9
11734.4
11551.9
11710.7
11732.8
11642.3
11552.9
11709.1
11642.9
11749.5
11740.3
11623
11713.3
11705.2
11725.5
11853.5
11784.3
11721.6
11600.2
11704.3
11707.2
11718.8
11919.3
11767.2
11716.1
11695.1
11645.5
11700.8
11723.1
11707.6
11608.8
11606.2
11557.4
11671.7
11783.7
11795
11679.6
11748.6
11830.7
11781.1
11999.6
11883.1
11630.9
11592.8
11547.8
11711.8
11679.5
11702.3
11654.1
11779.6
11634.1
11716.7
11716.1
11774.5
11745.9
11693.3
11677.3
11771.9
11632.9
11658.2
11804.3
11871.2
11748.3
11719.2
11963.2
11800.4
11810.2
11769.5
11646.2
11700
11654.6
11626.7
11608.5
11661.4
11811.2
11681.9
11638
11813.8
11869.9
11823.5
11625.1
11637.8
11736.6
11752.2
11816.8
11774.1
11832.7
11812.6
11744.7
11798
11737.9
11768.1
11669.5
11782.9
11780
11789.5
11674
11864.1
11943.3
11839.7
11751.6
11774.5
11923.2
11854.5
11505
11658.9
11864.1
12086.8
11909.3
12010.9
11668.3
11752.3
11787.5
11681.2
11715.6
11843.3
11833.9
12002
11785.5
11660.8
11688.1
11661.2
11651.6
11670.7
11877.9
11741.7
11785
11736.8
11711
11971.8
11947.2
11776.9
11833.9
11872.3
11872.2
11933.3
11840.6
11876.6
11856.5
11949.2
11889.9
11952.2
11923.1
11902.4
11720.5
11774
11854.9
11876.5
11914.2
11999
11977.4
12089.3
11861.2
12025.5
12059
11968.2
11838.8
11893.3
11902.7
11881.3
11908.9
11969.1
11944.6
11904.8
11780
11941.1
11997.6
11948.8
12030.2
12015.5
11945.3
11933
11983.7
12122.6
12022.1
11953.8
11965
11991.1
12008
12196.7
12001
12117.9
12129.8
11879.9
11767
12029.1
11955.9
11998.3
12008.1
11908.2
11884.9
11890.1
12056.1
12002.9
12027.5
12058.9
12170.2
12064.4
12035.6
11933.1
12158.7
12020.2
12017.6
12183.3
12269.7
12139.2
12136.2
11877.5
12117.2
12154.8
12077.6
12207.9
12273
12095.7
12124
12054.1
12261.4
12248
12191.9
12159.6
12131.7
12002.8
12196.8
12255.1
12271.4
12296.7
12222.2
12276.3
12238.2
12142.7
12124.1
12143.3
12155
12152
12150.8
12416.2
12287.3
12255.4
12214.9
12232
12260
12153.2
12176.7
12323.3
12309.9
12352.8
12374.5
12264.6
12090.3
12213.5
12232.2
12168.8
12295.1
12371
12336.9
12277.1
12115.9
12183.6
12210
12207.3
12258.3
12175.3
12175.4
12439.4
12390.6
12192.5
12281.5
12207.6
12131.3
12269
12278.5
12305.2
12214.1
12160.1
12329.8
12181
12214.9
12422.5
12410.7
12355.6
12411.1
12421.7
12295.3
12234.8
12391.6
12483.4
12351
12443.7
12397.8
12270
12353
12385
12516.3
12408.4
12329.4
12455
12372.7
12365.9
12266.8
12180.1
12499.7
12595.6
12499.8
12592.7
12465
12316.3
12495.2
12651
12387.2
12429.6
12590.6
12403.1
12469
12566.2
12680.4
12699.7
12559.7
12662.3
12531.5
12629.6
12560.3
12637.1
12645.7
12599.5
12554.5
12624.1
12636.8
12569.7
12452.1
12547.5
12587.6
12546.2
12477
12536.5
12656.2
12580.7
12677.9
12702.7
12685.5
12805.9
12679.9
12661.2
12732.5
12585.7
12817.7
12658.9
12471.5
12709.4
12760.1
12766
12837.4
12921.5
12862
12811.9
12763.3
12739.3
12694.1
12844.9
13016.4
12806.7
12904.2
13001.7
12990.2
12921.4
12937.1
12741.1
12804.6
12782
12967.9
12957.4
12972.4
12934.1
12997.2
12843.9
12861.4
12840.7
12933.6
13006.7
12998.9
12994.6
12951.7
13048.4
12943.5
13063.1
12997
12969.9
13167
13007.7
12874.2
12889.2
13143.7
13154.7
13223
13306.9
13082.2
13252.1
13096.5
13255.2
13155.7
13125.4
13018.4
13134.5
13238.8
13205.3
13221.5
13158.2
13132.4
13191.2
13116.1
13149.5
13252.8
13330.2
13311.9
13289.4
13286
13290.8
13317.4
13451.6
13338.7
13390.2
13612.8
13312.1
13382.8
13594.3
13372.1
13338.9
13525
13612.3
13570
13528.6
13687
13469.1
13390.3
13570.5
13544.3
13540.1
13517.5
13520.6
13539.2
13492.3
13676.5
13897.6
13833.5
13773.1
13735.1
13744.7
13912.6
13852.5
13853.2
13967.1
14025.6
13917.7
13920.7
13944.6
13969.5
13968.9
14015.6
14049.9
14049.5
14048
13991.4
14044.9
14231.1
14353.6
14383.3
14284.6
14223.1
14279.3
14452.2
14346
14171.5
13935.8
14043.3
14130.8
14239.5
14117
14032.8
13994.6
14000.2
13967.5
13961.3
13970.9
13981.5
14020.5
13934.9
13830.1
14108.8
14008.3
13875
14016
14097.3
13975.7
14093.2
14100.1
14204.6
13941.3
14081.6
14147.9
14111.3
14133.8
14194.2
14287.4
14514.7
14331.9
14406.3
14225.4
14302.7
14309.3
14374.1
14479.4
14439.4
14583.4
14779.2
14838.5
14753.9
14846.7
14881.6
15077.9
14904.1
14936.1
14752.4
14873.8
14976
14943.2
15001.2
14985.3
14915.5
14861.2
14765
14939.7
15056.4
15088.6
14841.2
14902.6
14909.1
14933.6
14750.5
14858
14852.8
14688.8
14877.5
14809.8
14779.3
14735
14952.6
14931.4
14876.1
14924.9
14874.5
14831.2
15035
14908.4
15001.9
15055.7
15100.7
15143.3
15048.4
14900.2
14964.3
15109.5
14964.4
15027.9
14938.7
14978.2
15099.2
15262.4
15150.4
15323.3
15177.6
15418.5
15486.9
15351.4
15334
15220.8
15333.9
15352.8
15500.6
15715.9
15936
16013.1
16203.4
16568.8
17004.6
17128.5
17455
17978.1
18368.8
18501.2
18783
18744.9
18830.1
18543.8
18203.4
17885.7
17609
17052.3
16773.4
16393.6
16005.6
15545
15117.4
14782
14547.8
14110.2
13851.6
13744.3
13538.8
13383.3
13614.3
13566.8
13349.6
13533.9
13420.6
13498.7
13480.7
13412.3
13625.5
13572.8
13572.8
13584.4
13699.2
13441.4
13736.9
13667.4
13730.7
13867
13644.9
13689.9
13971
13841.7
13890.1
14061.1
13992.5
13934.6
14188
14093.8
14186.5
14350.5
14533.9
14567.9
14881.6
15394.7
15655.2
16098.5
16546.2
17097.7
17499.6
17776.9
18081.6
18057.2
18196.3
18032.7
17662.6
16991.6
16449.2
15687.7
15052.2
14017.7
13409.6
12999
12349.9
11953.2
11657.5
11044.8
10591.5
10585.5
10448.2
10313.1
10082.6
10109.9
10200.4
10213.8
10536.1
10557.3
10672
10957
11243
11494.9
11629.4
11518.2
11436.3
11354.2
11031
10832.7
10400.5
10316.7
10157
10106.4
10013.7
10147.4
10206
10206.8
10384.5
10607.5
10728
10815.6
11075.9
11321.1
11656.9
11896.4
12257.5
12725.2
13192
13896.5
14763.8
15719.7
17141.6
19117.4
22152.4
26625.2
33582.5
43318.8
57468.9
74850.4
93390.3
107111
111095
104582
88986.1
68274.6
47903.5
32301.7
22847.9
17092.9
13978.3
12103.4
10924.4
10180.3
9721.88
9402.23
9248
8928.65
8868.25
9076.9
9301.12
9495.57
9653.96
9980.5
9934.11
9875.02
9706.89
9376.59
8833.32
8224.31
7863.67
7558.45
7328.34
7101.76
7042.67
6882.32
7068.25
7245.91
7271.99
7407.89
7660.71
7868.99
8252.69
8583.35
8797.49
9262.59
9971.83
10610.8
11338.1
12456
13707.3
15305.5
17411.8
20461.9
24812.5
31347.8
41298.4
55695.2
75584.5
100526
126759
147039
153252
144305
122131
92414.2
63613.9
40908.7
26784
18648.3
13718.7
10755.3
8772.33
7478.88
6502.22
5710.42
5272.49
4823.36
4410.9
4140.85
3903.59
3700.19
3546.43
3358.13
3264.72
3173.32
3133.94
3040.37
2939.17
2860.47
2765.2
2669.98
2608.92
2530.97
2498.37
2511.09
2491.29
2463.37
2398.33
2420.52
2363.52
2225.81
2170.08
2205.81
2174.55
2166.76
2201.05
2148.34
2116.09
2172.17
2212.34
2172.82
2107.48
2083.27
2090.89
2137.58
2086.8
2097.63
2076.11
2015.3
2032.81
2105.73
1979.18
2022.16
1986.78
1965.13
1954.6
1967.52
1933.73
1853.56
1866.17
1859.72
1904.6
1925.27
1881.14
1868.77
1892.51
1955.63
1903.34
1924.36
1890.38
1865.87
1897.15
1858.42
1868.85
1864.5
1877.63
1863.31
1899.8
1884.49
1907.43
1913.14
1807.43
1847.32
1844.6
1838.66
1822.83
1859.93
1891.2
1852.73
1826.05
1870.99
1859.65
1848.21
1860.22
1828.22
1809.5
1848.08
1827.77
1835.28
1882.76
1796.73
1852.08
1851.16
1867.66
1795.22
1820.14
1851.97
1829.21
1841.13
1879.65
1830.81
1920.35
1886.64
1833.04
1867.58
1892.09
1892
1884.7
1851.61
1822.95
1779.33
1810.62
1783.16
1806.66
1848.59
1828.17
1821.29
1823.75
1842.75
1852.99
1853.12
1836.74
1855.1
1841.78
1867.58
1842.06
1802.93
1839.79
1879.45
1846.3
1841.34
1876.52
1844.02
1772.02
1845.66
1786.64
1802.99
1779.63
1828.91
1830.47
1840.02
1796.92
1846.3
1858.08
1841.84
1812.68
1787.92
1829.93
1857.73
1851.22
1890.09
1782.31
1761.21
1845.95
1874.56
1835.6
1805.32
1827.53
1778.7
1876.46
1784.85
1818.85
1815.87
1891.93
2.57029
Ag4d
Ag in 2 mbar H2
2020
3
13
13
4
6
0
14
Casa Info Follows
0
0
0
0
File = C:/Users/Mark/ownCloud/Muelheim Group/Projects/Gas phase background/EX340_CEC356_effect of lens modes.sle
Group = Ag in 2 mbar H2 , #Treatments: , #Temp: RT , #Pressure:2, #Gas1:H2, #Gas2:, #Gas Ratio:, #Comments:
First of group = 0
Analyzer lens = AngleResolvedMode22:1.5kV
Analyzer slit = 4:7x20c\C:mesh
Scan mode = FixedAnalyzerTransmission
Kinetic energy start = 1346.61
C:\Users\Mark\ownCloud\Muelheim Group\Projects\Gas phase background\EX340_CEC356_effect of lens modes.vms
Sum of 19 spectra in column containing 19 scans
XPS
1
Al
1486.61
0
0
0
54.5
180
FAT
20
1
4.156
0
0
0
0
0
Ag
4d
-1
kinetic energy
eV
1346.61
0.1
2
counts
d
Transmission
d
pulse counting
1.9
1
0
0
0
0
2
ESCAPE DEPTH TYPE
d
0
MFP Exponent
d
0
0.43548
2.24496
2491.74
2521.84
2595.27
2621.29
2629.05
2551.59
2643.92
2584.86
2614.75
2572.65
2619.15
2581.77
2625.26
2573.02
2650.15
2607.06
2631.87
2655.43
2568.17
2561.5
2623.38
2617.46
2606.78
2636.15
2612.34
2554.22
2580.34
2537.86
2611.48
2616.84
2567.71
2601.82
2635.74
2642.34
2612.6
2658.69
2560.95
2616.96
2619.93
2608.15
2549.92
2641.6
2690.52
2651.19
2616.14
2620.1
2619
2631.07
2622.64
2568.87
2613.74
2660.84
2547.97
2555.76
2615.49
2544
2572.05
2603.43
2628.31
2652.98
2675.01
2605.76
2638.67
2619.58
2678.88
2612.45
2614.12
2681.06
2534.13
2603.84
2594.81
2607.2
2581.62
2595.55
2576.12
2646.18
2625.64
2626.38
2652.79
2669.53
2700.71
2582.6
2582.59
2670.84
2575.28
2643.52
2670.39
2655.83
2630.73
2629.05
2651.64
2678.2
2676.5
2641.23
2632.5
2611.36
2626.39
2667.67
2601.05
2716.78
2721.46
2671.79
2638.75
2668.89
2694.13
2657.1
2633.77
2681.38
2687.05
2660.89
2643.85
2658.87
2626.54
2598.89
2642.71
2625.46
2644.15
2569.3
2635.37
2625.43
2651.26
2661.98
2613.72
2603.78
2614.23
2653.09
2665.75
2738.64
2649.61
2710.78
2675.49
2690.14
2666.92
2617.15
2652.38
2674.2
2606.86
2602.54
2712.71
2670.56
2659.76
2635.17
2652.98
2703.01
2675.79
2681.83
2667.32
2731.8
2666.93
2741.89
2755.63
2727.29
2683.06
2689.22
2706.05
2703.67
2789.46
2695.2
2632.81
2629.64
2724.75
2748.55
2752.92
2713.21
2673.63
2652.89
2769.7
2731.38
2710.29
2753.16
2704.38
2665.86
2688.15
2706.67
2706.81
2715.97
2683.79
2754.31
2664.67
2757.94
2789.95
2704.97
2718.47
2696.43
2735.9
2707.29
2714.39
2734.34
2674.14
2636.66
2736.8
2720.13
2716.98
2705.69
2761.6
2729.5
2698.9
2693.99
2779.5
2739.97
2752.25
2760.84
2708.8
2670.85
2740.03
2783.82
2741.86
2758.96
2767.16
2762.34
2764.72
2766.9
2821.13
2756.42
2798.62
2785.55
2744.2
2727.5
2662.52
2686.52
2734.59
2728.17
2749.04
2787.14
2689.34
2764.58
2770.5
2767.35
2763.02
2746.96
2786.17
2778.55
2750.12
2748.69
2737.53
2760.89
2854.39
2803.26
2807
2733.5
2747.24
2704.12
2702.13
2773.1
2788.59
2799.01
2764.72
2806.57
2817.72
2853.53
2724.86
2803.19
2814.33
2843.96
2805.13
2747.94
2763.8
2728.42
2821.6
2776.66
2829.23
2854.32
2790.51
2766.51
2798.97
2844.07
2821.68
2810.58
2729.21
2708.36
2813.21
2807.11
2876.31
2829.34
2866.89
2781.64
2802.73
2826.95
2872.45
2833.39
2832.45
2842.88
2766.79
2889.74
2869.72
2877.2
2887.34
2852.87
2808.58
2759.85
2895.04
2922.74
2851.92
2896.4
2960.83
2856.7
2835.17
2884.98
2891.75
2911.78
2876.84
2897.2
2852.73
2799.6
2833.95
2850.95
2882.33
2884.96
2874.84
2781.36
2783.3
2860.74
2855.09
2939.83
2855.34
2865.57
2850.93
2857.65
2841.24
2849.61
2794.18
2869.55
2811.84
2763.91
2766.22
2735.1
2791.31
2884.45
2818.87
2841.9
2827.52
2823.2
2802.31
2857
2741.48
2739.89
2835.9
2850.57
2813.34
2801.93
2833.52
2798.55
2761.9
2799.43
2848.59
2861.96
2832.24
2819
2850.4
2860.96
2853.93
2829.86
2892.1
2828.14
2842.36
2794.89
2754.6
2824.59
2843.29
2896.97
2851.69
2860.22
2882.84
2855.12
2822.62
2873.24
2918.16
2915.41
2851.59
2837.95
2871.21
2921.74
2835.76
2910.17
2906.84
2905.49
2884.06
2932.97
2881.19
2919.42
2889.19
2925.62
2950.91
3016
3000.99
2947.9
2960.69
3051.22
3007.85
3126.28
3066.26
3014.25
3052.52
3060.39
3041.34
3063.87
3168.81
3128.61
3192.29
3090.59
3097.92
3086.95
3152.39
3241.29
3276.75
3226.87
3170.46
3278.08
3355.32
3373.6
3318.31
3434.56
3371.62
3449.4
3432.55
3446.27
3574.29
3613.26
3533.77
3580.68
3583.04
3617.06
3721.64
3782.79
3710.51
3688.76
3731.86
3735.03
3741.55
3758.19
3789.27
3769.77
3769.12
3744.62
3780.35
3729.75
3634.17
3742.85
3613.7
3596.68
3611.34
3574.92
3643.1
3432
3395.06
3453.86
3403.48
3263.12
3338.81
3303.73
3237.21
3224.49
3224.11
3183.53
3183.5
3166.84
3124.58
3064.82
3093.5
3003.96
3082.56
3050.86
2922.94
2916.48
2967.65
3020.44
2943.79
3006.7
2924.74
2822.99
2881.33
2893.77
2834.83
2770.08
2830.26
2783.94
2813.91
2867.3
2793.53
2785.7
2747.74
2782.06
2743.86
2734.86
2778.61
2765.85
2809.55
2802.32
2760.32
2804.19
2775.14
2843.57
2829.84
2760.87
2781.46
2787.39
2760.5
2727.11
2749.61
2746.92
2820.33
2798.63
2756.28
2783.7
2753.11
2731.62
2653.87
2649.18
2670.61
2733.36
2722
2753.03
2735.06
2817.26
2785.46
2731.36
2735.78
2671.76
2741.81
2665.05
2698.56
2762.12
2718.78
2784.52
2827.22
2800.19
2719.83
2735.3
2686.26
2681.5
2755.6
2721.48
2697.9
2752.87
2744.28
2677.85
2714.84
2744.24
2720.02
2683.99
2720.56
2772.54
2783.04
2731.83
2752.48
2648.3
2765.06
2731.84
2777.33
2788.3
2757.94
2706
2728.53
2726.38
2744.95
2743.82
2605.17
2724.58
2731.01
2737.74
2715.66
2762.77
2790.5
2712.29
2786.04
2764.21
2768.17
2793.23
2779.2
2778.35
2772.87
2792.71
2777.66
2718.95
2720.93
2855.59
2873.96
2806.19
2868.86
2803.55
2740.64
2809.36
2732.63
2758.29
2815.19
2799.31
2873.51
2846.99
2839.07
2808.85
2795.84
2772.04
2745.26
2754.06
2793.34
2729.37
2813.95
2842.77
2789.79
2810.5
2859.23
2835.56
2860.01
2812.38
2805.17
2806.42
2790.18
2898.86
2929.35
2914.76
2868.32
2821.3
2774.09
2830.31
2835.79
2869.47
2909.99
2796.97
2763.18
2855.16
2879.25
2905.71
2908.96
2892.33
2809.53
2860.56
2867.36
2921.13
2843.52
2816.8
2841.71
2855.09
2925.53
2900.8
2888.27
2894.99
2831.89
2754.47
2829.13
2888.4
2885.53
2876.9
2847.72
2900.66
2881.5
2968.61
2904.94
2901.07
2896.82
2964.78
2931.63
2877.84
2921.74
2928.07
2943.79
2852.17
2923.56
2929.38
2890.17
2832.88
2886.96
2924.09
2878.4
2919.85
2868.07
2870.44
2913.09
2993.63
2982.78
2920.34
2924.24
2958.4
2932
2884.42
2893.07
2871.46
2889.12
2893
2920.97
2915.97
2920.96
2866.47
2879.89
2939.85
2938.27
2860.98
2929.81
2936.26
3012.65
2937.18
2919.77
2907.81
2986.02
2987.96
3012.04
2932.9
2958.29
2917.91
2923.09
3058.36
2982.4
2972.68
2983.12
3016.76
2997.07
2961.16
2952.3
2945.27
2959.85
3022.68
3028.61
3042.32
2973.49
2938.85
3035.71
3071.6
3074.52
3017.25
2999.13
3022.69
3103.69
3132.37
3151.43
3066.09
3131.62
3155.02
3184.24
3133.56
3073.93
3182.14
3228.02
3222.03
3101.15
3179.58
3240.86
3263.68
3177.42
3283.61
3362.84
3295.82
3289.71
3332.36
3428.06
3456.15
3404.66
3455.58
3434.99
3461.84
3457.14
3464.62
3487.48
3462.43
3474.54
3496.86
3592.25
3535.19
3511.9
3520.82
3503.07
3623.13
3569.17
3676.17
3534.06
3621.46
3647.33
3641.65
3602.14
3664.26
3601.05
3697.12
3681.47
3703.7
3720.43
3734.4
3636.58
3668.09
3716.2
3679.72
3775.7
3665.49
3697.53
3724.86
3790.12
3821.21
3770.66
3751.2
3772.45
3770.25
3720.11
3807.1
3836.86
3799.24
3832.45
3711.34
3749.71
3830.58
3851.77
3932.6
3838.57
3881.26
3961.21
3950.75
3863.94
3865.14
3878.09
3949.17
3848.19
3880.17
3766.03
3878.79
3866.07
3826.72
3908.55
3950.01
3950.2
3942.49
3969.16
3965.79
3879.74
3923.93
3847.35
3897.76
3963.77
3975.92
3870.45
3875.06
3806.24
3823.27
3685.16
3653.48
3698.03
3768.68
3648.03
3554.52
3660.69
3544.57
3452.05
3489.73
3462.1
3438.82
3350.13
3266.84
3219.22
3260.04
3262.6
3179.89
3069.65
3017.85
3041.69
2909.51
2873.47
2872.32
2837.22
2764.41
2630.19
2653.71
2616.73
2676.49
2666.4
2547.48
2459.02
2463.83
2448.07
2384.64
2324.36
2283.25
2298.25
2287.07
2225.42
2180.89
2201.5
2059.2
2167.04
2128.1
2056.34
2014.24
2054.78
1975.78
1982.7
1973.61
1921.45
1847.39
1847.45
1908.12
1890.48
1835.22
1813.1
1772.24
1751.08
1815.01
1759.36
1740.9
1722.96
1707.5
1721.06
1671.94
1639.1
1704.57
1656.7
1595.16
1569
1550.12
1545.09
1566.78
1545.76
1552.06
1474
1563.07
1547.24
1530.11
1475
1447.6
1444.76
1460.74
1421.25
1477.58
1466.42
1474.74
1490.26
1448.1
1441.29
1401.49
1416.15
1449.22
1407.03
1385.45
1410.58
1402.15
1408.46
1405.29
1350.01
1330.46
1349.05
1372.58
1376.97
1342.34
1348.95
1376.48
1321.78
1369
1399.69
1369.98
1252.75
1323.37
1320.79
1311.2
1323.47
1304.74
1297.87
1288.29
1322.6
1265.83
1284.12
1257.15
1282.14
1295.38
1323.9
1314.1
1339.25
1376.77
1333.53
1371.53
1313.93
1262.92
1311.64
1372.57
1356.39
1336.94
1302.26
1323.64
1252.09
1277.19
1304.36
1337.44
1294.41
1404.13
1314.26
1268.27
1303.13
1316.49
1311.02
1329.3
1274.85
1258.59
1273.51
1312.22
1299.18
1279.51
1254.65
1308.84
1281.28
1278.15
1283.62
1343.57
1333.96
1319.75
1343.29
1291.42
1320.08
1314.63
1329.4
1315.62
1328.47
1333.11
1288.53
1290.27
1290.3
1327.32
1279.82
1316.68
1264.05
1316.97
1310.07
1282.61
1332.66
1319.27
1348.69
1302.19
1300.17
1332.68
1290.08
1307.11
1312.59
1333.04
1297.34
1295.98
1324.8
1325.08
1291.51
1282.72
1282.76
1324.64
1332.79
1291.87
1366.81
1319.18
1337.06
1325.79
1304.59
1305.46
1282.64
1346.65
1318.25
1324.49
1281.38
1322.23
1250.51
1308.42
1350.3
1312.82
1331.62
1297.72
1303.32
1366.15
1360.32
1318.35
1360.02
1349.83
1364.56
1303.14
1377.52
1329.36
1405.79
1368.82
1343.81
1405.19
1389.2
1388.26
1338.2
1358.61
1379.1
1323.99
1380.38
1389.27
1356.53
1337.2
1408.08
1445.89
1407.16
1385.39
1376.83
1386.38
1388.71
1429.4
1424.6
1384.71
1412.36
1418.6
1445.77
1444.93
1447.97
1415.92
1444.83
1413.46
1460.43
1444.12
1460.12
1492.89
1418.49
1429.66
1393.47
1402.27
1375.22
1371.62
1395.4
1451.17
1473.13
1435.58
1483.17
1454.23
1464.72
1477.23
1388.98
1390.07
1410.67
1432.69
1384.59
1450.92
1407.46
1368.45
1337.97
1363.97
1337.41
1380.13
1398.34
1424.15
1412.37
1407.8
1442.52
1428.66
1349.79
1405.42
1403.71
1470.59
1422.6
1399.93
1462.41
1400.03
1426.68
1431.39
1402.63
1419.61
1399.84
1427.29
1321.71
1339.96
1375.24
1417.85
1418.34
1498.07
1442.82
1447.27
1420.08
1467.32
1431.98
1515.55
1493.32
1412.58
1463.76
1504.21
1480.68
1490.81
1446.94
1493.55
1503.77
1480.9
1528.59
1562.49
1527.88
1538.44
1574.65
1560.03
1522.75
1547.44
1563.4
1597.06
1630.98
1540.32
1587.62
1537.92
1557.09
1649.09
1574.67
1532.86
1570.26
1588.32
1586
1530.61
1561.89
1503.29
1540.65
1632.31
1599.82
1643.9
1590.15
1597.54
1664.05
1678.67
1573.27
1683.14
1724.92
1705.53
1748.68
1710.42
1736.58
1731.74
1757.95
1789.79
1818.39
1896.61
1850.85
1858.85
1846.47
[...]
2.42192
148.919
2.42163
155.814
2.42135
161.272
2.42106
157.526
2.42078
148.817
2.4205
151.577
2.42021
151.558
2.41993
152.245
2.41964
155.734
2.41936
157.568
2.41908
144.705
2.41879
148.133
2.41851
166.57
2.41822
157.106
2.41794
152.131
2.41766
156.507
2.41737
160.203
2.41709
155.136
2.41681
157.717
2.41653
149.665
2.41624
158.545
2.41596
161.158
2.41568
151.252
2.41539
147.571
2.41511
151.496
2.41483
147.815
2.41455
155.269
2.41426
152.802
2.41398
162.734
2.4137
156.985
2.41342
150.663
2.41314
147.425
2.41286
160.486
2.41257
158.829
2.41229
154.959
2.41201
153.024
2.41173
158.709
2.41145
158.714
2.41117
161.886
2.41089
148.334
2.41061
154.691
2.41032
151.718
2.41004
149.535
2.40976
155.361
2.40948
154.631
2.4092
157.232
2.40892
158.201
2.40864
163.644
2.40836
152.563
2.40808
147.975
2.4078
157.518
2.40752
165.184
2.40724
164.396
2.40696
160.909
2.40668
154.099
2.4064
163.108
2.40612
155.774
2.40584
161.797
2.40557
159.7
2.40529
166.837
2.40501
157.827
2.40473
165.369
2.40445
160.464
2.40417
153.31
2.40389
162.366
2.40361
161.85
2.40334
159.837
2.40306
156.849
2.40278
159.15
2.4025
161.058
2.40222
160.676
2.40195
160.516
2.40167
160.213
2.40139
161.409
2.40111
174.866
2.40084
154.743
2.40056
161.031
2.40028
158.266
2.4
161.599
2.39973
164.561
2.39945
161.168
2.39917
161.672
2.3989
162.791
2.39862
159.15
2.39834
151.552
2.39807
158.477
2.39779
164.462
2.39751
166.104
2.39724
165.829
2.39696
168.675
2.39668
169.994
2.39641
158.317
2.39613
165.781
2.39586
167.004
2.39558
170.148
2.39531
161.947
2.39503
168.139
2.39475
159.812
2.39448
165.706
2.3942
156.731
2.39393
169.466
2.39365
171.834
2.39338
168.199
2.3931
165.494
2.39283
158.219
2.39255
162.447
2.39228
166.835
2.39201
160.494
2.39173
162.591
2.39146
163.934
2.39118
165.004
2.39091
156.333
2.39063
163.521
2.39036
168.872
2.39009
173.404
2.38981
170.447
2.38954
176.011
2.38927
164.438
2.38899
171.595
2.38872
172.047
2.38845
175.074
2.38817
164.014
2.3879
168.277
2.38763
173.506
2.38735
170.205
2.38708
181.782
2.38681
173.349
2.38654
155.444
2.38626
167.81
2.38599
173.199
2.38572
163.54
2.38545
164.672
2.38517
172.655
2.3849
176.539
2.38463
171.243
2.38436
166.101
2.38409
170.451
2.38382
176.02
2.38354
168.773
2.38327
179.524
2.383
159.699
2.38273
172.236
2.38246
173.749
2.38219
171.286
2.38192
177.146
2.38165
169.121
2.38137
169.913
2.3811
176.877
2.38083
170.249
2.38056
171.987
2.38029
178.516
2.38002
181.93
2.37975
171.525
2.37948
182.505
2.37921
170.413
2.37894
173.969
2.37867
170.966
2.3784
176.014
2.37813
177.645
2.37786
181.211
2.37759
178.77
2.37732
171.539
2.37705
173.952
2.37679
175.004
2.37652
173.904
2.37625
167.324
2.37598
184.002
2.37571
181.977
2.37544
178.034
2.37517
176.505
2.3749
180.559
2.37463
182.966
2.37437
173.621
2.3741
179.642
2.37383
174.522
2.37356
174.371
2.37329
182.378
2.37303
178.407
2.37276
182.441
2.37249
172.542
2.37222
188.594
2.37195
181.419
2.37169
184.13
2.37142
187.099
2.37115
179.259
2.37088
192.956
2.37062
191.83
2.37035
194.517
2.37008
188.478
2.36982
184.546
2.36955
184.658
2.36928
188.844
2.36902
191.331
2.36875
187.379
2.36848
189.425
2.36822
191.517
2.36795
189.396
2.36768
201.228
2.36742
180.663
2.36715
185.035
2.36689
183.272
2.36662
195.124
2.36636
187.186
2.36609
200.676
2.36582
182.622
2.36556
191.452
2.36529
189.298
2.36503
196.957
2.36476
188.8
2.3645
194.837
2.36423
186.391
2.36397
188.53
2.3637
197.256
2.36344
194.058
2.36317
198.078
2.36291
201.96
2.36264
207.128
2.36238
204.233
2.36212
185.567
2.36185
193.187
2.36159
184.626
2.36132
190.745
2.36106
203.322
2.3608
192.89
2.36053
193.519
2.36027
186.944
2.36
193.186
2.35974
194.591
2.35948
200.853
2.35921
199.762
2.35895
194.145
2.35869
200.681
2.35843
199.925
2.35816
197.392
2.3579
194.877
2.35764
204.249
2.35737
195.812
2.35711
203.421
2.35685
195.509
2.35659
199.88
2.35632
199.409
2.35606
198.431
2.3558
198.679
2.35554
190.96
2.35528
195.169
2.35501
192.119
2.35475
199.28
2.35449
200.471
2.35423
198.754
2.35397
192.958
2.35371
198.514
2.35344
190.622
2.35318
186.836
2.35292
203.399
2.35266
194.623
2.3524
194.643
2.35214
193.32
2.35188
198.053
2.35162
200.663
2.35136
200.323
2.3511
186.622
2.35083
197.771
2.35057
194.11
2.35031
193.132
2.35005
198.608
2.34979
207.11
2.34953
203.486
2.34927
211.274
2.34901
217.454
2.34875
215.518
2.34849
228.564
2.34823
220.479
2.34797
228.756
2.34772
236.831
2.34746
247.612
2.3472
267.168
2.34694
290.215
2.34668
328.681
2.34642
354.6
2.34616
420.673
2.3459
466.074
2.34564
480.672
2.34538
489.611
2.34512
435.16
2.34487
381.626
2.34461
344.713
2.34435
295.242
2.34409
263.124
2.34383
246.495
2.34357
226.433
2.34332
206.902
2.34306
198.335
2.3428
183.083
2.34254
198.615
2.34229
186.721
2.34203
181.657
2.34177
173.666
2.34151
177.829
2.34126
174.634
2.341
174.5
2.34074
179.027
2.34048
177.062
2.34023
167.452
2.33997
170.099
2.33971
177.256
2.33946
166.737
2.3392
174.136
2.33894
173.972
2.33869
171.019
2.33843
174.249
2.33817
159.755
2.33792
169.437
2.33766
169.499
2.33741
164.329
2.33715
163.685
2.33689
167.224
2.33664
170.612
2.33638
171.461
2.33613
167.809
2.33587
160.487
2.33562
167.639
2.33536
173.718
2.3351
176.401
2.33485
174.052
2.33459
174.543
2.33434
173.659
2.33408
174.758
2.33383
177.209
2.33357
173.803
2.33332
185.133
2.33306
181.942
2.33281
175.378
2.33256
175.032
2.3323
182.019
2.33205
171.434
2.33179
184.496
2.33154
178.068
2.33128
182.921
2.33103
177.244
2.33078
187.221
2.33052
186.298
2.33027
182.893
2.33002
189.248
2.32976
178.687
2.32951
182.021
2.32926
187.361
2.329
190.823
2.32875
189.604
2.3285
181.569
2.32824
191.874
2.32799
196.97
2.32774
183.065
2.32748
182.162
2.32723
194.24
2.32698
194.976
2.32673
186.525
2.32647
194.906
2.32622
196.471
2.32597
189.736
2.32572
194.496
2.32546
190.329
2.32521
194.037
2.32496
202.777
2.32471
191.139
2.32446
200.569
2.3242
200.897
2.32395
202.882
2.3237
201.422
2.32345
204.413
2.3232
201.097
2.32295
202.029
2.3227
202.205
2.32244
209.737
2.32219
200.97
2.32194
200.44
2.32169
196.744
2.32144
197.683
2.32119
205.896
2.32094
187.595
2.32069
191.337
2.32044
191.367
2.32019
185.916
2.31994
181.629
2.31969
177.379
2.31944
185.894
2.31919
181.544
2.31894
174.8
2.31869
181.826
2.31844
172.724
2.31819
170.646
2.31794
177.378
2.31769
175.104
2.31744
175.747
2.31719
173.921
2.31694
167.203
2.31669
186.827
2.31644
180.41
2.31619
180.433
2.31594
182.318
2.31569
177.784
2.31544
180.363
2.31519
172.219
2.31495
175.505
2.3147
176.672
2.31445
165.777
2.3142
171.469
2.31395
161.868
2.3137
170.579
2.31345
173.517
2.31321
164.497
2.31296
169.862
2.31271
172.008
2.31246
173.513
2.31221
162.039
2.31197
173.469
2.31172
179.825
2.31147
181.168
2.31122
176.46
2.31098
178.764
2.31073
184.021
2.31048
194.715
2.31023
200.922
2.30999
204.513
2.30974
225.231
2.30949
235.962
2.30925
257.099
2.309
294.051
2.30875
314.754
2.30851
361.113
2.30826
429.092
2.30801
477.066
2.30777
521.471
2.30752
550.224
2.30727
528.79
2.30703
509.214
2.30678
528.03
2.30654
540.998
2.30629
624.232
2.30604
714.519
2.3058
759.7
2.30555
757.02
2.30531
676.546
2.30506
521.198
2.30481
431.166
2.30457
320.495
2.30432
264.601
2.30408
221.919
2.30383
187.319
2.30359
156.323
2.30334
130.735
2.3031
123.902
2.30285
111.691
2.30261
106.848
2.30236
88.1289
2.30212
83.5041
2.30187
80.6783
2.30163
75.1266
2.30139
69.9715
2.30114
65.553
2.3009
68.2329
2.30065
58.8861
2.30041
59.8686
2.30016
58.5424
2.29992
55.2842
2.29968
53.4485
2.29943
53.8899
2.29919
53.2294
2.29895
51.606
2.2987
49.1146
2.29846
46.0543
2.29822
51.1658
2.29797
45.5293
2.29773
43.1594
2.29749
42.8708
2.29724
45.253
2.297
42.0235
2.29676
43.3469
2.29651
40.1702
2.29627
40.9544
2.29603
35.8797
2.29579
42.5451
2.29554
36.04
2.2953
42.8406
2.29506
43.3779
2.29482
41.0087
2.29457
38.9598
2.29433
38.4286
2.29409
41.5046
2.29385
36.7214
2.29361
39.8536
2.29336
40.188
2.29312
38.4955
2.29288
40.7709
2.29264
40.8063
2.2924
38.4893
2.29215
37.7224
2.29191
40.8396
2.29167
39.9289
2.29143
40.9026
2.29119
34.1334
2.29095
34.6719
2.29071
36.6929
2.29047
38.5084
2.29023
37.5797
2.28998
36.7519
2.28974
36.3603
2.2895
35.1341
2.28926
37.3824
2.28902
38.3409
2.28878
38.4447
2.28854
36.6753
2.2883
39.0352
2.28806
41.7459
2.28782
39.5676
2.28758
35.278
2.28734
40.9745
2.2871
36.8258
2.28686
36.6796
2.28662
38.2734
2.28638
36.4985
2.28614
36.913
2.2859
38.428
2.28566
43.928
2.28542
38.5734
2.28518
43.7283
2.28495
41.3564
2.28471
36.6429
2.28447
38.9872
2.28423
33.7294
2.28399
38.3545
2.28375
35.7624
2.28351
40.9337
2.28327
37.1057
2.28303
43.4487
2.2828
39.4803
2.28256
42.4906
2.28232
38.6514
2.28208
36.5462
2.28184
36.1209
2.2816
39.748
2.28137
37.3744
2.28113
38.3279
2.28089
40.9289
2.28065
39.4884
2.28041
39.0766
2.28018
38.8658
2.27994
35.0328
2.2797
41.5274
2.27946
42.0851
2.27923
37.7998
2.27899
40.9369
2.27875
41.3449
2.27851
41.6231
2.27828
39.1089
2.27804
43.6114
2.2778
43.6651
2.27757
41.1209
2.27741
Cu2s
Cu in vacuum
2020
3
12
13
58
49
0
15
Casa Info Follows
0
0
0
0
File = C:/Users/Mark/ownCloud/Muelheim Group/Projects/Gas phase background/EX340_CEC356_effect of lens modes.sle
Group = Cu in 2mbar H2 , #Treatments: , #Temp: RT , #Pressure: 2mbar, #Gas1:H2, #Gas2:, #Gas Ratio:, #Comments:
First of group = 0
Analyzer lens = AngleResolvedMode22:1.5kV
Analyzer slit = 4:7x20c\C:mesh
Scan mode = FixedAnalyzerTransmission
Kinetic energy start = 286.61
C:\Users\Mark\ownCloud\Muelheim Group\Projects\Gas phase background\EX340_CEC356_effect of lens modes.vms
PCA Coefs = 66670.2, 1868.63,
c:\users\mark\owncloud\muelheim group\projects\gas phase background\ex340_cec356_cu h2 arm22.vms
XPS
21
Al
1486.61
0
0
0
54.5
180
FAT
20
1
4.156
0
0
0
0
0
Cu
2s
-1
kinetic energy
eV
286.61
0.1
2
counts
d
Transmission
d
pulse counting
0.2
1
0
0
0
0
2
ESCAPE DEPTH TYPE
d
0
MFP Exponent
d
0
1623.64
4.25897
1694.27
1701.03
1694.87
1705.62
1662.24
1666.08
1677.9
1685.47
1696.75
1715.04
1669.6
1690.21
1693.4
1717.86
1699.79
1693.21
1685.72
1707.31
1685.9
1702.12
1688.86
1678.99
1675.09
1690.72
1678.14
1691.1
1716.91
1714
1684.47
1679.73
1679.05
1694.27
1693.16
1722.44
1710.36
1713.89
1704.26
1680.63
1709.66
1679.41
1715.48
1688.64
1674.3
1696.33
1703.74
1687.52
1666.56
1695.27
1665.05
1676.32
1692.41
1708.35
1709.04
1724.45
1685.29
1680.52
1702.19
1692.78
1682.6
1691.82
1696.28
1717.02
1704.27
1699.35
1703.85
1703.81
1688.52
1714.69
1738.19
1710.66
1719.34
1713.36
1719.49
1687.65
1668.12
1676.66
1671.38
1714.71
1720.34
1683.95
1674.92
1683.1
1694.2
1712.14
1693.72
1720.57
1686.75
1698.3
1716.18
1722.15
1700.33
1698.61
1688.99
1689.43
1694.34
1712.59
1710.25
1722.02
1709.72
1684.77
1700.44
1662.02
1692.93
1709.97
1685.05
1699.53
1704.74
1706.34
1691.87
1705.41
1704.18
1696.62
1667.9
1659.95
1689.96
1697.66
1683.23
1693.33
1680.28
1695.25
1684.07
1704.59
1713.44
1695.71
1701.77
1681.91
1685.45
1691.35
1695.96
1696.91
1704.08
1669.47
1672.08
1701.68
1721.55
1689.86
1707.67
1687.52
1677.45
1689.29
1706.03
1689.45
1700.16
1660.43
1692.72
1683.77
1708.4
1669.9
1693.38
1708.65
1707.17
1726.32
1712.82
1699.06
1713.07
1684.46
1708.12
1690.9
1708.26
1726.69
1717.79
1691.77
1700.3
1716.8
1715.49
1707.67
1690.01
1691.19
1675.88
1685.42
1666.61
1707.86
1699.58
1696.9
1713.5
1726.43
1722.56
1702.79
1710.02
1712.17
1702.82
1672.41
1665.51
1704.26
1656.98
1679.82
1689.94
1687.56
1701.92
1695.3
1703.36
1692.15
1671.46
1728.37
1704.13
1691.4
1691.58
1687.32
1716.8
1706.26
1690.74
1696.42
1678.89
1679.71
1704.28
1684.73
1707.42
1687.4
1735.78
1720.31
1705.58
1719.8
1695.79
1725.81
1720.74
1706.75
1698.39
1704.54
1722.28
1721.83
1668.52
1690.81
1716.7
1689.38
1695.75
1708.26
1699.23
1679.41
1677.67
1698.57
1709.68
1692.64
1717.38
1740.71
1707.48
1703.37
1709.86
1727.17
1718.79
1685.57
1724.79
1707.61
1707.46
1710.86
1712.34
1709.74
1716.99
1691.75
1713.88
1714
1703.2
1700.97
1686.67
1692.53
1684.97
1676.31
1664.02
1691.38
1722.78
1721.39
1724.49
1703.25
1693.97
1689.26
1686.49
1706.26
1726.33
1692.8
1716.86
1691.72
1686.8
1708.14
1699.75
1730.37
1713.39
1696.17
1693.99
1688.92
1715.32
1729.68
1701.85
1719.74
1728.46
1689.11
1695.71
1687.84
1712.16
1715.52
1706.47
1671.64
1704.66
1700.7
1723.9
1683.84
1694.66
1715.69
1715.08
1702.74
1732.78
1713.03
1730.46
1762.98
1726.42
1724.45
1731.43
1715.64
1737.1
1713.37
1739.76
1732.02
1717.39
1725.26
1723.86
1721.46
1740.09
1720.4
1704.51
1736.66
1726.45
1717.61
1727.02
1684.95
1673.55
1697.76
1716.02
1716.75
1724.69
1704.51
1715.34
1689.68
1711.07
1726.51
1717.94
1718.34
1699.06
1705.03
1725.29
1700.59
1721.89
1727.23
1701.14
1734.68
1726.32
1707.96
1720.16
1744.19
1744.3
1724.52
1709.7
1718.31
1730.99
1716.75
1736.34
1699.43
1714.18
1706.81
1704.46
1720.76
1706.59
1723.89
1711.24
1710.91
1748.16
1745.64
1727.87
1720.01
1700.13
1723.15
1756.8
1740.61
1725.03
1755.12
1715.41
1741.87
1719.88
1706.05
1694.83
1750.78
1718.3
1698.81
1702.74
1725.47
1727.28
1696.14
1735.42
1735.38
1696.12
1732.21
1734.6
1744.68
1750.97
1730.62
1733.94
1729.26
1723.56
1699.71
1733.72
1746.85
1740.84
1754.52
1742.14
1715.66
1742.51
1757.05
1748.22
1712.48
1724.08
1721.17
1739.39
1727.63
1718.52
1751.28
1731.82
1760.74
1758.35
1762.69
1768.64
1739.52
1755.94
1763.91
1745.42
1709.5
1717.91
1763.92
1741.94
1740.41
1777.24
1754.98
1728.52
1753.35
1736.55
1723.91
1739.66
1744.42
1744.68
1734.93
1749.52
1730.47
1747.53
1754.88
1744.22
1745.43
1747.28
1743.78
1778.85
1771.81
1779.3
1762.59
1755.32
1753.97
1749.9
1727.15
1779.99
1765.75
1769.43
1751.53
1744.3
1769.36
1756.4
1728.01
1775.06
1747.88
1786.46
1783.24
1766.02
1758.41
1746.28
1755.91
1761.04
1780.22
1770.66
1782.82
1748.65
1749.28
1772.71
1779.13
1753.91
1773.9
1767.24
1756.02
1752.95
1783.03
1773.56
1771.57
1757.3
1770.11
1752.26
1732.8
1774.76
1776.65
1786.94
1778.35
1754.96
1757.91
1772.82
1763.92
1761.3
1772.74
1762.23
1773.62
1752.27
1767.46
1771.13
1785.25
1785.97
1776.43
1766.74
1765.59
1757.88
1771.68
1762.47
1786.86
1747.15
1747.15
1776.88
1785.4
1752.68
1785.33
1783.05
1749.06
1768.5
1793.73
1764.62
1781.71
1781.89
1739.71
1764.28
1752.38
1779.36
1751.63
1772.61
1779.54
1774.87
1775.42
1794.72
1751.11
1786.8
1799.22
1784.9
1785.67
1780.69
1783.04
1774.99
1767.6
1766.7
1807.84
1795.46
1752.53
1750.37
1790.89
1816.25
1785.23
1757.98
1791.44
1784.46
1792.8
1798.53
1778.18
1807.38
1801.66
1796.17
1822.35
1796.53
1775
1772.56
1794.33
1808.22
1814.89
1811.7
1817.27
1799.99
1820.08
1830.83
1817.86
1788.76
1800.01
1827.96
1801.34
1813.33
1837.7
1810.17
1795.14
1817.47
1805.7
1802.43
1779.04
1785.1
1794.27
1840.36
1822.89
1798.59
1816.55
1790.93
1797.39
1819.14
1804.93
1798.03
1787.67
1793.11
1811.53
1823.03
1847.55
1812.62
1799.11
1820.4
1827.61
1816.67
1824.35
1791.57
1796.29
1796.17
1819.07
1820.21
1797.49
1829.69
1827.83
1811.36
1852.89
1831.62
1825.54
1842.24
1847.95
1850.04
1814.26
1809.72
1811.31
1815.1
1840.9
1817.11
1819.97
1831.93
1815.49
1819.63
1831.13
1827.26
1819.78
1825.29
1820.18
1845.4
1807.44
1829.85
1819.28
1833.14
1807.59
1804.02
1811.32
1815.22
1852.32
1868.38
1816.94
1841.57
1831.01
1817.87
1796.21
1789.08
1861.14
1845.09
1804.88
1808.15
1804.69
1819.72
1819.61
1834.99
1825.07
1841.66
1833.94
1841.69
1820.47
1835.69
1823.61
1853.89
1856.33
1872.2
1839.01
1845.54
1831.42
1839.79
1851.83
1835.88
1850.93
1852.18
1861.45
1850.06
1851.47
1860.1
1844.95
1842.06
1833.54
1826.77
1851.73
1860.75
1847.86
1821.61
1820.24
1869.39
1866.65
1886.79
1864.36
1856.82
1861.59
1865.61
1830.34
1867.61
1848.84
1835.58
1876.64
1847
1836.73
1862.53
1858.14
1869.99
1851.43
1857.29
1859.93
1900.24
1867.4
1871.56
1861.48
1850.96
1883.95
1813.54
1843.13
1858.83
1883.84
1892.6
1868.43
1861.78
1885.92
1880.31
1896.58
1845.87
1866.15
1858.32
1899.23
1877.05
1906.29
1872.79
1897.93
1871.83
1871.93
1862.98
1853.33
1890.66
1895.99
1896.23
1870.86
1846.22
1843.64
1857.26
1880.35
1905.56
1874.74
1890.1
1881.31
1872.13
1909.24
1869.61
1911.25
1883.23
1901.79
1906.44
1923.18
1918.58
1885.86
1878.46
1871.62
1898.17
1901.01
1893.86
1865.67
1893.03
1895.42
1900.56
1902
1875.56
1907.96
1921.72
1896.87
1905.83
1909.32
1933.05
1894.82
1901.17
1910.62
1918.46
1913.53
1900.82
1901.33
1929.43
1900.02
1889.23
1905.74
1889.41
1886.78
1894.3
1908.19
1896.46
1905.63
1931.75
1922.86
1897.89
1941.61
1936.21
1917.66
1910.24
1921.63
1972.54
1948.58
1915.74
1928.89
1916.71
1915.26
1931.46
1963.3
1926.1
1927.81
1880.56
1892.33
1951.2
1954.38
1976.46
1957.18
1939.63
1939.68
1937.34
1923.24
1965.55
1969.64
1956.64
1936.91
1929.64
1963.12
1960.8
1940.69
1943.05
1926.03
1925.69
1967.08
1944.8
1949.86
1944.33
1941.28
1966.76
1958.32
1981.39
1952.27
1950.32
1956.67
1930.72
1951.05
1954.54
1921.32
1928.16
1951.27
1909.28
1934.72
1937.29
1934.9
1936.28
1954.54
1976.74
1953.39
1938.89
1935
1931.35
1968.36
1942.55
1937.93
1969.36
1955.23
1921.1
1957.03
1981.37
2006.26
1943.55
1947.04
1948.31
1962.75
1953.43
1980.46
1963.59
1923.9
1922.25
1959.77
1929.88
1978.65
1976.46
1982.95
1971.94
1959.84
1952.98
1948.33
1961.7
1978.45
1969.7
1941.69
1936.45
1949.36
1971.1
1972.27
1965.67
1943.78
1964.53
1969.37
1947.29
1936.95
1943.97
1956.61
1929.79
1951.89
1962.54
1960.94
1938.6
1972.21
1979.59
1954.66
1966.73
1938.99
1979.87
1958.41
1970.23
1997.73
1969.01
1948.55
1940.13
1956.63
1946.35
1952.15
1943.7
1944.63
1964.7
1968.55
1951.59
1954.1
1951.93
1955.38
1955.66
1950.76
1939.3
1956.06
1963.79
1971.79
2002.12
1974.31
1971.55
1959.61
1983.08
2016.9
1996.56
1990.28
1956.01
1971.34
1960.69
1972.13
1952.59
1980.67
1968.36
1937.95
1985.76
1974.66
1976.13
1978.38
1976.42
1955.7
1983.73
1967.93
1990.9
1975.69
1967.11
1977.58
1994.99
1997.53
2005.42
2011.24
2017.1
1989.52
1995.7
2026.93
2039.64
2013.31
2012.91
2032.04
2039.41
2042.88
2037.47
2041.26
2048.22
2052.6
2027.05
2073.74
2051.13
2067.63
2057.07
2056.35
2088.97
2087.37
2098.5
2101.72
2047.12
2071.98
2086.61
2107.78
2121.98
2119.47
2112.2
2134.5
2156.6
2153.99
2155.47
2175.15
2168.81
2174.2
2207.29
2189.32
2184.77
2214.2
2240.12
2226.39
2241.86
2237.6
2256.01
2292.02
2260.87
2281.8
2261.77
2295.16
2312.74
2270.23
2263.49
2303.37
2342.66
2330.87
2298.79
2348.33
2329.92
2259.91
2274.78
2272.01
2294.63
2290.42
2291.13
2299.24
2302.16
2262.88
2246.32
2231.07
2220.05
2257.94
2231.88
2186.58
2197.1
2201.29
2189.47
2164.05
2150.3
2119.81
2134.46
2132.34
2153.53
2121.99
2112.56
2105.57
2097.46
2138.44
2065.81
2065.45
2090.56
2062.81
2019.07
2055.45
2053.51
2051.28
2029.84
2031.49
1996.47
2011.28
2063.64
2021.46
2013.34
1950.21
1967.88
1979.96
1992.12
2004.32
1997.66
1966.32
1967.46
1987.42
1954.83
1926.72
1949.18
1929.55
1957.64
1978.37
1939.51
1923.77
1940.81
1946.67
1976.81
1968.59
1928.86
1975.96
1959.37
1936.28
1951.2
1933.75
1952.4
1943.19
1923.36
1911.05
1909.11
1921.77
1939.95
1930.08
1924.65
1922.37
1904.82
1929.96
1886.11
1914.97
1914.8
1909.95
1906.18
1945.17
1928.66
1948.62
1952.38
1893.89
1895.97
1901.89
1895.15
1888.09
1912.23
1897.4
1893.72
1878.24
1893.19
1905.43
1867.83
1902.57
1902.19
1903.02
1881.76
1880.09
1890.37
1873.81
1892.75
1913.99
1889.34
1879.84
1881.26
1911.07
1903.77
1868.37
1913.96
1899.98
1899.03
1911.31
1925.64
1917.66
1888.59
1919.91
1913.75
1916.05
1896.59
1933.83
1925.5
1911.12
1888.25
1919.08
1921.56
1898.84
1904.43
1896.56
1908.79
1887.53
1885.98
1896.81
1876.69
1896.99
1896.08
1923.78
1915.39
1911.43
1883.82
1875.03
1911.32
1895.37
1937.58
1938.07
1884.21
1905.95
1911.54
1934.86
1926.81
1901.3
1899.55
1878.05
1903.2
1898.18
1884.52
1892.31
1880.62
1870.35
1917.42
1915.64
1878.83
1892.91
1888.5
1899.29
1900.98
1892.8
1916.03
1895.36
1910.29
1899.49
1895.01
1893.94
1899.34
1908.92
1924.34
1927.65
1889.14
1906.55
1888.86
1940.8
1929.87
1905.36
1891.11
1867.31
1892.73
1895.59
1900.02
1903.54
1884.13
1924.89
1903.17
1922.2
1925.29
1892.45
1930.03
1914.99
1907.1
1910.03
1923.16
1917.77
1922.36
1907.76
1926.56
1936.72
1943.17
1918.75
1890.41
1894.95
1891.38
1918.24
1928.54
1913.27
1921.7
1921.22
1942.5
1919.57
1937.18
1916.37
1909.98
1934.43
1925.83
1936.85
1935.19
1921.48
1905.51
1936.04
1950.58
1908.58
1954.57
1940.03
1917.78
1926.64
1907.77
1932.56
1963.22
1960.56
1933.21
1945.71
1915.92
1932.74
1919.51
1905.96
1960.03
1939.96
1944.09
1940.71
1922.58
1947.38
1948.62
1967.9
1963.68
1969.95
1962.18
1958.04
1954.99
4.25897
end of experiment