File: data/O2/Au, Ag, Cu in O2.vms
VAMAS Surface Chemical Analysis Standard Data Transfer Format 1988 May 4
Not Specified
Not Specified
Not Specified
Not Specified
15
Casa Info Follows CasaXPS Version 2.3.24rev1.0F
0
SourceAnalyserAngle: 56.500000 d
CasaRowLabel:Au in 4.0 mbar O2
CasaRowLabel:Au in vacuum
CasaRowLabel:Au in 2.0 mbar O2
CasaRowLabel:Ag in 4.0 mbar O2
CasaRowLabel:Ag in vacuum
CasaRowLabel:Ag in 2.0 mbar O2
CasaRowLabel:Cu in 4.0 mbar O2
CasaRowLabel:Cu in vacuum
CasaRowLabel:Cu in 2.0 mbar O2
CasaRowLabel:Cu in vacuum
CasaRowLabel:Au in vacuum
CasaRowLabel:Au in 25mBar O2
NORM
REGULAR
8
1
Exp Variable
d
0
0
0
0
33
Survey
Au in 4.0 mbar O2
2020
2
8
21
25
27
0
12
Casa Info Follows
0
0
1
CASA region (*Survey*) (*Spline Linear*) 292.60101 1252.3614 1 6 76.332562 1.357978 -334.91028 -554.11118 -599.16233 -447.64629 (*NoTag*) 0 0 0
0
C:\Users\Mark\ownCloud\Muelheim Group\Projects\Gas phase background\EX321_CEC356_Au Ag and Cu in O2.xy
Group: Au in 4.0 mbar O2, #Treatments:  , #Temp: RT , #Pressure: 4.0 mbar, #Gas1: O2, #Gas2:, #Gas Ratio:, #Comments:
Analyzer Lens: LargeArea
Analyzer Slit:
Scan Mode: FixedAnalyzerTransmission
c:\users\mark\owncloud\muelheim group\projects\gas phase background\ex321_cec356_au ag and cu in o2_clean.vms
XPS
0
Al
1486.61
0
0
0
56.5
180
FAT
100
1
4.241
0
0
0
0
0
Survey

-1
kinetic energy
eV
286.61
0.5
2
counts
d
Transmission
d
pulse counting
0.1
1
0
0
0
0
2
ESCAPE DEPTH TYPE
d
0
MFP Exponent
d
0
1
74.341
76.7894
77.9555
79.2675
79.2056
78.8638
83.0906
80.6023
82.6496
81.8263
86.7672
81.7874
83.4635
90.7899
87.3951
88.4403
90.4089
93.0505
92.8101
96.5591
93.5374
96.3045
98.301
96.3312
98.4563
100.555
100.374
97.6598
102.609
100.942
103.661
101.376
108.702
107.747
112.766
107.818
110.475
111.468
114.25
115.24
118.911
114.884
115.409
122.758
117.161
119.755
121.243
127.784
117.01
125.911
130.454
131.894
130.286
133.826
127.831
133.198
130.963
134.314
138.291
139.435
143.15
140.067
141.285
140.52
141.545
152.653
152.29
147.282
150.411
151.629
153.079
154.245
152.373
152.442
150.358
157.227
152.911
158.732
163.669
162.536
166.1
167.512
175.572
174.328
170.557
170.803
177.945
178.775
173.37
173.192
179.063
180.175
180.239
184.838
178.394
184.076
189.629
187.837
187.336
189.813
195.712
206.286
197.891
194.474
202.898
203.998
205.767
205.405
212.666
210.559
221.229
211.467
213.514
216.294
215.989
219.431
223.33
220.04
227.104
220.724
231.429
233.265
226.297
235.069
238.164
237.679
239.116
241.558
247.927
246.896
239.759
245.765
252.118
244.612
255.746
258.467
249.753
258.619
264.146
263.08
257.992
269.701
266.409
277.6
274.338
274.235
267.78
277.429
280.548
278.475
283.7
288.589
285.938
286.368
296.163
290.282
295.182
294.828
301.859
302.511
305.649
309.272
300.684
307.92
316.354
318.118
316.452
327.206
317.377
325.526
332.381
324.459
330.801
338.459
332.165
344.081
341.921
339.666
344.308
346.144
346.13
348.191
353.025
356.845
355.116
362.738
351.719
362.973
358.401
367.665
368.846
365.925
374.878
375.589
384.722
385.367
373.053
378.079
385.942
390.164
387.583
374.313
396.434
390.444
389.812
394.501
397.179
403.393
402.043
424.902
410.159
415.959
403.506
418.172
420.311
419.961
414.63
438.336
438.263
438.569
417.557
411.105
418.014
417.847
417.779
429.39
420.134
428.816
437.714
440.174
434.629
435.458
438.479
440.498
440.961
432.771
445.517
448.605
455.052
461.655
471.136
467.614
471.099
465.406
466.384
466.416
464.707
480.255
470.742
478.245
486.064
483.6
487.191
497.179
499.801
493.335
495.272
509.18
513.22
504.547
510.348
512.278
512.358
522.987
520.724
518.693
518.127
522.845
523.754
542.415
533.319
539.013
545.067
539.05
550.921
546.971
549.928
551.414
551.491
562.327
561.184
568.89
573.946
571.099
576.692
578.125
590.117
585.728
593.973
602.904
596.141
599.648
607.684
599.962
608.95
602.389
617.023
619.402
624.844
620.249
626.243
619.566
621.002
632.914
638.885
638.576
637.147
647.016
645.408
654.677
657.019
654.681
661.697
666.786
677.055
671.583
662.863
678.049
672.219
691.7
705.535
689.852
691.818
695.822
691.388
702.316
707.635
710.4
724.612
727.03
715.47
723.61
728.903
728.064
741.364
738.207
739.594
749.754
756.492
750.164
760.737
754.653
778.817
756.669
787.334
767.794
800.611
785.734
810.597
786.814
811.299
792.725
795.071
790.98
815.295
819.225
811.7
812.892
820.943
831.173
828.677
841.035
836.579
828.801
853.69
840.121
847.206
858.926
860.953
870.916
862.911
869.431
863.728
877.79
883.029
900.204
884.774
899.212
896.259
894.667
915.211
908.721
929.99
913.934
909.877
919.016
938.108
928.684
943.814
947.738
941.801
950.85
947.643
940.712
964.292
969.001
960.242
980.002
975.446
979.678
986.168
977.098
983.942
992.374
990.549
994.247
1007.88
1010.75
993.703
1021.92
1037.34
1039.57
1009.14
1042.24
1029.53
1055.3
1052.02
1054.88
1053.1
1053.91
1068.56
1070.88
1079.88
1072.83
1070.09
1067.19
1084.47
1079.08
1088.63
1070.59
1100.8
1118.16
1096.23
1115.52
1107.77
1142.27
1121.66
1126.8
1149.34
1148.67
1134.94
1144.39
1143.06
1166.65
1147.13
1164.38
1152.43
1158.57
1158.68
1164.75
1167.68
1184.15
1169.69
1167.84
1197.3
1203.31
1186.08
1197.29
1190.94
1199.9
1213.51
1207.51
1234.37
1210.9
1242.33
1243.74
1239.3
1254.16
1237.27
1256.53
1256.53
1265.05
1271.58
1269.17
1278.23
1294.06
1292.81
1302.01
1286.73
1313.1
1305.67
1307.75
1303.92
1321.63
1324.36
1341.25
1334.57
1341.15
1350.35
1365
1372.99
1366.33
1346.79
1384.98
1392.56
1378.94
1389.16
1393.1
1395.29
1413.94
1399.44
1422.08
1418.85
1431.38
1413.26
1434.37
1455.97
1447.95
1446.14
1457.59
1468.11
1485.25
1486.37
1480.56
1488.46
1489.27
1486.09
1492.9
1511.11
1500.1
1508.65
1514.86
1524.38
1516.24
1537.56
1544.4
1551.85
1554
1564.58
1571.49
1589.09
1582.91
1566.88
1591.63
1599.81
1598.75
1608.11
1597.74
1618.72
1621.13
1618.47
1630.6
1638.87
1643.11
1633.17
1665.03
1657.73
1655.38
1657
1687.41
1678.66
1677.33
1680.54
1686.27
1709.84
1717.89
1724.05
1742.81
1718.37
1732.3
1744.94
1733.83
1731.71
1738.84
1740.28
1726.69
1735.44
1739.87
1750.07
1759.45
1746.73
1784.36
1764.55
1762.42
1787.24
1777.74
1788.79
1814.28
1786.99
1818.39
1829.65
1805.91
1822.46
1826.25
1849.82
1834.78
1845.8
1867.61
1868.33
1869.47
1864.73
1880.85
1902.72
1893.84
1907.19
1928.09
1915.47
1907.33
1925.86
1929.64
1935.72
1942.22
1926.43
1944.14
1978.84
1973.5
1982.87
2005.76
2003.01
1997.86
1996.77
2011.08
2015.95
2042.32
2022
2023.77
2054.21
2054.54
2055.35
2065.65
2063.56
2056.69
2059.9
2074.18
2072.58
2058.19
2093.33
2121.75
2090.63
2097.13
2113.31
2119.13
2136.82
2126.11
2130.88
2139.17
2154.66
2150.44
2168.02
2170.97
2135.01
2118.78
2145.4
2134.69
2147.86
2125.26
2115.53
2106.54
2113.86
2168.11
2224.19
2334.23
2394.86
2392.11
2320.78
2201.87
2140.68
2127.69
2122.45
2298
2655.03
2688.46
2275.53
2030.94
2006.65
1990.83
1978.18
2020.17
2028.06
2014.4
2020.91
2010.91
2027.55
2033.73
2015.59
2044.3
2039.62
2049.5
2049.4
2066.16
2070.17
2085.84
2074.04
2097.18
2100.61
2082.38
2115.6
2108.02
2137.28
2137.52
2147.98
2149.28
2166.46
2150.89
2169.04
2196.19
2173.29
2187.69
2197.07
2212.66
2198.81
2235.64
2206.54
2223.2
2224.23
2227.58
2248.48
2275.89
2281.79
2290.38
2281.28
2281.53
2303.56
2320.09
2301.05
2334.12
2314.91
2329.71
2361.13
2368.27
2356.75
2349.03
2376.66
2409.3
2383.96
2411.15
2419.94
2414.27
2397.38
2424.73
2455.23
2435.05
2437.17
2435.33
2468.41
2467.01
2464.97
2484.32
2481.84
2494.48
2509.89
2533.03
2530.65
2554.19
2555.2
2535.08
2580.91
2546.31
2577.79
2592.25
2615.87
2613.99
2616.04
2615.55
2639.07
2632.51
2649.71
2639.06
2627.78
2667.95
2692.56
2692.33
2681.65
2703
2713.88
2729.03
2700.76
2728.17
2750.24
2748.99
2763
2761.92
2758.21
2803.18
2786.4
2805.58
2793.77
2802.52
2810.55
2828.94
2836.01
2836.26
2840.42
2837.17
2875.44
2877.11
2874.44
2860.51
2893.96
2909.36
2889.04
2896.97
2894.19
2933.53
2892.94
2932.6
2905.03
2973.21
2943.05
2962.8
2961.78
2984.55
2982.71
2953.94
2966.94
2975.4
2974.31
2983.27
3011.37
2978.01
3001.85
2997.13
3000.54
3010.84
2988.13
3001.15
2984.93
3010.26
3019.6
3019.97
3059.13
3039.19
3017.33
2994.21
3034.77
3013.54
3011.3
3025.64
3018.63
3021.88
3014.06
2971.06
2934.28
2900.98
2871.46
2877.6
2872.42
2901.78
2906.98
2905.06
2904.69
2906.04
2936.06
3050.48
3207.42
3442.42
3566.89
3496.6
3256.21
2969.16
2741.15
2556.84
2445.34
2366.33
2342.07
2362.6
2319.47
2310.78
2283.96
2308.61
2356.67
2505.98
2771.98
3140.52
3434.17
3356.34
2956.32
2503.94
2196.14
2021.84
1916.39
1832.44
1791.9
1765.22
1728.34
1717.58
1705.13
1692.68
1685.07
1671.07
1658.75
1689.92
1677.06
1694.18
1686.33
1684.13
1686.88
1686.09
1699.89
1701.41
1687.69
1694.88
1677.02
1704.5
1704.42
1711.18
1705.24
1713.48
1720.42
1725.61
1732.86
1751.59
1706.74
1736.78
1746.15
1743.64
1763.73
1762.06
1782.09
1754.14
1778.64
1763.51
1790.33
1798.09
1802.32
1838.47
1837.74
1791.08
1795.27
1801.61
1805.2
1799.9
1830.09
1825.46
1816.53
1831.66
1832.57
1862.64
1850.47
1843.7
1864.5
1876.72
1856.54
1873.35
1878.25
1887.02
1877.03
1890.82
1888.13
1904.69
1894.58
1888.4
1939.99
1919.19
1946.62
1935.28
1938.44
1936.09
1954.75
1967.86
1972.99
1974.71
1974.37
1970.28
1987.21
1999.05
2008.03
2025.73
2015.67
2026.22
2021.51
2056.49
2042.48
2049.18
2039.62
2050.89
2055.31
2069.88
2087.9
2083.07
2076.36
2104.66
2092.84
2096.9
2097.64
2130.98
2126.51
2143.86
2138.16
2160.19
2160.33
2175.42
2159.38
2154.01
2171.27
2164.52
2199.44
2218.09
2185.4
2222.55
2215.9
2231.58
2223.4
2238.45
2237.48
2258.75
2268.63
2279.5
2276.04
2281.34
2283.74
2288.76
2268.29
2300.81
2303.91
2321.38
2328.01
2327
2338.48
2343.06
2347.44
2352.76
2367.43
2373.47
2366.4
2389.59
2409.23
2399.76
2411.11
2415.26
2421.23
2448.8
2443.47
2435.16
2463.56
2452.13
2463.56
2488.31
2454.25
2486.29
2506.73
2515
2489.16
2499.11
2518.54
2508.69
2533.41
2524.63
2551.51
2541.26
2553.46
2574.42
2561.52
2555.65
2566.14
2603.69
2620.14
2601.84
2604.16
2602.58
2605.15
2621.03
2615.68
2602.74
2626.22
2628.02
2642.12
2632.05
2626.24
2647.93
2649.65
2627.53
2670.44
2645.26
2669.37
2667.37
2672.43
2695
2682.64
2688.27
2708.53
2704.51
2681.05
2670.45
2679.87
2697.49
2681.59
2665.87
2676.63
2646.44
2677.91
2641.67
2648.11
2666.48
2665.55
2660.41
2687.29
2706.08
2707.85
2707.41
2702.83
2713.1
2668.41
2663.69
2659.33
2665.84
2644.36
2538.44
2473.33
2397.89
2241.55
2080.62
2034.9
2067.68
1920.76
1737.76
1810.13
1939.87
1805.95
1727.24
2286.86
4579.51
6013.33
3562.04
3098.91
6291.64
6148.58
2075.77
848.29
664.837
600.667
563.485
567.391
551.74
569.669
570.291
562.538
545.379
514.702
484.196
467.463
447.538
441.109
431.034
432.791
433.279
435.281
447.765
460.474
495.569
523.686
571.074
596.557
594.474
545.202
480.345
424.778
395.252
379.313
359.014
345.485
333.419
329.773
324.323
323.197
317.708
315.066
327.137
314.807
310.462
307.764
309.86
299.772
313.148
320.209
324.138
316.462
305.051
306.803
308.217
310.131
317.204
314.259
306.859
297.415
306.2
311.391
314.247
308.733
317.649
297.679
243.189
214.358
208.45
199.334
209.203
204.678
205.834
197.751
183.166
195.327
279.291
481.263
663.401
686.42
713.895
783.986
579.263
257.563
84.5321
1
Au4f
Au in 4.0 mbar O2
2020
2
8
21
32
2
0
11
Casa Info Follows
0
0
0
0
C:\Users\Mark\ownCloud\Muelheim Group\Projects\Gas phase background\EX321_CEC356_Au Ag and Cu in O2.xy
Group: Au in 4.0 mbar O2, #Treatments:  , #Temp: RT , #Pressure: 4.0 mbar, #Gas1: O2, #Gas2:, #Gas Ratio:, #Comments:
Analyzer Lens: AngleResolvedMode22
Analyzer Slit:
Scan Mode: FixedAnalyzerTransmission
c:\users\mark\owncloud\muelheim group\projects\gas phase background\ex321_cec356_au ag and cu in o2_clean.vms
XPS
0
Al
1486.61
0
0
0
56.5
180
FAT
20
1
4.241
0
0
0
0
0
Au
4f
-1
kinetic energy
eV
1311.61
0.1
2
counts
d
Transmission
d
pulse counting
0.3
3
0
0
0
0
2
ESCAPE DEPTH TYPE
d
0
MFP Exponent
d
0
586.818
1
2823.37
2810.41
2830.48
2839.46
2839.85
2851.43
2791.42
2814.46
2839.85
2835.63
2873.05
2838.04
2839.76
2868.45
2829.2
2828.46
2822.75
2874.72
2875.26
2845.73
2854.65
2868.77
2871.28
2873.4
2860.06
2855.79
2887.39
2896.21
2891.08
2808.98
2825.02
2809.8
2864.99
2846.78
2853.35
2855.81
2885.45
2858.24
2884.4
2861.92
2846.22
2862.89
2857.94
2872.06
2839.79
2886.2
2925.52
2876.68
2846.25
2829.56
2840.7
2856.58
2851.06
2869.97
2847.71
2800.91
2860.8
2871.41
2838.91
2849.97
2874.36
2875.44
2859.08
2900.69
2892.99
2870.08
2847.56
2897.91
2870.41
2888.66
2854.13
2887.79
2889.99
2840.94
2878.43
2892.36
2844.3
2885.14
2847.17
2860.6
2883.24
2884.68
2842.27
2874.44
2834.45
2897.11
2869.43
2900.53
2957.39
2864.59
2883.72
2891.58
2894.39
2883.68
2897.09
2880.56
2879.61
2909.68
2887.98
2881.1
2839.24
2890.39
2911.51
2869.18
2890.11
2895.85
2889.39
2887.14
2862.44
2889.94
2882.73
2905.56
2915.08
2930.45
2902.12
2924.1
2901.24
2869.99
2916.99
2912.63
2918.03
2894.8
2872.07
2876.4
2889.32
2881.42
2867.54
2904
2916.4
2921.08
2900.72
2882.91
2927.61
2939.8
2889.46
2940.5
2909.34
2924.22
2907.07
2878.83
2909.58
2941.53
2913.24
2898.43
2895.34
2907.76
2905.65
2949.67
2965.02
2918.83
2911.02
2914.4
2936.77
2924.62
2917.46
2944.41
2949.38
2915.83
2955.92
2899.76
2917.26
2956.55
2916.2
2898.37
2932.14
2941.89
2902.52
2920.24
2946.68
2944.9
2910.4
2857.23
2936.59
2905.09
2906.69
2946.91
2909.16
2933.05
2926.88
2933.61
2958.85
2938.44
2995.7
2955.82
2958.17
2928.02
2900.68
2906.67
2947.08
2959.98
2945.12
2963.43
2947.03
2932.8
2933.62
2944.96
2959.59
2958.15
2935.14
2963.3
2921.16
2958.62
2968.41
2994.17
2968.48
2973.3
2928.91
2937.35
2949.62
2929.51
2960.88
2952.24
2974.84
2972.89
2882.7
2923.27
2978.11
2976.11
2956.39
2973.03
2975.74
2942.13
2985.55
2964.97
2903.68
3005.15
2971
2984.36
3002.09
3039.54
2969.89
2968.9
2944.19
2958.57
2960.47
3018.44
2987.59
3037.81
2971.36
2984.03
3022.52
2982.24
3024.9
2975.59
2970.59
2953.58
2983.06
2977.88
3015.21
2996.18
2977.8
2994.52
3001.78
2988.56
2983.84
3005.6
2992.33
3006.41
3001.14
2952.67
2934.73
2960.66
2973.49
3011.42
2947.33
2980.59
2984.37
2970.67
2984.86
2999.35
3003.36
3003.87
2964.24
2996.56
3010.6
3005.53
2967.86
2949.58
3022.51
2971.94
2986.27
2966.56
3006.67
3001.04
2997.77
2994.9
2985.25
2979.67
3006.72
3014.38
2959.68
2970.89
2987.53
3013
2938.85
2959.01
2979.77
2973.94
3006.89
3012.8
3009.72
3018.85
3003.51
2975.34
3019.29
3016.51
2985.08
3002.44
3046.3
2959.71
2985.38
3000.74
2966.29
3001.04
2982.41
2960.32
2999.61
3033.79
2985.68
2987.92
2950.95
2980.43
3006.12
3009.49
3018.21
3030.52
3000.93
3007.4
3015.32
2977.55
3002.69
2996.74
2977.43
2983.73
3024.66
2955.34
2993.39
2987.76
2991.9
2995.11
2992.46
3006.04
3012.89
3022.62
2997.21
3039.6
3019.5
3014.9
3026.59
2995.88
3005.52
2999.62
3009.33
3040.09
3041.93
3050.14
3056.37
3002.94
3015.75
3011.53
2996.28
3035.1
3030.77
3038.7
3066.01
3066.75
3010.21
3006.05
3025.54
3042.67
2979.7
2989.04
3011.67
3000.51
3032.02
3044.14
3005.96
3027.84
3002.31
3047.65
3012.77
3049.29
3021.85
3010.91
3036.62
3051.02
2980.25
3040.17
3033.38
3058.58
3046.88
3033.06
3018.54
3007.68
3036.2
3024.94
3001.48
3004.46
3074.75
3020.12
3052.92
3000.51
3069.3
3054.55
3015.5
3030.86
3031.75
3016.82
3009.99
3000.92
3014.13
3020.88
3031.78
3064.51
3058.44
3051.92
3004.82
3029.22
3006.15
3008.73
3033.37
3075.71
3052.88
3016.35
3040.49
3019.57
2992.04
3042.92
3052.47
3027.04
3051.98
3001.24
3038.05
3058.66
3003.29
3044.41
3008.79
3053.66
3073.25
3018.54
3053.97
3064.91
3040.88
3050.77
3057.96
3053.87
3052.6
3063.63
3082.21
3053.44
3062.5
3030.88
3070.65
3104
3098.64
3076.17
3055.6
3057.04
3087.97
3054.75
3025.37
3075.4
3062.29
3036.3
3063.03
3090.91
3028.61
3080.93
3046.38
3045.35
3100.53
3043.62
2991.06
3035.93
3037.71
3044.35
3035.07
3041.34
3056.78
3030.04
3062.34
3069.87
3017.51
3021.56
3041.57
2972.84
2990.61
3017.01
2991.86
3034.02
2999.55
3048.07
3016.73
3062.55
3040.43
2982.14
3028.02
3054.75
3026.04
3021.03
2998.15
3036.16
3037.2
3063.53
3088.33
3024.65
3036.53
3024.04
3025.8
3041.08
3045.26
3020.05
3045.15
3026.41
3034.26
3040.45
3059.8
3033.01
3016.53
3009.31
3002.94
2963.88
3026.8
3017.29
3045.76
3053.08
3028.5
3036.82
3051.81
3030.4
3079.24
3053.34
2983.24
3020.2
3050.9
3026.51
3004.18
3021.7
3055.91
3035.67
2996.98
3005.7
3006.25
3035.12
3012.31
3037.94
3042.43
3025.16
3010.18
3027.96
3008.6
3007.05
3002.43
3019.41
2979.68
3019.91
3010
3001.41
2998.47
3001.35
3041.66
3036.46
3070.49
3019.06
3021.35
3021.69
3037.43
3053.99
3068.71
3005.19
3031.14
3040.66
3002.36
2991.76
3014.98
3020.5
3017.12
2961.55
2994.57
3036.4
3001.8
2998.57
2975.84
2969.47
3026.55
3018.14
3019.08
2973.24
3037.42
2992.22
2965.66
3032.95
3061.57
3019.52
3034.89
3047.25
2986.95
2979.31
3031.37
2998.41
3004.68
2996.94
2999.83
3012.09
3016.35
2994.21
3045.19
3017.72
3035.15
3005.99
2984.59
2991.45
3037.45
3006.58
3017.8
3007.99
3001.86
3026
3043.8
3030.8
3044.18
3054.96
3009.56
3028.87
3036.06
3058.3
3064.32
3048.37
3048.43
3049.23
3053.95
3048.21
3043.88
3077.08
3097.81
3082.41
3059.42
3055.35
3099.25
3119.71
3098.25
3066.57
3078.93
3079.62
3070.01
3107.81
3104.3
3056.21
3101.67
3078.74
3085.73
3079.69
3052.43
3007.13
3036.14
3056.03
3096.21
3095.42
3043.17
3086.48
3069.95
3030.58
3080.69
3094.79
3069.43
3043.02
3024.9
3073.84
3078.89
3070.6
3107.31
3067.66
3033.52
3054.9
3045.71
3066.76
3078.57
3040.48
3009.82
3044.75
3062.99
3061.58
3034.56
2980.06
3009.5
2999.94
3032.57
3026.27
3005.55
3007.69
2980.88
2999.56
2982.59
3000.9
2953.29
2973.02
2958.09
2994.87
3014.07
3009.91
3029.68
3050
3062.16
2997.64
3039.52
3033.98
3013.32
3037.85
3042.02
3002.23
2986.63
2984.98
2997.88
2961.76
2957.71
3036.5
2999.31
3028.42
3040.48
2997.42
3031.6
2969.74
2980.59
2929.5
2899.16
2827.22
2753.83
2715.69
2732.25
2736.67
2738.63
2703.44
2721.51
2726.47
2746.76
2784.02
2781.09
2843.01
2840.33
2837.71
2842.41
2815.97
2843.19
2772.97
2751.49
2719.42
2698.33
2662.18
2627.65
2584.98
2533.87
2554.11
2548.12
2570.25
2593.92
2578.43
2568.05
2576.1
2532.28
2484.55
2456.01
2408.51
2359.91
2352.83
2269.32
2256.94
2224.43
2178.93
2172.02
2157.53
2160.14
2136.99
2154.58
2165.97
2159.86
2198.99
2191.28
2227.74
2282.83
2289.01
2316.78
2354.81
2383.54
2437.17
2476.85
2474.25
2456.73
2469.04
2420.02
2391.66
2367.82
2333.69
2249.6
2209.55
2174.6
2102.11
2049.65
2005.23
1941.55
1893.63
1865.03
1865.18
1833.32
1835.1
1784.5
1781.5
1804.13
1819.82
1814.89
1777.04
1816.68
1778.58
1823.67
1821.45
1838.48
1830.51
1885.73
1977.31
2047.57
2079.75
2135.49
2261.35
2315.28
2335.32
2390.67
2469.14
2428.88
2390.13
2339.6
2269.51
2253.52
2144.14
2101.64
2020.89
1975.11
1887.31
1846.88
1809.89
1755.25
1739.58
1723.49
1704.53
1695.23
1654.57
1697.48
1670.17
1689.4
1689.81
1688.44
1687.73
1722.41
1713.81
1687.33
1726.32
1712.71
1736.61
1739.02
1805.53
1861.9
1920.79
2026.44
2112.12
2235.62
2478.69
2762.92
3129.31
3687.6
4495.59
5654.57
7194.59
9008.09
11029.2
12841.7
13897.4
14079.4
13159.6
11428
9370.74
7368.31
5777.19
4442.23
3580.08
2946.81
2466.99
2193.04
2006.92
1827.82
1734.43
1689.3
1636.72
1588.63
1580.26
1598.09
1599.76
1628.24
1689.81
1796.97
1875.02
2017.28
2177.67
2435.57
2777.79
3290.45
4132.11
5241.91
6837.81
8924.32
11470.2
14148.3
16321.7
17566.2
17338.4
15871.8
13506
10699
7986.92
5998.49
4404.46
3293.99
2516.56
2014.14
1689.3
1424.77
1280.06
1161.99
1058.76
1012.06
966.598
938.864
889.366
863.357
820.689
828.222
776.744
782.802
752.19
741.923
723.382
734.773
700.643
685.189
685.969
685.455
672.037
668.767
659.189
645.079
650.009
649.655
663.775
640.211
638.421
622.174
637.401
612.881
630.676
615.089
633.208
615.886
604.264
604.409
587.902
614.908
600.853
614.409
602.246
613.327
602.623
625.46
619.203
606.21
614.435
609.206
586.818
602.741
609.855
611.326
587.188
592.322
618.548
596.517
618.627
612.948
600.708
621.313
602.889
609.567
599.893
602.981
626.143
624.4
610.777
610.952
616.326
625.171
624.87
608.979
623.107
605.629
617.64
631.936
1
Au4d
Au in 4.0 mbar O2
2020
2
8
21
25
27
0
13
Casa Info Follows
0
0
0
0

C:\Users\Mark\ownCloud\Muelheim Group\Projects\Gas phase background\EX321_CEC356_Au Ag and Cu in O2.xy
Group: Au in 4.0 mbar O2, #Treatments:  , #Temp: RT , #Pressure: 4.0 mbar, #Gas1: O2, #Gas2:, #Gas Ratio:, #Comments:
Analyzer Lens: LargeArea
Analyzer Slit:
Scan Mode: FixedAnalyzerTransmission
EX321_CEC356_Au Ag and Cu in O2_clean_vb_regions.vms
c:\users\mark\owncloud\muelheim group\projects\gas phase background\ex321_cec356_au ag and cu in o2_clean.vms
XPS
1e+037
Al
1486.61
0
0
0
56.5
180
FAT
100
1
4.241
0
0
0
0
0
Au
4d
-1
Kinetic Energy
eV
960.61
0.5
2
Intensity
d
Intensity
d
pulse counting
0.1
1
0
0
0
0
2
ESCAPE DEPTH TYPE
d
0
MFP Exponent
d
0
1058
0
1
0
1
1192.87
1
1157.95
1
1169.31
1
1183.86
1
1183.49
1
1176.36
1
1184.19
1
1183.42
1
1185.73
1
1180.49
1
1195.61
1
1194.42
1
1191.92
1
1195.59
1
1217.54
1
1208.41
1
1211.92
1
1193.75
1
1194.32
1
1214.03
1
1215.08
1
1214.58
1
1228.83
1
1193.47
1
1217.97
1
1223.8
1
1225.14
1
1213.32
1
1229.62
1
1239.68
1
1230.48
1
1237
1
1250.97
1
1244.54
1
1252.9
1
1242.92
1
1258.57
1
1257.16
1
1243.6
1
1238.65
1
1232.26
1
1253.84
1
1257.56
1
1278.03
1
1271.2
1
1252.16
1
1264.33
1
1263.58
1
1275.34
1
1269.97
1
1285.09
1
1282.57
1
1260.58
1
1265.72
1
1300.64
1
1299.54
1
1298.51
1
1267.42
1
1287.79
1
1281.05
1
1276.03
1
1279.05
1
1312.68
1
1279.35
1
1306.5
1
1297.2
1
1316.41
1
1321.55
1
1320.34
1
1324.38
1
1336.6
1
1329.89
1
1346.58
1
1317.7
1
1318.76
1
1314.86
1
1328.17
1
1333.78
1
1323.95
1
1347.2
1
1334.53
1
1325.04
1
1333.21
1
1354.97
1
1341.28
1
1332.62
1
1334.95
1
1344.28
1
1345.08
1
1372.53
1
1356.37
1
1376.5
1
1365.07
1
1361.81
1
1360.49
1
1350.91
1
1359.97
1
1375.34
1
1357.72
1
1404.78
1
1391.9
1
1376.22
1
1376.74
1
1400.19
1
1416.9
1
1405.75
1
1399.64
1
1396.84
1
1392.93
1
1376.7
1
1363.84
1
1400.79
1
1424
1
1428.02
1
1425.76
1
1404.56
1
1404.43
1
1403.39
1
1390.23
1
1398.25
1
1404.03
1
1428.03
1
1438.29
1
1423.32
1
1405.64
1
1417.94
1
1418.58
1
1433.96
1
1436.21
1
1428.14
1
1443.08
1
1437.42
1
1440.15
1
1449.47
1
1462.92
1
1469.23
1
1464.98
1
1463.46
1
1448.45
1
1483.61
1
1448.21
1
1481.21
1
1486.79
1
1457.68
1
1499.15
1
1500.08
1
1482.74
1
1462.05
1
1472.96
1
1490.09
1
1496.39
1
1501.09
1
1513.39
1
1521.24
1
1516.6
1
1515.88
1
1535.67
1
1514.45
1
1508.49
1
1510.47
1
1511.84
1
1530.48
1
1522.86
1
1520.4
1
1538.11
1
1534.08
1
1540.71
1
1519.88
1
1528.63
1
1505.06
1
1539.63
1
1541.67
1
1522.34
1
1562.71
1
1555.33
1
1558.9
1
1540.13
1
1544.63
1
1558.67
1
1562.38
1
1559.97
1
1569.65
1
1571.26
1
1581.18
1
1577.58
1
1549.27
1
1570.49
1
1573.04
1
1577.67
1
1591.45
1
1582.18
1
1586.54
1
1563.06
1
1596.87
1
1579.16
1
1592.1
1
1583.68
1
1584.69
1
1600.67
1
1625.95
1
1600.79
1
1605.45
1
1601.16
1
1620.89
1
1602.73
1
1605.34
1
1599.53
1
1610.34
1
1618.94
1
1614.61
1
1601.11
1
1629.22
1
1629.16
1
1632.51
1
1643.64
1
1628.96
1
1621.88
1
1629.31
1
1633.83
1
1622.25
1
1639.24
1
1656.68
1
1633.24
1
1654.52
1
1643.59
1
1647.99
1
1664.5
1
1630.2
1
1639.68
1
1659.79
1
1674.85
1
1671.31
1
1643.46
1
1647.1
1
1666.65
1
1651.12
1
1631.67
1
1644.43
1
1641.33
1
1679.86
1
1662.68
1
1635.34
1
1650.41
1
1671.06
1
1662.41
1
1639.54
1
1656.35
1
1703.76
1
1669.72
1
1669.63
1
1688.57
1
1685.4
1
1675.75
1
1680.39
1
1706.26
1
1699.17
1
1687.17
1
1693.32
1
1669.53
1
1660.53
1
1663.48
1
1669.5
1
1671.77
1
1673.93
1
1675.66
1
1668.79
1
1670.39
1
1673.7
1
1690.23
1
1697.74
1
1678.97
1
1660.31
1
1663.26
1
1680.06
1
1658.94
1
1671.25
1
1668.61
1
1670.56
1
1682.07
1
1676.76
1
1685.83
1
1649.93
1
1667.08
1
1658.83
1
1642.43
1
1638.47
1
1640.61
1
1659.66
1
1658.07
1
1664.85
1
1672.75
1
1661.06
1
1668.61
1
1696.05
1
1670.74
1
1671.94
1
1671.46
1
1645.89
1
1647.55
1
1618.58
1
1658.75
1
1654.94
1
1647.67
1
1629.5
1
1623.39
1
1623.04
1
1620.65
1
1633.16
1
1603.01
1
1621.91
1
1624.42
1
1620.92
1
1624.59
1
1608.86
1
1575.44
1
1561.6
1
1564.5
1
1520.55
1
1509.92
1
1482.98
1
1476.02
1
1449.18
1
1459.27
1
1451.04
1
1449.12
1
1441.56
1
1448.23
1
1466.62
1
1453.19
1
1467.51
1
1487.3
1
1461.28
1
1465.55
1
1456.58
1
1455.27
1
1453.59
1
1484.31
1
1479.27
1
1557.84
1
1589.35
1
1655.6
1
1741.94
1
1863.25
1
1972.58
1
2045.39
1
2092.69
1
2087.7
1
2018.02
1
1884.6
1
1773.26
1
1628.65
1
1481.81
1
1362.75
1
1249.41
1
1169.6
1
1060.7
1
984.583
1
944.793
1
902.197
1
861.371
1
840.154
1
832.694
1
847.894
1
848.799
1
816.226
1
801.239
1
792.18
1
788.103
1
753.858
1
756.84
1
755.053
1
777.043
1
780.492
1
820.642
1
874.381
1
965.488
1
1095.75
1
1227.01
1
1379.09
1
1591.08
1
1756.98
1
1880.26
1
1882.29
1
1797.94
1
1640.09
1
1393.43
1
1155.03
1
936.541
1
748.439
1
624.246
1
518.899
1
445.43
1
374.749
1
335.472
1
292.746
1
246.997
1
221.406
1
201.931
1
177.927
1
170.719
1
146.467
1
129.303
1
131.905
1
114.002
1
97.869
1
97.0052
1
99.503
1
80.0025
1
54.3379
1
67.8301
1
68.2278
1
49.2695
1
57.2481
1
32.3831
1
46.5611
1
58.9775
1
60.0582
1
41.5405
1
43.9054
1
54.0861
1
25.5222
1
41.651
1
44.2424
1
34.852
1
29.2838
1
33.0137
1
14.4909
1
27.6176
1
23.8249
1
36.8152
1
18.4952
1
33.7241
1
19.9437
1
15.3952
1
-3.5208
1
17.9628
1
5.18259
1
-4.5151
1
15.0659
1
18.33
1
18.9441
1
13.6264
1
13.8868
1
15.7498
1
4.3263
1
5.1704
1
2.11482
1
8.76658
1
21.7338
1
11.0621
1
3.51559
1
11.5972
1
8.32435
1
14.1976
1
17.8562
1
28.2709
1
12.327
1
-21.2458
1
-25.9286
1
4.13326
1
3.84711
1
8.83173
1
-8.85946
1
1.65188
1
5.86058
1
17.0658
1
16.9082
1
10.7126
1
6.40978
1
26.0627
1
-1.72774
1
-6.57652
1
21.5557
1
13.2359
1
9.70751
1
-6.58585
1
3.54906
1
15.5404
1
5.41618
1
18.5983
1
8.10444
1
18.1248
1
31.204
1
49.5705
1
65.0872
1
44.132
1
7.51063
1
-7.23485
1
3.22158
1
-7.75844
1
-8.25595
1
-6.13359
1
-23.9987
1
-7.26359
1
2.57329
1
-17.2798
1
-1.67364
1
8.18393
1
0.17031
1
-1.1699
1
-1.20514
1
-14.8281
1
-27.0895
1
-4.42841
1
14.1404
1
-8.25513
1
11.5555
1
17.0788
1
5.06152
1
0.168475
1
-1.63073
1
-11.3341
1
-24.4112
1
4.71742
1
16.8007
1
12.1944
1
-10.807
1
-12.727
1
-16.7992
1
-0.668785
1
6.30189
1
-0.518869
1
1.68473
1
3.50805
1
14.3931
1
-11.2335
1
-13.5523
1
-2.19818
1
-1.06851
1
Survey
Au in vacuum
2020
2
9
9
29
6
0
12
Casa Info Follows
0
0
1
CASA region (*Survey*) (*Spline Linear*) 292.60101 1252.3614 1 6 76.332562 1.357978 -334.91028 -554.11118 -599.16233 -447.64629 (*NoTag*) 0 0 0
0
C:\Users\Mark\ownCloud\Muelheim Group\Projects\Gas phase background\EX321_CEC356_Au Ag and Cu in O2.xy
Group: Au in vacuum, #Treatments:  , #Temp: RT , #Pressure: vacuum, #Gas1:, #Gas2:, #Gas Ratio:, #Comments:
Analyzer Lens: LargeArea
Analyzer Slit:
Scan Mode: FixedAnalyzerTransmission
c:\users\mark\owncloud\muelheim group\projects\gas phase background\ex321_cec356_au ag and cu in o2_clean.vms
XPS
0
Al
1486.61
0
0
0
56.5
180
FAT
100
1
4.241
0
0
0
0
0
Survey

-1
kinetic energy
eV
286.61
0.5
2
counts
d
Transmission
d
pulse counting
0.1
1
0
0
0
0
2
ESCAPE DEPTH TYPE
d
0
MFP Exponent
d
0
1
3949.58
3933.64
3953.22
3972.87
3921.35
3938.54
3977.91
3984.68
4002.71
3997.71
3981.54
3989.43
4014.47
4004.4
4018.56
4050.73
4060.57
3989.27
4053.56
4065.14
4060.17
4066.37
4097.86
4099.09
4085.2
4099.56
4100.91
4124.07
4120.53
4140.77
4139.4
4159.33
4188.46
4209.98
4218.61
4214.93
4232.78
4281.69
4228.75
4246.86
4271.95
4250.28
4269.38
4266.13
4274.32
4238.91
4288.27
4276.06
4305.55
4274.08
4315.15
4340.42
4335.33
4335.65
4348.52
4336.43
4368.78
4337.92
4348.14
4358.6
4363.8
4382.01
4372.82
4385.21
4386.75
4429.16
4433.29
4467.99
4461.02
4450.91
4462.46
4460.02
4457.97
4450.83
4451.94
4470.88
4459.95
4481.84
4498.9
4502.55
4490.58
4464.75
4507.82
4521.04
4514.2
4505.44
4537.66
4531.08
4542.66
4564.54
4547.28
4593.64
4581.65
4599.21
4591.65
4602.38
4602.05
4662.33
4606.75
4614.97
4621.01
4676.69
4651.07
4686.7
4716.66
4686.67
4758.4
4744.03
4771.47
4714.25
4766.69
4745.02
4760.87
4748.25
4753.57
4720.26
4709.76
4756.92
4712.02
4731.05
4687.15
4713.37
4717.2
4718.45
4733.5
4736.11
4721.52
4752.76
4747.4
4768.32
4792.65
4767.84
4812.95
4803.1
4798.36
4837.75
4797.86
4826.11
4853.88
4852.92
4881.22
4859.95
4877.89
4876.56
4881.68
4924.04
4918.72
4919.45
4932.04
4959.7
4961
4978.95
4936.47
4978.54
5015.4
4982.28
5005.12
5010.3
5034.63
5062.91
5082.78
5075.02
5082.15
5132.66
5101.43
5089.58
5129.51
5133.07
5124.86
5119.25
5134.2
5133.43
5150.22
5131.2
5187.03
5137.92
5141.29
5161.77
5155.53
5184.57
5198.07
5236.9
5206.15
5245.9
5242.37
5265.33
5264.02
5312.91
5290.87
5318.12
5344.56
5333.72
5332.9
5332.66
5348.17
5371.07
5352.8
5386.07
5384.72
5373.76
5393.9
5412.77
5398.37
5451.18
5413.26
5473.12
5438.36
5474.31
5460.21
5431.23
5459.62
5480.5
5508.64
5491.25
5511.91
5523.03
5510.67
5555.04
5544.79
5594.31
5620.1
5611.77
5607.65
5689.92
5674.61
5707.77
5707.56
5744.9
5733.15
5730.61
5743.6
5759.78
5712.05
5706.33
5673.24
5717.51
5710.84
5728.92
5720.7
5690.29
5691.01
5763.5
5789.83
5790.11
5784.88
5802.42
5788.67
5817.96
5849.53
5823.26
5862.56
5823.57
5859.15
5897.05
5893.83
5913.84
5943.04
5955.53
5944.74
5965.65
5954.54
5952.63
5953.55
6000.85
6019.96
5999.16
6005.32
5982.13
6069.17
6058.64
6088.91
6038.75
6072.84
6065.09
6104.76
6106.6
6120.92
6181.81
6141.54
6173.42
6189.7
6175
6165.93
6195.23
6205.63
6234.81
6252.61
6222.45
6265.8
6249.16
6250.21
6242.44
6264.62
6257.88
6268.62
6302.6
6286.27
6324.3
6335.68
6311.62
6377.93
6349.1
6357.8
6357.14
6370.89
6365.96
6399.39
6410.48
6419.73
6414.59
6450.23
6462.99
6458.24
6442.81
6427.95
6506.99
6508.91
6530.06
6551.79
6530.65
6576.47
6576.75
6563.48
6573.47
6623.94
6607.69
6623.08
6633.82
6732.15
6672.8
6671.85
6703.61
6700.15
6694.48
6741.28
6739.7
6743.66
6752.38
6794.45
6763.16
6781.55
6801.29
6776.47
6804.05
6869.26
6879.78
6882.27
6840.03
6850.76
6870.17
6922.67
6918.94
6961.55
6978.61
6962.11
7025.73
7000.91
7004.42
7017.12
7044.22
7036.49
7069.31
7086.14
7071.92
7110.18
7114.59
7133.59
7196.84
7165.51
7195.47
7215.74
7233.41
7247.02
7242.66
7236.9
7326.14
7257.88
7305
7306.36
7333.18
7357.59
7386.41
7354.68
7401.09
7420.57
7403.59
7398.8
7429.84
7436.81
7481.84
7496.42
7501.07
7472.26
7505.2
7561.91
7627.59
7568.2
7604.84
7613.42
7585.33
7609.23
7647.22
7648.11
7717.99
7689.87
7691.03
7751.16
7828.23
7789.28
7794.5
7810.59
7862.65
7815.76
7860.99
7856.83
7896.37
7864.95
7898.05
7941.1
7910.67
7992.61
7955.1
8045.47
8016.68
8041.99
8034.65
8080.56
8124.24
8101.5
8200.93
8254.41
8305.39
8324.06
8426.92
8561.49
8676.18
8839.04
8913.72
8948.54
8842.64
8782.52
8618.46
8503.58
8374.54
8215.23
8182.72
8135.2
8117.85
8062.78
8007.21
8011.7
8007.51
7990.68
8069.22
8027.75
8074.16
8039.97
8036.74
8084.15
8062.39
8063.69
8024.69
8057.6
8129.46
8070.59
8165.8
8165.81
8136.52
8203.89
8219.57
8201.18
8196.82
8221.51
8225.96
8254.79
8306.14
8255.3
8276.89
8371.54
8356.11
8369.02
8343.56
8399.21
8397.63
8383.99
8423.97
8443.96
8474.85
8537.08
8434.15
8488.72
8528.06
8513.1
8531.8
8574.05
8609.61
8601.48
8568.16
8648.92
8665.88
8697.59
8725.06
8679.81
8740.04
8724.24
8766.65
8774.81
8802.95
8803.58
8861.38
8904.1
8886.03
8905.84
8933.77
8928.97
8977.18
8935.96
8980.93
9004.96
9019.67
9059.84
9085.8
9082.34
9068.85
9186.12
9148.15
9168.99
9206.99
9238.77
9264.46
9233.97
9299.38
9296.28
9345.91
9321.6
9289.71
9306.8
9414.44
9382.76
9407.03
9411.82
9437.86
9481.86
9470.04
9527.66
9586.54
9608.57
9609.28
9650.51
9771.44
9812.44
9913.07
10084.4
10217.2
10490.2
10669.7
10898.2
10960.6
10854.4
10661.1
10422.8
10139.5
9953.53
9797.09
9686.93
9626.7
9538.61
9524.11
9497.45
9507.62
9488.77
9445.19
9448.57
9435.12
9496.04
9505.64
9467.36
9517.91
9497.3
9588.59
9585.9
9571.01
9549.48
9620.74
9617.32
9676.23
9670.98
9707.28
9720.44
9755.87
9740.86
9806.62
9782.43
9843.98
9840.69
9839.07
9883.27
9901.2
9865.28
9945.05
9965.2
9956.73
9979.66
10000.3
10059.3
10102.4
10081.3
10114.7
10128.2
10242.2
10237.3
10245.7
10263.2
10313.5
10321.8
10396
10411.6
10399.7
10436
10510.5
10554.4
10556.7
10601.3
10648
10621
10649.6
10713.9
10740
10748.1
10754.4
10763.1
10803.4
10826.5
10725.7
10830.9
10866.5
10831.2
10896.4
10964.2
10940.8
11020.8
11056.7
11127.8
11166.9
11227.4
11389.3
11567
11807.9
12201.2
12836.5
13684.4
14946.4
16280.2
17028.1
16551
14960.2
13413.6
12150.8
11335.1
10738
10410.2
10143.3
9973.58
9875.6
9843.87
9818.02
9866.49
9979.03
10046.3
9925.79
9607.01
9479.35
9455.41
9427.45
9452.57
9467.69
9450.95
9455.73
9488.3
9512.14
9499
9487.46
9507.64
9516.37
9529.58
9534.04
9590.02
9625.94
9594.39
9585.52
9653.41
9663.04
9691.21
9669.08
9697.91
9719.17
9793.12
9779.87
9770.74
9811.04
9834.67
9859.51
9872.05
9880.35
9826.34
9844.45
9943.7
9971.55
9959.6
10008.7
9992.77
10047
10049.4
10051.3
10108.8
10132.9
10138.3
10131
10217.1
10171.2
10271.2
10293.1
10259.8
10297.6
10283.7
10322.3
10354.2
10404.3
10425.8
10451.3
10462.5
10475.8
10540
10551
10573.5
10572.3
10602.5
10671.8
10668
10656.3
10703.9
10756.9
10752
10803.2
10836.5
10811.6
10862.6
10914.2
10922.9
11000.3
10986.9
10953.3
11018.8
11025.4
11080.2
11160.7
11159.9
11221.7
11240
11294.5
11249.1
11325.9
11317.9
11421.4
11381.6
11467.2
11466.6
11528.8
11468.7
11581.9
11594.8
11684.8
11659.3
11714.8
11748.5
11752.3
11766.7
11839.8
11876.8
11907.2
11975.3
11968.1
12038.2
12066.4
12073.6
12117.5
12196.7
12198.9
12241.5
12317.2
12325.4
12288.8
12366.2
12435.3
12535
12557.9
12560
12569
12638.3
12807
12791.3
12827.2
12951.8
12874.1
12986.3
13026.7
13065.2
13114.6
13210.3
13254.3
13365.1
13335.9
13476.5
13525.8
13593.9
13621.8
13628.5
13721.6
13777.1
13824.1
13935.9
13933.6
13970.7
13991.7
14051.7
14029.9
14127
14202.5
14282.4
14369.7
14472.8
14547.2
14569.3
14607.9
14721.6
14821.8
14910.2
15085.8
15263
15549
15946.1
16538.1
17457.7
18960.7
21407.2
24391.3
26613.5
25948
22722.5
19127
16597.4
15048.1
14082.9
13466.5
13111.4
12914.3
12880.5
13089.9
13557.2
14286.1
15569.5
17850.1
21562.9
26695.9
30803.8
29831.3
24120.7
17981.6
13930.6
11332.7
9772.94
8852.12
8164.87
7684.44
7386.1
7147.08
6993.6
6831.6
6711.94
6676.03
6575.12
6508.28
6448.52
6454.75
6376.95
6367.59
6301.83
6269.79
6247.48
6258.18
6220.05
6219.26
6241.25
6211.88
6220.75
6208.3
6210.38
6197.44
6198.35
6202.27
6191.69
6216.31
6207.72
6206.85
6189.91
6189.28
6230.98
6244.46
6258.61
6282.72
6337.34
6393.55
6474.73
6536.72
6770.09
7126.75
7011.78
6488.4
6312.54
6257.98
6268.71
6303.49
6331.98
6257.62
6311.84
6390.88
6358.8
6358.13
6347.15
6393.11
6403.23
6421.22
6405.04
6444.48
6428.82
6481.43
6483.37
6460.4
6491.34
6464.79
6490.88
6503.52
6523.16
6552.66
6570.17
6541.73
6594.68
6589.96
6588.8
6646.77
6620.92
6637.23
6662.03
6685.03
6700.66
6787.05
6817.93
6901.01
6991.15
6953.85
6798.82
6809
6781.3
6794.86
6824.72
6839.55
6871.01
6888.61
6910.47
6922.23
6951.72
6920.43
6942.77
6973.99
7001.75
7002.06
7008.1
7002.48
7033.78
7057.6
7058.08
7104.56
7153.86
7143.23
7141.7
7153.94
7193.59
7216.96
7261.73
7227.19
7282.52
7309.82
7308.82
7341.88
7315.72
7339.51
7345.47
7401.35
7392.38
7431.54
7484.64
7464.13
7502.38
7522.76
7562.62
7534.18
7589.73
7622.27
7630.47
7638.24
7686.24
7700.73
7687.08
7768.56
7773.68
7785.14
7818.8
7868.47
7914.38
7900.89
7929.52
8009.9
8018.1
8031.4
8064.9
8035.06
8089.27
8105.17
8160.76
8169.1
8154.36
8187.95
8212.17
8270.55
8261.89
8292.43
8309.05
8363.76
8367.86
8466.29
8449.29
8507.94
8537.89
8561.65
8608.82
8624.99
8714.42
8693.51
8810.97
8848.94
8857.19
8840.58
8887
8971.22
8986.54
8987.09
9043.36
9011.6
9048.92
9007.27
9166.49
9174.04
9151.61
9236.72
9279.03
9344.72
9407.42
9428.27
9521.81
9538.54
9630.16
9646.29
9687.61
9766.78
9892.06
10006.9
10131.5
10230
10308.4
10449.2
10497.7
10556.8
10648.7
10665.2
10771
10835.3
10955.2
11090.5
11156.6
11084.5
11032.5
10895.7
10713.4
10458.7
10292.8
10252
10184.8
10237.9
10285.8
10302.3
10376.3
10338.1
10220
10056.3
10046.2
10201.4
10162.8
10270.3
10850
12299.7
18243
39814.9
53234.8
30299.3
25974.7
55954.5
54539.8
16384.7
5071.24
3521.54
2816.39
2528.57
2456.16
2532.51
2608.57
2669.95
2658.24
2478.14
2310.39
2125.6
1988.06
1909.47
1834.36
1832.02
1836.14
1880.45
1968.5
2098.21
2282.8
2535.71
2940.62
3308.47
3551.89
3487.74
3060.86
2561.45
2162.71
1859.42
1603.33
1461.42
1338.26
1257.3
1205.6
1165.69
1126.9
1120.04
1100.8
1103.41
1108.96
1127.17
1106.29
1112.66
1095.03
1096.59
1094.77
1085.36
1091.56
1096.8
1107.65
1122.53
1128.29
1101.65
1090.66
1076.21
1053.17
1047.62
1033.84
1042.99
1067
1063.59
1048.41
1052.97
1053.51
1054.34
1042.06
1039.43
1057.02
1084.17
1135.66
1243.44
1499.67
2325.76
4109.81
5709.33
5835
6097.33
6673.22
5020.04
2158.5
738.074
1
Au4f
Au in vacuum
2020
2
9
9
35
40
0
11
Casa Info Follows
0
0
0
0
C:\Users\Mark\ownCloud\Muelheim Group\Projects\Gas phase background\EX321_CEC356_Au Ag and Cu in O2.xy
Group: Au in vacuum, #Treatments:  , #Temp: RT , #Pressure: vacuum, #Gas1:, #Gas2:, #Gas Ratio:, #Comments:
Analyzer Lens: AngleResolvedMode22
Analyzer Slit:
Scan Mode: FixedAnalyzerTransmission
c:\users\mark\owncloud\muelheim group\projects\gas phase background\ex321_cec356_au ag and cu in o2_clean.vms
XPS
0
Al
1486.61
0
0
0
56.5
180
FAT
20
1
4.241
0
0
0
0
0
Au
4f
-1
kinetic energy
eV
1311.61
0.1
2
counts
d
Transmission
d
pulse counting
0.3
3
0
0
0
0
2
ESCAPE DEPTH TYPE
d
0
MFP Exponent
d
0
2611.66
1
9533.96
9542.29
9547.3
9642.02
9585.98
9605.11
9565.95
9587.17
9537.3
9600.33
9668.47
9628.64
9655.69
9604.34
9575.78
9561.69
9582.85
9581.85
9670.05
9585.13
9541.49
9577.11
9615.14
9608.5
9647.16
9606.71
9533.05
9545.49
9554.68
9563
9602.22
9574.17
9685.19
9639.21
9609.8
9660.22
9595.63
9677.59
9644.3
9682.49
9638.62
9576.1
9689.51
9694.37
9715.58
9684.27
9735.7
9598.45
9607.72
9619.31
9621.67
9705.93
9675.22
9639.84
9721.43
9700.65
9574.91
9543.21
9670.04
9754.96
9700.26
9685.57
9653.92
9705.37
9697.85
9784.51
9713.09
9718.64
9636.29
9743.61
9737.93
9733.89
9664
9767.77
9754.29
9725.15
9683.58
9730.21
9803.73
9704.21
9801.25
9788.14
9637.96
9687.48
9729.98
9720.41
9754.84
9711.39
9804.31
9694.95
9711.19
9725.36
9746.88
9772.75
9800.68
9826.43
9841.63
9810.94
9788.52
9739.26
9808.42
9792.36
9669.42
9756.15
9788.65
9767.63
9763.48
9859.61
9828.52
9835.07
9879.73
9784.33
9812
9873.36
9828.65
9764.95
9799.22
9787.41
9832.57
9810.25
9808.78
9803.82
9865.73
9887.28
9825.57
9801.04
9874.11
9851.74
9879.89
9894.72
9901.09
9871.1
9902.21
9910.99
9937.19
9875.97
9841.28
9903.68
9883.16
9904.08
9949.48
9864.88
9941.04
9848.65
9926.67
9877.25
9922.32
9959.02
9894.4
9937.6
9993.65
9939.65
9966.52
10086
10009.2
10024.9
9915.79
9952.66
9948.6
9969.16
9943.24
9957.94
9974.35
9947.03
10023.9
9962.89
9998.66
9998.77
9968.1
9975.11
10012.1
9924.38
9988.35
10022.6
10040.5
10029.6
10086.5
9993.41
9977.48
10054.4
10033.4
10045.3
10070.9
10023.5
10083.4
10088.7
10001.2
10064.9
10113.6
10066.3
9997.98
10012.3
10139.8
10050.3
10087
10143.7
10185.1
10034.7
10128
10085.3
10198.5
10114.3
10153.4
10072.1
10102.7
10165.2
10238.4
10206.3
10189.2
10184.4
10235.9
10148.9
10154.9
10262.5
10225.9
10232.5
10250.8
10306.8
10236.4
10257.2
10190.4
10215
10214.2
10204.6
10292
10283.1
10219.6
10312.3
10287.7
10307.3
10264.1
10273
10338.7
10409.6
10334.3
10343.5
10283.9
10321.7
10228.6
10277.5
10397.5
10392.9
10308.8
10335.6
10402.5
10426
10443.1
10347.3
10414.7
10307.8
10370.1
10454
10439.8
10340.6
10401
10347.2
10360.1
10346.8
10403.2
10402.9
10392.3
10354.7
10259.1
10415.9
10424.5
10422.9
10317.8
10433.3
10507.4
10428.8
10467.1
10417.4
10442.3
10406.1
10440
10401.4
10404.3
10496.8
10386.5
10460.5
10513.8
10598.1
10510.7
10466.1
10469.1
10511.9
10478.4
10394.9
10438
10389.6
10476.5
10507.4
10559.1
10437.4
10420.3
10394.4
10415.8
10514.4
10474.1
10482
10505.3
10477.1
10520.8
10530.8
10531
10541.5
10559.3
10506.3
10494
10531.2
10530.6
10419.8
10453.9
10589.1
10502.4
10543.2
10565.9
10508.7
10523.3
10558.5
10543.3
10541.5
10594.7
10626.9
10603.7
10489.1
10595.7
10533.3
10609.7
10539.5
10559.5
10539.4
10555.5
10557.5
10552.4
10662.2
10611.8
10571.4
10549.9
10569.5
10585.6
10530.8
10619.8
10636.7
10614.4
10540.6
10502.2
10610.3
10672.6
10734.6
10661.6
10620.7
10557.4
10654.4
10659.7
10595.5
10621.7
10613.5
10594.9
10628.9
10683.4
10643.7
10588
10677.6
10735.8
10722.7
10747
10758.6
10758.2
10659.1
10711.6
10706.8
10667
10740.7
10710.4
10742.8
10786.8
10739.8
10705
10774
10787.6
10867
10785.8
10817
10899.5
10910.8
10829.8
10850.5
10824.5
10724.1
10753.9
10826.6
10792.7
10798
10809.5
10927.1
10931.8
10800.1
10868.8
10856.1
10846
10870.7
10920.1
10949.1
10963.4
10972.6
10875.8
10947.8
10930.7
10895.2
10924
10929.3
10998.5
11003.7
10892.2
10845.6
10908
10961.2
10940
11017.1
10963.4
10929.1
10999.4
10992.6
10948.3
10964.2
10935.7
10972.4
10979.4
10959
10968.3
10994.2
10943.7
11089.3
11074.9
11092.1
11044.4
11019.2
11113.8
11044.1
11116.9
10985.9
10985.8
10968.9
11027.2
11073.1
11084.7
11044.1
11088.7
11116.9
11113
11113.7
11199.3
11102.6
11205.9
11167.5
11206.7
11236.1
11155.2
11154.6
[...]
25639.1
25736.9
25918.9
26151.4
26379.5
26553.3
26770.7
27052.6
27621.4
27918.2
28272.4
28799.7
29273.6
30199.6
30838.3
31676
32758.2
34164.6
35636.5
37210.3
39166.9
41035.1
42934.8
44542.1
45690.3
46302.4
46232.5
45434.8
43818.8
41878.4
39661.4
37383.7
35246.1
32943.5
31124.4
29420.9
28108.1
26758.8
25686.6
24807.9
24207
23517.5
23042.6
22617.9
22225
21979.3
21676.2
21504
21251.9
21110.8
20919.9
20812.8
20738.7
20650.4
20561.6
20487.9
20463.3
20374.5
20168.6
20124.3
20155.7
20023.4
19990.7
19944.3
20013.7
19910.6
19938.9
19802.7
19833
19874.9
19916.5
20040.6
19795.6
19918.8
20029.5
20009
20133.2
20130
20246
20482
20522.4
20646.3
20709.8
20799.2
20783.8
20732.6
20722.6
20723.1
20623.9
20441.8
20372.2
20285.3
20273.7
20255.1
20203.1
20266.2
20368.1
20396.2
20413.3
20519.3
20697.3
20990.4
20931.1
21135
21396.6
21707.9
21846.5
22126
22446
22574.4
22706.2
22841.4
22791.6
22858.5
22830.4
22761.9
22612
22391.5
22195.6
22130.2
21863.8
21770.4
21649.2
21546.7
21498.2
21291.5
21329.3
21279.2
21268.5
21178.8
21243.7
21247.1
21193.5
21105.5
21112.1
21207.2
21103.8
21193.3
21312.2
21173.9
21403.1
21306.5
21334
21183.1
21112.3
21095.2
20934.7
20762
20522.9
20224.3
19975.8
19780.3
19479.2
19239
19100
18809.5
18634.8
18489.4
18256.1
18143
18069.1
18084.2
18062.4
17994.2
17959.3
17857
17928.7
17944.7
17946.6
17880.4
18048.7
18221.1
18142.1
18212.1
18250.4
18300.9
18376.1
18581.3
18696.5
18788.4
18955.4
18919.6
19011.3
19266.9
19327
19445.8
19606.9
19940.6
20164.1
20381.9
20671.3
20963.7
21235.2
21728.5
21987.7
22291
22649.3
22928.3
23294.4
23731
24008.2
24363.4
24663.6
25100.4
25560.6
25965.6
26555
27066.4
27683.8
28479.6
29393.3
30559
31941
33622.9
35977.2
38988
42872.5
47965.9
54259.1
61574.9
69337.8
76660.7
82399.2
85863.3
86071.3
82831.9
76963.1
69545.2
61273.7
53298.5
45800.2
39378
34087.4
29805.5
26383.1
23839.1
21780.7
20102.1
18801.2
17708.6
16901.8
16270.5
15659.8
15189.3
14853.2
14457.3
14388
14212
14013.6
13764.8
13551.5
13443.4
13363.3
13185.4
13047.5
13004.5
12798.4
12760.8
12699.2
12666.6
12594.3
12623.6
12617.7
12440.7
12484.9
12452.1
12371
12277.4
12255.5
12252.3
12147.1
12268.4
12205.9
12180.8
12093.7
12165.4
12118.6
12150.1
12111.8
12012.4
12084.4
12154.4
11994.1
12062.9
12030.8
11956.7
11934.9
11949.7
11897.1
11899.8
11948.1
11943.8
11899.1
11865.1
11918.9
11945.2
11927.1
11879.2
11941.9
11946.1
11970.7
11822.4
11855.2
11864.6
11844.9
11845.1
11877.4
11900.8
11930.8
11794.6
11775.9
11781.4
11800.1
11722.8
11777.7
11830.6
11824.7
11846.5
11796.9
11821.9
11709.9
11739.3
11839.2
11778
11860.4
11915.1
11794.6
11773.4
11867.9
11779.2
11746.8
11727
11802
11836.5
11743.6
11816.4
11809.7
11821.3
11810.9
11883.1
11859.3
11783.8
11845.8
11802.4
11819.3
11807.5
11800.7
11858.1
11859.6
11886.4
1
Au4f
Au in vacuum
2020
8
27
9
8
45
0
15
Casa Info Follows
0
0
0
0
File = C:/Users/Mark/Downloads/EX439_S718_Au in 25 mbar O2.sle
Group = Au in vacuum, #Treatments:  , #Temp: RT , #Pressure: vacuum, #Gas1: , #Gas2:, #Gas Ratio:, #Comments:
First of group = 0
Analyzer lens = AngleResolvedMode22:1.5kV
Analyzer slit = 4:7x20c\C:mesh
Scan mode = FixedAnalyzerTransmission
Kinetic energy start = 1311.61
PCA Coefs = 2810.31, -2392.78,
C:\Users\Mark\Desktop\EX439_S718_Au in 25 mbar O2.vms
C:\Users\Mark\ownCloud\Muelheim Group\Projects\Gas phase background\data\EX439 Au O2 25mbar bg_sub.vms
XPS
1e+037
Al
1486.61
0
0
0
54.5
180
FAT
20
1
4.156
0
0
0
0
0
Au
4f
-1
kinetic energy
eV
1311.8005
0.1
2
counts
d
Transmission
d
pulse counting
0.1
3
0
0
0
0
3
ESCAPE DEPTH TYPE
d
0
MFP Exponent
d
0
PROPAGATION_CONVERGED
d
1
10.8956
2.30555
45.6131
45.723
45.8114
45.552
45.8344
45.2177
44.9617
45.1421
45.1725
45.6413
45.8466
45.8464
46.3196
46.2556
45.8038
45.6359
45.567
45.1096
45.4744
45.603
46.2196
46.3934
46.0059
45.9018
46.1468
46.2978
46.272
46.0604
45.8722
46.37
46.1335
46.655
45.7642
45.7157
46.27
46.1591
46.1019
46.1795
46.0121
46.1182
46.0282
46.0015
46.5822
46.7305
46.6036
46.363
45.8328
46.2405
46.0736
46.2798
45.8003
46.0122
45.96
46.0799
46.7442
46.7366
46.1712
46.5708
46.9231
46.7127
46.3689
46.9264
46.6465
46.5951
46.9783
47.1395
46.7899
47.3304
47.0061
46.4128
47.0425
46.9484
46.9916
46.7225
46.6272
46.3349
46.6986
46.749
46.8372
47.1987
46.6742
47.1657
47.0876
47.0231
46.413
46.2137
46.6114
46.601
47.3915
46.9123
46.9942
46.9204
46.6906
47.1718
46.848
47.3707
47.5196
47.2675
46.6339
46.9293
46.8189
46.8573
46.9592
47.5461
47.292
46.8738
48.1874
48.0774
47.6361
47.1393
47.409
47.3213
46.7668
47.3542
47.4733
47.824
47.8161
47.9757
48.1635
47.6268
47.7605
47.7259
48.0075
47.8082
47.5855
47.2488
47.6921
47.1405
47.3463
47.6571
47.6579
47.5887
47.854
47.7637
47.1255
47.4981
47.5847
47.8354
47.5163
47.4071
48.1287
48.0389
47.9117
48.3805
48.2168
47.5199
47.6171
47.7834
47.8363
47.5896
47.8374
47.5934
47.967
48.0913
48.2475
48.1134
48.2864
48.0985
47.6327
48.3453
49.1088
48.4105
48.1008
48.2337
48.4227
48.6556
48.5073
48.5426
48.797
48.5172
48.8339
48.8983
48.403
48.0136
48.0055
48.4733
48.7435
48.8102
49.1229
48.926
48.8638
48.6519
49.2312
48.3998
48.9326
49.4266
48.6955
48.7635
49.1606
49.0202
49.6856
49.3715
48.8442
49.1653
49.1385
49.4429
49.4706
49.1728
49.0105
49.4186
49.2953
49.4182
49.4595
49.4161
49.5122
49.4859
49.6714
49.6063
49.2038
49.0227
49.2876
50.3271
49.5608
49.5783
49.9751
50.0091
49.7519
49.6431
50.1068
49.9719
50.0803
50.0939
49.6845
49.7448
49.5372
50.1507
50.4921
50.491
50.1516
49.8199
50.1904
50.3271
50.1307
50.536
50.505
50.0939
50.2215
50.1257
50.1942
50.2562
50.1854
50.4878
50.6299
50.4642
50.0477
50.2272
50.4471
50.5699
51.0047
50.9639
50.9269
50.6183
50.5005
50.486
50.6867
50.9334
51.0074
50.7872
50.8782
51.217
51.2089
51.655
51.3733
51.181
50.8762
50.9937
50.8076
50.9731
51.0698
50.4844
50.6566
50.8289
51.0134
51.2392
51.2986
50.4838
50.7995
50.9938
50.727
51.6851
51.2951
50.9486
50.5847
50.8609
51.248
51.0253
50.9677
50.7482
51.3319
51.0618
51.0888
51.3378
51.6154
50.8842
50.7204
51.0834
50.7496
51.407
51.1992
51.64
51.3996
51.578
51.4381
51.5857
51.5119
51.4952
52.076
52.1958
51.1802
50.5155
51.2489
51.6338
51.6373
51.2969
51.2549
51.6388
51.3204
51.7052
51.2549
51.2955
51.5349
51.7836
51.1237
51.474
51.7395
52.3759
52.0951
51.5698
52.0685
51.4615
51.5138
51.6338
51.8128
52.08
52.7748
52.438
51.8805
52.1885
51.9664
52.0582
51.4365
51.7723
51.5944
51.4329
52.3293
52.4484
52.1383
51.4729
52.3206
52.8228
52.5572
52.6829
52.8768
52.5033
52.6826
52.4747
52.5082
52.3289
51.9694
52.1257
52.3303
52.4306
52.6199
52.9516
52.556
52.509
52.7082
52.0551
52.4655
52.941
52.6057
52.7559
52.7376
53.006
53.1196
52.7401
52.6119
52.3646
51.9298
52.5899
52.4963
52.939
52.9315
53.1625
53.5581
53.3885
52.7494
53.0057
52.9848
52.8084
52.7292
53.0168
53.4873
53.3141
53.5836
53.8836
53.1533
53.6353
53.3335
53.554
53.3463
53.4845
53.7995
53.7437
53.4943
53.4381
53.673
53.3675
53.0733
54.182
53.9034
54.0445
54.2884
54.3984
54.2188
54.194
53.912
54.216
54.0288
54.0488
54.0133
54.267
53.841
54.0216
53.4644
53.6498
54.1446
54.437
54.1554
53.8666
54.1151
54.4449
54.4916
54.5352
54.0289
54.3291
54.6421
53.9632
54.214
54.8446
54.5842
54.6918
54.8541
54.3263
54.7721
55.0619
55.0485
54.8749
55.5587
54.8247
55.4737
55.199
54.8219
54.7022
55.0663
55.3539
55.4787
55.2754
55.2435
54.5467
54.9454
55.6283
55.2442
55.5736
55.0512
55.4448
55.7743
55.3839
55.7168
55.5657
55.6699
56.0594
55.7603
55.4817
55.7974
56.1332
56.0206
56.5409
56.6276
55.8252
56.0918
55.9377
55.9134
56.533
56.6582
55.9998
55.7346
56.3035
56.9216
56.5587
56.2932
56.8589
56.8821
56.7029
56.7996
56.3237
56.9641
56.77
56.814
57.0581
57.169
57.2
57.0234
57.8092
57.4499
57.8861
57.7248
58.1415
57.9765
57.2771
57.9218
57.5524
57.6587
58.4705
57.8804
58.2875
58.7786
58.1177
58.2526
58.7466
58.17
58.2884
58.6671
58.4019
58.7347
58.529
58.45
59.0906
58.7096
58.5822
58.6884
59.1494
58.8008
59.3609
59.3945
58.9152
59.6039
59.6183
59.3565
59.2294
59.4711
60.0827
59.8672
59.7327
60.0209
59.6693
59.9257
59.7522
60.0191
60.1264
60.7777
60.8579
60.5134
60.7702
60.4858
60.2865
60.6388
61.1774
60.7222
60.9091
60.7372
60.3038
60.8489
60.545
60.8991
61.4589
61.3257
60.7916
60.2244
60.4716
61.1908
60.7365
61.2963
60.6515
60.648
60.5914
60.9167
61.6393
61.6807
61.0414
60.8647
60.6902
60.7817
61.1392
60.5805
61.4837
61.518
60.9191
60.7737
61.922
61.9785
61.6542
61.4226
61.9295
62.1201
62.0487
61.988
62.076
62.3462
62.2681
61.6313
62.155
62.4061
62.5599
62.3282
62.4057
62.4663
62.4399
62.4472
62.5806
62.7114
62.9703
62.8984
62.6336
62.574
63.2771
63.0478
63.5009
63.0764
62.745
63.3884
63.9499
63.2643
63.8612
63.9735
63.551
64.398
64.2887
64.1713
64.2873
64.4029
64.0731
64.3038
64.5777
64.3205
64.7476
64.183
64.8238
65.1076
65.2277
64.8622
64.9973
64.5034
64.5682
64.8947
64.3481
64.187
64.8908
64.9358
64.6713
64.7328
64.4048
64.5661
64.4981
63.2061
64.233
63.8602
63.3141
62.6908
62.7378
63.2287
63.2517
63.6456
62.532
62.2177
62.7059
62.9627
63.1231
63.0113
62.096
61.9435
62.3074
61.4623
61.9111
62.1493
62.2158
61.4738
61.1529
60.5965
60.8865
59.9004
60.1457
59.9704
59.9559
59.7421
59.2121
59.5631
59.273
58.7945
58.774
58.4649
58.5237
59.121
59.0248
58.2841
57.965
58.0819
58.4775
58.1604
58.2517
58.383
58.0902
58.4686
58.5185
58.3509
57.8766
58.2304
58.8668
58.5463
58.4874
58.289
58.6315
58.649
58.2349
58.0283
57.7577
58.2702
58.5294
58.0438
57.8551
57.7231
57.6608
56.9653
57.1646
57.2956
56.5596
57.0774
57.2198
56.8918
56.4053
57.0167
57.1609
56.7001
57.0339
56.8278
56.8973
57.3952
57.7246
56.9783
56.3928
56.9643
56.7702
56.8318
56.1351
56.311
56.8189
56.75
56.9863
56.6066
56.4407
56.3284
56.3309
56.4712
56.3422
56.6221
55.9922
56.0439
56.0449
55.4601
55.1455
54.9188
54.1593
54.4274
54.7679
54.7521
54.1466
54.0214
53.6835
53.6414
53.6578
53.8531
53.844
53.0635
53.1773
53.3299
52.408
52.7103
53.1715
53.2019
53.1755
52.9828
52.3335
53.1199
52.352
52.2242
51.8367
51.3772
51.8614
51.929
51.2964
50.411
50.18
50.3284
50.0369
49.8857
50.0264
49.9474
49.6047
49.4501
49.5453
49.1013
49.3694
49.7609
49.0413
49.3096
49.9204
50.4702
50.6429
50.5333
49.6996
50.2069
49.6836
49.5468
49.7352
50.0845
50.7426
51.2675
51.3207
50.7721
50.4562
50.5169
50.657
50.8245
50.3951
50.3624
49.5173
49.6982
49.5597
49.3118
48.7122
48.6793
48.7474
49.5714
49.923
49.9992
50.7267
50.7457
50.674
51.5405
52.0403
52.8128
53.7429
54.3792
54.5124
54.5509
54.7204
55.3575
55.2418
55.0552
55.3296
55.6844
56.0597
56.6422
58.0217
59.8567
61.5235
64.9944
69.0673
73.1554
78.5328
86.6309
96.4519
108.951
128.409
157.105
199.044
257.837
340.67
440.492
553.037
654.631
718.928
731.901
683.321
589.574
475.769
364.364
273.912
205.049
155.294
121.554
99.2339
83.3393
73.2776
66.4598
61.023
56.8072
53.5096
51.7971
51.609
51.9936
52.6632
53.9041
56.7273
60.2926
65.4562
72.4148
82.2151
95.1209
112.466
137.648
177.387
236.105
317.411
430.215
568.566
716.465
843.29
913.966
906.007
826.237
693.093
539.484
396.206
282.651
199.985
141.463
101.449
74.1792
55.7776
43.6196
35.6172
29.9048
25.1249
21.4136
19.3707
16.5874
14.7942
13.024
11.549
10.3267
9.5516
8.9016
7.7866
6.8114
6.1908
5.73
5.0686
4.5028
4.1219
3.7654
3.1849
2.847
2.4702
2.3775
2.1114
2.0135
1.4984
1.5377
1.3501
1.3866
1.1946
1.111
1.1529
0.6671
0.4371
0.2615
0.3196
0.3068
0.146
-0.06
-0.1081
0.0368
0.1007
-0.2234
-0.2053
-0.279
-0.1347
0.026
-0.0971
-0.0086
-0.0135
-0.2813
-0.2808
-0.2203
0
0
0
0
0
0
0
0
0
0
0
0
0
0
0
0
0
0
0
0
0
0
0
0
0
0
2.30555
Au4f
Au in 25mBar O2
2020
8
28
6
43
27
0
15
Casa Info Follows
0
0
0
0
File = C:/Users/Mark/Downloads/EX439_S718_Au in 25 mbar O2.sle
Group = Au in 25mBar O2, #Treatments:  , #Temp: RT , #Pressure:25mBar, #Gas1: O2, #Gas2:, #Gas Ratio:, #Comments:
First of group = 0
Analyzer lens = AngleResolvedMode22:1.5kV
Analyzer slit = 4:7x20c\C:mesh
Scan mode = FixedAnalyzerTransmission
Kinetic energy start = 1311.61
PCA Coefs = 682.762, 55.3653,
C:\Users\Mark\Desktop\EX439_S718_Au in 25 mbar O2.vms
C:\Users\Mark\ownCloud\Muelheim Group\Projects\Gas phase background\data\EX439 Au O2 25mbar bg_sub.vms
XPS
1e+037
Al
1486.61
0
0
0
54.5
180
FAT
20
1
4.156
0
0
0
0
0
Au
4f
-1
kinetic energy
eV
1311.8005
0.1
2
counts
d
Transmission
d
pulse counting
1
1
0
0
0
0
2
ESCAPE DEPTH TYPE
d
0
MFP Exponent
d
0
2.55924
2.30555
35.8511
37.3759
36.597
34.9449
34.5239
35.5732
35.3303
35.643
35.1489
36.0654
36.8494
37.3506
36.4051
36.0521
36.0723
35.6574
35.5037
36.2663
36.6936
37.4539
37.7221
36.3876
37.4698
36.9182
35.6453
35.2349
36.9327
36.8867
35.6285
35.8251
36.2095
35.7438
35.6622
35.0215
36.0147
35.0659
35.5387
35.2382
36.3073
36.6177
36.1921
36.3493
36.0211
36.0556
36.3181
35.686
35.6767
35.7751
35.5996
36.279
36.3977
35.0537
35.5331
35.735
35.6463
34.7481
35.1684
35.1311
36.6791
35.0147
35.0362
36.4376
36.3637
35.5274
34.9943
35.6959
35.6182
34.6062
35.69
35.0459
35.4149
34.6427
34.8649
35.0042
35.1374
34.7111
36.0521
35.3126
34.7907
34.2702
33.9469
36.0489
36.4645
33.7281
34.1069
34.1524
35.2751
35.8817
35.4583
34.7706
33.639
34.6083
34.2864
35.5192
34.8111
35.0939
35.4402
36.1078
33.8335
33.1867
33.9982
34.1447
35.4248
33.4953
34.3741
33.6302
34.9437
35.267
34.7725
34.753
35.3043
34.8667
34.5591
33.5929
35.1814
35.4457
35.2169
34.8808
34.8675
34.9848
34.2121
34.7833
33.5479
33.7564
33.81
33.6924
34.1067
34.7937
32.4902
34.5541
33.7545
34.2632
33.6564
32.8395
33.6985
34.3392
33.5328
34.4425
33.9026
34.303
33.9756
33.2299
33.1332
34.2715
34.0208
35.2945
33.6472
34.0054
33.8246
33.2024
33.8131
34.416
33.9234
33.824
33.3518
34.8678
34.0645
32.546
33.227
33.7861
33.7502
33.8739
34.6843
33.6371
33.2062
33.2073
34.4044
33.4623
33.4422
32.7953
33.3407
33.4179
33.7803
33.3668
32.7997
33.9923
33.4474
33.6966
34.3378
34.5831
33.9336
33.4145
33.1817
33.5298
33.227
32.702
33.2928
34.0669
33.7824
33.5968
33.1127
33.9188
33.0222
32.513
33.1516
33.0492
31.8788
33.3729
33.9722
33.11
33.6675
34.035
33.2765
33.1227
32.6818
33.7373
33.9215
34.4317
33.0635
32.1384
32.4423
33.3454
33.6218
32.8935
33.3321
33.2412
33.2296
32.8177
33.645
32.2266
31.6981
33.0735
33.1523
32.5507
33.1907
31.8296
32.208
32.4086
31.7923
32.3002
31.6085
30.8476
31.9687
32.6762
32.559
32.2949
32.5574
32.3393
32.3676
33.0676
31.711
31.3531
31.1408
31.8761
31.6765
31.3671
31.7064
32.0591
32.9424
32.9766
32.3288
32.354
31.7224
31.905
31.5734
32.5334
31.4715
33.5049
31.4057
30.5314
32.2552
32.3558
31.4752
31.8879
30.9486
30.9117
30.8972
31.2959
31.7658
30.8256
32.0012
31.4981
30.53
30.1711
31.6581
31.5507
31.3139
30.9813
31.4398
30.6776
30.5244
30.4537
30.6776
30.9048
31.4661
30.4111
30.8899
31.3896
31.2902
31.3243
31.835
31.7808
32.4022
31.3388
31.1492
31.0784
29.3578
31.105
31.2596
29.4488
30.0971
31.2901
31.7408
32.4053
31.8791
29.8316
31.7407
30.6125
29.7181
30.1665
30.4892
30.7605
29.932
31.124
30.692
30.7532
30.9114
30.3229
30.7744
30.158
30.0779
30.417
29.939
29.328
28.7215
29.2498
30.2412
30.7226
31.3132
29.9488
30.1806
30.6024
29.7039
29.4896
29.8867
29.489
29.9993
29.3168
30.1323
29.3429
29.467
29.5335
29.3914
28.187
29.77
29.8831
29.657
29.7629
30.1541
29.8464
30.0925
28.6124
29.0944
28.602
28.3226
29.3683
30.3501
31.0095
29.432
29.3986
29.2399
28.777
28.3591
29.1406
29.166
30.2903
29.9077
29.1153
29.4468
27.7041
28.7288
29.5748
29.2535
28.9039
29.8745
29.5839
28.8493
28.8942
29.606
28.8817
28.9859
28.6497
29.1319
28.4238
27.5465
28.6115
28.6172
29.2709
29.0986
28.2057
28.1017
27.7527
28.1763
28.3124
28.2727
28.2047
28.3913
28.4972
28.8148
28.9625
27.5243
27.769
27.7718
28.4231
27.9284
27.7341
28.7617
28.6814
26.9714
28.1344
27.4201
28.1923
27.6478
28.1275
26.5922
28.2147
28.5019
27.6021
27.4455
27.2059
27.5645
27.4236
28.174
29.6085
27.532
27.4716
26.519
27.0077
26.886
27.1897
27.5169
27.6224
26.8892
26.6865
28.3977
27.4759
27.3853
26.6132
27.8728
27.7397
27.9479
27.9673
27.1743
26.7817
27.0671
26.9654
27.3196
27.033
26.5909
26.9421
25.603
27.3925
26.4722
27.593
26.8064
26.8309
26.0938
26.7549
27.9496
25.1539
26.1925
26.4848
25.8624
26.0952
26.3579
26.5275
25.8343
26.2164
26.4059
26.2093
25.9769
26.0611
25.8602
25.7054
26.0657
26.0015
25.8906
26.8235
26.5351
25.7845
26.1603
26.0696
25.2026
26.1554
26.1646
26.1934
25.5534
25.1969
25.6793
25.7178
26.0352
26.0194
25.5068
25.3072
25.1174
24.8219
24.2884
23.8266
24.9749
24.8673
25.0963
25.7606
25.2738
24.2415
25.081
24.842
23.354
24.4822
25.1407
27.284
26.4962
25.4789
24.3362
24.3549
24.4425
24.4399
23.3115
24.6686
23.6873
23.9844
24.5681
25.4276
24.6549
24.081
24.2129
24.6326
24.2811
23.6863
23.5896
24.2949
23.2471
24.471
24.1846
23.9728
24.3674
24.4556
25.457
24.0621
23.9165
24.4809
23.9019
23.9768
23.1903
23.7143
22.7889
22.6987
22.7415
23.7258
24.5331
23.396
23.5753
23.4277
23.1005
22.1522
22.8357
22.3403
21.6677
23.8068
23.5704
23.1812
21.7364
23.2774
22.8062
22.7859
22.4812
21.912
22.9098
21.734
22.6551
23.6721
23.1261
22.6079
21.7221
22.2869
23.4258
22.5512
22.4357
21.9657
21.6228
22.9019
22.5154
22.6023
21.7364
21.8572
21.9911
22.6838
22.8955
22.2828
22.5348
21.5261
22.23
21.3802
21.0673
20.9597
21.252
21.1655
21.5397
22.2925
21.4718
20.8894
20.5979
21.3056
21.1967
21.1751
21.9777
22.2081
21.5943
21.0632
20.5386
20.6266
21.1902
20.0496
20.3677
21.183
20.9118
21.0044
21.4423
21.5725
20.7544
21.2107
20.7039
19.5857
20.0674
21.479
20.3457
20.3206
20.5864
20.8255
20.6198
20.396
20.6235
19.3723
19.851
20.4977
21.1526
20.737
21.2864
20.2977
19.9915
20.8383
20.6445
20.4442
20.3772
19.8618
20.8058
20.169
19.9852
19.6707
19.9874
21.6401
20.7325
20.3854
20.1459
19.9908
20.5719
20.5356
20.2785
20.443
20.075
19.9004
20.7623
20.1819
19.446
20.1196
19.2213
19.9878
19.9351
20.5059
20.006
19.8731
19.0101
19.7238
21.4816
21.4156
19.7713
19.5502
20.0098
19.6417
19.8912
20.1361
20.6067
19.2941
20.6633
19.0215
18.9242
18.6483
19.4489
18.6991
19.0189
18.5971
19.6218
19.7865
19.4428
18.7151
19.5556
19.1403
17.6404
19.5994
19.2242
19.8885
19.515
19.8089
19.1199
18.7417
19.4049
19.0029
18.1082
19.2024
18.9756
18.8982
17.629
18.2437
18.3895
18.6615
18.3807
19.1019
18.8907
19.0292
19.2606
17.9672
17.3778
17.7871
18.0446
16.993
16.0464
17.0653
16.5118
15.691
16.3315
15.2637
15.4365
16.4203
15.9132
15.9608
16.9784
17.0624
16.381
16.0691
16.5574
16.4295
17.1679
16.4792
16.3067
16.1619
15.5944
15.1702
14.449
14.9429
14.236
14.445
15.0067
14.7408
14.4711
15.6527
14.6136
14.2308
14.2959
13.1894
13.3779
13.4648
12.875
12.0397
11.797
11.5751
11.0982
11.9183
10.9139
10.936
10.6414
11.7219
10.3725
10.9635
10.5749
11.6666
10.8797
10.665
11.4281
11.2357
11.787
12.4231
12.1594
12.6723
13.851
13.7372
13.0612
12.6636
12.9945
12.744
12.5681
11.8964
11.5955
11.2444
10.7354
10.2399
10.5452
9.70086
8.66976
8.36146
8.24876
6.96256
6.88426
7.20426
7.99706
7.14676
7.58106
7.34736
7.58586
8.18886
7.59216
6.75886
6.58376
7.51596
7.75656
7.60746
8.49746
9.01306
9.26586
8.62146
10.6709
12.0809
11.9009
11.4133
12.454
12.6863
11.5824
11.9556
12.4258
10.9951
10.5436
9.95786
10.5976
9.29626
8.23396
8.40896
7.79876
7.19116
6.97826
6.41276
6.37546
5.64576
6.30306
6.14216
5.78166
5.72196
6.25706
6.24056
4.97136
5.81246
5.42576
5.23306
5.50466
5.11596
5.70976
5.56386
5.37296
6.08336
6.09646
6.81546
6.91446
7.70136
8.36066
8.91456
9.12966
10.715
12.8931
15.9996
22.1073
29.024
35.4868
43.4754
50.1988
55.6261
53.5214
48.8066
43.6005
36.7485
28.9626
22.0406
17.1846
13.6515
10.3487
9.13506
8.24176
6.74196
5.44306
5.37596
5.83946
5.07016
4.57856
4.97946
4.62606
4.42076
4.35606
4.47866
4.80496
5.88226
5.73566
6.37696
7.99096
9.14166
11.8031
15.5714
19.6754
25.9406
34.9932
46.6535
56.9887
64.367
68.5966
67.6982
59.0602
48.0752
39.0802
30.8354
24.0967
17.3563
12.6103
8.99726
6.28026
5.27156
4.54326
3.41816
2.98046
3.12806
2.46196
2.32574
1.68546
1.56221
1.34613
1.24708
1.88185
1.59456
1.12767
1.3181
0.85109
1.03034
1.00416
0.79845
0.67364
0.85598
1.05838
0.9417
1.04684
0.69811
0.24601
0.61348
0.67414
0.68259
0.64076
0.66064
0.40305
0.61428
1.08354
0.7156
1.00391
0.4211
0.03151
0.86687
0.51781
0.47067
1.17605
1.19113
0.7082
0.49705
0.86661
1.03303
0.26656
0.30146
0.5685
0.58931
0.04385
0.29053
0.45993
0.44147
0.25689
1.16156
0.44158
0.55853
0.23352
0.30543
0.443
0.4096
0.01505
-0.06962
0.80113
0.03312
0.33745
0.5679
0.38934
0.26787
0.26494
0.13933
0.20193
0.4217
0.33673
0.36474
0.33227
0.70993
0.29381
-0.14986
0
2.30555
end of experiment