File: data/O2/Au, Ag, Cu in O2.vms
VAMAS Surface Chemical Analysis Standard Data Transfer Format 1988 May 4
Not Specified
Not Specified
Not Specified
Not Specified
17
Casa Info Follows CasaXPS Version 2.3.24rev1.0F
0
SourceAnalyserAngle: 56.500000 d
CasaRowLabel:1. Cu in 2 mbar O2
CasaRowLabel:1. Cu in vacuum
CasaRowLabel:2. Au in vacuum
CasaRowLabel:2. Au in 25mBar O2
CasaRowLabel:3. Cu in 4mbar O2
CasaRowLabel:3. Cu in vacuum
CasaRowLabel:4. Ag in 4 mbar O2
CasaRowLabel:4. Ag in vacuum
CasaRowLabel:4. Ag in 2 mbar O2
CasaRowLabel:5. Au in 4 mbar O2
CasaRowLabel:5. Au in vacuum
CasaRowLabel:6. Au in vacuum
CasaRowLabel:6. Au in 4 mbar O2
CasaRowLabel:6. Au in 2 mbar O2
NORM
REGULAR
12
1
Sample Identifier
d
0
0
0
0
42
Cu2p
1. Cu in 2 mbar O2
2020
2
9
14
30
15
0
10
Casa Info Follows
0
0
0
0
EX321_CEC356_Au Ag and Cu in O2.xy
Group: Cu in 2.0 mbar O2
Analyzer Lens: AngleResolvedMode22
Analyzer Slit:
Scan Mode: FixedAnalyzerTransmission
XPS
0
Al
1486.61
0
0
0
56.5
180
FAT
20
1
4.241
0
0
0
0
0
Cu2p

-1
kinetic energy
eV
456.61
0.1
2
counts
d
Transmission
d
pulse counting
0.5
5
0
0
0
0
2
ESCAPE DEPTH TYPE
d
0
MFP Exponent
d
0
9227.09
1
12578.1
12602.2
12658.3
12720.1
12513.7
12627
12712.3
12742
12714.6
12782.8
12822.5
12764.5
12757.6
12704
12800.6
12782.8
12684.3
12697.7
12678.2
12827.2
12781.8
12677.4
12761.1
12668.3
12686
12733.2
12845
12803.2
12833.8
12763.6
12635.4
12743.5
12799.3
12729.5
12860.5
12828.6
13016.2
12967.4
12982.7
12914
12946.1
12902.9
12741.2
12809.5
12845.2
12840.3
12871.3
12873.9
13000.3
13021.9
12971.1
12927.1
12919.8
12917.7
12806.3
12982.6
12958.3
13015.7
13011.3
12949.4
13050.6
12946.7
12884.7
12892.3
12860.4
13015.3
13036.6
12951
12966.1
13027.7
13016
12904.3
12955.4
13007.6
13079.8
13097.1
13096
13128.9
13099.2
13120.1
13068.5
13079.2
13105.2
13087.6
13039.2
13134.9
13032.9
13071.7
13084.2
13049.1
13119.6
13215.8
13151.4
13156.4
13245.3
13186.9
13178.3
13104.4
13211.3
13198.6
13209
13277
13339.5
13181.1
13314.5
13238.6
13198.1
13206.1
13264.5
13254.2
13312.2
13283.4
13210
13272.3
13298.7
13182.4
13184.9
13289.6
13262.6
13213.6
13351.1
13396.9
13362.5
13262.6
13282.6
13314.7
13294.5
13363.3
13230.6
13259.1
13338.1
13347.1
13254.8
13485.3
13324.5
13365.4
13346.1
13344.6
13371.4
13387
13392.5
13316.2
13333.1
13469.4
13409.7
13375.6
13350
13332.2
13320.1
13322.1
13446.8
13457.4
13426.5
13426.2
13419.9
13336.7
13429.4
13487.4
13510.8
13554.4
13521.7
13654.5
13445.7
13454.8
13630.8
13564.5
13576.8
13507.8
13527.5
13557.1
13451.1
13535.7
13495.3
13489.5
13551.9
13606.7
13610.2
13693.9
13638
13515.6
13578.5
13610.4
13687.7
13580.2
13617.9
13549.3
13592.8
13579.7
13550.4
13590.9
13584.1
13562.9
13554.7
13667.1
13655.6
13653.6
13613.7
13612.2
13577
13670.9
13690
13749.7
13671.7
13625.9
13513.8
13631.2
13706.2
13673.7
13700.2
13758
13747.2
13877.7
13685.9
13651.4
13812.8
13768.4
13818.1
13769.2
13679.4
13861.4
13871.5
13699.2
13664.8
13773.8
13709.7
13698.8
13789.7
13800.7
13807.4
13808.5
13791.7
13834.8
13792
13667.6
13833.5
13844.7
13836.8
13868.2
13819.9
13696.1
13795.2
13887.6
13960.7
13930.9
13847
14010.1
13894.6
13905.4
13917.6
13900.6
13849.3
14009.4
14026.3
13911.3
13829.8
13861
13924.9
13819.2
13867.8
13868.4
13909.4
13880.6
13802.5
13851.8
13914.5
13847
13727.7
13779.4
13991.2
13937.1
13865.6
13804.3
13822.4
14054.2
13878.1
13854.1
13937.5
13872.6
13709
13771.3
13855.6
13947.8
13850.8
13887.7
13939.5
13896.1
13861.1
13972.9
14041.5
14062
13943.4
13886.3
13945
13896.6
13787.7
13808.7
13935.4
13893.2
14069.4
13939.9
13918.9
13859
13877.4
13874.5
13835.1
13844.5
13950.8
13993.2
13977
13952.1
14167.1
14019.2
14021.9
14030.9
13917.8
14014.5
13999.3
14114.6
14038.3
14046
14102.3
14159.7
14168.9
14006.3
14024.6
14070.1
13997.7
14050.3
14033.4
14063
14014.7
14027.3
14133.2
14098.2
14048.4
14154.4
14164.8
13947.1
14091.2
14148.2
14257.6
14224.1
14197.6
14210.8
14118
14177.5
14090.1
14200
14104.9
14158.5
14274.6
14217.8
14009.9
14054.4
14318
14236.6
14250.4
14209.4
14149.3
14276.5
14330.5
14293.9
14205.7
14143.4
14248.7
14207.7
14168.6
14234.5
14259
14180.8
14166.5
14281.4
14269.8
14259.9
14273.4
14290.8
14168.8
14150.8
14260.2
14202.8
14203.7
14133.2
14293.2
14292.4
14371.4
14303.4
14273.2
14285.1
14078
14172.7
14302.3
14287.6
14283.1
14349.5
14431.9
14421.8
14351.8
14403.3
14305.1
14456.9
14644.4
14672.1
14541.9
14596.9
14574.1
14429
14269.7
14168.2
14166.6
14193.7
14289.8
14199.4
14253.8
14237.1
14295.7
14165.2
14349.8
14142.7
14227.2
14248.4
14235.1
14152
14191.9
14100.3
14311
14276.8
14406.1
14334.1
14280
14462.4
14398.4
14477.8
14324.6
14399.6
14554.9
14365.2
14366.7
14335.6
14377.1
14461.6
14336.8
14423.2
14355
14378
14313.5
14281.6
14290
14309.9
14307
14350.4
14296.1
14087.5
14218
14254.4
14178.3
14241.8
14140.4
14256.9
14120.9
14047.6
14100.5
14115.1
14168
14024.8
14104.5
14110.3
14119.2
14119.9
14238.3
14287.9
14281.4
14269.8
14318.2
14440.5
14541.2
14568.1
14546
14674
14758.3
14750.8
14743.5
14718.3
14912.6
15042.7
14932.6
15035.3
15106.8
15217.8
15069
14975.6
14662.2
14545.7
14469.6
14301.6
14292.5
14395.1
14440.1
14544.2
14493.1
14431.1
14493.8
14405.4
14239.8
14216.4
14238.6
14177.1
14145.9
14171
14247.5
14145.5
14087
14226.5
14217.8
14130.7
14114.2
13990.7
14127.2
14202.3
14244.2
14122.5
14151.5
14193.8
14129.5
14206.4
14187
14347.4
14292.2
14330
14343.8
14260.4
14219.8
14132.8
14270.1
14212.7
14284.6
14216.8
14233.2
14183.5
14280
14274.6
14220.1
14272.9
14467.4
14300
14274.2
14394.6
14417.3
14503.7
14496.5
14346.7
14325.5
14413.6
14413.9
14449.1
14454.3
14467.2
14448.2
14310.9
14291.2
14444.9
14458.8
14384.2
14411.7
14402.1
14463.5
14290.3
14347.5
14325.2
14358.5
14246.9
14232.7
14272.2
14126.9
14169.7
14311.1
14187.8
14098.8
14188.5
14269.3
14234.3
14133
14138.6
14137
14185
14064.7
14046.1
14129.6
14144.1
14009.8
13997.2
14110.5
14194.3
14008.6
13994.8
14086.9
14161.3
14174.9
14038.1
14028.4
14147.5
14151
14026.7
14019.3
14064.9
13982
14029.5
14095.7
14065.7
14065
13980.6
13919.6
13964.5
13909.2
14024.8
13874.3
13743.4
13745.4
13787.7
13775.3
13895.8
13866.3
13787.1
13660.8
13996.1
13934.2
13821.7
13830.4
13787.9
13793.8
13723.7
13739
13657.8
13765
13716.1
13754.9
13750.3
13835.6
13684.1
13572
13619.2
13667.9
13677.7
13851.2
13793.7
13642.2
13807
13814.6
13830.3
13828
13745.3
13784.6
13789.2
13608.4
13675
13686.2
13585.7
13721.3
13709.1
13727.9
13721.4
13614.7
13642.7
13571.2
13673.8
13576.4
13689.1
13832.8
13738.6
13738.4
13784.8
13750.1
13857.2
13800.5
13839.4
13886.5
13925.3
13948.8
13967.7
14027.4
14084.7
13989.8
14060.2
14195.1
14197.4
14046
14079.2
14113.2
13961.6
14007.8
14156.1
14041.5
14013.6
13903.9
13714.9
13775.1
13746
13729.5
13584.3
13584.6
13626.8
13518
13467.2
13532
13410.3
13334.7
13283.8
13302.5
13283.8
13256.3
13146.8
13108.8
13150.6
12992.5
13057.6
13098.1
13025.9
13050.3
13072.7
12977.4
13106.3
12994.1
12975.8
13003.1
12979.9
13092.6
13109.2
13147.1
13085
13068.3
13099.6
13107.4
13069.1
13154.6
13201.6
13178.2
13192.5
13222.4
13253.8
13293.1
13399.6
13434.8
13485
13391
13470.4
13464.4
13547.1
13691.4
13701.8
13631.2
13686.6
13629.1
13722.5
13722.5
13787.5
13945.6
14060.7
14053.7
14084.6
14165.9
14183.5
14313.1
14556
14662.3
14653
14885.6
15015.7
15258.6
15734.3
16001.4
16231.7
16679
17404.9
17808.7
18063.6
18722
18997.1
19153.1
19212.1
18921.3
18627.7
18064.7
17537.7
16936.5
16372.5
15913.1
15351.1
14809.2
14547.1
14114.4
13808.4
13644.7
13396.3
13296.4
13207.1
13049.9
12975.8
12833.1
12676.9
12901.1
12821.1
12701.6
12725.7
12676.4
12556.5
12526.9
12581.3
12640.2
12503.7
12461.1
12563.5
12390.4
12359.9
12255.9
12472.3
12336.5
12236.8
12295.2
12316.7
12315.9
12341.1
12293.7
12302.5
12314.5
12308.5
12185.4
12185.5
12206.5
12128.8
12057.2
12131.6
12060
11963.3
12081.2
11864.6
11957.3
12112.3
12027.2
12025
12039
11930.1
11915.9
11866.2
11833
11716.8
11660.3
11791
11745.3
11698.4
11698.9
11734.1
11757.9
11644.7
11703.5
11770.3
11698.4
11766.1
11856.2
11935.2
11885.6
11956.3
12015.2
11997.6
12124.7
12088.2
12002.1
12069
12187.8
12156.9
12015.9
11995.2
11867
11984.5
11947.8
11905.8
11834.1
11977.7
11961.3
11968.7
12058.4
12042.2
12190.2
12112
12099.7
12154.5
12266.7
12397.4
12525.6
12600.6
12501
12611.5
12741.1
12720.7
12542.9
12485.1
12473
12308.4
12247
12134.6
11948.5
11823.5
11795.6
11653
11438.8
11341.8
11147.4
11168.1
11138.3
10968.2
10958.4
10905.5
10844.2
10804
10636.3
10730.8
10731.2
10779
10624.2
10633.3
10707.5
10678.8
10654.8
10476.8
10658.4
10753.4
10756
10689.6
10856.1
10796.9
10746.2
10787
10738
10812.3
10921.8
10834.8
10960
10953.5
11022
11035.3
11084.7
11170.3
11215.5
11323.1
11419.8
11374.6
11522.3
11583.8
11714.3
11845.9
11977.8
12039.6
12061.5
12211.8
12385.8
12482.5
12425.3
12625.3
12770.3
12879.7
12991.7
13197.1
13364.4
13739.1
13926.5
14348.9
14814.1
15375
16122.5
17380.3
18720.5
20425.6
22489.3
24634.6
26688
28197.1
29165.1
29223.5
28484
26878.5
24950.2
22644.4
20425.4
18497.1
16706.7
15373.5
14124.5
13135.3
12478.3
11948.8
11523.4
11015.4
10704.4
10500.3
10365.3
10227
10171.4
10059.7
9995.96
9849.31
9809.18
9880.77
9580.51
9665.75
9677.4
9614.18
9605.74
9620.78
9561.84
9573.5
9530.34
9593.77
9404.31
9513.37
9443.22
9376.41
9429.62
9376.29
9265.67
9349.05
9480.55
9371.87
9297.97
9409.14
9398.19
9389.8
9378.28
9376.89
9367.28
9358.12
9427.09
9399.13
9345.43
9396.37
9331.06
9290.17
9338.34
9287.76
9377.01
9290.34
9333.18
9361.46
9356.64
9296.35
9359.35
9454.79
9334.72
9349.77
9346.1
9370.98
9276.77
9295.04
9332.52
9365.9
9290.38
9227.09
9504.6
9398.79
9333.72
9351.67
9362.57
9408.94
9416.19
9363.21
9289.05
9423.83
9325.73
9406.33
9563.19
9378.36
9377.08
9437.29
9403.05
9456.44
9498.3
9441.94
9448.23
9330.69
9337.42
9410.28
9378.71
9488.1
9400.07
9361.4
9381.33
9395.75
9372.78
9464.75
9452.75
9447.84
9407.76
9437.82
9453.97
9438.36
9560.52
9567.73
9481.1
9457.04
9508.58
9445.8
9403.87
9473.97
9485.21
1
Cu2p
1. Cu in vacuum
2020
2
9
18
34
17
0
10
Casa Info Follows
0
0
0
0
EX321_CEC356_Au Ag and Cu in O2.xy
Group: Cu in vacuum
Analyzer Lens: AngleResolvedMode22
Analyzer Slit:
Scan Mode: FixedAnalyzerTransmission
XPS
0
Al
1486.61
0
0
0
56.5
180
FAT
20
1
4.241
0
0
0
0
0
Cu2p

-1
kinetic energy
eV
456.61
0.1
2
counts
d
Transmission
d
pulse counting
0.3
3
0
0
0
0
2
ESCAPE DEPTH TYPE
d
0
MFP Exponent
d
0
11709.9
1
20073.8
20079
20048.5
20241
20171.8
20178.2
20053.1
20100.7
20214.8
20167.5
20009.7
20113.9
20111.6
20126.1
20089.3
20127.3
20062.2
20265.5
20204.3
20151.2
20174.3
20239.3
20089.7
20099.3
20197.8
20149.7
20202.2
20209.4
20169.1
20142.4
20224.7
20393.9
20335.4
20351.6
20349.6
20343.4
20270.1
20412.5
20356.7
20367.7
20361.5
20292.6
20284.3
20380.5
20386.6
20367.3
20337.6
20302.1
20330.7
20323.9
20422
20393.7
20306.6
20301.9
20511.7
20453
20331.8
20345.2
20399.2
20325.6
20377.6
20297.9
20477.7
20459
20425.8
20349.8
20428.7
20354.6
20466
20378.2
20444.6
20373.1
20395.7
20445.4
20536.4
20462.8
20479.4
20481.4
20481.7
20499.3
20483.2
20614.2
20548.2
20472
20407.2
20501.6
20616
20535.6
20533.2
20448.1
20592.5
20577.5
20714.9
20703.2
20603.2
20555
20597.9
20584.6
20768.8
20619.6
20559
20608.4
20636.8
20735.7
20706.8
20662.5
20679.1
20644.5
20605
20769.6
20639.9
20644.5
20734.1
20721.5
20712.8
20722.1
20760.2
20846.8
20953.5
20958.4
20781
20799.6
20787.3
20892.8
20879
20709.9
20752.3
20995
20955.1
20827.8
20673.7
20754.9
20981.2
20982.5
20955
20746.9
20879.2
20841.9
20753.5
20792.6
20967.9
20880.1
20876.7
20846.2
20959.1
20948.7
20862.6
20976.8
20919.2
21000.7
20983
20895.1
21036.8
21061.1
21125
21139.2
21078.4
21008.8
21051.8
21029.2
21092.9
21026
21084.1
21178.9
21080.1
21214.9
21095.2
21071.5
21096.5
21098.8
21161.7
21092.7
21153.3
21121
21127
21138
21164.6
21182.2
21182.4
21101.3
21289.8
21227.9
21232.5
21263.5
21358.7
21379.4
21226.1
21306
21257.9
21378.7
21251.4
21177.3
21267.4
21249.1
21130.8
21262.6
21306.6
21283.6
21299.9
21269.7
21432.4
21425.6
21525.8
21303
21313.5
21480.3
21464.4
21413.3
21391.1
21462.9
21531.1
21545.3
21527.3
21468.6
21454.5
21380
21470.3
21471.1
21542.1
21545.2
21532.4
21649.9
21532.9
21587.2
21565.4
21494.3
21557.7
21510.5
21412.1
21486.2
21518.6
21592.9
21524.3
21560.7
21567.8
21549.7
21540.8
21445.7
21541
21649.7
21576.9
21577.1
21631.9
21567.2
21695.8
21548.9
21430.2
21594.9
21649.3
21633.6
21667.8
21559.8
21545.9
21668.6
21512.1
21529.4
21606.6
21715.3
21669.3
21688.2
21645.2
21662.1
21576.9
21557.3
21623.7
21635.5
21699.2
21710.2
21640.9
21748.4
21734.9
21789.1
21811.8
21713.2
21670.3
21642.6
21778.9
21805.1
21825.5
21743.5
21684.1
21792.5
21818.5
21782.3
21847.1
21814
21985.4
21988.2
21945.6
21908.8
21917.7
21871.4
21926.8
21947.3
21974.2
21999.2
21800.1
21856
21901.8
21918.2
21969.2
21929.4
22006.9
22045.4
21971
22024.4
22012.3
22122
21955.2
21924.6
22088.1
21985.2
22079.5
22052.3
22149.1
22056.5
22112
22184.9
22137.4
22191.2
22176.8
22207.3
22263.5
22269.2
22233.3
22255.4
22094.4
22180.8
22292.9
22277.7
22332.1
22337.1
22360.5
22466.6
22415.5
22321.9
22419.6
22454.3
22434.9
22511.2
22414.1
22493.6
22513.7
22471.6
22502.1
22572.8
22573
22610.5
22719.6
22564.4
22752.5
22836.8
22558.9
22716.6
22729.9
22596.9
22662.4
22634.8
22670.1
22702.1
22720.8
22656.8
22706.7
22643.5
22694.7
22774.1
22690.6
22618.7
22648.3
22653.2
22538.9
22675
22644.5
22664.5
22641.1
22621.7
22572.9
22648.7
22481.7
22614.7
22692.3
22628.6
22566.3
22538.3
22661.5
22617.4
22570.7
22570.8
22580.2
22529
22488.9
22548.3
22505.6
22617.4
22562.1
22355.2
22457.7
22589.2
22542.6
22547.1
22423.3
22500.8
22592.2
22535.3
22630.4
22631.9
22674.2
22685.6
22605.7
22460.7
22597.4
22704.2
22702.4
22685.4
22664.9
22598.4
22664.6
22566.6
22564.8
22692.2
22595.2
22579.4
22720.5
22795.2
22695.8
22716.8
22636.9
22641.2
22794.2
22591.2
22757.8
22762.3
22633.3
22705.9
22743.6
22806.4
22656.3
22620.6
22696.7
22676.8
22847.8
22698.7
22740.8
22749.7
22734.3
22734.5
22827.8
22682.2
22742.4
22788.2
22679.9
22736.2
22735.2
22788.9
22810.3
22742.2
22871.2
22868.5
22811.6
22826.5
22683.3
22746.8
22706.4
22866.1
22949.8
22889.1
22928.2
22968.1
22823.1
22795.2
22876
22825.7
22773.7
22891.6
23004.4
22990.5
22915.3
23016.5
23078.5
23018.5
23078.2
22980.6
22958.1
23109.5
23027.4
23024.7
23126.5
23063.6
23103.1
23019.7
23150.3
23303.3
23118.9
23297.4
23360.5
23217.6
23313.4
23394
23363.1
23261.3
23308.2
23324.7
23275.9
23394.1
23293.7
23339.7
23333.1
23450.3
23586
23507.2
23492.8
23399.3
23626.5
23602.5
23404
23482.8
23503.9
23597.3
23682
23702.3
23649.1
23698.7
23769.9
23846.3
23998.8
23934.1
24058.8
24032.5
24100.7
24049.3
24020.8
24207.1
24225.5
24216.4
24168.4
24247.9
24461.5
24301.8
24431.2
24542.3
24592.6
24618.7
24628.3
24704.6
24673.8
24773.8
24776.6
24856
25047.9
25054.6
24884.7
25020.8
24994.6
25089.8
25089.8
25230.5
25149.5
25118.9
25069.3
25038.7
25018.1
25025.6
24953
24852.1
24930.9
24961.3
24769.4
24651.8
24596.4
24528
24480.3
24521.6
24440.5
24451.1
24497
24418.9
24352.9
24415.8
24219.9
24277.4
24296.9
24298.5
24037.6
24195
24096.8
24117.3
24317.5
24167.3
24017.9
23977
23910.7
23851.7
23953.5
23898.2
23913.4
23976.7
23932
23949.5
23847.9
23673.2
23829.4
23663.8
23757.8
23793.1
23768
23709
23715.9
23497.1
23537.9
23538.4
23378.8
23552.5
23600.8
23450.1
23431.5
23365.7
23478.2
23455.8
23380
23496.6
23455.7
23525.1
23498.3
23419.5
23467.7
23512
23497.7
23490.4
23601.2
23534.6
23498
23510.8
23598.1
23592.6
23650.4
23667.5
23737.8
23878.4
23791.5
23928.7
24037.5
24020
23941.2
24044.2
24032.1
24129.7
24078.5
24052.3
24081.8
24213.2
24317.6
24194.8
24381.3
24307.8
24205.4
24099.3
24127.3
24109.7
24035.4
24083
24154.3
24245.2
24174.8
24329.7
24370.2
24410.9
24569.5
24621.2
24720.5
24876.3
25033.4
25029.2
25040.4
25249.6
25527.9
25610.6
25796.3
25827.5
25849.6
25754.7
25777.5
25609.5
25540.3
25543.2
25354.1
25095.7
24942
24855.9
24733.2
24764.7
24474.5
24351.7
24052.2
23944.9
23752.4
23597.5
23711.6
23634.7
23408.6
23252.6
23083.4
23030.3
23038
22926.6
22827
22725.2
22728.5
22540
22557.4
22501.4
22444
22524.7
22479.5
22464.7
22290.4
22339.8
22377.2
22509.7
22564.1
22440.2
22519.1
22441.9
22421.5
22470.8
22526.2
22548.2
22602.7
22802.9
22811.5
22740.2
22739.9
22910
23002.2
22971.3
23121.1
23187.6
23306.8
23342.3
23407.6
23600.3
23799.3
23814.4
23924.6
24048
24314
24452.3
24547.2
24776.4
24979.1
25072.6
25230.3
25639.1
25736.9
25918.9
26151.4
26379.5
26553.3
26770.7
27052.6
27621.4
27918.2
28272.4
28799.7
29273.6
30199.6
30838.3
31676
32758.2
34164.6
35636.5
37210.3
39166.9
41035.1
42934.8
44542.1
45690.3
46302.4
46232.5
45434.8
43818.8
41878.4
39661.4
37383.7
35246.1
32943.5
31124.4
29420.9
28108.1
26758.8
25686.6
24807.9
24207
23517.5
23042.6
22617.9
22225
21979.3
21676.2
21504
21251.9
21110.8
20919.9
20812.8
20738.7
20650.4
20561.6
20487.9
20463.3
20374.5
20168.6
20124.3
20155.7
20023.4
19990.7
19944.3
20013.7
19910.6
19938.9
19802.7
19833
19874.9
19916.5
20040.6
19795.6
19918.8
20029.5
20009
20133.2
20130
20246
20482
20522.4
20646.3
20709.8
20799.2
20783.8
20732.6
20722.6
20723.1
20623.9
20441.8
20372.2
20285.3
20273.7
20255.1
20203.1
20266.2
20368.1
20396.2
20413.3
20519.3
20697.3
20990.4
20931.1
21135
21396.6
21707.9
21846.5
22126
22446
22574.4
22706.2
22841.4
22791.6
22858.5
22830.4
22761.9
22612
22391.5
22195.6
22130.2
21863.8
21770.4
21649.2
21546.7
21498.2
21291.5
21329.3
21279.2
21268.5
21178.8
21243.7
21247.1
21193.5
21105.5
21112.1
21207.2
21103.8
21193.3
21312.2
21173.9
21403.1
21306.5
21334
21183.1
21112.3
21095.2
20934.7
20762
20522.9
20224.3
19975.8
19780.3
19479.2
19239
19100
18809.5
18634.8
18489.4
18256.1
18143
18069.1
18084.2
18062.4
17994.2
17959.3
17857
17928.7
17944.7
17946.6
17880.4
18048.7
18221.1
18142.1
18212.1
18250.4
18300.9
18376.1
18581.3
18696.5
18788.4
18955.4
18919.6
19011.3
19266.9
19327
19445.8
19606.9
19940.6
20164.1
20381.9
20671.3
20963.7
21235.2
21728.5
21987.7
22291
22649.3
22928.3
23294.4
23731
24008.2
24363.4
24663.6
25100.4
25560.6
25965.6
26555
27066.4
27683.8
28479.6
29393.3
30559
31941
33622.9
35977.2
38988
42872.5
47965.9
54259.1
61574.9
69337.8
76660.7
82399.2
85863.3
86071.3
82831.9
76963.1
69545.2
61273.7
53298.5
45800.2
39378
34087.4
29805.5
26383.1
23839.1
21780.7
20102.1
18801.2
17708.6
16901.8
16270.5
15659.8
15189.3
14853.2
14457.3
14388
14212
14013.6
13764.8
13551.5
13443.4
13363.3
13185.4
13047.5
13004.5
12798.4
12760.8
12699.2
12666.6
12594.3
12623.6
12617.7
12440.7
12484.9
12452.1
12371
12277.4
12255.5
12252.3
12147.1
12268.4
12205.9
12180.8
12093.7
12165.4
12118.6
12150.1
12111.8
12012.4
12084.4
12154.4
11994.1
12062.9
12030.8
11956.7
11934.9
11949.7
11897.1
11899.8
11948.1
11943.8
11899.1
11865.1
11918.9
11945.2
11927.1
11879.2
11941.9
11946.1
11970.7
11822.4
11855.2
11864.6
11844.9
11845.1
11877.4
11900.8
11930.8
11794.6
11775.9
11781.4
11800.1
11722.8
11777.7
11830.6
11824.7
11846.5
11796.9
11821.9
11709.9
11739.3
11839.2
11778
11860.4
11915.1
11794.6
11773.4
11867.9
11779.2
11746.8
11727
11802
11836.5
11743.6
11816.4
11809.7
11821.3
11810.9
11883.1
11859.3
11783.8
11845.8
11802.4
11819.3
11807.5
11800.7
11858.1
11859.6
11886.4
1
Au4f
2. Au in vacuum
2020
8
27
9
8
45
0
12
Casa Info Follows
0
0
0
0
EX439_S718_Au in 25 mbar O2.sle
Group = Au in vacuum
First of group = 0
Analyzer lens = AngleResolvedMode22:1.5kV
Analyzer slit = 4:7x20c\C:mesh
Scan mode = FixedAnalyzerTransmission
Kinetic energy start = 1311.61
XPS
0
Al
1486.61
0
0
0
54.5
180
FAT
20
1
4.156
0
0
0
0
0
Au4f

-1
kinetic energy
eV
1311.8005
0.1
2
counts
d
Transmission
d
pulse counting
0.1
10
0
0
0
0
3
ESCAPE DEPTH TYPE
d
0
MFP Exponent
d
0
PROPAGATION_CONVERGED
d
1
10.8956
2.30555
45.6131
45.723
45.8114
45.552
45.8344
45.2177
44.9617
45.1421
45.1725
45.6413
45.8466
45.8464
46.3196
46.2556
45.8038
45.6359
45.567
45.1096
45.4744
45.603
46.2196
46.3934
46.0059
45.9018
46.1468
46.2978
46.272
46.0604
45.8722
46.37
46.1335
46.655
45.7642
45.7157
46.27
46.1591
46.1019
46.1795
46.0121
46.1182
46.0282
46.0015
46.5822
46.7305
46.6036
46.363
45.8328
46.2405
46.0736
46.2798
45.8003
46.0122
45.96
46.0799
46.7442
46.7366
46.1712
46.5708
46.9231
46.7127
46.3689
46.9264
46.6465
46.5951
46.9783
47.1395
46.7899
47.3304
47.0061
46.4128
47.0425
46.9484
46.9916
46.7225
46.6272
46.3349
46.6986
46.749
46.8372
47.1987
46.6742
47.1657
47.0876
47.0231
46.413
46.2137
46.6114
46.601
47.3915
46.9123
46.9942
46.9204
46.6906
47.1718
46.848
47.3707
47.5196
47.2675
46.6339
46.9293
46.8189
46.8573
46.9592
47.5461
47.292
46.8738
48.1874
48.0774
47.6361
47.1393
47.409
47.3213
46.7668
47.3542
47.4733
47.824
47.8161
47.9757
48.1635
47.6268
47.7605
47.7259
48.0075
47.8082
47.5855
47.2488
47.6921
47.1405
47.3463
47.6571
47.6579
47.5887
47.854
47.7637
47.1255
47.4981
47.5847
47.8354
47.5163
47.4071
48.1287
48.0389
47.9117
48.3805
48.2168
47.5199
47.6171
47.7834
47.8363
47.5896
47.8374
47.5934
47.967
48.0913
48.2475
48.1134
48.2864
48.0985
47.6327
48.3453
49.1088
48.4105
48.1008
48.2337
48.4227
48.6556
48.5073
48.5426
48.797
48.5172
48.8339
48.8983
48.403
48.0136
48.0055
48.4733
48.7435
48.8102
49.1229
48.926
48.8638
48.6519
49.2312
48.3998
48.9326
49.4266
48.6955
48.7635
49.1606
49.0202
49.6856
49.3715
48.8442
49.1653
49.1385
49.4429
49.4706
49.1728
49.0105
49.4186
49.2953
49.4182
49.4595
49.4161
49.5122
49.4859
49.6714
49.6063
49.2038
49.0227
49.2876
50.3271
49.5608
49.5783
49.9751
50.0091
49.7519
49.6431
50.1068
49.9719
50.0803
50.0939
49.6845
49.7448
49.5372
50.1507
50.4921
50.491
50.1516
49.8199
50.1904
50.3271
50.1307
50.536
50.505
50.0939
50.2215
50.1257
50.1942
50.2562
50.1854
50.4878
50.6299
50.4642
50.0477
50.2272
50.4471
50.5699
51.0047
50.9639
50.9269
50.6183
50.5005
50.486
50.6867
50.9334
51.0074
50.7872
50.8782
51.217
51.2089
51.655
51.3733
51.181
50.8762
50.9937
50.8076
50.9731
51.0698
50.4844
50.6566
50.8289
51.0134
51.2392
51.2986
50.4838
50.7995
50.9938
50.727
51.6851
51.2951
50.9486
50.5847
50.8609
51.248
51.0253
50.9677
50.7482
51.3319
51.0618
51.0888
51.3378
51.6154
50.8842
50.7204
51.0834
50.7496
51.407
51.1992
51.64
51.3996
51.578
51.4381
51.5857
51.5119
51.4952
52.076
52.1958
51.1802
50.5155
51.2489
51.6338
51.6373
51.2969
51.2549
51.6388
51.3204
51.7052
51.2549
51.2955
51.5349
51.7836
51.1237
51.474
51.7395
52.3759
52.0951
51.5698
52.0685
51.4615
51.5138
51.6338
51.8128
52.08
52.7748
52.438
51.8805
52.1885
51.9664
52.0582
51.4365
51.7723
51.5944
51.4329
52.3293
52.4484
52.1383
51.4729
52.3206
52.8228
52.5572
52.6829
52.8768
52.5033
52.6826
52.4747
52.5082
52.3289
51.9694
52.1257
52.3303
52.4306
52.6199
52.9516
52.556
52.509
52.7082
52.0551
52.4655
52.941
52.6057
52.7559
52.7376
53.006
53.1196
52.7401
52.6119
52.3646
51.9298
52.5899
52.4963
52.939
52.9315
53.1625
53.5581
53.3885
52.7494
53.0057
52.9848
52.8084
52.7292
53.0168
53.4873
53.3141
53.5836
53.8836
53.1533
53.6353
53.3335
53.554
53.3463
53.4845
53.7995
53.7437
53.4943
53.4381
53.673
53.3675
53.0733
54.182
53.9034
54.0445
54.2884
54.3984
54.2188
54.194
53.912
54.216
54.0288
54.0488
54.0133
54.267
53.841
54.0216
53.4644
53.6498
54.1446
54.437
54.1554
53.8666
54.1151
54.4449
54.4916
54.5352
54.0289
54.3291
54.6421
53.9632
54.214
54.8446
54.5842
54.6918
54.8541
54.3263
54.7721
55.0619
55.0485
54.8749
55.5587
54.8247
55.4737
55.199
54.8219
54.7022
55.0663
55.3539
55.4787
55.2754
55.2435
54.5467
54.9454
55.6283
55.2442
55.5736
55.0512
55.4448
55.7743
55.3839
55.7168
55.5657
55.6699
56.0594
55.7603
55.4817
55.7974
56.1332
56.0206
56.5409
56.6276
55.8252
56.0918
55.9377
55.9134
56.533
56.6582
55.9998
55.7346
56.3035
56.9216
56.5587
56.2932
56.8589
56.8821
56.7029
56.7996
56.3237
56.9641
56.77
56.814
57.0581
57.169
57.2
57.0234
57.8092
57.4499
57.8861
57.7248
58.1415
57.9765
57.2771
57.9218
57.5524
57.6587
58.4705
57.8804
58.2875
58.7786
58.1177
58.2526
58.7466
58.17
58.2884
58.6671
58.4019
58.7347
58.529
58.45
59.0906
58.7096
58.5822
58.6884
59.1494
58.8008
59.3609
59.3945
58.9152
59.6039
59.6183
59.3565
59.2294
59.4711
60.0827
59.8672
59.7327
60.0209
59.6693
59.9257
59.7522
60.0191
60.1264
60.7777
60.8579
60.5134
60.7702
60.4858
60.2865
60.6388
61.1774
60.7222
60.9091
60.7372
60.3038
60.8489
60.545
60.8991
61.4589
61.3257
60.7916
60.2244
60.4716
61.1908
60.7365
61.2963
60.6515
60.648
60.5914
60.9167
61.6393
61.6807
61.0414
60.8647
60.6902
60.7817
61.1392
60.5805
61.4837
61.518
60.9191
60.7737
61.922
61.9785
61.6542
61.4226
61.9295
62.1201
62.0487
61.988
62.076
62.3462
62.2681
61.6313
62.155
62.4061
62.5599
62.3282
62.4057
62.4663
62.4399
62.4472
62.5806
62.7114
62.9703
62.8984
62.6336
62.574
63.2771
63.0478
63.5009
63.0764
62.745
63.3884
63.9499
63.2643
63.8612
63.9735
63.551
64.398
64.2887
64.1713
64.2873
64.4029
64.0731
64.3038
64.5777
64.3205
64.7476
64.183
64.8238
65.1076
65.2277
64.8622
64.9973
64.5034
64.5682
64.8947
64.3481
64.187
64.8908
64.9358
64.6713
64.7328
64.4048
64.5661
64.4981
63.2061
64.233
63.8602
63.3141
62.6908
62.7378
63.2287
63.2517
63.6456
62.532
62.2177
62.7059
62.9627
63.1231
63.0113
62.096
61.9435
62.3074
61.4623
61.9111
62.1493
62.2158
61.4738
61.1529
60.5965
60.8865
59.9004
60.1457
59.9704
59.9559
59.7421
59.2121
59.5631
59.273
58.7945
58.774
58.4649
58.5237
59.121
59.0248
58.2841
57.965
58.0819
58.4775
58.1604
58.2517
58.383
58.0902
58.4686
58.5185
58.3509
57.8766
58.2304
58.8668
58.5463
58.4874
58.289
58.6315
58.649
58.2349
58.0283
57.7577
58.2702
58.5294
58.0438
57.8551
57.7231
57.6608
56.9653
57.1646
57.2956
56.5596
57.0774
57.2198
56.8918
56.4053
57.0167
57.1609
56.7001
57.0339
56.8278
56.8973
57.3952
57.7246
56.9783
56.3928
56.9643
56.7702
56.8318
56.1351
56.311
56.8189
56.75
56.9863
56.6066
56.4407
56.3284
56.3309
56.4712
56.3422
56.6221
55.9922
56.0439
56.0449
55.4601
55.1455
54.9188
54.1593
54.4274
54.7679
54.7521
54.1466
54.0214
53.6835
53.6414
53.6578
53.8531
53.844
53.0635
53.1773
53.3299
52.408
52.7103
53.1715
53.2019
53.1755
52.9828
52.3335
53.1199
52.352
52.2242
51.8367
51.3772
51.8614
51.929
51.2964
50.411
50.18
50.3284
50.0369
49.8857
50.0264
49.9474
49.6047
49.4501
49.5453
49.1013
49.3694
49.7609
49.0413
49.3096
49.9204
50.4702
50.6429
50.5333
49.6996
50.2069
49.6836
49.5468
49.7352
50.0845
50.7426
51.2675
51.3207
50.7721
50.4562
50.5169
50.657
50.8245
50.3951
50.3624
49.5173
49.6982
49.5597
49.3118
48.7122
48.6793
48.7474
49.5714
49.923
49.9992
50.7267
50.7457
50.674
51.5405
52.0403
52.8128
53.7429
54.3792
54.5124
54.5509
54.7204
55.3575
55.2418
55.0552
55.3296
55.6844
56.0597
56.6422
58.0217
59.8567
61.5235
64.9944
69.0673
73.1554
78.5328
86.6309
96.4519
108.951
128.409
157.105
199.044
257.837
340.67
440.492
553.037
654.631
718.928
731.901
683.321
589.574
475.769
364.364
273.912
205.049
155.294
121.554
99.2339
83.3393
73.2776
66.4598
61.023
56.8072
53.5096
51.7971
51.609
51.9936
52.6632
53.9041
56.7273
60.2926
65.4562
72.4148
82.2151
95.1209
112.466
137.648
177.387
236.105
317.411
430.215
568.566
716.465
843.29
913.966
906.007
826.237
693.093
539.484
396.206
282.651
199.985
141.463
101.449
74.1792
55.7776
43.6196
35.6172
29.9048
25.1249
21.4136
19.3707
16.5874
14.7942
13.024
11.549
10.3267
9.5516
8.9016
7.7866
6.8114
6.1908
5.73
5.0686
4.5028
4.1219
3.7654
3.1849
2.847
2.4702
2.3775
2.1114
2.0135
1.4984
1.5377
1.3501
1.3866
1.1946
1.111
1.1529
0.6671
0.4371
0.2615
0.3196
0.3068
0.146
-0.06
-0.1081
0.0368
0.1007
-0.2234
-0.2053
-0.279
-0.1347
0.026
-0.0971
-0.0086
-0.0135
-0.2813
-0.2808
-0.2203
0
0
0
0
0
0
0
0
0
0
0
0
0
0
0
0
0
0
0
0
0
0
0
0
0
0
2.30555
Au4f
2. Au in 25mBar O2
2020
8
28
6
43
27
0
12
Casa Info Follows
0
0
0
0
EX439_S718_Au in 25 mbar O2.sle
Group = Au in 25mBar O2
First of group = 0
Analyzer lens = AngleResolvedMode22:1.5kV
Analyzer slit = 4:7x20c\C:mesh
Scan mode = FixedAnalyzerTransmission
Kinetic energy start = 1311.61
XPS
0
Al
1486.61
0
0
0
54.5
180
FAT
20
1
4.156
0
0
0
0
0
Au4f

-1
kinetic energy
eV
1311.8005
0.1
2
counts
d
Transmission
d
pulse counting
0.1
30
0
0
0
0
2
ESCAPE DEPTH TYPE
d
0
MFP Exponent
d
0
2.55924
2.30555
35.8511
37.3759
36.597
34.9449
34.5239
35.5732
35.3303
35.643
35.1489
36.0654
36.8494
37.3506
36.4051
36.0521
36.0723
35.6574
35.5037
36.2663
36.6936
37.4539
37.7221
36.3876
37.4698
36.9182
35.6453
35.2349
36.9327
36.8867
35.6285
35.8251
36.2095
35.7438
35.6622
35.0215
36.0147
35.0659
35.5387
35.2382
36.3073
36.6177
36.1921
36.3493
36.0211
36.0556
36.3181
35.686
35.6767
35.7751
35.5996
36.279
36.3977
35.0537
35.5331
35.735
35.6463
34.7481
35.1684
35.1311
36.6791
35.0147
35.0362
36.4376
36.3637
35.5274
34.9943
35.6959
35.6182
34.6062
35.69
35.0459
35.4149
34.6427
34.8649
35.0042
35.1374
34.7111
36.0521
35.3126
34.7907
34.2702
33.9469
36.0489
36.4645
33.7281
34.1069
34.1524
35.2751
35.8817
35.4583
34.7706
33.639
34.6083
34.2864
35.5192
34.8111
35.0939
35.4402
36.1078
33.8335
33.1867
33.9982
34.1447
35.4248
33.4953
34.3741
33.6302
34.9437
35.267
34.7725
34.753
35.3043
34.8667
34.5591
33.5929
35.1814
35.4457
35.2169
34.8808
34.8675
34.9848
34.2121
34.7833
33.5479
33.7564
33.81
33.6924
34.1067
34.7937
32.4902
34.5541
33.7545
34.2632
33.6564
32.8395
33.6985
34.3392
33.5328
34.4425
33.9026
34.303
33.9756
33.2299
33.1332
34.2715
34.0208
35.2945
33.6472
34.0054
33.8246
33.2024
33.8131
34.416
33.9234
33.824
33.3518
34.8678
34.0645
32.546
33.227
33.7861
33.7502
33.8739
34.6843
33.6371
33.2062
33.2073
34.4044
33.4623
33.4422
32.7953
33.3407
33.4179
33.7803
33.3668
32.7997
33.9923
33.4474
33.6966
34.3378
34.5831
33.9336
33.4145
33.1817
33.5298
33.227
32.702
33.2928
34.0669
33.7824
33.5968
33.1127
33.9188
33.0222
32.513
33.1516
33.0492
31.8788
33.3729
33.9722
33.11
33.6675
34.035
33.2765
33.1227
32.6818
33.7373
33.9215
34.4317
33.0635
32.1384
32.4423
33.3454
33.6218
32.8935
33.3321
33.2412
33.2296
32.8177
33.645
32.2266
31.6981
33.0735
33.1523
32.5507
33.1907
31.8296
32.208
32.4086
31.7923
32.3002
31.6085
30.8476
31.9687
32.6762
32.559
32.2949
32.5574
32.3393
32.3676
33.0676
31.711
31.3531
31.1408
31.8761
31.6765
31.3671
31.7064
32.0591
32.9424
32.9766
32.3288
32.354
31.7224
31.905
31.5734
32.5334
31.4715
33.5049
31.4057
30.5314
32.2552
32.3558
31.4752
31.8879
30.9486
30.9117
30.8972
31.2959
31.7658
30.8256
32.0012
31.4981
30.53
30.1711
31.6581
31.5507
31.3139
30.9813
31.4398
30.6776
30.5244
30.4537
30.6776
30.9048
31.4661
30.4111
30.8899
31.3896
31.2902
31.3243
31.835
31.7808
32.4022
31.3388
31.1492
31.0784
29.3578
31.105
31.2596
29.4488
30.0971
31.2901
31.7408
32.4053
31.8791
29.8316
31.7407
30.6125
29.7181
30.1665
30.4892
30.7605
29.932
31.124
30.692
30.7532
30.9114
30.3229
30.7744
30.158
30.0779
30.417
29.939
29.328
28.7215
29.2498
30.2412
30.7226
31.3132
29.9488
30.1806
30.6024
29.7039
29.4896
29.8867
29.489
29.9993
29.3168
30.1323
29.3429
29.467
29.5335
29.3914
28.187
29.77
29.8831
29.657
29.7629
30.1541
29.8464
30.0925
28.6124
29.0944
28.602
28.3226
29.3683
30.3501
31.0095
29.432
29.3986
29.2399
28.777
28.3591
29.1406
29.166
30.2903
29.9077
29.1153
29.4468
27.7041
28.7288
29.5748
29.2535
28.9039
29.8745
29.5839
28.8493
28.8942
29.606
28.8817
28.9859
28.6497
29.1319
28.4238
27.5465
28.6115
28.6172
29.2709
29.0986
28.2057
28.1017
27.7527
28.1763
28.3124
28.2727
28.2047
28.3913
28.4972
28.8148
28.9625
27.5243
27.769
27.7718
28.4231
27.9284
27.7341
28.7617
28.6814
26.9714
28.1344
27.4201
28.1923
27.6478
28.1275
26.5922
28.2147
28.5019
27.6021
27.4455
27.2059
27.5645
27.4236
28.174
29.6085
27.532
27.4716
26.519
27.0077
26.886
27.1897
27.5169
27.6224
26.8892
26.6865
28.3977
27.4759
27.3853
26.6132
27.8728
27.7397
27.9479
27.9673
27.1743
26.7817
27.0671
26.9654
27.3196
27.033
26.5909
26.9421
25.603
27.3925
26.4722
27.593
26.8064
26.8309
26.0938
26.7549
27.9496
25.1539
26.1925
26.4848
25.8624
26.0952
26.3579
26.5275
25.8343
26.2164
26.4059
26.2093
25.9769
26.0611
25.8602
25.7054
26.0657
26.0015
25.8906
26.8235
26.5351
25.7845
26.1603
26.0696
25.2026
26.1554
26.1646
26.1934
25.5534
25.1969
25.6793
25.7178
26.0352
26.0194
25.5068
25.3072
25.1174
24.8219
24.2884
23.8266
24.9749
24.8673
25.0963
25.7606
25.2738
24.2415
25.081
24.842
23.354
24.4822
25.1407
27.284
26.4962
25.4789
24.3362
24.3549
24.4425
24.4399
23.3115
24.6686
23.6873
23.9844
24.5681
25.4276
24.6549
24.081
24.2129
24.6326
24.2811
23.6863
23.5896
24.2949
23.2471
24.471
24.1846
23.9728
24.3674
24.4556
25.457
24.0621
23.9165
24.4809
23.9019
23.9768
23.1903
23.7143
22.7889
22.6987
22.7415
23.7258
24.5331
23.396
23.5753
23.4277
23.1005
22.1522
22.8357
22.3403
21.6677
23.8068
23.5704
23.1812
21.7364
23.2774
22.8062
22.7859
22.4812
21.912
22.9098
21.734
22.6551
23.6721
23.1261
22.6079
21.7221
22.2869
23.4258
22.5512
22.4357
21.9657
21.6228
22.9019
22.5154
22.6023
21.7364
21.8572
21.9911
22.6838
22.8955
22.2828
22.5348
21.5261
22.23
21.3802
21.0673
20.9597
21.252
21.1655
21.5397
22.2925
21.4718
20.8894
20.5979
21.3056
21.1967
21.1751
21.9777
22.2081
21.5943
21.0632
20.5386
20.6266
21.1902
20.0496
20.3677
21.183
20.9118
21.0044
21.4423
21.5725
20.7544
21.2107
20.7039
19.5857
20.0674
21.479
20.3457
20.3206
20.5864
20.8255
20.6198
20.396
20.6235
19.3723
19.851
20.4977
21.1526
20.737
21.2864
20.2977
19.9915
20.8383
20.6445
20.4442
20.3772
19.8618
20.8058
20.169
19.9852
19.6707
19.9874
21.6401
20.7325
20.3854
20.1459
19.9908
20.5719
20.5356
20.2785
20.443
20.075
19.9004
20.7623
20.1819
19.446
20.1196
19.2213
19.9878
19.9351
20.5059
20.006
19.8731
19.0101
19.7238
21.4816
21.4156
19.7713
19.5502
20.0098
19.6417
19.8912
20.1361
20.6067
19.2941
20.6633
19.0215
18.9242
18.6483
19.4489
18.6991
19.0189
18.5971
19.6218
19.7865
19.4428
18.7151
19.5556
19.1403
17.6404
19.5994
19.2242
19.8885
19.515
19.8089
19.1199
18.7417
19.4049
19.0029
18.1082
19.2024
18.9756
18.8982
17.629
18.2437
18.3895
18.6615
18.3807
19.1019
18.8907
19.0292
19.2606
17.9672
17.3778
17.7871
18.0446
16.993
16.0464
17.0653
16.5118
15.691
16.3315
15.2637
15.4365
16.4203
15.9132
15.9608
16.9784
17.0624
16.381
16.0691
16.5574
16.4295
17.1679
16.4792
16.3067
16.1619
15.5944
15.1702
14.449
14.9429
14.236
14.445
15.0067
14.7408
14.4711
15.6527
14.6136
14.2308
14.2959
13.1894
13.3779
13.4648
12.875
12.0397
11.797
11.5751
11.0982
11.9183
10.9139
10.936
10.6414
11.7219
10.3725
10.9635
10.5749
11.6666
10.8797
10.665
11.4281
11.2357
11.787
12.4231
12.1594
12.6723
13.851
13.7372
13.0612
12.6636
12.9945
12.744
12.5681
11.8964
11.5955
11.2444
10.7354
10.2399
10.5452
9.70086
8.66976
8.36146
8.24876
6.96256
6.88426
7.20426
7.99706
7.14676
7.58106
7.34736
7.58586
8.18886
7.59216
6.75886
6.58376
7.51596
7.75656
7.60746
8.49746
9.01306
9.26586
8.62146
10.6709
12.0809
11.9009
11.4133
12.454
12.6863
11.5824
11.9556
12.4258
10.9951
10.5436
9.95786
10.5976
9.29626
8.23396
8.40896
7.79876
7.19116
6.97826
6.41276
6.37546
5.64576
6.30306
6.14216
5.78166
5.72196
6.25706
6.24056
4.97136
5.81246
5.42576
5.23306
5.50466
5.11596
5.70976
5.56386
5.37296
6.08336
6.09646
6.81546
6.91446
7.70136
8.36066
8.91456
9.12966
10.715
12.8931
15.9996
22.1073
29.024
35.4868
43.4754
50.1988
55.6261
53.5214
48.8066
43.6005
36.7485
28.9626
22.0406
17.1846
13.6515
10.3487
9.13506
8.24176
6.74196
5.44306
5.37596
5.83946
5.07016
4.57856
4.97946
4.62606
4.42076
4.35606
4.47866
4.80496
5.88226
5.73566
6.37696
7.99096
9.14166
11.8031
15.5714
19.6754
25.9406
34.9932
46.6535
56.9887
64.367
68.5966
67.6982
59.0602
48.0752
39.0802
30.8354
24.0967
17.3563
12.6103
8.99726
6.28026
5.27156
4.54326
3.41816
2.98046
3.12806
2.46196
2.32574
1.68546
1.56221
1.34613
1.24708
1.88185
1.59456
1.12767
1.3181
0.85109
1.03034
1.00416
0.79845
0.67364
0.85598
1.05838
0.9417
1.04684
0.69811
0.24601
0.61348
0.67414
0.68259
0.64076
0.66064
0.40305
0.61428
1.08354
0.7156
1.00391
0.4211
0.03151
0.86687
0.51781
0.47067
1.17605
1.19113
0.7082
0.49705
0.86661
1.03303
0.26656
0.30146
0.5685
0.58931
0.04385
0.29053
0.45993
0.44147
0.25689
1.16156
0.44158
0.55853
0.23352
0.30543
0.443
0.4096
0.01505
-0.06962
0.80113
0.03312
0.33745
0.5679
0.38934
0.26787
0.26494
0.13933
0.20193
0.4217
0.33673
0.36474
0.33227
0.70993
0.29381
-0.14986
0
2.30555
Cu2p
3. Cu in 4mbar O2
2020
3
14
20
56
45
0
13
Casa Info Follows
0
0
0
0
EX340_CEC356_effect of lens modes.sle

Group = Cu in 4mbar O2

First of group = 0

Analyzer lens = AngleResolvedMode22:1.5kV

Analyzer slit = 4:7x20c\C:mesh

Scan mode = FixedAnalyzerTransmission

Kinetic energy start = 456.61

Sum of 20 spectra in column containing 20 scans
XPS
0
Al
1486.61
0
0
0
54.5
180
FAT
20
1
4.156
0
0
0
0
0
Cu2p

-1
kinetic energy
eV
456.61
0.1
2
counts
d
Transmission
d
pulse counting
0.15
20
0
0
0
0
2
ESCAPE DEPTH TYPE
d
0
MFP Exponent
d
0
66.6283
3.64711
3200.58
3155.5
3194.35
3212.78
3157.33
3130.74
3093.03
3045.5
3102.43
3155.98
3169.52
3135.11
3098.46
3085.88
3143.34
3084.83
3104.68
3167.42
3148.32
3176.13
3148.29
3068.08
3133.05
3137.61
3169.38
3130.84
3026.79
3093.94
3103.57
3116.25
2990.56
3105.54
3169.35
3191.65
3105.4
3090.95
3123.22
3211.22
3158.19
3152.47
3094.98
3180
3111.58
3071.71
3129.34
3223.48
3238.31
3214.17
3142.99
3185.97
3226.59
3147.24
3122.49
3209.14
3234.89
3134.75
3152.17
3153.21
3179.49
3242.52
3212.35
3154.09
3225.02
3136.95
3110.82
3164.79
3250.52
3179.95
3188.61
3242.08
3114.1
3161.18
3231.56
3232.01
3274.49
3178.16
3143.21
3231.19
3281.18
3205.61
3224.58
3256.73
3271.96
3249.56
3371.48
3333.15
3161.18
3105.51
3269.54
3238.12
3112.62
3082.44
3147.82
3236.79
3279.22
3216.56
3160.46
3165.75
3091.01
3200.97
3217.72
3213.77
3222.41
3244.6
3166.95
3177.15
3135.39
3209.48
3217.08
3199.77
3229.52
3277.51
3272.32
3296.46
3306.48
3281.95
3169.63
3110.58
3120.34
3182.65
3239.85
3240.88
3149.24
3174.05
3155.61
3203.57
3191.87
3252.71
3220.52
3188.87
3298.28
3253.37
3302.89
3263.3
3315.05
3258.45
3318.02
3345.13
3247.52
3144.93
3204.13
3175.36
3255.11
3194.09
3318.12
3253.98
3227.9
3276.76
3281.79
3269.97
3340.55
3258.24
3228.2
3318.58
3265.69
3331.91
3257.11
3240.59
3229.05
3241.53
3272.83
3362.99
3202.49
3172.13
3222.15
3285.03
3225.51
3256.05
3318.74
3201.63
3288.78
3185.48
3244.65
3267.9
3325.04
3336.2
3370.25
3390.43
3265.13
3224.27
3311.62
3355.24
3312.9
3215.28
3315.84
3335
3277.84
3261.14
3303.12
3305.64
3294.7
3353.95
3396.89
3363.2
3322.42
3267.47
3408.8
3354.65
3325.86
3310.12
3231.98
3256.81
3359.25
3356.54
3185.8
3173.98
3271.94
3318.16
3300.56
3340.85
3293.28
3261.02
3277.87
3309.8
3330.37
3298.51
3289.48
3309.5
3385.23
3267.5
3357.34
3406
3279.11
3243.28
3304.08
3266.03
3353.44
3375.19
3370.46
3523.06
3488.74
3416.2
3411.53
3448.93
3439.57
3414.77
3288.96
3283.28
3306.72
3309.5
3304.76
3319.06
3415.62
3376.89
3321.55
3438.6
3366.95
3370.78
3313.02
3363.92
3406.86
3334.5
3260.17
3345.67
3300.73
3340.9
3303.53
3266.3
3347.47
3360.81
3373.23
3342.01
3350.68
3356.43
3291.82
3257.55
3288.03
3287.12
3228.93
3177.08
3176.68
3233.91
3286.94
3255.33
3221.52
3282.41
3273.43
3289.01
3256.09
3220.7
3284.04
3282.47
3382.45
3328.88
3269.41
3336.79
3350.47
3384.16
3399.4
3365.86
3319.26
3390.54
3376.48
3348.29
3346.93
3431.5
3304.61
3267.85
3333.6
3275.91
3363.88
3323.4
3282.74
3316.48
3247.35
3356.95
3314.61
3307.82
3305.34
3406.29
3225.4
3294.57
3379.94
3359.88
3399.63
3344.56
3330.77
3376.54
3331.67
3407.73
3433.16
3373.15
3262.24
3313.69
3368.9
3268.76
3304.21
3256.12
3141.2
3225.72
3223.15
3290.61
3241.87
3270.9
3315.15
3247.81
3381.12
3330.73
3352.34
3359.36
3353.66
3358.25
3315.77
3245.93
3288.8
3369.97
3319.15
3303
3359.69
3351.9
3389.17
3268.61
3376.53
3312.39
3373.83
3409.37
3289.62
3322.7
3340.3
3328.45
3290.65
3310.61
3317.95
3275.82
3270.4
3309.17
3297.91
3341.13
3394.37
3331.64
3284.39
3302.47
3341.94
3332.71
3302.68
3318.27
3421.1
3427.96
3316.99
3245.15
3323.2
3341.09
3278.27
3373.58
3398.73
3376.13
3299.17
3283.79
3362.84
3442.54
3478.91
3299.23
3394.82
3457.78
3442.35
3408.75
3492.91
3465.35
3493.99
3607.83
3498.16
3414.47
3295.8
3362.89
3271.64
3284.76
3351.34
3360.65
3386.22
3380.12
3321.08
3282.32
3359.6
3346.96
3257.8
3281.37
3195.53
3184.48
3345.1
3317.17
3301.77
3304
3367.36
3390.45
3404.22
3282.9
3392.96
3382.59
3474.75
3559.46
3432.25
3387.27
3372.59
3351.03
3380.31
3333.65
3347.5
3333.67
3430.12
3400.03
3347.29
3316.68
3279.11
3303.81
3291.25
3216.23
3322.23
3303.06
3311.79
3310.47
3307.24
3321.64
3288.45
3261.37
3239.49
3211.95
3218.35
3207.4
3243.29
3246.75
3198.57
3168.65
3247.5
3352.4
3345.47
3295.92
3245.07
3314.07
3257.51
3228.52
3414.88
3434.09
3485.1
3517.86
3558.08
3532.62
3537.93
3569.54
3459.7
3450.18
3545.27
3546.1
3684.29
3685.51
3665.64
3537.91
3526.78
3420.39
3334.43
3350.28
3302.13
3281.72
3436.47
3370.13
3289.17
3364.8
3410.69
3301.5
3176.07
3206.03
3287.97
3320.32
3247.7
3281.21
3188.64
3196.26
3258.84
3225.17
3289.63
3208.17
3172.96
3186.15
3124.66
3260.88
3242.22
3153.39
[...]
4539.74
6643.05
5914.09
2813.28
906.917
1
Survey
3. Cu in 4mbar O2
2020
3
14
20
50
43
0
13
Casa Info Follows
0
0
0
0
EX340_CEC356_effect of lens modes.sle
Group = Cu in 4mbar O2
First of group = 1
Analyzer lens = AngleResolvedMode22:1.5kV
Analyzer slit = 4:7x20c\C:mesh
Scan mode = FixedAnalyzerTransmission
Kinetic energy start = 286.61
Sum of 20 spectra in column containing 20 scans
XPS
0
Al
1486.61
0
0
0
54.5
180
FAT
20
1
4.156
0
0
0
0
0
Survey

-1
kinetic energy
eV
286.61
0.5
2
counts
d
Transmission
d
pulse counting
1
1
0
0
0
0
2
ESCAPE DEPTH TYPE
d
0
MFP Exponent
d
0
2.24647
170.919
182.971
214.542
214.288
183.176
214.961
210.567
188.512
208.632
218.861
215.258
205.259
200.604
192.585
224.671
221.854
220.498
227.356
219.448
225.867
222.712
243.373
240.462
255.074
241.225
233.433
237.456
247.94
251.29
242.107
273.054
270.618
244.532
249.803
276.398
255.418
252.435
256.145
253.681
281.098
270.257
270.962
293.853
286.274
268.055
273.627
282.458
272.167
289.162
296.743
289.805
301.835
310.017
302.897
297.495
302.806
293.847
301.415
274.393
314.26
338.607
316.981
349.15
336.438
332.264
322.987
321.498
301.245
317.464
341.768
353.78
292.657
339.551
323.402
355.05
368.609
335.066
338.933
360.67
349.954
389.388
358.177
363.872
389.235
379.728
401.65
384.387
366.856
410.788
396.931
378.498
408.647
395.674
427.451
417.459
390.374
402.236
439.384
426.582
401.604
459.191
463.25
434.426
435.662
415.625
435.99
431.643
459.719
467.751
464.559
451.744
463.711
463.903
454.013
513.374
490.223
481.955
470.415
501.059
531.85
469.485
486.689
513.164
491.285
492.249
515.563
543.638
535.87
497.496
522.461
501.46
551.097
538.485
565.813
535.589
549.35
555.301
561.741
579.652
562.76
573.481
575.918
601.693
555.784
558.026
591.19
593.523
585.789
639.066
572.961
599.034
611.769
568.095
606.767
602.387
636.861
603.573
635.607
654.876
622.096
636.347
645.578
659.591
687.926
603.406
673.655
647.644
641.922
682.393
675.277
642.496
707.259
664.41
731.922
669.387
673.872
682.925
639.013
671.935
708.366
709.267
700.434
683.345
674.979
655.027
673.234
709.972
726.827
728.889
675.946
718.068
722.611
720.391
718.641
687.83
711.541
743.724
707.138
742.449
708.737
710.431
717.242
703.982
692.931
691.78
737.544
762.717
770.617
735.803
771.48
731.057
713.695
741.867
742.667
714.219
717.1
749.788
779.293
782.428
762.699
705.531
688.45
730.927
700.557
673.82
725.074
683.566
683.54
692.012
738.667
658.562
744.73
747.176
698.204
677.17
702.88
691.54
666.375
708.351
673.851
648.403
698.325
662.375
681.59
668.952
681.755
721.922
798.538
755.934
708.554
706.109
707.719
669.805
671.337
651.712
666.499
679.939
630.24
672.195
663.512
672.135
629.493
623.182
639.17
657.937
659.41
746.256
1040.88
708.958
658.974
588.851
639.442
640.506
646.153
650.51
682.533
664.494
638.133
647.068
667.101
687.673
635.345
652.978
688.07
686.114
690.484
697.115
699.474
684.751
712.562
673.834
695.079
726.746
735.069
694.87
744.755
726.733
756.331
746.99
759.213
728.651
686.41
724.399
772.401
776.98
761.711
758.135
764.139
784.404
755.764
756.799
777.204
796.013
787.75
826.797
808.387
790.071
788.302
828.776
825.021
824.352
836.278
833.373
786.461
869.479
849.062
885.873
886.253
881.072
857.456
918.236
868.358
885.401
896.676
874.324
919.265
861.283
875.226
889.86
902.051
966.165
924.092
924.211
954.979
952.813
910.222
962.122
972.421
928.759
956.275
962.791
946.15
982.552
938.403
997.62
963.755
991.45
1004.33
1050.83
975.83
985.816
1046.77
958.987
1021.26
1036.36
1014.23
1005.42
1059.24
1013.91
1082.84
1016.61
1025.39
1043.97
1101.89
1092.42
1088.03
1086.74
1073.88
1112.46
1086.41
1071.28
1100.73
1135.24
1161.04
1140.13
1076.13
1105.27
1138.69
1132.81
1129.13
1134.64
1157.66
1136.26
1151.1
1201.59
1141.56
1170.31
1114.9
1232.06
1160.93
1148.68
1210.35
1168.64
1159.13
1222.82
1216.1
1195.19
1187.14
1216.8
1295.61
1241.12
1254.88
1214.24
1255.63
1257.41
1230.81
1239.7
1278.21
1247.28
1279.06
1278.49
1290.59
1264.68
1269.94
1284.54
1265.8
1296.29
1278.36
1293.67
1277.88
1310.4
1317.14
1291.13
1337.7
1307.4
1375.33
1310.01
1380.03
1348.05
1374.93
1360.99
1362.38
1327.59
1336.31
1381.61
1390.27
1368.51
1339.67
1370.47
1415.82
1343.5
1393.25
1376.59
1346.93
1379.47
1299.43
1356.91
1393.81
1399.84
1375.21
1360.5
1401.31
1429.74
1363.29
1402.55
1361.05
1442.72
1394.94
1344.99
1380.85
1322.07
1372.01
1372.42
1347.13
1384.26
1426.64
1427.3
1403.24
1350.15
1369.52
1334.42
1407.25
1392.84
1404.63
1418.33
1378.2
1374.74
1413.12
1385.16
1313.3
1381.02
1370
1323.03
1331
1337.49
1356.19
1383.18
1349.37
1348.89
1328.53
1393.2
1355.02
1383.73
1398.4
1412.95
1341.53
1405.07
1376.77
1399.32
1313.37
1337.11
1335.17
1386.61
1386.76
1352.47
1390.9
1375.92
1331.57
1394.32
1356.13
1302.11
1372.82
1417.28
1343.62
1392.17
1370.72
1380.83
1368.61
1323.97
1368.92
1411.66
1347.94
1309.76
1338.07
1358.47
1363.67
1397.48
1350.43
1360.15
1363.18
1332.28
1375.16
1269.71
1325.84
1293.91
1327.92
1331.25
1295.56
1349.37
1355.41
1458.25
1353
1380.95
1353.51
1232.28
1298.11
1238.22
1267.35
1143.64
1251.64
1282.89
1279.84
1184.53
1223.57
1217.79
1162.34
1187.99
1190.31
1231.79
1192.6
1195.21
1203.08
1190.39
1141.64
1189.27
1179.69
1124.79
1171.03
1134.75
1132.61
1167.91
1103.32
1171.44
1167.42
1140.08
1124.55
1179.5
1136.95
1155.75
1191.44
1108.99
1126.65
1168.87
1154.75
1110.23
1149.93
1111.63
1067.23
1128.68
1096.68
1139.28
1070.34
1120.53
1097.11
1124.8
1033.21
1102.32
1134.05
1105.08
1100.68
1167.84
1129.15
1097.49
1061.48
1067.67
1072.91
1071
972.77
1013.11
1050.99
945.071
990.233
980.451
975.318
1029.81
995.812
1009.05
996.027
1078.65
1159.54
1206.76
1228.56
1170.39
915.075
925.175
836.683
796.509
772.119
786.962
740.611
735.119
728.431
704.024
700.284
715.312
662.283
592.448
562.774
555.008
588.059
659.443
789.681
817.023
584.682
429.225
369.528
347.332
352.431
405.303
945.375
1723.37
2219.58
383.582
338.811
338.414
330.959
360.281
376.261
470.462
540.607
387.672
324.552
343.009
329.165
347.048
313.043
320.737
296.728
301.482
296.331
323.237
321.55
357.441
301.56
310.349
321.853
336.813
304.862
323.349
292.817
305.131
336.923
345.065
338.425
306.807
317.221
304.043
307.28
321.687
339.895
327.663
298.505
319.579
326.135
335.825
356.836
345.044
334.643
344.681
340.467
337.309
351.036
344.164
373.053
349.109
351.006
356.973
324.394
353.158
370.82
347.943
339.762
322.168
311.806
348.957
372.504
345.535
384.87
359.358
374.333
349.257
334.955
391.478
331.495
357.089
348.433
378.523
384.922
375.581
371.819
364.389
351.163
370.864
374.739
357.615
342.934
422.02
386.049
380.479
356.991
362.274
371.115
358.399
394.061
389.161
360.868
366.866
357.058
353.47
410.415
408.315
432.108
401.457
402.702
385.837
397.618
381.873
378.431
381.599
396.653
399.56
394.869
412.317
409.423
448.953
403.529
404.786
385.286
398.136
422.043
374.064
441.734
378.18
420.284
365.804
376.624
420.593
425.296
400.224
430.307
402.943
395.04
420.545
405.598
436.407
451.45
435.333
445.778
411.459
434.428
448.248
411.324
449.855
414.08
405.19
413.803
397.061
449.135
401.577
438.32
417.538
438.492
437.973
480.029
425.36
429.747
449.469
434.142
470.398
445.545
419.039
475.841
456.831
411.046
411.669
492.733
476.274
442.971
432.617
463.659
466.299
475.415
460.059
453.676
466.293
482.714
479.8
485.301
420.454
504.328
511.638
485.655
448.697
493.149
437.667
493.172
508.596
480.724
486.613
479.375
473.09
486.06
490.708
489.823
500.994
500.604
469.055
498.371
483.467
507.684
506.163
466.413
507.953
518.694
481.445
495.541
480.419
508.023
521.993
519.53
506.46
536.401
515.811
559.324
512.492
544.721
535.976
513.332
536.503
537.95
567.174
539.027
525.701
501.282
514.157
556.593
552.21
504.3
541.06
587.856
542.979
553.706
551.592
551.551
572.488
505.852
557.958
560.021
579.024
565.746
528.719
579.203
536.741
584.829
568.711
559.964
539.992
568.221
587.65
572.849
569.742
629.112
596.514
590.941
595.187
637.828
601.76
550.436
549.686
534.628
611.042
587.22
567.939
558.206
551.742
545.939
555.509
576.155
553.8
582.173
603.811
579.933
576.853
560.034
581.018
565.405
580.612
606.334
590.471
634.557
618.194
587.189
601.885
623.683
596.242
620.327
620.953
624.526
629.5
667.907
628.355
618.28
621.368
584.6
625.514
625.128
611.843
613.35
656.377
636.767
622.285
664.244
617.854
576.64
636.001
649.012
672.097
620.082
616.109
625.61
660.838
667.503
687.965
671.985
650.008
665.372
641.147
658.186
660.345
650.567
687.941
662.1
719.524
728.813
657.034
648.961
714.329
706.672
674.341
703.546
686.67
695.116
674.542
681.167
718.497
672.042
709.68
683.651
683.209
709.159
691.816
713.932
700.354
659.938
727.578
773.128
765.001
724.906
754.983
715.916
757.668
703.997
716.894
713.528
751.488
701.191
720.255
685.329
764.013
785.057
787.614
773.638
736.775
733.959
703.719
755.779
723.081
737.847
720.764
740.87
740.588
682.5
732.451
765.184
736.658
728.83
724.992
715.863
746.392
738.067
747.503
708.903
795.12
772.222
808.855
743.133
749.639
720.815
741.814
719.841
722.291
738.268
762.7
786.638
725.139
732.09
818.738
775.016
788.658
747.575
756.497
766.215
726.915
781.843
745.509
697.464
716.33
734.001
752.947
724.151
674.424
685.263
654.663
717.107
739.484
761.621
803.221
962.877
874.476
711.306
662.856
638.04
680.725
618.691
650.29
650.737
679.305
645.2
606.993
646.689
625.521
576.735
601.132
635.674
611.803
556.457
608.119
612.197
610.072
587.785
645.676
623.207
617.336
563.124
595.656
564.869
645.652
567.501
540.256
515.366
516.04
456.684
454.222
419.416
474.48
429.031
439.929
437.172
417.97
422.502
410.758
619.673
787.95
791.235
1028.74
942.599
476.115
385.366
276.162
251.531
215.655
200.541
207.752
192.668
199.718
201.014
170.804
188.562
187.08
200.086
187.988
199.615
194.287
200.293
181.706
175.426
196.191
181.451
183.741
193.127
200.213
168.778
170.295
185.35
194.801
199.549
173.738
202.818
195.04
152.402
187.802
164.479
193.085
175.702
216.108
224.376
194.631
170.885
178.241
187.851
153.201
210.429
152.805
168.657
156.012
173.298
192.379
194.801
158.192
266.116
208.006
130.387
131.291
132.278
127.216
106.51
127.38
127.66
118.259
82.7352
65.4443
77.2792
88.8495
77.2363
117.3
231.034
467.949
492.863
108.508
40.1445
2.24647
Survey
3. Cu in vacuum
2020
3
15
3
44
58
0
13
Casa Info Follows
0
0
0
0
EX340_CEC356_effect of lens modes.sle
Group = Cu in vacuum
First of group = 1
Analyzer lens = LargeArea:1.5kV
Analyzer slit = 4:7x20c\C:mesh
Scan mode = FixedAnalyzerTransmission
Kinetic energy start = 286.61
Sum of 20 spectra in column containing 20 scans
XPS
0
Al
1486.61
0
0
0
54.5
180
FAT
20
1
4.156
0
0
0
0
0
Survey

-1
kinetic energy
eV
286.61
0.5
2
counts
d
Transmission
d
pulse counting
1
1
0
0
0
0
2
ESCAPE DEPTH TYPE
d
0
MFP Exponent
d
0
2.24647
16601.3
16609.2
16615.6
16453
16654.3
16579.3
16833.4
16874.9
16752.4
16855.3
17125.8
17072.1
16828.2
16920.8
17121.8
16935.4
16865.4
17102
16974
17139.1
17333.1
17165
17155.1
17252.9
17057
17125.7
17199.4
17277.5
17227
17311.4
17203.4
17555.5
17458.2
17590
17462.8
17277.6
17458.7
17542.2
17651.6
17535.7
17470.4
17645.4
17570.6
17820.8
17738.7
17853.5
18025.4
17778.7
17742.1
17819.1
17776.1
17915.2
18104.3
17977.9
18144.6
17946.8
17810.4
18168.6
17926.2
18078.1
18309.2
18252.6
18121.9
18251.5
18152.6
18382.9
18097.6
18402.3
18668.4
18434.7
18491.9
18537.1
18626.1
18413.5
18720.3
18660.3
18482.5
18452.6
18603.5
18869.2
18491.2
18710.5
18849.6
18849.9
18882.4
18871.9
19035
19029.4
18917.2
19051.4
19078.6
18887
18968.7
18955.1
19076.5
18999.1
19123.9
19337.7
19394.8
19788.6
20089.8
20455.3
20853.1
20935.4
20548.5
19873.6
19340.3
18723.3
18663.2
18614.5
18502.3
18339.2
18215.6
18370.3
18273.7
18036.6
18114.4
18133.8
18188.4
18262.5
18272.8
18467.3
18308.2
18015.3
18124.1
18306.2
18342.2
18377.8
18342
18361.2
18698.7
18512.3
18435.8
18633.7
18560
18528.5
18726.7
18548.7
18693.3
18510.4
18649.6
18640.6
18969.8
19007.6
18941.2
18929.9
18929.7
18861.5
19111.9
19186.4
19216.6
19362.8
19247.2
19156.8
19211.4
19327.7
19311.7
19217.5
19350.4
19425.7
19504.9
19511.6
19537.9
19504.2
19695.4
19606
19789.3
19905.1
19648.9
19657.2
19953
20011.6
19935.5
20127.3
20156.1
20331.5
20247.4
20223.6
20067.4
20300.5
20262.4
20537.2
20509.9
20803.3
20555.2
20559.2
20822.2
20842.1
20891.9
21028.2
21053.7
21095.5
21144.6
21058.2
21136.4
21240
21358.5
21681.9
21481.6
21825.1
21766.1
21811.4
21709.7
21908
21934.1
22200.4
22014.9
21974.2
22268.8
22095.8
22226.7
22341.1
22148.3
22217.1
22332
22370.6
22411.6
22652.5
22849.9
22695.3
23044.5
23292.5
23570
23858.1
24275.6
24207.8
23689.3
23435.6
23524.1
23188.5
23280.2
23021.7
23007.1
23071.2
23540
23378.8
23064.7
22958.7
22316.7
22038.7
21752.3
21735.1
22132.8
22350.2
23253.5
24932.2
30579.7
46321
30270.3
22221.9
20290.3
19712.9
19936.1
20391.2
19722
19981.2
19572.3
18408.4
17681.6
17359.9
17013
17048.8
17379.1
17658.3
19604.2
21522.4
37455
83275.8
24647.2
14613.6
12868.7
12015.4
11862.6
11856.5
11723.7
11609.9
11608
11807.3
11486.8
11538.9
11645.3
11765.7
11723.4
11588.7
11753.5
11599.6
11665.7
11589.8
11831.5
11750.5
11856.3
11924.2
11622.9
11916.4
11960.6
11880.4
11829.9
11841.9
11962.3
11900.1
12006.3
11936.3
11983.6
12050.1
12025.1
12014.6
12030.7
12062.5
12119.5
12053.4
12151.2
12205.8
12188.2
12039.3
12325.8
12297.1
12209
12298.2
12457.4
12494.3
12522.8
12377.8
12500.6
12424.9
12433.6
12414
12477.7
12551.5
12405.3
12760.8
12725.9
12667.4
12836
12604.6
12683.8
12688.6
12756.5
12844.4
12822.3
12693.7
12808
12878.3
12864.1
13042.7
13054
12877.2
12857.5
13037.5
12893
13165.8
13002
13000.8
13201.1
13224.8
13172.5
13230.4
13197.4
13238.3
13375.9
13385.7
13395
13360.7
13339.2
13394.7
13560.3
13447.3
13656.3
13592.4
13602.2
13648.1
13661.7
13827.3
13624
13729.7
13611.4
13842.1
13875.2
13939.7
13823.3
13913.8
13846.5
14131.1
14160.2
14313.5
14110.4
14153.2
14043.5
14196.8
14218.5
14467
14302.6
14518.3
14398.2
14503.5
14535.2
14683.4
14426.2
14487.7
14718.9
14786.4
14745.5
14764.8
14632.5
14916.8
14944.1
14979.2
15015.7
15008.7
15040.4
14983
14960
15188.5
15302.4
15308.7
15175.7
15284.3
15475.6
15500.3
15594.9
15590.5
15649.1
15739.6
15740.8
15988.3
16024.8
16034.1
16142.2
16225.1
16205.4
16258.2
16278.4
16270.7
16073.7
16260.1
16267.8
16022.4
16136.5
16263.8
16247.1
16566
16419
16522.3
16549.7
16764.4
16525.1
16652.5
16369.5
16325.5
16032.1
16307.2
16465.8
16278.9
16459.6
16138.5
16457.7
16555.1
16476.3
16746.3
16517
16691
16644.5
16919.8
16752
16993.9
17109.4
17019.3
17230.5
17141.6
17353.9
17225.7
17485.6
17416.2
17777.8
17630.6
17749.4
17954.6
18061
18264.9
18431.8
18729.7
18611.4
18315.6
18235.4
18018.3
17841
17776.4
17933.2
17759.1
17150.4
16618
16048.5
15406.7
15110.6
14914
14762.2
14699.1
14729.3
14721
14614.8
14575.7
14472
14703.6
14529.3
14498
14418
14446.2
14504.1
14419.3
14358.2
14251.1
14412.2
14277.2
14266.3
13854.2
13855.4
13848
13937.5
13839.8
13852.1
13762.9
13978.4
14104.7
14335.9
14242
14244.3
14174.4
14213.4
14339
14563
14519.5
14606
14695
14663.3
14808.6
14693.5
14846.9
14753
14984.2
15059.3
15223.6
15435
15620.9
15861.5
15978
15976
16034
16113.5
16317.1
17024.9
17907.6
18423.4
18748.2
18240.8
16681.7
15837.4
14898.4
15013.5
15360.9
15725.6
15639.8
15091.1
14046.9
13259
12697.3
12253.7
11853.2
11818.5
11409.7
11708.1
11801.4
11824.2
11437.8
11357.3
11023.2
10602.7
10605.9
10258.9
10311.4
10338.6
10337.2
10086.2
9824.08
9791.62
9801.49
9813.06
9856.48
9639.17
9823.36
9811.2
9885.19
9947.18
9888.76
10012.6
9961.69
10140.7
10120.8
10098.7
10410.4
10133.5
10527
10334.1
10600.2
10449.3
10661.4
10643.3
10770.1
10828.8
11031.4
10929.4
11139.5
11181
11195.3
11126.1
11303.4
11269.6
11284.1
11271.4
11206.6
11577.1
11656.1
12017.1
12300.8
12429.2
13017.4
13562.2
14194.3
15131.4
16096
16965.2
20107.6
20943.6
22881.1
18594.8
12500.5
11770.5
9239.2
7566.92
6935.49
6679.08
6613.6
6313.62
5956.38
5873.6
5736.71
5610.93
5878.34
5956.77
6129.59
6212.29
6371.88
6553.72
6723.84
5470.98
4443.28
3992.4
3451.3
3134.32
3100.33
2850.08
2876.4
2758.1
2617.58
2626.12
2718.65
2679.99
2858.35
3375.33
5139.3
7883.53
9004.27
3298.16
2186.75
2064.48
1970.71
2083.43
2080.15
2072.6
2042.8
2027.52
2038.67
2003.12
1968.99
1996.12
1967.72
1919.13
1988.18
2004.19
1955.81
1972.06
2022.34
1952.95
1998.88
1931.46
1982.83
2009.71
2051.23
1989.39
2014.15
2034.17
2004.46
2021.08
2077.62
2037.34
1990.41
2066.6
2014.59
2056.68
2031.21
2020.27
2102.13
2106.57
1988.61
2024.1
2042.36
2021.45
2037
2023.81
2111.9
2084.79
2128.55
2019.42
2041
2085.9
2044.56
2037.84
2062.07
2032.21
2077.54
2028.64
2088.81
2010.19
2031.6
2101.88
2063.55
2084.66
2057.86
2058.51
2099.9
2048.7
2091.61
1983.97
2086.43
2109.18
2069.99
2050.6
2052.44
2088.29
2070.29
2076.41
2008.2
2113.3
2102.63
2123.8
2129.18
2062.38
2072.98
2063.98
2167.95
2109.25
2166.33
2214.25
2116.95
2139.87
2154.27
2127.55
2186.44
2127.04
2110.19
2224.82
2121.43
2223.88
2172.05
2152.48
2163.24
2237.13
2180.89
2206.55
2220.36
2182.9
2198.14
2171.43
2281.13
2157.6
2246.43
2250.11
2217.27
2249.9
2108.96
2218.45
2254.99
2289.43
2306.74
2326.89
2249.69
2316.08
2259.14
2325.12
2281.52
2211.08
2288.93
2316.27
2360.69
2335.48
2340.96
2196.44
2256.52
2213.91
2229.96
2249.79
2276.99
2234.03
2244.72
2308.17
2266.29
2199.13
2213.61
2180.06
2257.33
2197.9
2189.11
2252.63
2229.58
2274.57
2264.01
2265.94
2298.26
2414.55
2277.6
2288.2
2231.79
2337.22
2413.27
2277.13
2325.22
2303.39
2245.83
2362.48
2297.15
2226.61
2257.56
2409.66
2290.68
2380.78
2307.72
2391.68
2323.89
2376.54
2306.22
2369.29
2337.33
2326.95
2370.23
2335.79
2397.24
2377.93
2452.69
2423.32
2449.8
2415.02
2448.67
2420
2454.87
2464.61
2344.51
2406.74
2450.55
2390.91
2519.71
2496.05
2436.89
2449.89
2433.55
2504.25
2459.62
2481.89
2547.29
2477.53
2519.98
2532.35
2510.28
2502.64
2492.2
2602
2480.99
2518.19
2520.05
2521.74
2539.71
2516.42
2469.72
2626.15
2483.24
2677.41
2601.24
2619.28
2629.56
2499.21
2591.81
2641.37
2484.77
2590.5
2609.94
2594.81
2569.79
2590.47
2528.29
2525.83
2497.45
2591.5
2670.79
2801.61
3157.38
2959.09
3281.46
3673.8
3033.84
2619.83
2544.94
2616.88
2620.5
2675.18
2617.03
2543.74
2560.02
2670.4
2574.11
2596.19
2651.77
2623.4
2649.78
2699.34
2691.96
2574.83
2605.45
2612.57
2689.14
2670.12
2580.02
2609.9
2673.4
2644.46
2693.94
2638.97
2675.57
2693.48
2676.18
2715.83
2660.54
2627.77
2732.09
2692.79
2663.11
2733.43
2814.65
2777.92
2837.9
2842.1
2950.19
2951.84
2748.32
2731.48
2619.63
2805.09
2639.81
2741.99
2662.42
2731.79
2782.01
2775
2773.36
2777.05
2797.65
2873.23
2888.98
2762.64
2852.79
2755.02
2808.16
2809.42
2847.47
2916.84
2930.44
2867.87
2846.19
2828.11
2909.21
2888.7
2882.47
2858.56
2880.81
2931.02
2877.32
2899.69
2955.76
2965.53
2985.99
2849.55
2963.15
2967.61
2964.77
3022.27
3001.44
3079.37
3014.57
3062.98
3017
3001.48
3006.27
3032.49
3082.69
3000.18
3030.24
3007.91
3145.73
3063.39
3186.96
3091.59
3072.52
3080.74
3142.21
3214.14
3157.91
3248.03
3269.46
3233.06
3141.6
3186.78
3155.1
3188.73
3226.3
3292.92
3310.68
3270.42
3404.01
3261.26
3343.94
3362.28
3465.62
3378.81
3324.82
3355.46
3332.6
3422.63
3412.41
3402.57
3464.71
3442.71
3448.04
3474.88
3589.79
3556.26
3542.74
3565.19
3516.31
3636.94
3631.56
3665.93
3656.6
3758.46
3673.16
3592.46
3722.59
3703.44
3728.61
3732.68
3624.59
3732.62
3684.71
3797.89
3690.16
3644.26
3755.5
3774.63
3925.56
4236.65
4761.67
6313.72
7858.59
6201.33
4301.54
3675.48
3368.33
3291.69
3271.82
3220.31
3221.56
3224.55
3076.13
3153.65
3134.46
3222.96
3184.26
3307.18
3307.27
3301.78
3352.33
3316.68
3439.15
3389.68
3458.59
3461.67
3489.09
3503.52
3528.49
3594.52
3523.8
3512.2
3430.89
3212.93
3195.62
3149.89
3246.01
3053.49
3074.94
3082.32
2952.31
2955.51
3005.23
3151
3715.1
4530.06
6528.44
9038.17
8997.2
11327.1
9328.46
4626.13
2563.39
1751.22
1367.19
1172.5
1068.97
993.618
885.939
843.174
876.948
778.079
767.808
816.499
777.974
787.381
784.848
766.005
788.592
785.683
694.734
788.28
771.603
774.112
780.465
776.062
783.486
762.977
737.035
742.654
794.684
801.223
771.559
775.89
795.939
801.389
802.752
823.062
825.95
793.084
839.11
831.81
841.839
829.866
896.142
915.567
876.262
880.451
976.377
983.151
983.445
1023.26
1052.92
935.334
867.737
798.618
830.224
827.629
855.393
877.844
819.453
839.092
703.715
729.218
716.817
678.298
730.586
879.577
1007.19
1390.03
2826.39
5490.86
4646.53
1104.77
346.701
2.24647
end of experiment