File: data/Ag_test.vms
VAMAS Surface Chemical Analysis Standard Data Transfer Format 1988 May 4
Not Specified
Not Specified
Not Specified
Not Specified
9
Casa Info Follows CasaXPS Version 2.3.20rev1.2G
0
Created by SpecsLab Prodigy, Version 4.63.4-r87993
SourceAnalyserAngle: 56.500000 d
CasaRowLabel:Ag in vacuum
CasaRowLabel:Ag in vacuum, short shirley
CasaRowLabel:Ag in vacuum, long shirley
CasaRowLabel:Ag in vacuum, short shirley, background subtr.
CasaRowLabel:Ag in vacuum, long shirley, background subtr.
NORM
REGULAR
1
1
Exp Variable
d
0
0
0
0
5
Ag3d
Ag in vacuum
2020
3
6
22
14
31
0
15
Casa Info Follows
0
0
1
CASA region (*Ag 3d*) (*Shirley*) 1039.11 1134.11 17.742184 2 0 0 833.83732 -450 0 0 (*Ag 3d*) 107.878 0 18.04
0
EX340_CEC356_effect of lens modes.sle
Group = Ag in vacuum
First of group = 0
Analyzer lens = LargeArea:1.5kV
Analyzer slit = 4:7x20c\C:mesh
Scan mode = FixedAnalyzerTransmission
Kinetic energy start = 1036.61
Sum of 8 spectra in column containing 8 scans
C:\Users\pielsticker\Lukas\MPI-CEC\Projects\Gas phase background\inelasticscattering\data\N2\Au, Ag, Cu in N2.vms
XPS
1
Al
1486.61
0
0
0
54.5
180
FAT
20
1
4.156
0
0
0
0
0
Ag3d

-1
kinetic energy
eV
1036.61
0.1
2
counts
d
Transmission
d
pulse counting
0.8
1
0
0
0
0
2
ESCAPE DEPTH TYPE
d
0
MFP Exponent
d
0
111.645
2.57029
7149.55
7212.09
7195.03
7215.52
7267.75
7148.26
7226.14
7304.93
7204.99
7220.56
7208.82
7201.59
7187.93
7311.09
7308.51
7281.85
7162.46
7162.77
7185.3
7240.53
7218.2
7170.12
7262.42
7181.35
7228.18
7201.42
7179.44
7141.15
7277.27
7186.11
7295.79
7253.32
7103.66
7131.25
7196.36
7281.68
7265.37
7173.95
7122.64
7196.81
7135.75
7118.88
7160.16
7214.67
7232.26
7167.63
7138.52
7193.3
7214.42
7120.75
7269.19
7321.18
7241.45
7269.88
7268.3
7088.43
7228.36
7276.47
7226.6
7114.05
7259.36
7275.82
7235.9
7116.11
7106.91
7187.5
7093.35
7172.08
7241.22
7185.28
7342.22
7337.72
7134.49
7303.82
7315.21
7207.65
7254.06
7172.87
7244.6
7223.47
7176.53
7158.85
7117.1
7173.21
7169.34
7322.11
7284.14
7246.46
7232.75
7311.4
7323.81
7093.13
7316.31
7209.1
7226
7255.26
7251.01
7239.68
7240.28
7263.9
7204.9
7179.2
7141.89
7238.73
7182.47
7248.01
7203.22
7115.56
7210.98
7209.8
7218
7293.85
7175.5
7208.09
7270.91
7180.85
7244.65
7141.78
7183.69
7214.23
7278.79
7117.48
7133.17
7338.38
7291.99
7252.58
7335.14
7328.65
7280.55
7246.18
7178.48
7197.48
7329.31
7084.13
7160.21
7193.21
7188.21
7345.19
7151.73
7191.87
7208.96
7264.74
7237.55
7154.63
7203.66
7259.92
7260.44
7123.22
7170.79
7239.03
7199.52
7327.29
7197.6
7201.9
7333.75
7325.55
7363.27
7217.66
7303.28
7278.45
7394.81
7273.76
7212.64
7178.06
7269.92
7373.08
7266.95
7329.56
7269.66
7378.94
7336.63
7193.82
7272.37
7110.33
7192.26
7278.2
7308.19
7200.82
7200.19
7157.76
7201.63
7243.55
7253.36
7088.15
7311.4
7245.2
7240.1
7285.79
7288.19
7260.64
7192.3
7193.73
7188.6
7265.31
7351.56
7304.94
7287.12
7246.81
7352.27
7321.55
7298.18
7297.93
7343.76
7259.53
7301.35
7372.91
7446.28
7301.99
7354.2
7302.49
7282.05
7251.3
7208.05
7317.16
7174.73
7210.24
7340.74
7378.52
7203.3
7395.44
7292.63
7204.56
7322.22
7280.77
7164.55
7226.73
7349.66
7299.29
7248.8
7352.42
7302.67
7401.85
7295.99
7291.26
7320.35
7425.04
7395.32
7518.35
7458.12
7280.69
7233.73
7283.76
7358.77
7382.91
7315.6
7313.93
7497.68
7396.51
7403.41
7287.91
7356.6
7432.07
7431.53
7375.54
7363.39
7493.52
7277.98
7336.98
7418.41
7354.34
7393.85
7371.44
7432.12
7539.68
7424.37
7351.03
7419.64
7378.39
7440.73
7332.05
7412.72
7447.6
7436.2
7346.83
7380.03
7430.88
7455.29
7419.29
7447.9
7453.07
7315.14
7295.87
7290.16
7381.01
7293.58
7421.21
7292.42
7428.55
7344.43
7385
7303.99
7407.07
7411.73
7376.3
7291.36
7447.42
7452.77
7327.58
7287.83
7351.69
7351.7
7467.86
7372.99
7322.47
7349.07
7474.08
7479.8
7360.44
7397.46
7251.01
7186.18
7245.13
7260.92
7287.86
7358.47
7521.02
7432.17
7260.78
7367.05
7309.94
7518.67
7407.31
7332.61
7433.1
7490.19
7344.88
7244.22
7456.39
7258.17
7349.17
7221.22
7260.94
7312.45
7291.54
7384.96
7337.68
7291.9
7178.06
7384.12
7422.37
7428.03
7431.56
7440.42
7468.36
7305.13
7300.06
7436.39
7341.46
7469.95
7425.03
7428.69
7432.75
7392.38
7442.55
7416.71
7453.86
7419.83
7373.53
7402.02
7457.28
7457.6
7453.76
7415.83
7416.39
7504.14
7539.66
7523.65
7439.28
7412.8
7445.83
7564.51
7443.77
7464.32
7451.94
7362.01
7542.07
7478.02
7399.56
7473.25
7391.69
7423.69
7537.19
7387.6
7419.11
7483.36
7479.19
7532.76
7482.61
7602.67
7570.07
7536.21
7573.38
7518.03
7523.73
7464.42
7604.37
7559.08
7487.52
7602.44
7592.27
7554.43
7512.3
7546.13
7553.11
7550.32
7683.53
7759.25
7587.97
7720.5
7608.74
7651.94
7717.86
7576.43
7660.74
7628.5
7657.66
7645.15
7718.26
7639.73
7554.57
7681.43
7673.92
7612.53
7629.27
7648.24
7852.76
7709.87
7780.52
7627.39
7588.32
7589.1
7657.04
7764.49
7884.29
7792.58
7815.59
7763.21
7784.81
7780.36
7769.49
7891.54
7853.04
7749.11
7688.47
7795.67
7801.86
7854.95
7806.59
7799.83
7951.48
7864.47
7862.35
7890.93
7835.32
7929.21
7932.56
8030.08
7841.01
7871.8
7839.27
7823.97
8017.23
8093.63
8055.4
7930.18
8008.3
8040.15
7934.57
7868.21
7816.11
7968.93
7918.76
8068.99
7866.63
7892.64
7863.12
7754.38
7907.07
8108.62
8141.2
7965.99
7914
8126.14
8106.02
8192.21
8082.14
8147.16
8212.5
8168.33
8178.58
8204.08
8132.22
8191.59
8301.73
8374.47
8396.53
8356.86
8347.37
8356.1
8386.48
8251
8346.68
8344.28
8329.86
8265.47
8273.87
8463.46
8465.35
8309.75
8530.77
8422.92
8326.88
8400.36
8392.3
8412.22
8296.71
8296.92
8401.31
8382.17
8486.41
8322.88
8428.77
8581.33
8415.43
8361.12
8325.39
8410.19
8373.4
8217.55
8217.98
8215.96
8192.4
8288.27
8260.47
8158.98
8356.43
8353.67
8496.96
8416.34
8435.31
8432.39
8377.93
8461.79
8403.63
8478.49
8432.57
8516.09
8507.5
8509.81
8462.3
8663.13
8580.7
8605.37
8708.57
8699.46
8758.22
8725
8725.89
8745.02
8650.03
8770.84
8766.16
8870.35
8913.03
8798.6
8752.54
8826.64
8725
8885.44
8764.39
8809.03
8729.02
8795.2
8761.32
8779.3
8944.46
8749.28
8750.5
8747.15
8801.81
8690.28
8652.04
8484.28
8697.4
8700.83
8707.87
8693.74
8624.5
8564.1
8625.52
8568.13
8619.84
8644.96
8581.27
8420.68
8543.82
8580.1
8535.56
8484.57
8437.56
8578.68
8648.47
8494
8403.79
8486.45
8399.3
8379.96
8478.7
8430.33
8345.05
8299.17
8442.87
8584.88
8473.31
8475.38
8431.21
8382.47
8363.76
8473.53
8692.02
8614.54
8468.01
8491.21
8473.27
8415.45
8541.89
8538.4
8478.5
8524.78
8617.12
8663.91
8617.97
8577.77
8524.9
8530.57
8525.25
8502.71
8543.97
8511.76
8485.37
8431.27
8465.08
8401.38
8383.94
8438.37
8440.88
8234.74
8367.48
8427.54
8360.39
8358.2
8316.27
8331.1
8315.02
8320.16
8398.25
8429.53
8373.01
8428.68
8507.56
8415.46
8276.67
8407.05
8421.43
8395.98
8368.89
8419.37
8555.81
8589.17
8503.82
8650.77
8691.8
8722.73
8708.47
8744.29
8863.55
8733.87
8715.36
8691.53
8780.05
8751.76
8719.86
8639.64
8612.39
8552.88
8788.35
8510.01
8431.36
8488.33
8375.78
8408.46
8494.59
8445.51
8377.72
8347.6
8166.27
8205.44
8232.43
8230.18
8271.3
8153.02
8076.87
8221.84
8245.44
8304.38
8176.97
8232.46
8355.17
8476.47
8517.14
8494.56
8618.38
8679.64
8848.88
9118.01
9131.7
9476.13
9743.74
9888.09
9986.34
10027.8
9736.3
9454.53
8894.25
8681.24
8553.96
8378.92
8473.44
8501.71
8672.49
8764.15
8733.02
8895.11
8956.47
9044.3
9166.04
9441.68
9839.47
9934.57
10319.9
10586.1
10975.2
11500
12140.2
12838.5
13701.3
15482.5
17459.4
19961.3
23708.3
28149.1
34042.1
42014.6
52075.4
63390.9
75659.3
87177.8
93030.4
89609.9
76148.8
57685.6
39613.5
27114.7
19266
14618.2
12111.3
10437.9
9442.25
8768.67
8255.06
7948.62
7883.68
7793.88
7786.01
7944.36
8146.01
8394.65
8446.08
8567.58
8717.66
8542.44
7985.22
7561.51
6934.09
6447.48
6111.17
5764.81
5492.96
5536.71
5481.4
5446.31
5593.67
5698.52
5889.42
6124.22
6275.85
6577.21
6825.32
7122.52
7583.83
8152.4
8734.25
9448.91
10295.4
11635.4
13223.2
15315.2
18292.1
22355.2
27516.4
34203.2
43157.4
54455.6
68532.6
85273.1
103041
118676
127237
122291
104007
77968.8
51640
33090.7
21662.7
15332.1
11126.2
8624.83
7089.69
5911.89
5179.58
4481.13
4027.56
3657.62
3374.64
3102.97
2863.9
2778.01
2642.39
2515.9
2378.24
2253.01
2170.85
2088.89
1995.92
1970.24
1840.52
1821.26
1787.43
1750.62
1709.48
1662.02
1651.31
1583.59
1546.7
1528.24
1582.86
1547.44
1503.72
1428.62
1358.84
1399.45
1395.38
1379.22
1371.58
1349.88
1305.13
1304.85
1278.88
1338.29
1334.14
1302.66
1306.21
1283.67
1278.12
1284.8
1288.47
1231.46
1232.98
1240.53
1192.57
1198.52
1184.33
1178.39
1171.37
1156.41
1164.44
1159.06
1180.45
1166.53
1196.75
1167.33
1177.13
1193.75
1174.17
1169.58
1166.48
1171
1101.19
1101.59
1132.01
1166.56
1159
1157.59
1158.42
1081.92
1118.57
1135.54
1110.55
1160.69
1167.56
1120.85
1073.44
1117.51
1174.05
1157.39
1136.91
1144.1
1067.87
1096.8
1084.97
1049.28
1103
1097.18
1151.45
1092.07
1099.99
1138.45
1161.39
1103.44
1100.71
1100.38
1128.5
1116.95
1179.52
1176.22
1105.23
1144.89
1097.9
1082.95
1135.14
1090.59
1089.51
1120.59
1082.26
1070.49
1082.03
1079.52
1089.85
1088.31
1131.71
1087.03
1075.76
1090
1144.47
1087.54
1097.43
1087.02
1111.08
1061.81
1058.42
1061.48
1092.94
1087.43
1131.69
1087.64
1101.69
1084.87
1064.88
1106.36
1092.69
1105.71
1106.37
1055.72
1075.01
1091.52
1077.73
1042.35
1074.87
1080.64
1040.78
1082
1092.65
1062.55
1106.25
1101.05
1063
1070.28
1114.67
1087.46
1048.46
1089.41
1021.31
1064.38
1095.59
1082.4
1096.78
1045.8
1096.03
1095.27
1097.59
1073.97
2.57029
Ag3d
Ag in vacuum, short shirley
2020
3
6
22
14
31
0
17
Casa Info Follows
1
BackgroundSubtract
0
1
CASA region (*Ag 3d*) (*Shirley*) 1102.5638 1133.9582 17.742184 2 0 0 833.83732 -450 0 0 (*Ag 3d*) 107.878 0 18.04
0
EX340_CEC356_effect of lens modes.sle
Group = Ag in vacuum
First of group = 0
Analyzer lens = LargeArea:1.5kV
Analyzer slit = 4:7x20c\C:mesh
Scan mode = FixedAnalyzerTransmission
Kinetic energy start = 1036.61
Sum of 8 spectra in column containing 8 scans
C:\Users\pielsticker\Lukas\MPI-CEC\Projects\Gas phase background\inelasticscattering\data\N2\Au, Ag, Cu in N2.vms
CasaXP3
XPS
1
Al
1486.61
0
0
0
54.5
180
FAT
20
1
4.156
0
0
0
0
0
Ag3d

-1
kinetic energy
eV
1036.61
0.1
2
counts
d
Transmission
d
pulse counting
0.8
1
0
0
0
0
2
ESCAPE DEPTH TYPE
d
0
MFP Exponent
d
0
111.645
2.57029
7149.55
7212.09
7195.03
7215.52
7267.75
7148.26
7226.14
7304.93
7204.99
7220.56
7208.82
7201.59
7187.93
7311.09
7308.51
7281.85
7162.46
7162.77
7185.3
7240.53
7218.2
7170.12
7262.42
7181.35
7228.18
7201.42
7179.44
7141.15
7277.27
7186.11
7295.79
7253.32
7103.66
7131.25
7196.36
7281.68
7265.37
7173.95
7122.64
7196.81
7135.75
7118.88
7160.16
7214.67
7232.26
7167.63
7138.52
7193.3
7214.42
7120.75
7269.19
7321.18
7241.45
7269.88
7268.3
7088.43
7228.36
7276.47
7226.6
7114.05
7259.36
7275.82
7235.9
7116.11
7106.91
7187.5
7093.35
7172.08
7241.22
7185.28
7342.22
7337.72
7134.49
7303.82
7315.21
7207.65
7254.06
7172.87
7244.6
7223.47
7176.53
7158.85
7117.1
7173.21
7169.34
7322.11
7284.14
7246.46
7232.75
7311.4
7323.81
7093.13
7316.31
7209.1
7226
7255.26
7251.01
7239.68
7240.28
7263.9
7204.9
7179.2
7141.89
7238.73
7182.47
7248.01
7203.22
7115.56
7210.98
7209.8
7218
7293.85
7175.5
7208.09
7270.91
7180.85
7244.65
7141.78
7183.69
7214.23
7278.79
7117.48
7133.17
7338.38
7291.99
7252.58
7335.14
7328.65
7280.55
7246.18
7178.48
7197.48
7329.31
7084.13
7160.21
7193.21
7188.21
7345.19
7151.73
7191.87
7208.96
7264.74
7237.55
7154.63
7203.66
7259.92
7260.44
7123.22
7170.79
7239.03
7199.52
7327.29
7197.6
7201.9
7333.75
7325.55
7363.27
7217.66
7303.28
7278.45
7394.81
7273.76
7212.64
7178.06
7269.92
7373.08
7266.95
7329.56
7269.66
7378.94
7336.63
7193.82
7272.37
7110.33
7192.26
7278.2
7308.19
7200.82
7200.19
7157.76
7201.63
7243.55
7253.36
7088.15
7311.4
7245.2
7240.1
7285.79
7288.19
7260.64
7192.3
7193.73
7188.6
7265.31
7351.56
7304.94
7287.12
7246.81
7352.27
7321.55
7298.18
7297.93
7343.76
7259.53
7301.35
7372.91
7446.28
7301.99
7354.2
7302.49
7282.05
7251.3
7208.05
7317.16
7174.73
7210.24
7340.74
7378.52
7203.3
7395.44
7292.63
7204.56
7322.22
7280.77
7164.55
7226.73
7349.66
7299.29
7248.8
7352.42
7302.67
7401.85
7295.99
7291.26
7320.35
7425.04
7395.32
7518.35
7458.12
7280.69
7233.73
7283.76
7358.77
7382.91
7315.6
7313.93
7497.68
7396.51
7403.41
7287.91
7356.6
7432.07
7431.53
7375.54
7363.39
7493.52
7277.98
7336.98
7418.41
7354.34
7393.85
7371.44
7432.12
7539.68
7424.37
7351.03
7419.64
7378.39
7440.73
7332.05
7412.72
7447.6
7436.2
7346.83
7380.03
7430.88
7455.29
7419.29
7447.9
7453.07
7315.14
7295.87
7290.16
7381.01
7293.58
7421.21
7292.42
7428.55
7344.43
7385
7303.99
7407.07
7411.73
7376.3
7291.36
7447.42
7452.77
7327.58
7287.83
7351.69
7351.7
7467.86
7372.99
7322.47
7349.07
7474.08
7479.8
7360.44
7397.46
7251.01
7186.18
7245.13
7260.92
7287.86
7358.47
7521.02
7432.17
7260.78
7367.05
7309.94
7518.67
7407.31
7332.61
7433.1
7490.19
7344.88
7244.22
7456.39
7258.17
7349.17
7221.22
7260.94
7312.45
7291.54
7384.96
7337.68
7291.9
7178.06
7384.12
7422.37
7428.03
7431.56
7440.42
7468.36
7305.13
7300.06
7436.39
7341.46
7469.95
7425.03
7428.69
7432.75
7392.38
7442.55
7416.71
7453.86
7419.83
7373.53
7402.02
7457.28
7457.6
7453.76
7415.83
7416.39
7504.14
7539.66
7523.65
7439.28
7412.8
7445.83
7564.51
7443.77
7464.32
7451.94
7362.01
7542.07
7478.02
7399.56
7473.25
7391.69
7423.69
7537.19
7387.6
7419.11
7483.36
7479.19
7532.76
7482.61
7602.67
7570.07
7536.21
7573.38
7518.03
7523.73
7464.42
7604.37
7559.08
7487.52
7602.44
7592.27
7554.43
7512.3
7546.13
7553.11
7550.32
7683.53
7759.25
7587.97
7720.5
7608.74
7651.94
7717.86
7576.43
7660.74
7628.5
7657.66
7645.15
7718.26
7639.73
7554.57
7681.43
7673.92
7612.53
7629.27
7648.24
7852.76
7709.87
7780.52
7627.39
7588.32
7589.1
7657.04
7764.49
7884.29
7792.58
7815.59
7763.21
7784.81
7780.36
7769.49
7891.54
7853.04
7749.11
7688.47
7795.67
7801.86
7854.95
7806.59
7799.83
7951.48
7864.47
7862.35
7890.93
7835.32
7929.21
7932.56
8030.08
7841.01
7871.8
7839.27
7823.97
8017.23
8093.63
8055.4
7930.18
8008.3
8040.15
7934.57
7868.21
7816.11
7968.93
7918.76
8068.99
7866.63
7892.64
7863.12
7754.38
7907.07
8108.62
8141.2
7965.99
7914
8126.14
8106.02
8192.21
8082.14
8147.16
8212.5
8168.33
8178.58
8204.08
8132.22
8191.59
8301.73
8374.47
8396.53
8356.86
8347.37
8356.1
8386.48
8251
8346.68
8344.28
8329.86
8265.47
8273.87
8463.46
8465.35
8309.75
8530.77
8422.92
8326.88
8400.36
8392.3
8412.22
8296.71
8296.92
8401.31
8382.17
8486.41
8322.88
8428.77
8581.33
8415.43
8361.12
8325.39
8410.19
8373.4
8217.55
8217.98
8215.96
8192.4
8288.27
8260.47
8158.98
8356.43
8353.67
8496.96
8416.34
8435.31
8432.39
8377.93
8461.79
8403.63
8478.49
8432.57
8516.09
8507.5
8509.81
8462.3
8663.13
8580.7
8605.37
8708.57
8699.46
8758.22
8725
8725.89
8745.02
8650.03
8770.84
8766.16
8870.35
8913.03
8798.6
8752.54
8826.64
8725
8885.44
8764.39
8809.03
8729.02
8795.2
8761.32
8779.3
8944.46
8749.28
8750.5
8747.15
8801.81
8690.28
8652.04
8484.28
8697.4
8700.83
8707.87
8693.74
8624.5
8564.1
8625.52
8568.13
8619.84
8644.96
8581.27
8420.68
8543.82
8580.1
8535.56
8484.57
8437.56
8578.68
8648.47
8494
8403.79
8486.45
8399.3
8379.96
8478.7
8430.33
8345.05
8299.17
8442.87
8584.88
8473.31
8475.38
8431.21
8382.47
8363.76
8473.53
8692.02
8614.54
8468.01
8491.21
8473.27
8415.45
8541.89
8538.4
8478.5
8524.78
8617.12
8663.91
8617.97
8577.77
8524.9
8530.57
8525.25
8502.71
8543.97
8511.76
8485.37
8431.27
8465.08
8401.38
8383.94
8438.37
8440.88
8234.74
8367.48
8427.54
8360.39
8358.2
8316.27
8331.1
8315.02
8320.16
8398.25
8429.53
8373.01
8428.68
8507.56
8415.46
8276.67
8407.05
8421.43
8395.98
8368.89
8419.37
8555.81
8589.17
8503.82
8650.77
8691.8
8722.73
8708.47
8744.29
8863.55
8733.87
8715.36
8691.53
8780.05
8751.76
8719.86
8639.64
8612.39
8552.88
8788.35
8510.01
8431.36
8488.33
8375.78
8408.46
8494.59
8445.51
8377.72
8347.6
8166.27
8205.44
8232.43
8230.18
8271.3
8153.02
8076.87
8221.84
8245.44
8304.38
8176.97
8232.46
8355.17
8476.47
8517.14
8494.56
8618.38
8679.64
8848.88
9118.01
9131.7
9476.13
9743.74
9888.09
9986.34
10027.8
9736.3
9454.53
8894.25
8681.24
8553.96
8378.92
8473.44
8501.71
8672.49
8764.15
8733.02
8895.11
8956.47
9044.3
9166.04
9441.68
9839.47
9934.57
10319.9
10586.1
10975.2
11500
12140.2
12838.5
13701.3
15482.5
17459.4
19961.3
23708.3
28149.1
34042.1
42014.6
52075.4
63390.9
75659.3
87177.8
93030.4
89609.9
76148.8
57685.6
39613.5
27114.7
19266
14618.2
12111.3
10437.9
9442.25
8768.67
8255.06
7948.62
7883.68
7793.88
7786.01
7944.36
8146.01
8394.65
8446.08
8567.58
8717.66
8542.44
7985.22
7561.51
6934.09
6447.48
6111.17
5764.81
5492.96
5536.71
5481.4
5446.31
5593.67
5698.52
5889.42
6124.22
6275.85
6577.21
6825.32
7122.52
7583.83
8152.4
8734.25
9448.91
10295.4
11635.4
13223.2
15315.2
18292.1
22355.2
27516.4
34203.2
43157.4
54455.6
68532.6
85273.1
103041
118676
127237
122291
104007
77968.8
51640
33090.7
21662.7
15332.1
11126.2
8624.83
7089.69
5911.89
5179.58
4481.13
4027.56
3657.62
3374.64
3102.97
2863.9
2778.01
2642.39
2515.9
2378.24
2253.01
2170.85
2088.89
1995.92
1970.24
1840.52
1821.26
1787.43
1750.62
1709.48
1662.02
1651.31
1583.59
1546.7
1528.24
1582.86
1547.44
1503.72
1428.62
1358.84
1399.45
1395.38
1379.22
1371.58
1349.88
1305.13
1304.85
1278.88
1338.29
1334.14
1302.66
1306.21
1283.67
1278.12
1284.8
1288.47
1231.46
1232.98
1240.53
1192.57
1198.52
1184.33
1178.39
1171.37
1156.41
1164.44
1159.06
1180.45
1166.53
1196.75
1167.33
1177.13
1193.75
1174.17
1169.58
1166.48
1171
1101.19
1101.59
1132.01
1166.56
1159
1157.59
1158.42
1081.92
1118.57
1135.54
1110.55
1160.69
1167.56
1120.85
1073.44
1117.51
1174.05
1157.39
1136.91
1144.1
1067.87
1096.8
1084.97
1049.28
1103
1097.18
1151.45
1092.07
1099.99
1138.45
1161.39
1103.44
1100.71
1100.38
1128.5
1116.95
1179.52
1176.22
1105.23
1144.89
1097.9
1082.95
1135.14
1090.59
1089.51
1120.59
1082.26
1070.49
1082.03
1079.52
1089.85
1088.31
1131.71
1087.03
1075.76
1090
1144.47
1087.54
1097.43
1087.02
1111.08
1061.81
1058.42
1061.48
1092.94
1087.43
1131.69
1087.64
1101.69
1084.87
1064.88
1106.36
1092.69
1105.71
1106.37
1055.72
1075.01
1091.52
1077.73
1042.35
1074.87
1080.64
1040.78
1082
1092.65
1062.55
1106.25
1101.05
1063
1070.28
1114.67
1087.46
1048.46
1089.41
1021.31
1064.38
1095.59
1082.4
1096.78
1045.8
1096.03
1095.27
1097.59
1073.97
2.57029
Ag3d
Ag in vacuum, long shirley
2020
3
6
22
14
31
0
17
Casa Info Follows
1
BackgroundSubtract
0
1
CASA region (*Ag 3d*) (*Shirley*) 1070.5707 1133.9582 17.742184 2 0 0 833.83732 -450 0 0 (*Ag 3d*) 107.878 0 18.04
0
EX340_CEC356_effect of lens modes.sle
Group = Ag in vacuum
First of group = 0
Analyzer lens = LargeArea:1.5kV
Analyzer slit = 4:7x20c\C:mesh
Scan mode = FixedAnalyzerTransmission
Kinetic energy start = 1036.61
Sum of 8 spectra in column containing 8 scans
C:\Users\pielsticker\Lukas\MPI-CEC\Projects\Gas phase background\inelasticscattering\data\N2\Au, Ag, Cu in N2.vms
CasaXP3
XPS
1
Al
1486.61
0
0
0
54.5
180
FAT
20
1
4.156
0
0
0
0
0
Ag3d

-1
kinetic energy
eV
1036.61
0.1
2
counts
d
Transmission
d
pulse counting
0.8
1
0
0
0
0
2
ESCAPE DEPTH TYPE
d
0
MFP Exponent
d
0
111.645
2.57029
7149.55
7212.09
7195.03
7215.52
7267.75
7148.26
7226.14
7304.93
7204.99
7220.56
7208.82
7201.59
7187.93
7311.09
7308.51
7281.85
7162.46
7162.77
7185.3
7240.53
7218.2
7170.12
7262.42
7181.35
7228.18
7201.42
7179.44
7141.15
7277.27
7186.11
7295.79
7253.32
7103.66
7131.25
7196.36
7281.68
7265.37
7173.95
7122.64
7196.81
7135.75
7118.88
7160.16
7214.67
7232.26
7167.63
7138.52
7193.3
7214.42
7120.75
7269.19
7321.18
7241.45
7269.88
7268.3
7088.43
7228.36
7276.47
7226.6
7114.05
7259.36
7275.82
7235.9
7116.11
7106.91
7187.5
7093.35
7172.08
7241.22
7185.28
7342.22
7337.72
7134.49
7303.82
7315.21
7207.65
7254.06
7172.87
7244.6
7223.47
7176.53
7158.85
7117.1
7173.21
7169.34
7322.11
7284.14
7246.46
7232.75
7311.4
7323.81
7093.13
7316.31
7209.1
7226
7255.26
7251.01
7239.68
7240.28
7263.9
7204.9
7179.2
7141.89
7238.73
7182.47
7248.01
7203.22
7115.56
7210.98
7209.8
7218
7293.85
7175.5
7208.09
7270.91
7180.85
7244.65
7141.78
7183.69
7214.23
7278.79
7117.48
7133.17
7338.38
7291.99
7252.58
7335.14
7328.65
7280.55
7246.18
7178.48
7197.48
7329.31
7084.13
7160.21
7193.21
7188.21
7345.19
7151.73
7191.87
7208.96
7264.74
7237.55
7154.63
7203.66
7259.92
7260.44
7123.22
7170.79
7239.03
7199.52
7327.29
7197.6
7201.9
7333.75
7325.55
7363.27
7217.66
7303.28
7278.45
7394.81
7273.76
7212.64
7178.06
7269.92
7373.08
7266.95
7329.56
7269.66
7378.94
7336.63
7193.82
7272.37
7110.33
7192.26
7278.2
7308.19
7200.82
7200.19
7157.76
7201.63
7243.55
7253.36
7088.15
7311.4
7245.2
7240.1
7285.79
7288.19
7260.64
7192.3
7193.73
7188.6
7265.31
7351.56
7304.94
7287.12
7246.81
7352.27
7321.55
7298.18
7297.93
7343.76
7259.53
7301.35
7372.91
7446.28
7301.99
7354.2
7302.49
7282.05
7251.3
7208.05
7317.16
7174.73
7210.24
7340.74
7378.52
7203.3
7395.44
7292.63
7204.56
7322.22
7280.77
7164.55
7226.73
7349.66
7299.29
7248.8
7352.42
7302.67
7401.85
7295.99
7291.26
7320.35
7425.04
7395.32
7518.35
7458.12
7280.69
7233.73
7283.76
7358.77
7382.91
7315.6
7313.93
7497.68
7396.51
7403.41
7287.91
7356.6
7432.07
7431.53
7375.54
7363.39
7493.52
7277.98
7336.98
7418.41
7354.34
7393.85
7371.44
7432.12
7539.68
7424.37
7351.03
7419.64
7378.39
7440.73
7332.05
7412.72
7447.6
7436.2
7346.83
7380.03
7430.88
7455.29
7419.29
7447.9
7453.07
7315.14
7295.87
7290.16
7381.01
7293.58
7421.21
7292.42
7428.55
7344.43
7385
7303.99
7407.07
7411.73
7376.3
7291.36
7447.42
7452.77
7327.58
7287.83
7351.69
7351.7
7467.86
7372.99
7322.47
7349.07
7474.08
7479.8
7360.44
7397.46
7251.01
7186.18
7245.13
7260.92
7287.86
7358.47
7521.02
7432.17
7260.78
7367.05
7309.94
7518.67
7407.31
7332.61
7433.1
7490.19
7344.88
7244.22
7456.39
7258.17
7349.17
7221.22
7260.94
7312.45
7291.54
7384.96
7337.68
7291.9
7178.06
7384.12
7422.37
7428.03
7431.56
7440.42
7468.36
7305.13
7300.06
7436.39
7341.46
7469.95
7425.03
7428.69
7432.75
7392.38
7442.55
7416.71
7453.86
7419.83
7373.53
7402.02
7457.28
7457.6
7453.76
7415.83
7416.39
7504.14
7539.66
7523.65
7439.28
7412.8
7445.83
7564.51
7443.77
7464.32
7451.94
7362.01
7542.07
7478.02
7399.56
7473.25
7391.69
7423.69
7537.19
7387.6
7419.11
7483.36
7479.19
7532.76
7482.61
7602.67
7570.07
7536.21
7573.38
7518.03
7523.73
7464.42
7604.37
7559.08
7487.52
7602.44
7592.27
7554.43
7512.3
7546.13
7553.11
7550.32
7683.53
7759.25
7587.97
7720.5
7608.74
7651.94
7717.86
7576.43
7660.74
7628.5
7657.66
7645.15
7718.26
7639.73
7554.57
7681.43
7673.92
7612.53
7629.27
7648.24
7852.76
7709.87
7780.52
7627.39
7588.32
7589.1
7657.04
7764.49
7884.29
7792.58
7815.59
7763.21
7784.81
7780.36
7769.49
7891.54
7853.04
7749.11
7688.47
7795.67
7801.86
7854.95
7806.59
7799.83
7951.48
7864.47
7862.35
7890.93
7835.32
7929.21
7932.56
8030.08
7841.01
7871.8
7839.27
7823.97
8017.23
8093.63
8055.4
7930.18
8008.3
8040.15
7934.57
7868.21
7816.11
7968.93
7918.76
8068.99
7866.63
7892.64
7863.12
7754.38
7907.07
8108.62
8141.2
7965.99
7914
8126.14
8106.02
8192.21
8082.14
8147.16
8212.5
8168.33
8178.58
8204.08
8132.22
8191.59
8301.73
8374.47
8396.53
8356.86
8347.37
8356.1
8386.48
8251
8346.68
8344.28
8329.86
8265.47
8273.87
8463.46
8465.35
8309.75
8530.77
8422.92
8326.88
8400.36
8392.3
8412.22
8296.71
8296.92
8401.31
8382.17
8486.41
8322.88
8428.77
8581.33
8415.43
8361.12
8325.39
8410.19
8373.4
8217.55
8217.98
8215.96
8192.4
8288.27
8260.47
8158.98
8356.43
8353.67
8496.96
8416.34
8435.31
8432.39
8377.93
8461.79
8403.63
8478.49
8432.57
8516.09
8507.5
8509.81
8462.3
8663.13
8580.7
8605.37
8708.57
8699.46
8758.22
8725
8725.89
8745.02
8650.03
8770.84
8766.16
8870.35
8913.03
8798.6
8752.54
8826.64
8725
8885.44
8764.39
8809.03
8729.02
8795.2
8761.32
8779.3
8944.46
8749.28
8750.5
8747.15
8801.81
8690.28
8652.04
8484.28
8697.4
8700.83
8707.87
8693.74
8624.5
8564.1
8625.52
8568.13
8619.84
8644.96
8581.27
8420.68
8543.82
8580.1
8535.56
8484.57
8437.56
8578.68
8648.47
8494
8403.79
8486.45
8399.3
8379.96
8478.7
8430.33
8345.05
8299.17
8442.87
8584.88
8473.31
8475.38
8431.21
8382.47
8363.76
8473.53
8692.02
8614.54
8468.01
8491.21
8473.27
8415.45
8541.89
8538.4
8478.5
8524.78
8617.12
8663.91
8617.97
8577.77
8524.9
8530.57
8525.25
8502.71
8543.97
8511.76
8485.37
8431.27
8465.08
8401.38
8383.94
8438.37
8440.88
8234.74
8367.48
8427.54
8360.39
8358.2
8316.27
8331.1
8315.02
8320.16
8398.25
8429.53
8373.01
8428.68
8507.56
8415.46
8276.67
8407.05
8421.43
8395.98
8368.89
8419.37
8555.81
8589.17
8503.82
8650.77
8691.8
8722.73
8708.47
8744.29
8863.55
8733.87
8715.36
8691.53
8780.05
8751.76
8719.86
8639.64
8612.39
8552.88
8788.35
8510.01
8431.36
8488.33
8375.78
8408.46
8494.59
8445.51
8377.72
8347.6
8166.27
8205.44
8232.43
8230.18
8271.3
8153.02
8076.87
8221.84
8245.44
8304.38
8176.97
8232.46
8355.17
8476.47
8517.14
8494.56
8618.38
8679.64
8848.88
9118.01
9131.7
9476.13
9743.74
9888.09
9986.34
10027.8
9736.3
9454.53
8894.25
8681.24
8553.96
8378.92
8473.44
8501.71
8672.49
8764.15
8733.02
8895.11
8956.47
9044.3
9166.04
9441.68
9839.47
9934.57
10319.9
10586.1
10975.2
11500
12140.2
12838.5
13701.3
15482.5
17459.4
19961.3
23708.3
28149.1
34042.1
42014.6
52075.4
63390.9
75659.3
87177.8
93030.4
89609.9
76148.8
57685.6
39613.5
27114.7
19266
14618.2
12111.3
10437.9
9442.25
8768.67
8255.06
7948.62
7883.68
7793.88
7786.01
7944.36
8146.01
8394.65
8446.08
8567.58
8717.66
8542.44
7985.22
7561.51
6934.09
6447.48
6111.17
5764.81
5492.96
5536.71
5481.4
5446.31
5593.67
5698.52
5889.42
6124.22
6275.85
6577.21
6825.32
7122.52
7583.83
8152.4
8734.25
9448.91
10295.4
11635.4
13223.2
15315.2
18292.1
22355.2
27516.4
34203.2
43157.4
54455.6
68532.6
85273.1
103041
118676
127237
122291
104007
77968.8
51640
33090.7
21662.7
15332.1
11126.2
8624.83
7089.69
5911.89
5179.58
4481.13
4027.56
3657.62
3374.64
3102.97
2863.9
2778.01
2642.39
2515.9
2378.24
2253.01
2170.85
2088.89
1995.92
1970.24
1840.52
1821.26
1787.43
1750.62
1709.48
1662.02
1651.31
1583.59
1546.7
1528.24
1582.86
1547.44
1503.72
1428.62
1358.84
1399.45
1395.38
1379.22
1371.58
1349.88
1305.13
1304.85
1278.88
1338.29
1334.14
1302.66
1306.21
1283.67
1278.12
1284.8
1288.47
1231.46
1232.98
1240.53
1192.57
1198.52
1184.33
1178.39
1171.37
1156.41
1164.44
1159.06
1180.45
1166.53
1196.75
1167.33
1177.13
1193.75
1174.17
1169.58
1166.48
1171
1101.19
1101.59
1132.01
1166.56
1159
1157.59
1158.42
1081.92
1118.57
1135.54
1110.55
1160.69
1167.56
1120.85
1073.44
1117.51
1174.05
1157.39
1136.91
1144.1
1067.87
1096.8
1084.97
1049.28
1103
1097.18
1151.45
1092.07
1099.99
1138.45
1161.39
1103.44
1100.71
1100.38
1128.5
1116.95
1179.52
1176.22
1105.23
1144.89
1097.9
1082.95
1135.14
1090.59
1089.51
1120.59
1082.26
1070.49
1082.03
1079.52
1089.85
1088.31
1131.71
1087.03
1075.76
1090
1144.47
1087.54
1097.43
1087.02
1111.08
1061.81
1058.42
1061.48
1092.94
1087.43
1131.69
1087.64
1101.69
1084.87
1064.88
1106.36
1092.69
1105.71
1106.37
1055.72
1075.01
1091.52
1077.73
1042.35
1074.87
1080.64
1040.78
1082
1092.65
1062.55
1106.25
1101.05
1063
1070.28
1114.67
1087.46
1048.46
1089.41
1021.31
1064.38
1095.59
1082.4
1096.78
1045.8
1096.03
1095.27
1097.59
1073.97
2.57029
Ag3d
Ag in vacuum, short shirley, background subtr.
2020
3
6
22
14
31
0
15
Casa Info Follows
0
0
0
0
EX340_CEC356_effect of lens modes.sle
Group = Ag in vacuum
First of group = 0
Analyzer lens = LargeArea:1.5kV
Analyzer slit = 4:7x20c\C:mesh
Scan mode = FixedAnalyzerTransmission
Kinetic energy start = 1036.61
Sum of 8 spectra in column containing 8 scans
C:\Users\pielsticker\Lukas\MPI-CEC\Projects\Gas phase background\inelasticscattering\data\N2\Au, Ag, Cu in N2.vms
CasaXP3
XPS
1e+037
Al
1486.61
0
0
0
54.5
180
FAT
20
1
4.156
0
0
0
0
0
Ag3d

-1
kinetic energy
eV
1036.61
0.1
2
counts
d
Transmission
d
pulse counting
0.8
1
0
0
0
0
2
ESCAPE DEPTH TYPE
d
0
MFP Exponent
d
0
111.645
2.57029
0
0
0
0
0
0
0
0
0
0
0
0
0
0
0
0
0
0
0
0
0
0
0
0
0
0
0
0
0
0
0
0
0
0
0
0
0
0
0
0
0
0
0
0
0
0
0
0
0
0
0
0
0
0
0
0
0
0
0
0
0
0
0
0
0
0
0
0
0
0
0
0
0
0
0
0
0
0
0
0
0
0
0
0
0
0
0
0
0
0
0
0
0
0
0
0
0
0
0
0
0
0
0
0
0
0
0
0
0
0
0
0
0
0
0
0
0
0
0
0
0
0
0
0
0
0
0
0
0
0
0
0
0
0
0
0
0
0
0
0
0
0
0
0
0
0
0
0
0
0
0
0
0
0
0
0
0
0
0
0
0
0
0
0
0
0
0
0
0
0
0
0
0
0
0
0
0
0
0
0
0
0
0
0
0
0
0
0
0
0
0
0
0
0
0
0
0
0
0
0
0
0
0
0
0
0
0
0
0
0
0
0
0
0
0
0
0
0
0
0
0
0
0
0
0
0
0
0
0
0
0
0
0
0
0
0
0
0
0
0
0
0
0
0
0
0
0
0
0
0
0
0
0
0
0
0
0
0
0
0
0
0
0
0
0
0
0
0
0
0
0
0
0
0
0
0
0
0
0
0
0
0
0
0
0
0
0
0
0
0
0
0
0
0
0
0
0
0
0
0
0
0
0
0
0
0
0
0
0
0
0
0
0
0
0
0
0
0
0
0
0
0
0
0
0
0
0
0
0
0
0
0
0
0
0
0
0
0
0
0
0
0
0
0
0
0
0
0
0
0
0
0
0
0
0
0
0
0
0
0
0
0
0
0
0
0
0
0
0
0
0
0
0
0
0
0
0
0
0
0
0
0
0
0
0
0
0
0
0
0
0
0
0
0
0
0
0
0
0
0
0
0
0
0
0
0
0
0
0
0
0
0
0
0
0
0
0
0
0
0
0
0
0
0
0
0
0
0
0
0
0
0
0
0
0
0
0
0
0
0
0
0
0
0
0
0
0
0
0
0
0
0
0
0
0
0
0
0
0
0
0
0
0
0
0
0
0
0
0
0
0
0
0
0
0
0
0
0
0
0
0
0
0
0
0
0
0
0
0
0
0
0
0
0
0
0
0
0
0
0
0
0
0
0
0
0
0
0
0
0
0
0
0
0
0
0
0
0
0
0
0
0
0
0
0
0
0
0
0
0
0
0
0
0
0
0
0
0
0
0
0
0
0
0
0
0
0
0
0
0
0
0
0
0
0
0
0
0
0
0
0
0
0
0
0
0
0
0
0
0
0
0
0
0
0
0
0
0
0
0
0
0
0
0
0
0
0
0
0
0
0
0
0
0
0
0
0
0
0
0
0
0
0
0
0
0
0
0
0
0
0
0
0
0
0
0
0
0
0
0
0
0
0
0
0
0
0
0
0
0
0
0
0
0
0
0
0
0
0
0
0
0
0
0
0
0
0
0
0
0
0
0
0
0
0
0
0
0
0
0
15.6191
-122.733
7.67435
22.1333
-3.30489
-30.2868
20.2655
157.267
191.309
106.339
254.196
296.283
328.384
315.249
352.326
473.275
344.825
327.484
304.741
394.669
367.691
336.993
257.693
231.268
172.373
409.303
131.432
52.9712
110.335
-2.20725
30.5819
117.13
68.2934
0.505237
-29.5095
-210.09
-170.312
-142.813
-144.547
-103.059
-220.552
-295.647
-150.142
-126.092
-66.9131
-193.632
-137.651
-14.888
106.793
147.991
125.86
250.574
312.951
483.917
755.744
772.189
1120.62
1393.2
1543.05
1647.18
1694.69
1408.21
1130.48
572.237
360.513
234.068
59.2396
154.31
183.234
355.282
448.542
418.907
583.077
646.745
737.205
862.021
1141.73
1545.04
1646.01
2038.61
2313.07
2711.84
3248.23
3902.36
4617.13
5499.55
7306.82
9316.96
11861.2
15664.1
20176.9
26163.2
34257.9
44477.4
55992.7
68505.5
80310.6
86471.7
83348.6
70137.7
51859.6
33908.5
21486.3
13686.5
9071.02
6587.62
4931.82
3950.26
3288.41
2784.74
2487.17
2430.91
2349.49
2350
2517.34
2728.72
2988.02
3050.34
3183.19
3345.21
3181.34
2633.52
2217.72
1595.99
1113.36
779.828
435.02
163.754
208.247
153.485
118.819
267.132
373.314
566.234
803.902
958.954
1264.83
1518.35
1822.05
2291.54
2870.35
3464.56
4194.19
5058.73
6421.64
8038.12
10166.4
13190.4
17315.2
22556.9
29348.4
38439.8
49916.1
64222.2
81252.6
99375.1
115422
124427
119909
101989
76222.3
50072.2
31635.8
20280.1
13999.5
9828.64
7353.51
5839.2
4678.09
3959.91
3273.14
2829.67
2468.54
2193.38
1928.59
1695.57
1615.45
1485.12
1363.5
1230.23
1108.96
1030.47
951.909
862.015
839.329
712.15
695.371
663.91
629.346
590.312
544.796
535.998
469.955
434.615
417.646
473.957
440.107
397.806
323.862
254.992
296.66
293.638
278.471
271.801
250.997
206.985
207.445
182.125
242.4
239.103
208.366
212.675
190.816
185.929
193.299
197.674
141.168
143.199
151.289
103.699
110.041
96.1947
90.5779
83.8571
69.1438
77.4501
72.3282
94.0537
80.4207
111.037
81.9091
92.0375
109.047
89.7869
85.502
82.697
87.5293
17.7828
18.2479
48.8422
83.6908
76.4034
75.2619
76.3644
-0.135156
36.6456
53.8076
28.9208
79.3439
86.5226
39.9551
-7.42837
36.7728
93.647
77.2626
56.986
64.4057
-11.7822
17.2092
5.39845
-30.1839
23.6204
17.8642
72.3925
13.059
21.0542
59.7273
82.9633
25.1028
22.453
22.2022
50.5024
39.0918
102.026
99.0794
28.19
68.0929
21.1785
6.25077
58.65
14.1505
13.1173
44.3556
6.04716
-5.7025
5.8584
3.36039
13.7394
12.2431
55.8423
11.2023
-0.0674484
14.2233
68.9393
12.0523
22.0208
11.6524
35.8403
-13.382
-16.7123
-13.6038
17.9201
12.4546
56.9177
12.9137
27.0603
10.277
-9.67851
31.9154
18.3107
31.4429
32.2178
-18.3666
0.926667
0
0
0
0
0
0
0
0
0
0
0
0
0
0
0
0
0
0
0
0
0
0
0
0
0
0
0
2.57029
Ag3d
Ag in vacuum, long shirley, background subtr.
2020
3
6
22
14
31
0
15
Casa Info Follows
0
0
0
0
EX340_CEC356_effect of lens modes.sle
Group = Ag in vacuum
First of group = 0
Analyzer lens = LargeArea:1.5kV
Analyzer slit = 4:7x20c\C:mesh
Scan mode = FixedAnalyzerTransmission
Kinetic energy start = 1036.61
Sum of 8 spectra in column containing 8 scans
C:\Users\pielsticker\Lukas\MPI-CEC\Projects\Gas phase background\inelasticscattering\data\N2\Au, Ag, Cu in N2.vms
CasaXP3
XPS
1e+037
Al
1486.61
0
0
0
54.5
180
FAT
20
1
4.156
0
0
0
0
0
Ag3d

-1
kinetic energy
eV
1036.61
0.1
2
counts
d
Transmission
d
pulse counting
0.8
1
0
0
0
0
2
ESCAPE DEPTH TYPE
d
0
MFP Exponent
d
0
111.645
2.57029
0
0
0
0
0
0
0
0
0
0
0
0
0
0
0
0
0
0
0
0
0
0
0
0
0
0
0
0
0
0
0
0
0
0
0
0
0
0
0
0
0
0
0
0
0
0
0
0
0
0
0
0
0
0
0
0
0
0
0
0
0
0
0
0
0
0
0
0
0
0
0
0
0
0
0
0
0
0
0
0
0
0
0
0
0
0
0
0
0
0
0
0
0
0
0
0
0
0
0
0
0
0
0
0
0
0
0
0
0
0
0
0
0
0
0
0
0
0
0
0
0
0
0
0
0
0
0
0
0
0
0
0
0
0
0
0
0
0
0
0
0
0
0
0
0
0
0
0
0
0
0
0
0
0
0
0
0
0
0
0
0
0
0
0
0
0
0
0
0
0
0
0
0
0
0
0
0
0
0
0
0
0
0
0
0
0
0
0
0
0
0
0
0
0
0
0
0
0
0
0
0
0
0
0
0
0
0
0
0
0
0
0
0
0
0
0
0
0
0
0
0
0
0
0
0
0
0
0
0
0
0
0
0
0
0
0
0
0
0
0
0
0
0
0
0
0
0
0
0
0
0
0
0
0
0
0
0
0
0
0
0
0
0
0
0
0
0
0
0
0
0
0
0
0
0
0
0
0
0
0
0
0
0
0
0
0
0
0
0
0
0
0
0
0
0
0
0
0
0
0
0
0
0
0
0
0
0
0
0
0
0
0
0
0
0
0
0
0
0
0
0
0
0
0
0
0
0
0
0
0
0
0
0
0
0
0
0
0
0
0
0.711742
4.25215
13.1443
41.1851
-121.747
-126.507
9.84668
-84.8756
43.7214
-1.19571
2.47034
6.54636
-33.7411
16.4692
-9.3479
27.8703
-6.14467
-52.3166
-23.7685
31.5688
31.967
28.196
-9.71025
-9.12791
78.815
114.615
98.8473
14.5128
-11.938
21.1438
140.167
19.4744
40.1226
27.8107
-61.9677
118.382
54.4653
-23.9362
49.8759
-31.6068
0.394198
114.174
-35.33
-3.81063
60.5876
56.556
110.396
60.394
180.897
148.66
115.082
152.625
97.5141
103.467
44.2656
184.668
139.719
68.3266
183.696
173.952
136.446
94.5471
128.692
136.005
133.542
267.406
343.968
173.111
306.391
195.108
238.893
305.561
164.533
249.454
217.747
247.512
235.579
309.446
231.482
146.681
274.212
267.357
206.472
223.759
243.325
448.943
306.804
378.38
225.803
187.191
188.432
257.001
365.345
486.335
395.593
419.63
368.151
390.707
387.204
377.257
500.532
463.166
360.117
300.212
408.411
415.618
469.858
422.532
416.792
569.836
484.01
483.073
512.908
458.419
553.664
558.381
657.51
469.589
501.606
470.227
456.043
650.896
729.08
692.544
568.716
648.423
681.942
577.775
512.67
461.7
616.027
567.245
719.235
518.143
545.488
517.234
409.496
563.565
766.992
801.533
627.86
577.282
791.359
773.131
861.429
753.202
820.229
887.741
845.641
857.99
885.657
815.794
877.31
989.873
1065.22
1089.95
1052.85
1045.92
1057.24
1090.29
957.15
1055.41
1055.6
1043.73
981.742
992.571
1185.06
1189.86
1036.8
1260.9
1155.88
1062.44
1138.71
1133.42
1156.17
1043.22
1045.98
1153.2
1136.84
1244.12
1083.24
1192.05
1347.91
1184.91
1133.37
1100.33
1188.04
1154.08
1000.67
1003.56
1004
982.843
1081.36
1056.14
956.995
1157.28
1157.35
1303.83
1226.21
1248.23
1248.37
1196.84
1283.84
1228.69
1306.74
1263.92
1350.74
1345.44
1351.06
1306.75
1511.28
1432.35
1460.6
1567.63
1562.35
1625.08
1595.77
1600.57
1623.68
1532.44
1657.3
1656.68
1765.19
1812.3
1702.04
1660.04
1738.39
1640.77
1805.63
1688.71
1737.6
1661.66
1732.07
1702.36
1724.56
1894.36
1703.34
1708.75
1709.58
1768.57
1661.1
1626.84
1462.66
1679.89
1687.45
1698.65
1688.65
1623.38
1566.82
1632.23
1578.7
1634.41
1663.6
1603.84
1446.79
1573.78
1614.01
1573.32
1526.06
1482.68
1627.79
1701.74
1551.07
1464.44
1550.89
1467.34
1451.55
1554.09
1509.41
1427.63
1385.14
1532.59
1678.71
1570.98
1576.91
1536.5
1491.41
1476.31
1589.97
1812.9
1739.67
1597.05
1624.23
1610.23
1556.22
1686.78
1687.42
1631.51
1681.91
1778.6
1829.87
1788.31
1752.39
1703.69
1713.56
1712.43
1694.03
1739.55
1711.53
1689.27
1639.18
1677.1
1617.35
1603.84
1662.34
1668.93
1466.38
1603.04
1667.18
1603.96
1605.7
1567.6
1586.31
1574.09
1583.1
1665.26
1700.71
1648.22
1708.07
1791.33
1703.4
1568.45
1703
1721.59
1700.3
1677.31
1732.03
1873.06
1911.09
1830.22
1982.02
2028.01
2063.99
2054.76
2095.71
2220.4
2095.85
2082.44
2063.66
2157.46
2134.39
2107.65
2032.4
2010.07
1955.35
2196.19
1922.55
1848.43
1910.07
1801.93
1839.11
1929.96
1885.5
1822.17
1796.44
1619.07
1662.31
1693.45
1695.35
1740.72
1626.42
1554.08
1703.22
1731.05
1794.38
1671.06
1730.79
1858.04
1984.2
2029.84
2012.18
2141.24
2207.9
2382.97
2658.61
2678.85
3030.7
3306.4
3459.22
3566.19
3616.5
3333.16
3058.87
2504.72
2297.34
2175.38
2005.25
2104.92
2138.42
2314.86
2412.43
2387.14
2555.48
2623.26
2717.74
2846.45
3129.75
3536.19
3640.2
4035.4
4312.15
4712.79
5250.43
5905.08
6619.58
7500.74
9304.71
11309.3
13845.1
17635.2
22130.2
28091.9
36152.9
46327
57783.9
70224.2
81943.2
88011.2
84798.2
71512.1
53179
35193
22749.9
14937.7
10315.2
7827.44
6169.14
5186.18
4523.67
4019.9
3722.57
3666.6
3585.57
3586.48
3754.02
3965.37
4224.35
4286.27
4418.58
4579.86
4415.45
3867.69
3452.43
2831.94
2351.09
2019.72
1677.46
1409.06
1456.37
1404.5
1372.77
1523.86
1632.7
1828.08
2067.94
2225.01
2532.57
2787.5
3092.27
3562.3
4141
4734.43
5462.46
6324.43
7683.23
9293.77
11413.7
14425.9
18534.4
23753.7
30515.2
39566.2
50989.1
65225.8
82167.3
100180
116099
124966
120315
102281
76429.8
50223.9
31752.3
20374.2
14078
9896.33
7413.1
5892.38
4726.15
4003.63
3313.29
2866.74
2502.92
2225.39
1958.51
1723.66
1641.78
1509.86
1386.76
1252.17
1129.7
1050.11
970.525
879.707
856.122
728.184
710.663
678.494
643.258
603.595
557.499
548.13
481.589
445.79
428.378
484.183
449.864
407.14
332.854
263.72
305.076
301.745
286.285
279.329
258.261
214.034
214.279
188.771
248.79
245.24
214.284
218.368
196.309
191.227
198.392
202.558
145.905
147.787
155.718
108.022
114.252
100.307
94.5985
87.7933
73.012
81.2408
76.0469
97.6759
83.9613
114.461
85.25
95.2832
112.178
92.8249
88.4513
85.5607
90.3016
20.5419
20.9933
51.5394
86.3006
78.9337
77.7139
78.7366
2.24207
38.9875
56.0947
31.181
81.5205
88.6074
42.0001
-5.39667
38.7682
95.542
79.0755
58.7392
66.091
-10.1143
18.8619
7.04912
-28.571
25.2107
19.4383
73.8891
14.5447
22.5198
61.1294
84.2756
26.3902
23.7182
23.4456
51.6921
40.2406
103.063
100.007
29.0887
68.9173
21.9811
7.04836
59.3837
14.8701
13.8239
45.014
6.70044
-5.05718
6.49872
3.9985
14.3637
12.8551
56.3931
11.7418
0.472996
14.7491
69.3889
12.4894
22.4343
12.0538
36.2024
-13.0357
-16.3856
-13.293
18.2115
12.7327
57.1325
13.1146
27.2312
10.4368
-9.52993
32.0284
18.4035
31.5006
32.2395
-18.3656
0.926667
0
0
0
0
0
0
0
0
0
0
0
0
0
0
0
0
0
0
0
0
0
0
0
0
0
0
0
2.57029
end of experiment