File: data/SiO2 O1s.vms
VAMAS Surface Chemical Analysis Standard Data Transfer Format 1988 May 4
Specs
Phoibos
SPECS
?
5
Casa Info Follows CasaXPS Version 2.3.20rev1.2G
0
Created by SpecsLab Prodigy, Version 4.73.2-r95032

SourceAnalyserAngle: Not Specified
CasaRowLabel:as-loaded, #Treatments: , #Temp: RT, #Pressure: UHV, #Atmosphere:{:}, #C
NORM
REGULAR
1
1
Loop
d
0
0
0
0
1
O1s
as-loaded, #Treatments: , #Temp: RT, #Pressure: UHV, #Atmosphere:{:}, #C
2021
9
10
0
20
11
0
17
Casa Info Follows
1
Replace
0
1
CASA region (*O 1s*) (*Min Limits*) 917.46714 957.56918 2.93 2 0 0 451.90506 551 436 3 (*O 1s*) 15.9994 0 2.93
1
CASA comp (*O 1s*) (*LA(1.53,243)*) Area 2891.5865 1e-020 1402076.2 -1 1 MFWHM 1.7124088 0.34 8.5 -1 1 Position 952.86134 917.46714 957.56918 -1 1 RSF 2.93 MASS 15.9994 INDEX -1 (*O 1s*) CONST (**) UNCORRECTEDRSF 2.93
File = E:/OwnCloud/XPS lab/EX542_S818_Si+ionic liquid.sle

Group =  as-loaded, #Treatments: , #Temp: RT, #Pressure: UHV, #Atmosphere:{:}, #Comments:

First of group = 1

Spectrum ID = 42

Analyzer lens = AngleResolvedMode22:1.5kV

Analyzer slit = 4:7x20c\C:mesh

Scan mode = FixedAnalyzerTransmission

Kinetic energy start = 916.61

Sum of 60 spectra in column containing 175 scans
XPS
1
Al
1486.61
0
0
0
54.5
180
FAT
20
1
4.1408
0
0
0
0
0
O
1s
-1
kinetic energy
eV
916.61
0.1
2
counts
d
Transmission
d
pulse counting
17.5
1
0
0
0
0
1
PROPAGATION_CONVERGED
d
1
902
15.0477
350.631
2.79531
2.86341
4525.83
2.86341
4433.77
2.86325
4401.68
2.86309
4499.5
2.86293
4517.26
2.86278
4452.86
2.86262
4445.69
2.86246
4445.26
2.86231
4476.79
2.86215
4427.2
2.86199
4531.43
2.86184
4436.55
2.86168
4477.86
2.86152
4426.62
2.86137
4410.04
2.86121
4449.02
2.86105
4402.62
2.8609
4428.25
2.86074
4381.4
2.86059
4455.24
2.86043
4458.29
2.86027
4335.8
2.86012
4346.02
2.85996
4352.98
2.8598
4291.22
2.85965
4325.29
2.85949
4421.23
2.85933
4452.25
2.85918
4453.43
2.85902
4420.62
2.85887
4441.1
2.85871
4432.53
2.85855
4396.2
2.8584
4392.76
2.85824
4413.78
2.85809
4365.81
2.85793
4423.98
2.85777
4291.76
2.85762
4263.01
2.85746
4296.96
2.85731
4382.09
2.85715
4395.04
2.85699
4393.25
2.85684
4419.32
2.85668
4360.87
2.85653
4446.4
2.85637
4452.14
2.85621
4364.5
2.85606
4375.75
2.8559
4380.72
2.85575
4440.88
2.85559
4442.01
2.85544
4393.67
2.85528
4393.76
2.85513
4319.1
2.85497
4379.01
2.85481
4529.69
2.85466
4504.99
2.8545
4433.15
2.85435
4498.6
2.85419
4535.63
2.85404
4666.36
2.85388
4485.44
2.85373
4457.27
2.85357
4559.17
2.85342
4619.6
2.85326
4605.29
2.85311
4595.14
2.85295
4603.57
2.8528
4616.93
2.85264
4580.39
2.85248
4585.34
2.85233
4596.01
2.85217
4623.67
2.85202
4586.74
2.85186
4629.66
2.85171
4701.06
2.85155
4721.92
2.8514
4760.59
2.85124
4734.08
2.85109
4672.36
2.85093
4756.27
2.85078
4713.97
2.85063
4776.46
2.85047
4750.24
2.85032
4708.04
2.85016
4857.7
2.85001
4750.8
2.84985
4810.6
2.8497
4765.64
2.84954
4745.56
2.84939
4774.25
2.84923
4812.97
2.84908
4847.34
2.84892
4816.03
2.84877
4822.09
2.84861
4954.02
2.84846
4904.81
2.84831
4956.36
2.84815
5003
2.848
4919.83
2.84784
4980.39
2.84769
4954.18
2.84753
4956.74
2.84738
4988.85
2.84723
4950.67
2.84707
4959.66
2.84692
5042.85
2.84676
4991.89
2.84661
5012.98
2.84645
5005.61
2.8463
5062.55
2.84615
5130.86
2.84599
5020.8
2.84584
4948.21
2.84568
5032.15
2.84553
5146.16
2.84538
5114.19
2.84522
4970.54
2.84507
5074.6
2.84491
5105.39
2.84476
5129.54
2.84461
5063.31
2.84445
5065.58
2.8443
5182.16
2.84415
5134.72
2.84399
5209.82
2.84384
5099.78
2.84368
5194.41
2.84353
5206.91
2.84338
5151.14
2.84322
5189.57
2.84307
5238.57
2.84292
5173.39
2.84276
5198.71
2.84261
5267.34
2.84246
5275.09
2.8423
5232.82
2.84215
5284.01
2.842
5298.91
2.84184
5348.95
2.84169
5269.87
2.84154
5235.69
2.84138
5246.46
2.84123
5280.71
2.84108
5303.19
2.84092
5348.26
2.84077
5255.74
2.84062
5254.03
2.84046
5321.78
2.84031
5266.13
2.84016
5179.42
2.84
5178.06
2.83985
5194.08
2.8397
5146.37
2.83954
5079.36
2.83939
5095.35
2.83924
5106.42
2.83908
5048.54
2.83893
4955.69
2.83878
4974.28
2.83863
5090.71
2.83847
4942.5
2.83832
4901.98
2.83817
4904.04
2.83801
4955.86
2.83786
4879.31
2.83771
4780.06
2.83756
4852.23
2.8374
4808.33
2.83725
4834.75
2.8371
4685.11
2.83695
4659.48
2.83679
4684.22
2.83664
4759.94
2.83649
4730.19
2.83634
4605.82
2.83618
4569.75
2.83603
4581.44
2.83588
4669.88
2.83573
4644.51
2.83557
4539.79
2.83542
4520.43
2.83527
4620.35
2.83512
4580.38
2.83496
4563.84
2.83481
4456.1
2.83466
4422.23
2.83451
4440.38
2.83436
4403.31
2.8342
4409.27
2.83405
4407.37
2.8339
4425.23
2.83375
4432.1
2.8336
4414.11
2.83344
4440.08
2.83329
4397.27
2.83314
4245.64
2.83299
4284.7
2.83284
4286.05
2.83268
4317.48
2.83253
4346.54
2.83238
4176.78
2.83223
4168.3
2.83208
4151.32
2.83192
4277.61
2.83177
4183.28
2.83162
4210.75
2.83147
4198.53
2.83132
4198.26
2.83117
4116.68
2.83101
4124.48
2.83086
4153.22
2.83071
4121.06
2.83056
4087.67
2.83041
4084.11
2.83026
4074.87
2.8301
4088.41
2.82995
4158.14
2.8298
4022.17
2.82965
4025.78
2.8295
4081.82
2.82935
3925.26
2.8292
3928.49
2.82904
3928.99
2.82889
3910.98
2.82874
3894.54
2.82859
3796.34
2.82844
3832.64
2.82829
3808.45
2.82814
3770.79
2.82799
3787.83
2.82783
3731.76
2.82768
3663.07
2.82753
3763.56
2.82738
3740.79
2.82723
3673.71
2.82708
3744.57
2.82693
3712.65
2.82678
3544.84
2.82663
3618.18
2.82648
3647.84
2.82632
3551.1
2.82617
3559.59
2.82602
3593.57
2.82587
3599.71
2.82572
3414.73
2.82557
3425.38
2.82542
3498.99
2.82527
3405.56
2.82512
3340.58
2.82497
3354.94
2.82482
3277.33
2.82467
3315.63
2.82452
3363.98
2.82437
3307.47
2.82421
3164.04
2.82406
3177.84
2.82391
3092.83
2.82376
3111.67
2.82361
3092.13
2.82346
3086.22
2.82331
3090.66
2.82316
3099.75
2.82301
2962.83
2.82286
2982.25
2.82271
3030.13
2.82256
2972.27
2.82241
2892.62
2.82226
2782.62
2.82211
2820.78
2.82196
2815.63
2.82181
2796.59
2.82166
2756.85
2.82151
2739.46
2.82136
2689.2
2.82121
2696.99
2.82106
2680.71
2.82091
2718.11
2.82076
2637.87
2.82061
2557.95
2.82046
2618.87
2.82031
2564.81
2.82016
2684.26
2.82001
2575.35
2.81986
2511.17
2.81971
2558.96
2.81956
2560.23
2.81941
2582.32
2.81926
2530.67
2.81911
2516.05
2.81896
2518.52
2.81881
2482.97
2.81866
2500.43
2.81851
2492.91
2.81836
2518.11
2.81821
2532.01
2.81806
2482.05
2.81791
2438.89
2.81776
2496.17
2.81761
2504.66
2.81746
2423.02
2.81731
2404.79
2.81717
2430.29
2.81702
2428.36
2.81687
2470.53
2.81672
2484.52
2.81657
2409.66
2.81642
2447.98
2.81627
2452.41
2.81612
2430.46
2.81597
2455.23
2.81582
2463.96
2.81567
2508.71
2.81552
2460.8
2.81537
2362.93
2.81522
2404.75
2.81508
2428.95
2.81493
2407.65
2.81478
2443.21
2.81463
2458.33
2.81448
2499.99
2.81433
2511.25
2.81418
2415.75
2.81403
2443.59
2.81388
2409.66
2.81373
2489.36
2.81359
2484.65
2.81344
2503.02
2.81329
2456.01
2.81314
2497.67
2.81299
2515.59
2.81284
2565.55
2.81269
2587.13
2.81254
2688.51
2.8124
2683.15
2.81225
2740.02
2.8121
2813.45
2.81195
2794.13
2.8118
2847.39
2.81165
3054.37
2.8115
3157.24
2.81136
3363.43
2.81121
3670.89
2.81106
3936.41
2.81091
4452.79
2.81076
4926.19
2.81061
5585.72
2.81046
6371.67
2.81032
7374.09
2.81017
8496.51
2.81002
9767.05
2.80987
11408.6
2.80972
13359.5
2.80958
15351.7
2.80943
17324.3
2.80928
19613.5
2.80913
22073.1
2.80898
24125.5
2.80883
25586.7
2.80869
27222.7
2.80854
28500.6
2.80839
29068.7
2.80824
29222
2.80809
28899.1
2.80795
27710.1
2.8078
26069.4
2.80765
24171.7
2.8075
21966.7
2.80735
19734.9
2.80721
17467.1
2.80706
15327.6
2.80691
13266.7
2.80676
11496.4
2.80662
9881.43
2.80647
8672.65
2.80632
7587.34
2.80617
6836.92
2.80602
6144.41
2.80588
5595.63
2.80573
5055.23
2.80558
4732.27
2.80543
4361.99
2.80529
4122.62
2.80514
3894.92
2.80499
3662.1
2.80484
3427.08
2.8047
3326.68
2.80455
3109.16
2.8044
2997.08
2.80425
2962.23
2.80411
2837.84
2.80396
2731.31
2.80381
2581.83
2.80367
2615.81
2.80352
2576.91
2.80337
2513.76
2.80322
2455.47
2.80308
2445.11
2.80293
2427.9
2.80278
2480.01
2.80263
2406.76
2.80249
2402.4
2.80234
2318.48
2.80219
2323.35
2.80205
2315.77
2.8019
2282.86
2.80175
2288.26
2.80161
2334.66
2.80146
2309.22
2.80131
2299.23
2.80116
2317.93
2.80102
2268.96
2.80087
2230.54
2.80072
2246.62
2.80058
2279.29
2.80043
2278.57
2.80028
2235.51
2.80014
2217.25
2.79999
2253.57
2.79984
2252.31
2.7997
2261.74
2.79955
2241.28
2.7994
2259.23
2.79926
2219.04
2.79911
2176.96
2.79896
2186.45
2.79882
2254.58
2.79867
2229.21
2.79852
2148.65
2.79838
2243.79
2.79823
2268.92
2.79808
2230.89
2.79794
2243
2.79779
2252.96
2.79765
2217.15
2.7975
2187.57
2.79735
2213.12
2.79721
2216.88
2.79706
2166.25
2.79691
2266.91
2.79677
2221.29
2.79662
2214.85
2.79648
2160.59
2.79633
2206.43
2.79618
2247.12
2.79604
2218.65
2.79589
2240.65
2.79575
2203.74
2.7956
2185.65
2.79545
2128.74
2.79531
end of experiment