File: data/test_spectrum.vms
VAMAS Surface Chemical Analysis Standard Data Transfer Format 1988 May 4
Not Specified
Not Specified
Not Specified
Not Specified
4
Casa Info Follows CasaXPS Version 2.3.24rev1.1H
0
Created by SpecsLab Prodigy, Version 4.63.4-r87993
SourceAnalyserAngle: 56.500000 d
NORM
REGULAR
1
1
Exp Variable
d
0
0
0
0
1
test spectrum Ag3d
1. Ag in 4 mbar He
2020
3
7
17
23
10
0
14
Casa Info Follows
0
0
0
0
EX340_CEC356_effect of lens modes.sle
Group = Ag in 4 mbar He
First of group = 0
Analyzer lens = AngleResolvedMode22:1.5kV
Analyzer slit = 4:7x20c\C:mesh
Scan mode = FixedAnalyzerTransmission
Kinetic energy start = 1036.61
Sum of 28 spectra in column containing 28 scans
C:\Users\Mark\ownCloud\Muelheim Group\Projects\inelasticscattering\data\He\Au, Ag, Cu in He.vms
XPS
1e+037
Al
1486.61
0
0
0
54.5
180
FAT
20
1
4.156
0
0
0
0
0
Ag3d

-1
kinetic energy
eV
1036.61
0.1
2
counts
d
Transmission
d
pulse counting
2.8
1
0
0
0
0
3
ESCAPE DEPTH TYPE
d
0
MFP Exponent
d
0
PROPAGATION_CONVERGED
d
1
79.5553
2.57029
2718.26
2718.26
2718.26
2718.26
2718.26
2718.26
2718.26
2718.26
2718.26
2718.26
2718.26
2718.26
2718.26
2718.26
2718.26
2718.26
2718.26
2718.26
2718.26
2718.26
2718.26
2718.26
2718.26
2718.26
2718.26
2718.26
2718.26
2718.26
2718.26
2718.26
2718.26
2718.26
2718.26
2718.26
2718.26
2718.26
2718.26
2718.26
2718.26
2718.26
2718.26
2718.26
2718.26
2718.26
2718.26
2718.26
2718.26
2718.26
2718.26
2718.26
2718.26
2718.26
2718.26
2718.26
2718.26
2718.26
2718.26
2718.26
2718.26
2718.26
2718.26
2718.26
2718.26
2718.26
2718.26
2718.26
2718.26
2718.26
2718.26
2718.26
2718.26
2718.26
2718.26
2718.26
2718.26
2718.26
2718.26
2718.26
2718.26
2718.26
2718.26
2718.26
2718.26
2718.26
2718.26
2718.26
2718.26
2718.26
2718.26
2718.26
2718.26
2718.26
2718.26
2718.26
2718.26
2718.26
2718.26
2718.26
2718.26
2718.27
2718.27
2718.27
2718.27
2718.27
2718.27
2718.27
2718.27
2718.27
2718.27
2718.27
2718.27
2718.27
2718.27
2718.27
2718.27
2718.27
2718.27
2718.27
2718.27
2718.27
2718.27
2718.27
2718.27
2718.27
2718.27
2718.27
2718.27
2718.27
2718.27
2718.27
2718.27
2718.27
2718.27
2718.27
2718.27
2718.27
2718.27
2718.27
2718.27
2718.27
2718.27
2718.27
2718.27
2718.27
2718.27
2718.27
2718.27
2718.27
2718.27
2718.27
2718.27
2718.27
2718.27
2718.27
2718.27
2718.27
2718.27
2718.27
2718.27
2718.27
2718.27
2718.27
2718.27
2718.27
2718.27
2718.27
2718.27
2718.27
2718.27
2718.27
2718.27
2718.27
2718.27
2718.27
2718.27
2718.27
2718.27
2718.27
2718.27
2718.27
2718.27
2718.27
2718.27
2718.27
2718.27
2718.27
2718.27
2718.27
2718.27
2718.27
2718.27
2718.27
2718.27
2718.27
2718.27
2718.27
2718.27
2718.27
2718.27
2718.27
2718.27
2718.27
2718.27
2718.27
2718.27
2718.27
2718.27
2718.27
2718.27
2718.27
2718.27
2718.28
2718.28
2718.28
2718.28
2718.28
2718.28
2718.28
2718.28
2718.28
2718.28
2718.28
2718.28
2718.28
2718.28
2718.28
2718.28
2718.28
2718.28
2718.28
2718.28
2718.28
2718.28
2718.28
2718.28
2718.28
2718.28
2718.28
2718.28
2718.28
2718.28
2718.28
2718.28
2718.28
2718.28
2718.28
2718.28
2718.28
2718.28
2718.28
2718.28
2718.28
2718.28
2718.28
2718.28
2718.28
2718.28
2718.28
2718.28
2718.28
2718.28
2718.28
2718.28
2718.28
2718.28
2718.28
2718.28
2718.28
2718.28
2718.28
2718.28
2718.28
2718.28
2718.29
2718.29
2718.29
2718.29
2718.29
2718.29
2718.29
2718.29
2718.29
2718.29
2718.29
2718.29
2718.29
2718.29
2718.29
2718.29
2718.29
2718.29
2718.29
2718.29
2718.29
2718.29
2718.29
2718.29
2718.29
2718.29
2718.29
2718.29
2718.29
2718.29
2718.29
2718.29
2718.29
2718.29
2718.29
2718.29
2718.29
2718.29
2718.29
2718.29
2718.29
2718.3
2718.3
2718.3
2718.3
2718.3
2718.3
2718.3
2718.3
2718.3
2718.3
2718.3
2718.3
2718.3
2718.3
2718.3
2718.3
2718.3
2718.3
2718.3
2718.3
2718.3
2718.3
2718.3
2718.3
2718.3
2718.3
2718.3
2718.3
2718.3
2718.3
2718.3
2718.31
2718.31
2718.31
2718.31
2718.31
2718.31
2718.31
2718.31
2718.31
2718.31
2718.31
2718.31
2718.31
2718.31
2718.31
2718.31
2718.31
2718.31
2718.31
2718.31
2718.31
2718.31
2718.31
2718.31
2718.32
2718.32
2718.32
2718.32
2718.32
2718.32
2718.32
2718.32
2718.32
2718.32
2718.32
2718.32
2718.32
2718.32
2718.32
2718.32
2718.32
2718.32
2718.32
2718.33
2718.33
2718.33
2718.33
2718.33
2718.33
2718.33
2718.33
2718.33
2718.33
2718.33
2718.33
2718.33
2718.33
2718.33
2718.33
2718.34
2718.34
2718.34
2718.34
2718.34
2718.34
2718.34
2718.34
2718.34
2718.34
2718.34
2718.34
2718.34
2718.34
2718.35
2718.35
2718.35
2718.35
2718.35
2718.35
2718.35
2718.35
2718.35
2718.35
2718.35
2718.35
2718.36
2718.36
2718.36
2718.36
2718.36
2718.36
2718.36
2718.36
2718.36
2718.36
2718.37
2718.37
2718.37
2718.37
2718.37
2718.37
2718.37
2718.37
2718.37
2718.38
2718.38
2718.38
2718.38
2718.38
2718.38
2718.38
2718.38
2718.38
2718.39
2718.39
2718.39
2718.39
2718.39
2718.39
2718.39
2718.4
2718.4
2718.4
2718.4
2718.4
2718.4
2718.4
2718.41
2718.41
2718.41
2718.41
2718.41
2718.41
2718.41
2718.42
2718.42
2718.42
2718.42
2718.42
2718.43
2718.43
2718.43
2718.43
2718.43
2718.43
2718.44
2718.44
2718.44
2718.44
2718.44
2718.45
2718.45
2718.45
2718.45
2718.46
2718.46
2718.46
2718.46
2718.46
2718.47
2718.47
2718.47
2718.47
2718.48
2718.48
2718.48
2718.48
2718.49
2718.49
2718.49
2718.5
2718.5
2718.5
2718.5
2718.51
2718.51
2718.51
2718.52
2718.52
2718.52
2718.53
2718.53
2718.53
2718.54
2718.54
2718.54
2718.55
2718.55
2718.55
2718.56
2718.56
2718.57
2718.57
2718.57
2718.58
2718.58
2718.59
2718.59
2718.6
2718.6
2718.6
2718.61
2718.61
2718.62
2718.62
2718.63
2718.63
2718.64
2718.64
2718.65
2718.65
2718.66
2718.67
2718.67
2718.68
2718.68
2718.69
2718.7
2718.7
2718.71
2718.72
2718.72
2718.73
2718.74
2718.74
2718.75
2718.76
2718.77
2718.77
2718.78
2718.79
2718.8
2718.81
2718.82
2718.82
2718.83
2718.84
2718.85
2718.86
2718.87
2718.88
2718.89
2718.9
2718.91
2718.92
2718.93
2718.95
2718.96
2718.97
2718.98
2718.99
2719.01
2719.02
2719.03
2719.05
2719.06
2719.08
2719.09
2719.11
2719.12
2719.14
2719.15
2719.17
2719.19
2719.21
2719.22
2719.24
2719.26
2719.28
2719.3
2719.32
2719.34
2719.36
2719.38
2719.41
2719.43
2719.45
2719.48
2719.51
2719.53
2719.56
2719.59
2719.61
2719.64
2719.67
2719.7
2719.74
2719.77
2719.8
2719.84
2719.87
2719.91
2719.95
2719.99
2720.03
2720.07
2720.11
2720.16
2720.21
2720.25
2720.3
2720.36
2720.41
2720.46
2720.52
2720.58
2720.64
2720.7
2720.77
2720.84
2720.91
2720.98
2721.05
2721.13
2721.22
2721.3
2721.39
2721.48
2721.58
2721.67
2721.78
2721.89
2722
2722.12
2722.24
2722.37
2722.51
2722.64
2722.79
2722.95
2723.11
2723.26
2723.45
2723.64
2723.83
2724.02
2724.25
2724.48
2724.71
2724.94
2725.22
2725.5
2725.79
2726.09
2726.43
2726.78
2727.14
2727.52
2727.96
2728.4
2728.84
2729.34
2729.89
2730.46
2731.02
2731.68
2732.41
2733.15
2733.88
2734.78
2735.75
2736.72
2737.7
2738.95
2740.27
2741.6
2742.93
2744.72
2746.57
2748.43
2750.29
2752.97
2755.65
2758.33
2761.18
2765.21
2769.25
2773.3
2777.87
2784.27
2790.67
2797.09
2804.97
2815.79
2823.76
2835.92
2850.06
2866.62
2886.19
2909.45
2937.33
2971.07
3012.39
3063.53
3127.69
3209.45
3315.71
3456.72
3648.98
3920.47
4321.66
4946.89
5973.51
7735.96
10832.2
16231.9
25294.4
39535.6
59944.6
86033.5
114967
141534
159533
164130
153980
131971
103767
75428.2
51338.1
33358.1
21278.9
13810.2
9442.94
6955.93
5532.67
4691.98
4170.77
3830.49
3596.77
3429.66
3306.45
3214.58
3144.24
3089.53
3046.62
3014.34
2988.89
2968.79
2953.55
2944.44
2938.08
2933.96
2936.52
2941.23
2942.02
2952.93
2966.7
2983.94
3005.82
3034.94
3070.69
3114.83
3170.11
3240.42
3329.38
3443.51
3592.79
3792.31
4065.02
4450.57
5020.84
5910.54
7371.59
9876.55
14283.3
21976.6
34904
55244.9
84474.9
121930
163591
202000
228203
235172
220902
189403
148842
107964
73140.4
47113.2
29607
18767.4
12430.9
8821.03
6754.46
5533.2
4775.91
4279.93
3938.06
3692.74
3510.91
3372.74
3265.64
3181.14
3113.45
3058.56
3013.55
2976.24
2945.04
2918.74
2896.41
2877.32
2860.88
2849.59
2834.43
2825.29
2816.15
2807.01
2798.43
2792.69
2786.94
2781.2
2775.99
2772.19
2768.39
2764.6
2761.26
2758.65
2756.03
2753.42
2751.18
2749.32
2747.46
2745.61
2744.05
2742.69
2741.33
2739.98
2738.86
2737.84
2736.82
2735.81
2734.99
2734.21
2733.43
2732.65
2732.04
2731.43
2730.83
2730.23
2729.75
2729.27
2728.79
2728.33
2727.95
2727.56
2727.18
2726.82
2726.51
2726.19
2725.89
2725.6
2725.34
2725.09
2724.83
2724.6
2724.39
2724.18
2723.97
2723.78
2723.6
2723.42
2723.25
2723.09
2722.94
2722.8
2722.65
2722.52
2722.39
2722.27
2722.14
2722.03
2721.92
2721.82
2721.71
2721.62
2721.52
2721.43
2721.34
2721.26
2721.18
2721.1
2721.03
2720.96
2720.89
2720.82
2720.75
2720.69
2720.63
2720.57
2720.51
2720.46
2720.41
2720.35
2720.3
2720.26
2720.21
2720.16
2720.12
2720.08
2720.04
2719.99
2719.96
2719.92
2719.88
2719.85
2719.81
2719.78
2719.75
2719.71
2719.68
2719.65
2719.63
2719.6
2719.57
2719.54
2719.52
2719.49
2719.47
2719.44
2719.42
2719.4
2719.38
2719.35
2719.33
2719.31
2719.29
2719.27
2719.25
2719.24
2719.22
2719.2
2719.18
2719.17
2719.15
2719.13
2719.12
2719.1
2719.09
2719.07
2719.06
2719.05
2719.03
2719.02
2719.01
2718.99
2718.98
2718.97
2718.96
2718.95
2718.94
2718.92
2718.91
2718.9
2718.89
2718.88
2.57029
end of experiment