File: data/Shirley/Ag_test_H2.vms
VAMAS Surface Chemical Analysis Standard Data Transfer Format 1988 May 4
Not Specified
Not Specified
Not Specified
Not Specified
6
Casa Info Follows CasaXPS Version 2.3.24PR1.0
0
Created by SpecsLab Prodigy, Version 4.64.1-r88350
SourceAnalyserAngle: 56.500000 d
CasaRowLabel:1. Ag in 2 mbar H2
CasaRowLabel:1. Ag in vacuum
NORM
REGULAR
0
1
Exp Variable
d
0
0
0
0
2
Ag3d
1. Ag in 2 mbar H2
2020
3
13
13
1
6
0
14
Casa Info Follows
0
0
0
0
EX340_CEC356_effect of lens modes.sle
Group = Ag in 2 mbar H2
First of group = 0
Analyzer lens = AngleResolvedMode22:1.5kV
Analyzer slit = 4:7x20c\C:mesh
Scan mode = FixedAnalyzerTransmission
Kinetic energy start = 1036.61
Sum of 19 spectra in column containing 19 scans
C:\Users\pielsticker\Lukas\MPI-CEC\Projects\Gas phase background\inelasticscattering\data\H2\Au, Ag, Cu in H2.vms
XPS
1
Al
1486.61
0
0
0
54.5
180
FAT
20
1
4.156
0
0
0
0
0
Ag3d

-1
kinetic energy
eV
1036.61
0.1
2
counts
d
Transmission
d
pulse counting
1.9
1
0
0
0
0
2
ESCAPE DEPTH TYPE
d
0
MFP Exponent
d
0
75.3769
2.57029
11561.9
11584.5
11635.6
11655.9
11670.5
11669.8
11560.4
11550.4
11480.7
11711.4
11701.4
11479
11542.4
11616.9
11689.5
11534
11425.4
11676.2
11671.3
11622
11621.7
11504.8
11645.6
11723.8
11882.8
11626
11682.8
11747.4
11587.1
11600.4
11650.8
11596.5
11576.8
11553.6
11702.5
11621.7
11648.2
11654.5
11586.8
11818.6
11772.1
11697.9
11583.9
11734.4
11551.9
11710.7
11732.8
11642.3
11552.9
11709.1
11642.9
11749.5
11740.3
11623
11713.3
11705.2
11725.5
11853.5
11784.3
11721.6
11600.2
11704.3
11707.2
11718.8
11919.3
11767.2
11716.1
11695.1
11645.5
11700.8
11723.1
11707.6
11608.8
11606.2
11557.4
11671.7
11783.7
11795
11679.6
11748.6
11830.7
11781.1
11999.6
11883.1
11630.9
11592.8
11547.8
11711.8
11679.5
11702.3
11654.1
11779.6
11634.1
11716.7
11716.1
11774.5
11745.9
11693.3
11677.3
11771.9
11632.9
11658.2
11804.3
11871.2
11748.3
11719.2
11963.2
11800.4
11810.2
11769.5
11646.2
11700
11654.6
11626.7
11608.5
11661.4
11811.2
11681.9
11638
11813.8
11869.9
11823.5
11625.1
11637.8
11736.6
11752.2
11816.8
11774.1
11832.7
11812.6
11744.7
11798
11737.9
11768.1
11669.5
11782.9
11780
11789.5
11674
11864.1
11943.3
11839.7
11751.6
11774.5
11923.2
11854.5
11505
11658.9
11864.1
12086.8
11909.3
12010.9
11668.3
11752.3
11787.5
11681.2
11715.6
11843.3
11833.9
12002
11785.5
11660.8
11688.1
11661.2
11651.6
11670.7
11877.9
11741.7
11785
11736.8
11711
11971.8
11947.2
11776.9
11833.9
11872.3
11872.2
11933.3
11840.6
11876.6
11856.5
11949.2
11889.9
11952.2
11923.1
11902.4
11720.5
11774
11854.9
11876.5
11914.2
11999
11977.4
12089.3
11861.2
12025.5
12059
11968.2
11838.8
11893.3
11902.7
11881.3
11908.9
11969.1
11944.6
11904.8
11780
11941.1
11997.6
11948.8
12030.2
12015.5
11945.3
11933
11983.7
12122.6
12022.1
11953.8
11965
11991.1
12008
12196.7
12001
12117.9
12129.8
11879.9
11767
12029.1
11955.9
11998.3
12008.1
11908.2
11884.9
11890.1
12056.1
12002.9
12027.5
12058.9
12170.2
12064.4
12035.6
11933.1
12158.7
12020.2
12017.6
12183.3
12269.7
12139.2
12136.2
11877.5
12117.2
12154.8
12077.6
12207.9
12273
12095.7
12124
12054.1
12261.4
12248
12191.9
12159.6
12131.7
12002.8
12196.8
12255.1
12271.4
12296.7
12222.2
12276.3
12238.2
12142.7
12124.1
12143.3
12155
12152
12150.8
12416.2
12287.3
12255.4
12214.9
12232
12260
12153.2
12176.7
12323.3
12309.9
12352.8
12374.5
12264.6
12090.3
12213.5
12232.2
12168.8
12295.1
12371
12336.9
12277.1
12115.9
12183.6
12210
12207.3
12258.3
12175.3
12175.4
12439.4
12390.6
12192.5
12281.5
12207.6
12131.3
12269
12278.5
12305.2
12214.1
12160.1
12329.8
12181
12214.9
12422.5
12410.7
12355.6
12411.1
12421.7
12295.3
12234.8
12391.6
12483.4
12351
12443.7
12397.8
12270
12353
12385
12516.3
12408.4
12329.4
12455
12372.7
12365.9
12266.8
12180.1
12499.7
12595.6
12499.8
12592.7
12465
12316.3
12495.2
12651
12387.2
12429.6
12590.6
12403.1
12469
12566.2
12680.4
12699.7
12559.7
12662.3
12531.5
12629.6
12560.3
12637.1
12645.7
12599.5
12554.5
12624.1
12636.8
12569.7
12452.1
12547.5
12587.6
12546.2
12477
12536.5
12656.2
12580.7
12677.9
12702.7
12685.5
12805.9
12679.9
12661.2
12732.5
12585.7
12817.7
12658.9
12471.5
12709.4
12760.1
12766
12837.4
12921.5
12862
12811.9
12763.3
12739.3
12694.1
12844.9
13016.4
12806.7
12904.2
13001.7
12990.2
12921.4
12937.1
12741.1
12804.6
12782
12967.9
12957.4
12972.4
12934.1
12997.2
12843.9
12861.4
12840.7
12933.6
13006.7
12998.9
12994.6
12951.7
13048.4
12943.5
13063.1
12997
12969.9
13167
13007.7
12874.2
12889.2
13143.7
13154.7
13223
13306.9
13082.2
13252.1
13096.5
13255.2
13155.7
13125.4
13018.4
13134.5
13238.8
13205.3
13221.5
13158.2
13132.4
13191.2
13116.1
13149.5
13252.8
13330.2
13311.9
13289.4
13286
13290.8
13317.4
13451.6
13338.7
13390.2
13612.8
13312.1
13382.8
13594.3
13372.1
13338.9
13525
13612.3
13570
13528.6
13687
13469.1
13390.3
13570.5
13544.3
13540.1
13517.5
13520.6
13539.2
13492.3
13676.5
13897.6
13833.5
13773.1
13735.1
13744.7
13912.6
13852.5
13853.2
13967.1
14025.6
13917.7
13920.7
13944.6
13969.5
13968.9
14015.6
14049.9
14049.5
14048
13991.4
14044.9
14231.1
14353.6
14383.3
14284.6
14223.1
14279.3
14452.2
14346
14171.5
13935.8
14043.3
14130.8
14239.5
14117
14032.8
13994.6
14000.2
13967.5
13961.3
13970.9
13981.5
14020.5
13934.9
13830.1
14108.8
14008.3
13875
14016
14097.3
13975.7
14093.2
14100.1
14204.6
13941.3
14081.6
14147.9
14111.3
14133.8
14194.2
14287.4
14514.7
14331.9
14406.3
14225.4
14302.7
14309.3
14374.1
14479.4
14439.4
14583.4
14779.2
14838.5
14753.9
14846.7
14881.6
15077.9
14904.1
14936.1
14752.4
14873.8
14976
14943.2
15001.2
14985.3
14915.5
14861.2
14765
14939.7
15056.4
15088.6
14841.2
14902.6
14909.1
14933.6
14750.5
14858
14852.8
14688.8
14877.5
14809.8
14779.3
14735
14952.6
14931.4
14876.1
14924.9
14874.5
14831.2
15035
14908.4
15001.9
15055.7
15100.7
15143.3
15048.4
14900.2
14964.3
15109.5
14964.4
15027.9
14938.7
14978.2
15099.2
15262.4
15150.4
15323.3
15177.6
15418.5
15486.9
15351.4
15334
15220.8
15333.9
15352.8
15500.6
15715.9
15936
16013.1
16203.4
16568.8
17004.6
17128.5
17455
17978.1
18368.8
18501.2
18783
18744.9
18830.1
18543.8
18203.4
17885.7
17609
17052.3
16773.4
16393.6
16005.6
15545
15117.4
14782
14547.8
14110.2
13851.6
13744.3
13538.8
13383.3
13614.3
13566.8
13349.6
13533.9
13420.6
13498.7
13480.7
13412.3
13625.5
13572.8
13572.8
13584.4
13699.2
13441.4
13736.9
13667.4
13730.7
13867
13644.9
13689.9
13971
13841.7
13890.1
14061.1
13992.5
13934.6
14188
14093.8
14186.5
14350.5
14533.9
14567.9
14881.6
15394.7
15655.2
16098.5
16546.2
17097.7
17499.6
17776.9
18081.6
18057.2
18196.3
18032.7
17662.6
16991.6
16449.2
15687.7
15052.2
14017.7
13409.6
12999
12349.9
11953.2
11657.5
11044.8
10591.5
10585.5
10448.2
10313.1
10082.6
10109.9
10200.4
10213.8
10536.1
10557.3
10672
10957
11243
11494.9
11629.4
11518.2
11436.3
11354.2
11031
10832.7
10400.5
10316.7
10157
10106.4
10013.7
10147.4
10206
10206.8
10384.5
10607.5
10728
10815.6
11075.9
11321.1
11656.9
11896.4
12257.5
12725.2
13192
13896.5
14763.8
15719.7
17141.6
19117.4
22152.4
26625.2
33582.5
43318.8
57468.9
74850.4
93390.3
107111
111095
104582
88986.1
68274.6
47903.5
32301.7
22847.9
17092.9
13978.3
12103.4
10924.4
10180.3
9721.88
9402.23
9248
8928.65
8868.25
9076.9
9301.12
9495.57
9653.96
9980.5
9934.11
9875.02
9706.89
9376.59
8833.32
8224.31
7863.67
7558.45
7328.34
7101.76
7042.67
6882.32
7068.25
7245.91
7271.99
7407.89
7660.71
7868.99
8252.69
8583.35
8797.49
9262.59
9971.83
10610.8
11338.1
12456
13707.3
15305.5
17411.8
20461.9
24812.5
31347.8
41298.4
55695.2
75584.5
100526
126759
147039
153252
144305
122131
92414.2
63613.9
40908.7
26784
18648.3
13718.7
10755.3
8772.33
7478.88
6502.22
5710.42
5272.49
4823.36
4410.9
4140.85
3903.59
3700.19
3546.43
3358.13
3264.72
3173.32
3133.94
3040.37
2939.17
2860.47
2765.2
2669.98
2608.92
2530.97
2498.37
2511.09
2491.29
2463.37
2398.33
2420.52
2363.52
2225.81
2170.08
2205.81
2174.55
2166.76
2201.05
2148.34
2116.09
2172.17
2212.34
2172.82
2107.48
2083.27
2090.89
2137.58
2086.8
2097.63
2076.11
2015.3
2032.81
2105.73
1979.18
2022.16
1986.78
1965.13
1954.6
1967.52
1933.73
1853.56
1866.17
1859.72
1904.6
1925.27
1881.14
1868.77
1892.51
1955.63
1903.34
1924.36
1890.38
1865.87
1897.15
1858.42
1868.85
1864.5
1877.63
1863.31
1899.8
1884.49
1907.43
1913.14
1807.43
1847.32
1844.6
1838.66
1822.83
1859.93
1891.2
1852.73
1826.05
1870.99
1859.65
1848.21
1860.22
1828.22
1809.5
1848.08
1827.77
1835.28
1882.76
1796.73
1852.08
1851.16
1867.66
1795.22
1820.14
1851.97
1829.21
1841.13
1879.65
1830.81
1920.35
1886.64
1833.04
1867.58
1892.09
1892
1884.7
1851.61
1822.95
1779.33
1810.62
1783.16
1806.66
1848.59
1828.17
1821.29
1823.75
1842.75
1852.99
1853.12
1836.74
1855.1
1841.78
1867.58
1842.06
1802.93
1839.79
1879.45
1846.3
1841.34
1876.52
1844.02
1772.02
1845.66
1786.64
1802.99
1779.63
1828.91
1830.47
1840.02
1796.92
1846.3
1858.08
1841.84
1812.68
1787.92
1829.93
1857.73
1851.22
1890.09
1782.31
1761.21
1845.95
1874.56
1835.6
1805.32
1827.53
1778.7
1876.46
1784.85
1818.85
1815.87
1891.93
2.57029
Ag3d
1. Ag in vacuum
2020
3
13
14
35
59
0
14
Casa Info Follows
0
0
0
0
EX340_CEC356_effect of lens modes.sle
Group = Ag in vacuum
First of group = 0
Analyzer lens = AngleResolvedMode22:1.5kV
Analyzer slit = 4:7x20c\C:mesh
Scan mode = FixedAnalyzerTransmission
Kinetic energy start = 1036.61
Sum of 4 spectra in column containing 4 scans
C:\Users\pielsticker\Lukas\MPI-CEC\Projects\Gas phase background\inelasticscattering\data\H2\Au, Ag, Cu in H2.vms
XPS
1
Al
1486.61
0
0
0
54.5
180
FAT
20
1
4.156
0
0
0
0
0
Ag3d

-1
kinetic energy
eV
1036.61
0.1
2
counts
d
Transmission
d
pulse counting
0.4
1
0
0
0
0
2
ESCAPE DEPTH TYPE
d
0
MFP Exponent
d
0
87.5029
2.57029
2857.07
2833.24
2753.74
2827.88
2856.6
2902.86
2835.15
2844.66
2914.41
2919.88
2870.02
2831.2
2791.87
2809.29
2784.89
2785.64
2857.52
2864.09
2893.91
2947.89
2853.47
2803.86
2815.62
2809.02
2813.64
2834.08
2924.81
2885.83
2811.12
2821.32
2817.78
2803.53
2814.24
2809.68
2812.68
2900.34
2838.2
2797.34
2915.54
2836.12
2858.81
2824.22
2856.88
2784.49
2806.88
2787.68
2834.64
2850.56
2853.22
2913.78
2875.91
2804.38
2825.66
2826.59
2889.53
2806.19
2850.18
2794.33
2830.88
2870.87
2887.74
2879.71
2763.05
2824.13
2904.93
2814
2837.23
2865.99
2877.54
2817.03
2811.28
2829.14
2915.02
2897.72
2913.74
2917.09
2872.98
2817.97
2834.58
2775.73
2797.24
2920.83
2884.78
2755.06
2793.57
2926.67
2788.7
2856.42
2929.77
2901.64
2800.05
2844.16
2852.03
2884.01
2815.21
2851.71
2896.59
2891.09
2910.82
2886.41
2828.57
2870.98
2863.45
2763.47
2921.9
2872.13
2896.59
2899.54
2813.72
2840.9
2866.55
2824.61
2881.07
2891.4
2821.69
2811.37
2815.88
2879.1
2876.46
2897.74
2929.32
2831.61
2898.3
2826.59
2870.7
2930.03
2913.86
2875.25
2864.6
2857.12
2854.86
2865.56
2975.06
2874.53
2848.15
2932.27
2884.38
2824.96
2780.2
2835.28
2831.58
2841.45
2848.68
2831.33
2927.88
2827.66
2815.38
2821.91
2952.84
2942.23
2860.44
2866.47
2884.01
2947.74
2918.27
2860.45
2872.96
2887.47
2880.9
2853.69
2854.92
2846.6
2842.88
2898.5
2895.38
2860.28
2833.48
2912.11
2879.87
2851.6
2868.33
2875.27
2831.02
2949.88
2889.25
2869.24
2921.86
2862.44
2873.25
2824.2
2876.18
2924.51
2926.12
2874.97
2904.18
2956.28
2879.48
2881.68
2994.59
2910.18
2905.13
2848.52
2887
2879.43
2824.69
2925.28
2934.87
2930.14
2879.33
2854.12
2970.2
2850.45
2869.01
2901.55
2840.93
2935.93
3009.17
2903.34
2864.32
2778.66
2813.71
2838.78
2815.07
2893.96
2881.9
2881.74
2887.96
2876.42
2892.73
2816.94
2869.63
2968.86
2910.99
2946.13
2855.23
2921.57
2968.34
2952.94
2893.45
2941.58
2934.22
2951.3
2910.86
2866.72
2926.35
2847.54
2941.95
2939.61
2879.07
2958.68
2956.63
2924.05
2955.88
2993.39
2913.42
2929.11
2912.11
2915.74
2905.65
2947.91
2895.24
2894.6
2951.24
2923.02
2910.36
2915.89
2951.38
2977.15
2922.69
2973.22
2943.33
2921.53
2848.78
2928.97
2947.51
3031.16
2975.52
2950.4
2942.34
2945.98
2972.95
2903.4
2950.14
2971.88
2935.49
2900.21
2923.83
2870.42
2947.54
3010.51
2965.95
2930.52
3029.26
2977.83
2888.59
2936.33
3002.61
2897.95
2891.69
2887.72
2916.82
2965.49
2924.38
2862.38
2921.18
2943.74
2891.38
2880.75
3033.13
2943.17
2918.03
2909.36
2855.42
2963.12
2895.88
2883.71
2847.43
2925.27
2963.9
2983.75
3009.15
2854.5
2894.17
2935.44
2998.28
2990.69
2903.16
2936.09
2999.13
2910.88
2941.52
2939.88
2908.63
2995.1
2937.8
2923.75
2989.95
2998.03
3005.36
3054.81
2933.66
2929.4
2972.44
2965.8
2962.32
2904.13
2883.32
2968.61
2964.36
2968.41
3073.41
3058.68
2974.54
2894.24
2888.41
2976.36
2950.64
2991.97
3079.25
3108.32
3004.79
3018.74
2950.6
2990.63
2958.41
2933.39
2976.81
3000.77
3004.45
3007.48
2956.53
2971.81
2947.77
2929.17
2969.15
3064.49
2989.85
2981.6
2974.2
3023.31
3007.52
3017.24
3014.45
3008.97
2958.98
2889.68
2984.94
2931.97
2965.55
2977.76
2997.68
3003.62
3004.46
3025.39
2959.37
3012.7
2968.01
3054.8
3021.45
3060.95
3031.29
3011.57
2998.85
2951.7
3003.13
3027.36
2964.37
2931.05
3081.93
3123.57
3075.26
3116.1
2998.04
3072.63
3074.81
3035.77
3053.81
3040.81
3073.69
3070.02
3047.09
3102.36
3053.62
3077.33
3099.54
3069.23
3084.92
3087.68
3113.02
3139.43
3097.69
3077.47
3120.02
3047.38
3068.78
3060.61
3142.76
3122.78
3038.49
3127.28
3094.88
3068.11
3038.64
3047.34
3130.5
3129.59
3216.2
3093.19
3141.22
3150.3
3084.52
3031.01
3217.9
3084.27
3123.73
3143.2
3134.74
3123.84
3174.03
3138.98
3119.17
3146.91
3150.99
3108.57
3129.99
3147.61
3116.07
3145.63
3148.45
3208.43
3122.01
3175.25
3231.26
3156.68
3174.24
3223.46
3203.68
3149.39
3280.24
3268.96
3193.21
3223.91
3210.82
3260.6
3223.96
3135.29
3189.53
3233.24
3333.09
3245.2
3269.78
3221.3
3209.04
3256.45
3307.28
3289.22
3255.82
3237.78
3275.11
3264.36
3343.32
3336.19
3323.76
3375.38
3340.91
3388.2
3345.19
3348.08
3269.96
3330.75
3431.02
3392.59
3372.96
3341.52
3428.71
3372.38
3398.35
3440.37
3367.41
3382.53
3407.72
3424.47
3355.38
3305.16
3328.7
3314.24
3332.17
3491.76
3503.91
3410.09
3421.63
3399.37
3331.52
3404.76
3482.84
3494.73
3411.11
3417.88
3370.8
3405.29
3375.84
3368.85
3330.82
3348.01
3356.18
3351.42
3495.16
3414.51
3393.13
3388.24
3364.01
3393.94
3496.37
3427.43
3427.79
3324.78
3377.26
3418.83
3444.08
3438.36
3488.08
3585.66
3505.28
3492.09
3385.32
3488.32
3552.28
3531.58
3485.02
3609.61
3597.38
3422.58
3532.72
3551.38
3621.11
3518.45
3606.83
3520.13
3519.25
3532.14
3584.9
3632.09
3577.63
3511.58
3544.34
3504.88
3557.62
3534.93
3519.11
3553
3514.45
3469.07
3549.94
3466.39
3537.65
3581.88
3497.81
3477.45
3504.41
3512.93
3502.92
3432.27
3479.97
3464.88
3317.52
3399.24
3397.01
3393.53
3365.97
3416.69
3420.46
3388.05
3400.43
3433.83
3425.58
3403.39
3456.49
3399.07
3345.04
3402.03
3371.74
3432.74
3355.07
3437.66
3483.19
3359.01
3302.25
3348.37
3381.98
3429.99
3395.65
3453.45
3386.55
3404.85
3426.98
3421.97
3362.25
3402.09
3404.76
3366.09
3323.59
3379.06
3465.26
3321.06
3343.85
3468.32
3416.9
3393.53
3409.52
3407.01
3309.99
3361.74
3229.14
3297.41
3257.09
3150.22
3334.64
3255.33
3353.49
3226.97
3258.86
3258.15
3279.29
3252.84
3193.7
3252.05
3274.7
3192.37
3227.01
3234.53
3130.44
3160.7
3199.93
3255.71
3098.26
3191.3
3193.95
3237.19
3348.51
3277.1
3214.74
3303.56
3240.53
3207.37
3294.33
3226.99
3298.35
3266.27
3208.01
3167.23
3168.6
3099.28
3206.05
3152.47
3156.7
3174.34
3280.57
3186.04
3127.64
3124.07
3175.14
3128.05
3125.43
3151.22
3060.29
3068.77
2946.58
2960.66
3028.48
2976.23
2999.45
3004.24
2964.88
3029.37
3067.67
3064.59
3067.84
3082.77
3054.58
3051.35
3035.32
3051.1
3112.17
3189.03
3198.9
3230.24
3316.85
3356.5
3464.4
3558.9
3586.2
3642.66
3582.36
3542.15
3459.33
3334.59
3206.19
3134.68
3053.94
3085.31
3118.62
3187.76
3190.69
3161.97
3292.48
3248.87
3350.62
3368.89
3418.73
3528.8
3601
3643.9
3752.03
3920.24
4084.01
4363.17
4597.26
4895.09
5284.81
5960.07
6960.25
8264.58
10592.6
13791.5
18335.9
23986.2
29952.4
34124.8
35775
33765.5
28898
22114
15286.7
10189.8
7196.63
5508.77
4360.2
3837.42
3391.18
3085.54
2975.7
2862.63
2717.83
2687.35
2698.81
2657.41
2828.3
2891.34
3019.78
3153.05
3136.5
3023.93
2954.21
2827.72
2700.78
2560.35
2427.98
2217.05
2167.76
2179.52
2142.49
2061.99
2182.71
2159.07
2149.41
2248.25
2343.76
2365.24
2447.95
2529.86
2712.54
2843.44
3115.59
3291.44
3504.81
3865.72
4261.89
4742.92
5438.01
6441.88
7765.33
9944.58
13232.6
17596.2
24208.9
32420.9
40928.7
47382.8
49208.8
46211.1
39223.6
29837.3
20322.9
13114.5
8457.25
5806.82
4231.13
3259.78
2701.71
2201.08
1993.08
1758.94
1508.68
1394.8
1242.44
1189.03
1108.74
1076.66
967.283
981.759
914.749
912.61
866.324
798.27
810.996
797.105
733.067
706.667
701.751
743.889
718.557
681.297
662.937
672.93
595.24
603.936
593.299
602.854
567.709
592.83
561.154
564.906
542.357
555.85
520.702
544.698
542.382
581.561
533.89
501.88
504.277
509.75
543.529
537.075
535.111
514.576
485.351
501.943
488.189
467.946
489.193
488.079
487.648
487.527
466.997
483.415
488.342
468.792
484.675
463.817
490.386
521.197
437.96
473.591
447.887
472.047
460.992
486.831
443.75
462.357
470.029
439.674
483.18
473.886
447.907
438.704
451.076
441.545
447.033
466.001
471.768
460.631
471.637
432.706
436.755
431.541
448.36
446.789
471.727
465.895
439.112
440.675
444.204
456.214
435.53
418.248
431.956
424.728
446.64
467.1
449.988
446.62
430.343
453.128
438.585
446.686
440.987
434.129
446.087
458.334
461.08
432.505
422.364
463.508
450.416
437.516
435.055
478.485
442.623
446.841
431.248
457.673
431.707
437.824
429.878
429.419
441.681
432.305
435.763
438.638
445.324
444.572
458.841
450.185
431.635
436.597
429.15
462.607
454.111
443.606
454.599
478.454
441.647
449.955
418.446
429.237
421.486
442.965
432.843
436.575
432.657
435.84
407.023
465.513
436.505
444.331
440.031
429.901
444.949
442.046
433.93
444.731
431.573
429.822
425.235
440.348
460.461
425.515
412.668
446.56
437.912
2.57029
end of experiment