File: data/Shirley/Au_test.vms
VAMAS Surface Chemical Analysis Standard Data Transfer Format 1988 May 4
Not Specified
Not Specified
Not Specified
Not Specified
9
Casa Info Follows CasaXPS Version 2.3.20rev1.2G
0
Created by SpecsLab Prodigy, Version 4.63.4-r87993
SourceAnalyserAngle: 56.500000 d
CasaRowLabel:Au in vacuum
CasaRowLabel:Au in vacuum, short shirley
CasaRowLabel:Au in vacuum, long shirley
CasaRowLabel:Au in vacuum, short shirley, background subtr.
CasaRowLabel:Au in vacuum, long shirley, background subtr.
NORM
REGULAR
1
1
Exp Variable
d
0
0
0
0
5
Au4f
Au in vacuum
2020
3
8
7
22
34
0
14
Casa Info Follows
0
0
0
0
EX340_CEC356_effect of lens modes.sle
Group = Au in vacuum
First of group = 0
Analyzer lens = LargeArea:1.5kV
Analyzer slit = 4:7x20c\C:mesh
Scan mode = FixedAnalyzerTransmission
Kinetic energy start = 1311.61
Sum of 20 spectra in column containing 20 scans
C:\Users\pielsticker\Lukas\MPI-CEC\Projects\Gas phase background\inelasticscattering\data\N2\Au, Ag, Cu in N2.vms
XPS
1
Al
1486.61
0
0
0
54.5
180
FAT
20
1
4.156
0
0
0
0
0
Au4f

-1
kinetic energy
eV
1311.61
0.1
2
counts
d
Transmission
d
pulse counting
2
1
0
0
0
0
2
ESCAPE DEPTH TYPE
d
0
MFP Exponent
d
0
259.839
2.30555
19490.5
19696.1
19545.9
19546.8
19671.3
19640.1
19592
19658.5
19837.5
19785.1
19689
19770.4
19912.4
19813.6
19924.8
20051.1
20043.3
19892
19967.8
19894.5
19866.2
20155.4
19961.8
19820.4
19964.9
19871.8
19868.8
19930.1
19882.3
20041.4
19821.9
19908.4
20153.2
20024.9
19995.5
19913.7
19897.8
19880.1
19771.3
19960.6
19997.1
19974.1
19827.4
19826.9
19913.6
20047.6
20200.6
19995.5
20009.4
20303
20043.7
20195.2
19972.5
19989.3
20011.9
19946.7
19920.4
20100
20103
20087.9
20031.5
20070
20036.6
20019.6
20051.7
20029.6
19944.4
19678
19948.2
20143.6
20194.3
20184.5
20013.6
20293
20286.6
20047.9
20011.8
20258.1
20167.3
20431.7
20208.9
20137.6
20093.4
20239.9
20256.8
20161.2
19877.8
20019.7
20340.1
20221.8
20090.5
20167.8
20287.4
20165.6
20075
20043.8
20250.4
20105.4
20181.9
20240.9
20290.3
20019.8
20010
20383.7
20306.2
20299.6
20218.8
20391.9
20415.2
20329.1
20531.8
20324.6
20206.2
20369.6
20528.4
20386.6
20468.4
20666.1
20524.2
20683.1
20527.3
20645.3
20457.2
20559.4
20636.2
20700.5
20627.1
20715.6
20792
20656.4
20621.1
20771.3
20748.3
20496.1
20606.7
20697.1
20856
20551.9
20731.8
20949.8
20788.6
20729.8
20515.7
20492.7
20609.8
20449.1
20368.1
20587.8
20638.2
20475.4
20573.9
20593.3
20563.2
20482.5
20556.8
20620.7
20593.5
20760.2
20765.8
20526.6
20451.7
20505.6
20591
20728.2
20687.3
20529.3
20604.1
20765.5
20784.9
20953
20874.5
20642.3
20596.4
20630.8
20778
20895.3
20883.7
20799.1
20852.4
20898.2
20670.3
20871.6
20850.2
20848.4
20878.8
20774.7
20778.6
20741.6
20943.2
21036.1
21068.6
20991.4
21048.8
20857.3
20932.3
20930.3
21132.5
21160.9
21009.8
21027.4
20866.4
21035.2
21051.9
20869.1
20993.4
21122.9
21290.8
20931.7
21030.9
21269.4
21085.2
21149.2
21183.1
20969
21143.2
21189.7
20974.6
21200.6
21387.1
21231.8
21278.9
21283.1
21040.6
21195.5
21202.5
21287.3
21397.7
21271.3
21163.8
21216.5
21288.6
21174.2
21281.5
21235.4
21615.1
21606.9
21434.2
21460.2
21370.5
21386.2
21251.1
21275.2
21452.8
21341.8
21247.7
21183.9
21309.6
21455.1
21562.9
21602.2
21343
21270.1
21324.6
21623
21532.2
21599.5
21735.1
21579.1
21537.5
21578.3
21574.1
21582.9
21489.8
21698.5
21611.4
21526.8
21745.4
21588.6
21419.7
21517.9
21582
21569.5
21633
21578.4
21752.3
21719.9
22062.3
21689.8
21752.5
21839.1
21807.5
22055.3
21899.9
21770.2
21893.4
21817.9
21750.9
21883.1
21682.5
21797.6
21645.6
21760.4
21831.1
21768.2
21893.9
21795.1
21686.6
21746.9
22007.4
21793.3
21719.5
21979.2
21810.3
22020.3
22038.4
22003.5
21846.8
21858.9
21611.4
21724.9
21817.5
21793.7
21751.1
21735.8
21853.7
21861
21885.5
21736.4
21795.6
21913.9
21823.1
21790.4
21817.9
22029.9
22004.7
21947.5
22046.7
22004.1
21895.9
21857.5
22153.1
22142.8
22024.5
21835.9
22085.5
22066.4
22096.1
21836.3
21944
21850.2
21980.8
22124.4
22274.7
22262.4
22121.5
22139.1
22081
22047.1
22002.6
22162.2
22301.3
22251.8
22319.1
22185.5
22109.5
22144
22334
22323.1
22171.5
22235.2
22302.1
22123.6
22151.8
22157.2
22256.2
22419.3
22231.3
22103.5
22110.5
22043.6
22142
22162.8
22264.8
22140.6
22077.2
22059.9
22401.6
22246.1
22193.1
22513.9
22619.6
22390.7
22323
22293.7
22200.9
22251
22202
22521.9
22461.3
22535.1
22358.9
22126.2
22564.5
22453.2
22463.6
22556.4
22228.8
22457.6
22499.1
22460.1
22719.3
22400
22347
22556
22505
22785.4
22613.5
22445.2
22676.5
22674.2
22722.2
22774.8
22600.5
22603.5
22744.2
22738.7
22772.8
22650.8
22637.5
22531.1
23005.1
22942
22720.7
22704.1
22782
22678.8
22991.3
22850.1
22869.8
22934.1
22942.2
22786.9
22766.3
22760.1
22915.4
22827.6
22917.4
22954.3
22974.6
22973
22917.5
22971.2
23173.7
23018.3
22746.7
22789.7
23043.4
23113.6
22963.7
23113.3
23104
23057.1
23149.7
23199.2
23009
23156.2
23115.9
23121.5
23148.9
23109
23264.4
23120.3
23226.8
23493.8
23276.8
23278.5
23066.9
23206.6
23251.2
23204.2
23348.4
23375
23443.3
23482.8
23197.6
23462.1
23653.3
23541.2
23449.6
23413.2
23375.7
23594.9
23622.1
23722.3
23658.5
23749.6
23635.5
23608.9
23780.6
23595.9
23615.2
23618.1
23817.8
23967.4
23826.8
23660.9
23957.5
23833.9
23960.1
23888.8
23924.5
23891.7
23912.4
24048.8
24017.1
24119.5
24262
24285.5
24006.2
24091.7
24115.8
24105.4
24275.1
24360
24273
24446.6
24356.8
24506.2
24472.8
24640.1
24504.4
24534.7
24672.8
24657.5
24539.2
24670.5
24485.2
24710.7
24743.2
24765.6
24434.6
24500.7
24737.6
24911.3
24859.7
24796.5
24707.3
24883.7
25158.4
25062.3
25049.2
24921.5
24973.9
25069.2
25279
25134
25166.2
25141.8
25338.1
25164.7
25381.9
25198.3
25435.9
25285.2
25203.5
25376.1
25289.9
25344
25363.2
25435.6
25544.9
25756.4
25656.7
25476.3
25727.1
25617.8
25489.7
25717.2
25581.4
25466.5
25639.5
25583.5
25350.3
25386.3
25336.8
25755
25430.3
25581.1
25596.9
25413.1
25361.3
25566.6
25467.7
25538.2
25519.4
25762.2
25855.8
25565
25675.6
25814.3
25729.5
25861.3
25635
25548.9
25754.3
25959
25822.4
25913.5
26141.6
25921.4
26139.5
25977.8
25871.1
26238
26295.2
26254
25957
26221.8
26180.6
26318.2
26288.6
26229.7
26413
26266
26527.4
26183.9
26450.6
26545.5
26287.1
26555.2
26529.5
26457.6
26436
26709.2
26594.4
26737.2
26905.7
26774.8
26751.1
26889.7
26837.2
26720.6
26803.9
26856
26876.4
26776.5
26890.2
27099.9
26920.5
26961.6
26848.6
27100
26967.5
26965.2
26973
26973.5
26761.2
26701.1
26710.8
26625.8
26593.9
26722.7
26623.7
26690.2
26614.1
26592.4
26594.6
26431.3
26441.4
26237.8
26443.3
26598.9
26156.8
26514
26311
26351.6
26521.3
26336.3
26277
26086.6
25973.8
25994.6
25768.3
25703.5
25686.3
25732.8
25800.7
25662.8
25711.7
25494.9
25567.6
25581.2
25353.2
25367.2
24984.3
25053.3
24939.8
25037.3
25045.7
25007.1
25054.2
25045.4
24640.3
24791.6
24712.9
24753.7
24751.6
24710.2
24603.7
24546.5
24647.7
24786.6
24725.8
24730
24689.8
24696
24582.1
24574.7
24845.7
24641
24850.3
24872
24683.2
24739.9
24803.9
24702.4
24878.5
24760.8
24470.1
24592.4
24934.5
24861
24533
24515.6
24728.2
24699.5
24862.8
24800.1
24675.1
24671.2
24874.4
24954.9
24936.5
25012.1
24800.4
24480.7
24588.5
24934.1
24870.6
24891.7
24805.2
24864.8
24953.1
24874.5
24992.8
25188
24688.2
25044
25190.9
25302
25355.6
24994.5
25201.4
25298.6
25111.8
25120.2
25121.6
25251.1
25213.3
25215.3
25044
25163.7
25188.9
25258.5
25295.9
25182.4
25399.3
25134.5
25224.6
24994.7
25092.7
25102.6
24876.2
24882.3
24612.2
24883.1
24781.9
24562.7
24445
24272.7
24298
24253.9
24151.4
24136.7
24125.3
23849.7
23649.2
23644.5
23560.4
23530.5
23539.1
23560.9
23555.9
23617.8
23718.8
23977.7
23837.2
23865.2
23768.9
23981.8
23972.7
24008.1
24001.5
24320.4
24375.2
24239.7
24557.2
24271.8
24377.7
24224.5
24379.5
24028.5
24147.1
24168.2
24057.4
24144.8
24043.9
23819.7
23893
23647.7
23666.9
23554.3
23335
23099.7
23088.4
23179.7
23069.4
23198.3
23182
23407.5
23433.6
23656.8
23698.5
23832.9
24158.4
24196.5
24476.6
24920.6
25283.5
25227.5
25349.8
25856.7
26056.5
26230.2
26480.2
26657
26910.9
27019.7
27113.7
26920.4
27110.7
27385.4
27606.2
27914.4
28414.1
29386.5
30358.5
31857.3
33989.6
36373.5
39865
44203.5
49900.2
57516.7
67378.6
80542.6
97517.6
119965
147050
179710
216247
251653
276570
281758
261219
221820
173540
129935
96041.9
72332.7
56244.6
46178.1
39437.9
35138.8
32010.9
30117.5
28426.3
27128.5
26410.7
25824
26088.3
26088.7
26923.1
27907.2
29492.4
31766.7
34741.1
38762.9
44526.8
52110.3
62035.4
75265.2
93219.5
115792
145643
183651
227441
275542
319381
348983
348164
314238
256494
193109
136929
96058.2
67713.6
49029
36944.3
29297.3
23873.8
20339.1
17674.5
15914.4
14460.2
13206.1
12362.2
11473.6
10739.7
10399.4
9792.32
9437.47
9016.35
8710.15
8339.87
8062.29
7945.59
7576.2
7378.66
7287.91
7103.73
6830.18
6750.55
6693.94
6495.26
6423.26
6360.64
6304.91
6264.83
6153.13
6056.15
6024.83
6016.35
5819.24
5823.56
5833.5
5742.56
5757.47
5679.74
5613.19
5576.24
5505.17
5534.52
5560.12
5593.33
5540
5536.17
5555.45
5526.27
5646.01
5684.82
5554.28
5554.31
5542.63
5567.95
5583.89
5505.89
5605.72
5590.92
5570.06
5615.21
5613.78
5653.41
5747.48
5757.99
5767.33
5815.28
5825.21
5899.33
5888.76
5941.22
5950.99
5993.19
6069.2
6037.73
6162.01
6092.89
6199.63
6360.81
6331.35
6205.62
2.30555
Au4f
Au in vacuum, short shirley
2020
3
8
7
22
34
0
17
Casa Info Follows
1
BackgroundSubtract
0
1
CASA region (*Au 4f*) (*Shirley*) 1393.9881 1408.9582 16.77802 2 0 0 833.83732 -450 0 0 (*Au 4f*) 196.967 0 17.12
0
EX340_CEC356_effect of lens modes.sle
Group = Au in vacuum
First of group = 0
Analyzer lens = LargeArea:1.5kV
Analyzer slit = 4:7x20c\C:mesh
Scan mode = FixedAnalyzerTransmission
Kinetic energy start = 1311.61
Sum of 20 spectra in column containing 20 scans
C:\Users\pielsticker\Lukas\MPI-CEC\Projects\Gas phase background\inelasticscattering\data\N2\Au, Ag, Cu in N2.vms
C:\Users\pielsticker\Lukas\MPI-CEC\Projects\Gas phase background\inelasticscattering\data\Au_test.vms
XPS
1
Al
1486.61
0
0
0
54.5
180
FAT
20
1
4.156
0
0
0
0
0
Au4f

-1
kinetic energy
eV
1311.61
0.1
2
counts
d
Transmission
d
pulse counting
2
1
0
0
0
0
2
ESCAPE DEPTH TYPE
d
0
MFP Exponent
d
0
259.839
2.30555
19490.5
19696.1
19545.9
19546.8
19671.3
19640.1
19592
19658.5
19837.5
19785.1
19689
19770.4
19912.4
19813.6
19924.8
20051.1
20043.3
19892
19967.8
19894.5
19866.2
20155.4
19961.8
19820.4
19964.9
19871.8
19868.8
19930.1
19882.3
20041.4
19821.9
19908.4
20153.2
20024.9
19995.5
19913.7
19897.8
19880.1
19771.3
19960.6
19997.1
19974.1
19827.4
19826.9
19913.6
20047.6
20200.6
19995.5
20009.4
20303
20043.7
20195.2
19972.5
19989.3
20011.9
19946.7
19920.4
20100
20103
20087.9
20031.5
20070
20036.6
20019.6
20051.7
20029.6
19944.4
19678
19948.2
20143.6
20194.3
20184.5
20013.6
20293
20286.6
20047.9
20011.8
20258.1
20167.3
20431.7
20208.9
20137.6
20093.4
20239.9
20256.8
20161.2
19877.8
20019.7
20340.1
20221.8
20090.5
20167.8
20287.4
20165.6
20075
20043.8
20250.4
20105.4
20181.9
20240.9
20290.3
20019.8
20010
20383.7
20306.2
20299.6
20218.8
20391.9
20415.2
20329.1
20531.8
20324.6
20206.2
20369.6
20528.4
20386.6
20468.4
20666.1
20524.2
20683.1
20527.3
20645.3
20457.2
20559.4
20636.2
20700.5
20627.1
20715.6
20792
20656.4
20621.1
20771.3
20748.3
20496.1
20606.7
20697.1
20856
20551.9
20731.8
20949.8
20788.6
20729.8
20515.7
20492.7
20609.8
20449.1
20368.1
20587.8
20638.2
20475.4
20573.9
20593.3
20563.2
20482.5
20556.8
20620.7
20593.5
20760.2
20765.8
20526.6
20451.7
20505.6
20591
20728.2
20687.3
20529.3
20604.1
20765.5
20784.9
20953
20874.5
20642.3
20596.4
20630.8
20778
20895.3
20883.7
20799.1
20852.4
20898.2
20670.3
20871.6
20850.2
20848.4
20878.8
20774.7
20778.6
20741.6
20943.2
21036.1
21068.6
20991.4
21048.8
20857.3
20932.3
20930.3
21132.5
21160.9
21009.8
21027.4
20866.4
21035.2
21051.9
20869.1
20993.4
21122.9
21290.8
20931.7
21030.9
21269.4
21085.2
21149.2
21183.1
20969
21143.2
21189.7
20974.6
21200.6
21387.1
21231.8
21278.9
21283.1
21040.6
21195.5
21202.5
21287.3
21397.7
21271.3
21163.8
21216.5
21288.6
21174.2
21281.5
21235.4
21615.1
21606.9
21434.2
21460.2
21370.5
21386.2
21251.1
21275.2
21452.8
21341.8
21247.7
21183.9
21309.6
21455.1
21562.9
21602.2
21343
21270.1
21324.6
21623
21532.2
21599.5
21735.1
21579.1
21537.5
21578.3
21574.1
21582.9
21489.8
21698.5
21611.4
21526.8
21745.4
21588.6
21419.7
21517.9
21582
21569.5
21633
21578.4
21752.3
21719.9
22062.3
21689.8
21752.5
21839.1
21807.5
22055.3
21899.9
21770.2
21893.4
21817.9
21750.9
21883.1
21682.5
21797.6
21645.6
21760.4
21831.1
21768.2
21893.9
21795.1
21686.6
21746.9
22007.4
21793.3
21719.5
21979.2
21810.3
22020.3
22038.4
22003.5
21846.8
21858.9
21611.4
21724.9
21817.5
21793.7
21751.1
21735.8
21853.7
21861
21885.5
21736.4
21795.6
21913.9
21823.1
21790.4
21817.9
22029.9
22004.7
21947.5
22046.7
22004.1
21895.9
21857.5
22153.1
22142.8
22024.5
21835.9
22085.5
22066.4
22096.1
21836.3
21944
21850.2
21980.8
22124.4
22274.7
22262.4
22121.5
22139.1
22081
22047.1
22002.6
22162.2
22301.3
22251.8
22319.1
22185.5
22109.5
22144
22334
22323.1
22171.5
22235.2
22302.1
22123.6
22151.8
22157.2
22256.2
22419.3
22231.3
22103.5
22110.5
22043.6
22142
22162.8
22264.8
22140.6
22077.2
22059.9
22401.6
22246.1
22193.1
22513.9
22619.6
22390.7
22323
22293.7
22200.9
22251
22202
22521.9
22461.3
22535.1
22358.9
22126.2
22564.5
22453.2
22463.6
22556.4
22228.8
22457.6
22499.1
22460.1
22719.3
22400
22347
22556
22505
22785.4
22613.5
22445.2
22676.5
22674.2
22722.2
22774.8
22600.5
22603.5
22744.2
22738.7
22772.8
22650.8
22637.5
22531.1
23005.1
22942
22720.7
22704.1
22782
22678.8
22991.3
22850.1
22869.8
22934.1
22942.2
22786.9
22766.3
22760.1
22915.4
22827.6
22917.4
22954.3
22974.6
22973
22917.5
22971.2
23173.7
23018.3
22746.7
22789.7
23043.4
23113.6
22963.7
23113.3
23104
23057.1
23149.7
23199.2
23009
23156.2
23115.9
23121.5
23148.9
23109
23264.4
23120.3
23226.8
23493.8
23276.8
23278.5
23066.9
23206.6
23251.2
23204.2
23348.4
23375
23443.3
23482.8
23197.6
23462.1
23653.3
23541.2
23449.6
23413.2
23375.7
23594.9
23622.1
23722.3
23658.5
23749.6
23635.5
23608.9
23780.6
23595.9
23615.2
23618.1
23817.8
23967.4
23826.8
23660.9
23957.5
23833.9
23960.1
23888.8
23924.5
23891.7
23912.4
24048.8
24017.1
24119.5
24262
24285.5
24006.2
24091.7
24115.8
24105.4
24275.1
24360
24273
24446.6
24356.8
24506.2
24472.8
24640.1
24504.4
24534.7
24672.8
24657.5
24539.2
24670.5
24485.2
24710.7
24743.2
24765.6
24434.6
24500.7
24737.6
24911.3
24859.7
24796.5
24707.3
24883.7
25158.4
25062.3
25049.2
24921.5
24973.9
25069.2
25279
25134
25166.2
25141.8
25338.1
25164.7
25381.9
25198.3
25435.9
25285.2
25203.5
25376.1
25289.9
25344
25363.2
25435.6
25544.9
25756.4
25656.7
25476.3
25727.1
25617.8
25489.7
25717.2
25581.4
25466.5
25639.5
25583.5
25350.3
25386.3
25336.8
25755
25430.3
25581.1
25596.9
25413.1
25361.3
25566.6
25467.7
25538.2
25519.4
25762.2
25855.8
25565
25675.6
25814.3
25729.5
25861.3
25635
25548.9
25754.3
25959
25822.4
25913.5
26141.6
25921.4
26139.5
25977.8
25871.1
26238
26295.2
26254
25957
26221.8
26180.6
26318.2
26288.6
26229.7
26413
26266
26527.4
26183.9
26450.6
26545.5
26287.1
26555.2
26529.5
26457.6
26436
26709.2
26594.4
26737.2
26905.7
26774.8
26751.1
26889.7
26837.2
26720.6
26803.9
26856
26876.4
26776.5
26890.2
27099.9
26920.5
26961.6
26848.6
27100
26967.5
26965.2
26973
26973.5
26761.2
26701.1
26710.8
26625.8
26593.9
26722.7
26623.7
26690.2
26614.1
26592.4
26594.6
26431.3
26441.4
26237.8
26443.3
26598.9
26156.8
26514
26311
26351.6
26521.3
26336.3
26277
26086.6
25973.8
25994.6
25768.3
25703.5
25686.3
25732.8
25800.7
25662.8
25711.7
25494.9
25567.6
25581.2
25353.2
25367.2
24984.3
25053.3
24939.8
25037.3
25045.7
25007.1
25054.2
25045.4
24640.3
24791.6
24712.9
24753.7
24751.6
24710.2
24603.7
24546.5
24647.7
24786.6
24725.8
24730
24689.8
24696
24582.1
24574.7
24845.7
24641
24850.3
24872
24683.2
24739.9
24803.9
24702.4
24878.5
24760.8
24470.1
24592.4
24934.5
24861
24533
24515.6
24728.2
24699.5
24862.8
24800.1
24675.1
24671.2
24874.4
24954.9
24936.5
25012.1
24800.4
24480.7
24588.5
24934.1
24870.6
24891.7
24805.2
24864.8
24953.1
24874.5
24992.8
25188
24688.2
25044
25190.9
25302
25355.6
24994.5
25201.4
25298.6
25111.8
25120.2
25121.6
25251.1
25213.3
25215.3
25044
25163.7
25188.9
25258.5
25295.9
25182.4
25399.3
25134.5
25224.6
24994.7
25092.7
25102.6
24876.2
24882.3
24612.2
24883.1
24781.9
24562.7
24445
24272.7
24298
24253.9
24151.4
24136.7
24125.3
23849.7
23649.2
23644.5
23560.4
23530.5
23539.1
23560.9
23555.9
23617.8
23718.8
23977.7
23837.2
23865.2
23768.9
23981.8
23972.7
24008.1
24001.5
24320.4
24375.2
24239.7
24557.2
24271.8
24377.7
24224.5
24379.5
24028.5
24147.1
24168.2
24057.4
24144.8
24043.9
23819.7
23893
23647.7
23666.9
23554.3
23335
23099.7
23088.4
23179.7
23069.4
23198.3
23182
23407.5
23433.6
23656.8
23698.5
23832.9
24158.4
24196.5
24476.6
24920.6
25283.5
25227.5
25349.8
25856.7
26056.5
26230.2
26480.2
26657
26910.9
27019.7
27113.7
26920.4
27110.7
27385.4
27606.2
27914.4
28414.1
29386.5
30358.5
31857.3
33989.6
36373.5
39865
44203.5
49900.2
57516.7
67378.6
80542.6
97517.6
119965
147050
179710
216247
251653
276570
281758
261219
221820
173540
129935
96041.9
72332.7
56244.6
46178.1
39437.9
35138.8
32010.9
30117.5
28426.3
27128.5
26410.7
25824
26088.3
26088.7
26923.1
27907.2
29492.4
31766.7
34741.1
38762.9
44526.8
52110.3
62035.4
75265.2
93219.5
115792
145643
183651
227441
275542
319381
348983
348164
314238
256494
193109
136929
96058.2
67713.6
49029
36944.3
29297.3
23873.8
20339.1
17674.5
15914.4
14460.2
13206.1
12362.2
11473.6
10739.7
10399.4
9792.32
9437.47
9016.35
8710.15
8339.87
8062.29
7945.59
7576.2
7378.66
7287.91
7103.73
6830.18
6750.55
6693.94
6495.26
6423.26
6360.64
6304.91
6264.83
6153.13
6056.15
6024.83
6016.35
5819.24
5823.56
5833.5
5742.56
5757.47
5679.74
5613.19
5576.24
5505.17
5534.52
5560.12
5593.33
5540
5536.17
5555.45
5526.27
5646.01
5684.82
5554.28
5554.31
5542.63
5567.95
5583.89
5505.89
5605.72
5590.92
5570.06
5615.21
5613.78
5653.41
5747.48
5757.99
5767.33
5815.28
5825.21
5899.33
5888.76
5941.22
5950.99
5993.19
6069.2
6037.73
6162.01
6092.89
6199.63
6360.81
6331.35
6205.62
2.30555
Au4f
Au in vacuum, long shirley
2020
3
8
7
22
34
0
17
Casa Info Follows
1
BackgroundSubtract
0
1
CASA region (*Au 4f*) (*Shirley*) 1356.6057 1408.9582 16.77802 2 0 0 833.83732 -450 0 0 (*Au 4f*) 196.967 0 17.12
0
EX340_CEC356_effect of lens modes.sle
Group = Au in vacuum
First of group = 0
Analyzer lens = LargeArea:1.5kV
Analyzer slit = 4:7x20c\C:mesh
Scan mode = FixedAnalyzerTransmission
Kinetic energy start = 1311.61
Sum of 20 spectra in column containing 20 scans
C:\Users\pielsticker\Lukas\MPI-CEC\Projects\Gas phase background\inelasticscattering\data\N2\Au, Ag, Cu in N2.vms
C:\Users\pielsticker\Lukas\MPI-CEC\Projects\Gas phase background\inelasticscattering\data\Au_test.vms
XPS
1
Al
1486.61
0
0
0
54.5
180
FAT
20
1
4.156
0
0
0
0
0
Au4f

-1
kinetic energy
eV
1311.61
0.1
2
counts
d
Transmission
d
pulse counting
2
1
0
0
0
0
2
ESCAPE DEPTH TYPE
d
0
MFP Exponent
d
0
259.839
2.30555
19490.5
19696.1
19545.9
19546.8
19671.3
19640.1
19592
19658.5
19837.5
19785.1
19689
19770.4
19912.4
19813.6
19924.8
20051.1
20043.3
19892
19967.8
19894.5
19866.2
20155.4
19961.8
19820.4
19964.9
19871.8
19868.8
19930.1
19882.3
20041.4
19821.9
19908.4
20153.2
20024.9
19995.5
19913.7
19897.8
19880.1
19771.3
19960.6
19997.1
19974.1
19827.4
19826.9
19913.6
20047.6
20200.6
19995.5
20009.4
20303
20043.7
20195.2
19972.5
19989.3
20011.9
19946.7
19920.4
20100
20103
20087.9
20031.5
20070
20036.6
20019.6
20051.7
20029.6
19944.4
19678
19948.2
20143.6
20194.3
20184.5
20013.6
20293
20286.6
20047.9
20011.8
20258.1
20167.3
20431.7
20208.9
20137.6
20093.4
20239.9
20256.8
20161.2
19877.8
20019.7
20340.1
20221.8
20090.5
20167.8
20287.4
20165.6
20075
20043.8
20250.4
20105.4
20181.9
20240.9
20290.3
20019.8
20010
20383.7
20306.2
20299.6
20218.8
20391.9
20415.2
20329.1
20531.8
20324.6
20206.2
20369.6
20528.4
20386.6
20468.4
20666.1
20524.2
20683.1
20527.3
20645.3
20457.2
20559.4
20636.2
20700.5
20627.1
20715.6
20792
20656.4
20621.1
20771.3
20748.3
20496.1
20606.7
20697.1
20856
20551.9
20731.8
20949.8
20788.6
20729.8
20515.7
20492.7
20609.8
20449.1
20368.1
20587.8
20638.2
20475.4
20573.9
20593.3
20563.2
20482.5
20556.8
20620.7
20593.5
20760.2
20765.8
20526.6
20451.7
20505.6
20591
20728.2
20687.3
20529.3
20604.1
20765.5
20784.9
20953
20874.5
20642.3
20596.4
20630.8
20778
20895.3
20883.7
20799.1
20852.4
20898.2
20670.3
20871.6
20850.2
20848.4
20878.8
20774.7
20778.6
20741.6
20943.2
21036.1
21068.6
20991.4
21048.8
20857.3
20932.3
20930.3
21132.5
21160.9
21009.8
21027.4
20866.4
21035.2
21051.9
20869.1
20993.4
21122.9
21290.8
20931.7
21030.9
21269.4
21085.2
21149.2
21183.1
20969
21143.2
21189.7
20974.6
21200.6
21387.1
21231.8
21278.9
21283.1
21040.6
21195.5
21202.5
21287.3
21397.7
21271.3
21163.8
21216.5
21288.6
21174.2
21281.5
21235.4
21615.1
21606.9
21434.2
21460.2
21370.5
21386.2
21251.1
21275.2
21452.8
21341.8
21247.7
21183.9
21309.6
21455.1
21562.9
21602.2
21343
21270.1
21324.6
21623
21532.2
21599.5
21735.1
21579.1
21537.5
21578.3
21574.1
21582.9
21489.8
21698.5
21611.4
21526.8
21745.4
21588.6
21419.7
21517.9
21582
21569.5
21633
21578.4
21752.3
21719.9
22062.3
21689.8
21752.5
21839.1
21807.5
22055.3
21899.9
21770.2
21893.4
21817.9
21750.9
21883.1
21682.5
21797.6
21645.6
21760.4
21831.1
21768.2
21893.9
21795.1
21686.6
21746.9
22007.4
21793.3
21719.5
21979.2
21810.3
22020.3
22038.4
22003.5
21846.8
21858.9
21611.4
21724.9
21817.5
21793.7
21751.1
21735.8
21853.7
21861
21885.5
21736.4
21795.6
21913.9
21823.1
21790.4
21817.9
22029.9
22004.7
21947.5
22046.7
22004.1
21895.9
21857.5
22153.1
22142.8
22024.5
21835.9
22085.5
22066.4
22096.1
21836.3
21944
21850.2
21980.8
22124.4
22274.7
22262.4
22121.5
22139.1
22081
22047.1
22002.6
22162.2
22301.3
22251.8
22319.1
22185.5
22109.5
22144
22334
22323.1
22171.5
22235.2
22302.1
22123.6
22151.8
22157.2
22256.2
22419.3
22231.3
22103.5
22110.5
22043.6
22142
22162.8
22264.8
22140.6
22077.2
22059.9
22401.6
22246.1
22193.1
22513.9
22619.6
22390.7
22323
22293.7
22200.9
22251
22202
22521.9
22461.3
22535.1
22358.9
22126.2
22564.5
22453.2
22463.6
22556.4
22228.8
22457.6
22499.1
22460.1
22719.3
22400
22347
22556
22505
22785.4
22613.5
22445.2
22676.5
22674.2
22722.2
22774.8
22600.5
22603.5
22744.2
22738.7
22772.8
22650.8
22637.5
22531.1
23005.1
22942
22720.7
22704.1
22782
22678.8
22991.3
22850.1
22869.8
22934.1
22942.2
22786.9
22766.3
22760.1
22915.4
22827.6
22917.4
22954.3
22974.6
22973
22917.5
22971.2
23173.7
23018.3
22746.7
22789.7
23043.4
23113.6
22963.7
23113.3
23104
23057.1
23149.7
23199.2
23009
23156.2
23115.9
23121.5
23148.9
23109
23264.4
23120.3
23226.8
23493.8
23276.8
23278.5
23066.9
23206.6
23251.2
23204.2
23348.4
23375
23443.3
23482.8
23197.6
23462.1
23653.3
23541.2
23449.6
23413.2
23375.7
23594.9
23622.1
23722.3
23658.5
23749.6
23635.5
23608.9
23780.6
23595.9
23615.2
23618.1
23817.8
23967.4
23826.8
23660.9
23957.5
23833.9
23960.1
23888.8
23924.5
23891.7
23912.4
24048.8
24017.1
24119.5
24262
24285.5
24006.2
24091.7
24115.8
24105.4
24275.1
24360
24273
24446.6
24356.8
24506.2
24472.8
24640.1
24504.4
24534.7
24672.8
24657.5
24539.2
24670.5
24485.2
24710.7
24743.2
24765.6
24434.6
24500.7
24737.6
24911.3
24859.7
24796.5
24707.3
24883.7
25158.4
25062.3
25049.2
24921.5
24973.9
25069.2
25279
25134
25166.2
25141.8
25338.1
25164.7
25381.9
25198.3
25435.9
25285.2
25203.5
25376.1
25289.9
25344
25363.2
25435.6
25544.9
25756.4
25656.7
25476.3
25727.1
25617.8
25489.7
25717.2
25581.4
25466.5
25639.5
25583.5
25350.3
25386.3
25336.8
25755
25430.3
25581.1
25596.9
25413.1
25361.3
25566.6
25467.7
25538.2
25519.4
25762.2
25855.8
25565
25675.6
25814.3
25729.5
25861.3
25635
25548.9
25754.3
25959
25822.4
25913.5
26141.6
25921.4
26139.5
25977.8
25871.1
26238
26295.2
26254
25957
26221.8
26180.6
26318.2
26288.6
26229.7
26413
26266
26527.4
26183.9
26450.6
26545.5
26287.1
26555.2
26529.5
26457.6
26436
26709.2
26594.4
26737.2
26905.7
26774.8
26751.1
26889.7
26837.2
26720.6
26803.9
26856
26876.4
26776.5
26890.2
27099.9
26920.5
26961.6
26848.6
27100
26967.5
26965.2
26973
26973.5
26761.2
26701.1
26710.8
26625.8
26593.9
26722.7
26623.7
26690.2
26614.1
26592.4
26594.6
26431.3
26441.4
26237.8
26443.3
26598.9
26156.8
26514
26311
26351.6
26521.3
26336.3
26277
26086.6
25973.8
25994.6
25768.3
25703.5
25686.3
25732.8
25800.7
25662.8
25711.7
25494.9
25567.6
25581.2
25353.2
25367.2
24984.3
25053.3
24939.8
25037.3
25045.7
25007.1
25054.2
25045.4
24640.3
24791.6
24712.9
24753.7
24751.6
24710.2
24603.7
24546.5
24647.7
24786.6
24725.8
24730
24689.8
24696
24582.1
24574.7
24845.7
24641
24850.3
24872
24683.2
24739.9
24803.9
24702.4
24878.5
24760.8
24470.1
24592.4
24934.5
24861
24533
24515.6
24728.2
24699.5
24862.8
24800.1
24675.1
24671.2
24874.4
24954.9
24936.5
25012.1
24800.4
24480.7
24588.5
24934.1
24870.6
24891.7
24805.2
24864.8
24953.1
24874.5
24992.8
25188
24688.2
25044
25190.9
25302
25355.6
24994.5
25201.4
25298.6
25111.8
25120.2
25121.6
25251.1
25213.3
25215.3
25044
25163.7
25188.9
25258.5
25295.9
25182.4
25399.3
25134.5
25224.6
24994.7
25092.7
25102.6
24876.2
24882.3
24612.2
24883.1
24781.9
24562.7
24445
24272.7
24298
24253.9
24151.4
24136.7
24125.3
23849.7
23649.2
23644.5
23560.4
23530.5
23539.1
23560.9
23555.9
23617.8
23718.8
23977.7
23837.2
23865.2
23768.9
23981.8
23972.7
24008.1
24001.5
24320.4
24375.2
24239.7
24557.2
24271.8
24377.7
24224.5
24379.5
24028.5
24147.1
24168.2
24057.4
24144.8
24043.9
23819.7
23893
23647.7
23666.9
23554.3
23335
23099.7
23088.4
23179.7
23069.4
23198.3
23182
23407.5
23433.6
23656.8
23698.5
23832.9
24158.4
24196.5
24476.6
24920.6
25283.5
25227.5
25349.8
25856.7
26056.5
26230.2
26480.2
26657
26910.9
27019.7
27113.7
26920.4
27110.7
27385.4
27606.2
27914.4
28414.1
29386.5
30358.5
31857.3
33989.6
36373.5
39865
44203.5
49900.2
57516.7
67378.6
80542.6
97517.6
119965
147050
179710
216247
251653
276570
281758
261219
221820
173540
129935
96041.9
72332.7
56244.6
46178.1
39437.9
35138.8
32010.9
30117.5
28426.3
27128.5
26410.7
25824
26088.3
26088.7
26923.1
27907.2
29492.4
31766.7
34741.1
38762.9
44526.8
52110.3
62035.4
75265.2
93219.5
115792
145643
183651
227441
275542
319381
348983
348164
314238
256494
193109
136929
96058.2
67713.6
49029
36944.3
29297.3
23873.8
20339.1
17674.5
15914.4
14460.2
13206.1
12362.2
11473.6
10739.7
10399.4
9792.32
9437.47
9016.35
8710.15
8339.87
8062.29
7945.59
7576.2
7378.66
7287.91
7103.73
6830.18
6750.55
6693.94
6495.26
6423.26
6360.64
6304.91
6264.83
6153.13
6056.15
6024.83
6016.35
5819.24
5823.56
5833.5
5742.56
5757.47
5679.74
5613.19
5576.24
5505.17
5534.52
5560.12
5593.33
5540
5536.17
5555.45
5526.27
5646.01
5684.82
5554.28
5554.31
5542.63
5567.95
5583.89
5505.89
5605.72
5590.92
5570.06
5615.21
5613.78
5653.41
5747.48
5757.99
5767.33
5815.28
5825.21
5899.33
5888.76
5941.22
5950.99
5993.19
6069.2
6037.73
6162.01
6092.89
6199.63
6360.81
6331.35
6205.62
2.30555
Au4f
Au in vacuum, short shirley, background subtr.
2020
3
8
7
22
34
0
15
Casa Info Follows
0
0
0
0
EX340_CEC356_effect of lens modes.sle
Group = Au in vacuum
First of group = 0
Analyzer lens = LargeArea:1.5kV
Analyzer slit = 4:7x20c\C:mesh
Scan mode = FixedAnalyzerTransmission
Kinetic energy start = 1311.61
Sum of 20 spectra in column containing 20 scans
C:\Users\pielsticker\Lukas\MPI-CEC\Projects\Gas phase background\inelasticscattering\data\N2\Au, Ag, Cu in N2.vms
C:\Users\pielsticker\Lukas\MPI-CEC\Projects\Gas phase background\inelasticscattering\data\Au_test.vms
XPS
1e+037
Al
1486.61
0
0
0
54.5
180
FAT
20
1
4.156
0
0
0
0
0
Au4f

-1
kinetic energy
eV
1311.61
0.1
2
counts
d
Transmission
d
pulse counting
2
1
0
0
0
0
2
ESCAPE DEPTH TYPE
d
0
MFP Exponent
d
0
259.839
2.30555
0
0
0
0
0
0
0
0
0
0
0
0
0
0
0
0
0
0
0
0
0
0
0
0
0
0
0
0
0
0
0
0
0
0
0
0
0
0
0
0
0
0
0
0
0
0
0
0
0
0
0
0
0
0
0
0
0
0
0
0
0
0
0
0
0
0
0
0
0
0
0
0
0
0
0
0
0
0
0
0
0
0
0
0
0
0
0
0
0
0
0
0
0
0
0
0
0
0
0
0
0
0
0
0
0
0
0
0
0
0
0
0
0
0
0
0
0
0
0
0
0
0
0
0
0
0
0
0
0
0
0
0
0
0
0
0
0
0
0
0
0
0
0
0
0
0
0
0
0
0
0
0
0
0
0
0
0
0
0
0
0
0
0
0
0
0
0
0
0
0
0
0
0
0
0
0
0
0
0
0
0
0
0
0
0
0
0
0
0
0
0
0
0
0
0
0
0
0
0
0
0
0
0
0
0
0
0
0
0
0
0
0
0
0
0
0
0
0
0
0
0
0
0
0
0
0
0
0
0
0
0
0
0
0
0
0
0
0
0
0
0
0
0
0
0
0
0
0
0
0
0
0
0
0
0
0
0
0
0
0
0
0
0
0
0
0
0
0
0
0
0
0
0
0
0
0
0
0
0
0
0
0
0
0
0
0
0
0
0
0
0
0
0
0
0
0
0
0
0
0
0
0
0
0
0
0
0
0
0
0
0
0
0
0
0
0
0
0
0
0
0
0
0
0
0
0
0
0
0
0
0
0
0
0
0
0
0
0
0
0
0
0
0
0
0
0
0
0
0
0
0
0
0
0
0
0
0
0
0
0
0
0
0
0
0
0
0
0
0
0
0
0
0
0
0
0
0
0
0
0
0
0
0
0
0
0
0
0
0
0
0
0
0
0
0
0
0
0
0
0
0
0
0
0
0
0
0
0
0
0
0
0
0
0
0
0
0
0
0
0
0
0
0
0
0
0
0
0
0
0
0
0
0
0
0
0
0
0
0
0
0
0
0
0
0
0
0
0
0
0
0
0
0
0
0
0
0
0
0
0
0
0
0
0
0
0
0
0
0
0
0
0
0
0
0
0
0
0
0
0
0
0
0
0
0
0
0
0
0
0
0
0
0
0
0
0
0
0
0
0
0
0
0
0
0
0
0
0
0
0
0
0
0
0
0
0
0
0
0
0
0
0
0
0
0
0
0
0
0
0
0
0
0
0
0
0
0
0
0
0
0
0
0
0
0
0
0
0
0
0
0
0
0
0
0
0
0
0
0
0
0
0
0
0
0
0
0
0
0
0
0
0
0
0
0
0
0
0
0
0
0
0
0
0
0
0
0
0
0
0
0
0
0
0
0
0
0
0
0
0
0
0
0
0
0
0
0
0
0
0
0
0
0
0
0
0
0
0
0
0
0
0
0
0
0
0
0
0
0
0
0
0
0
0
0
0
0
0
0
0
0
0
0
0
0
0
0
0
0
0
0
0
0
0
0
0
0
0
0
0
0
0
0
0
0
0
0
0
0
0
0
0
0
0
0
0
0
0
0
0
0
0
0
0
0
0
0
0
0
0
0
0
0
0
0
0
0
0
0
0
0
0
0
0
0
0
0
0
0
0
0
0
0
0
0
0
0
0
0
0
0
0
0
0
0
0
0
0
0
0
0
0
0
0
0
0
0
0
0
0
0
0
0
0
0
0
0
0
0
0
0
0
0
0
0
0
0
0
0
0
0
0
0
0
0
0
0
0
0
0
0
0
0
0
0
0
0
0
0
0
0
0
0
0
0
0
0
0
0
0
0
0
0
0
0
0
0
0
0
0
0
0
0
0
0
0
0
0
0
0
0
0
0
0
0
0
0
0
0
0
0
0
0
0
-34.1045
57.3561
-52.796
76.3177
60.1863
286.489
313.466
538.174
581.502
717.913
1046.34
1087.49
1371.43
1820.53
2189.56
2139.55
2268.2
2782.9
2991.07
3173.66
3433.28
3620.22
3885
4005.01
4110.52
3928.23
4130.09
4417.16
4650.99
4973.12
5488.18
6478.73
7471.65
8995.65
11159.2
13581.1
17120.6
21519.3
27292.5
35007
44994.9
58322.3
75508.7
98231.2
125668
158773
195858
231914
257552
263478
243621
204796
156955
113669
79999.6
56448.5
40473.8
30492.7
23819.2
19574.9
16493.2
14640.8
12986
11721
11034.1
10476.7
10771.2
10801.8
11668.9
12688.6
14313.8
16634.7
19664.2
23752.5
29599.3
37287.2
47344.9
60744.9
78920.2
101778
131998
170484
214876
263715
308418
338969
339100
306031
248984
186120
130305
89685.7
61513.4
42949.1
30951.1
23369.5
17996.4
14502.3
11871
10139.3
8709.46
7476.29
6651.02
5778.6
5058.87
4731.82
4136.33
3792.1
3380.45
3082.88
2720.22
2449.5
2339.35
1975.49
1782.94
1696.95
1517.01
1246.96
1170.61
1117.12
921.023
851.408
791.003
737.338
699.216
589.166
493.568
463.547
456.345
259.963
265.025
275.737
185.316
200.788
123.404
57.0136
20.1199
-50.8078
-21.3979
4.21394
37.529
-15.7568
-19.5321
-0.251427
-29.3492
90.6446
129.818
-0.7198
-0.687873
-12.3333
0
0
0
0
0
0
0
0
0
0
0
0
0
0
0
0
0
0
0
0
0
0
0
0
0
0
0
2.30555
Au4f
Au in vacuum, long shirley, background subtr.
2020
3
8
7
22
34
0
15
Casa Info Follows
0
0
0
0
EX340_CEC356_effect of lens modes.sle
Group = Au in vacuum
First of group = 0
Analyzer lens = LargeArea:1.5kV
Analyzer slit = 4:7x20c\C:mesh
Scan mode = FixedAnalyzerTransmission
Kinetic energy start = 1311.61
Sum of 20 spectra in column containing 20 scans
C:\Users\pielsticker\Lukas\MPI-CEC\Projects\Gas phase background\inelasticscattering\data\N2\Au, Ag, Cu in N2.vms
C:\Users\pielsticker\Lukas\MPI-CEC\Projects\Gas phase background\inelasticscattering\data\Au_test.vms
XPS
1e+037
Al
1486.61
0
0
0
54.5
180
FAT
20
1
4.156
0
0
0
0
0
Au4f

-1
kinetic energy
eV
1311.61
0.1
2
counts
d
Transmission
d
pulse counting
2
1
0
0
0
0
2
ESCAPE DEPTH TYPE
d
0
MFP Exponent
d
0
259.839
2.30555
0
0
0
0
0
0
0
0
0
0
0
0
0
0
0
0
0
0
0
0
0
0
0
0
0
0
0
0
0
0
0
0
0
0
0
0
0
0
0
0
0
0
0
0
0
0
0
0
0
0
0
0
0
0
0
0
0
0
0
0
0
0
0
0
0
0
0
0
0
0
0
0
0
0
0
0
0
0
0
0
0
0
0
0
0
0
0
0
0
0
0
0
0
0
0
0
0
0
0
0
0
0
0
0
0
0
0
0
0
0
0
0
0
0
0
0
0
0
0
0
0
0
0
0
0
0
0
0
0
0
0
0
0
0
0
0
0
0
0
0
0
0
0
0
0
0
0
0
0
0
0
0
0
0
0
0
0
0
0
0
0
0
0
0
0
0
0
0
0
0
0
0
0
0
0
0
0
0
0
0
0
0
0
0
0
0
0
0
0
0
0
0
0
0
0
0
0
0
0
0
0
0
0
0
0
0
0
0
0
0
0
0
0
0
0
0
0
0
0
0
0
0
0
0
0
0
0
0
0
0
0
0
0
0
0
0
0
0
0
0
0
0
0
0
0
0
0
0
0
0
0
0
0
0
0
0
0
0
0
0
0
0
0
0
0
0
0
0
0
0
0
0
0
0
0
0
0
0
0
0
0
0
0
0
0
0
0
0
0
0
0
0
0
0
0
0
0
0
0
0
0
0
0
0
0
0
0
0
0
0
0
0
0
0
0
0
0
0
0
0
0
0
0
0
0
0
0
0
0
0
0
0
0
0
0
0
0
0
0
0
0
0
0
0
0
0
0
0
0
0
0
0
0
0
0
0
0
0
0
0
0
0
0
0
0
0
0
0
0
0
0
0
0
0
0
0
0
0
0
0
0
0
0
0
0
0
0
0
0
0
0
0
0
0
0
0
0
0
0
0
0
0
0
0
0
0
0
0
0
0
0
0
0
0
0
0
0
0
0
0
0
0
0
0
0
0
0
0
0
0
0
0
0
0
0
0
0
0
0
0
0
0
0
0
0
0
0
0
0
0
12.5625
-34.2579
58.4779
108.229
-81.7809
65.5714
25.3302
31.0022
58.5381
18.6815
174.487
30.4574
137.276
405.217
188.655
190.798
-20.7534
119.223
164.205
117.478
262.287
289.559
358.692
399.119
114.184
379.565
572.094
461.065
370.325
334.702
297.894
518.297
546.767
648.473
586.034
678.71
565.924
540.579
713.937
530.469
551.049
555.238
756.695
908.405
769.592
605.097
903.796
782.012
910.326
840.979
878.719
847.888
870.61
1009.35
979.929
1084.85
1230.21
1256.62
979.598
1067.58
1094.22
1086.34
1258.96
1346.99
1262.93
1439.87
1353.21
1506.11
1476.14
1647.26
1515.08
1548.98
1691
1679.6
1564.94
1700.19
1518.41
1747.97
1784.62
1811.22
1483.67
1553.38
1794.44
1972.72
1925.59
1866.73
1781.67
1962.62
2242.53
2151.43
2143.31
2020.3
2077.52
2177.88
2393.24
2253.47
2290.99
2271.87
2473.91
2305.87
2528.94
2350.8
2594.42
2449.41
2373.22
2551.75
2471.29
2531.26
2556.4
2634.92
2750.61
2969
2875.98
2701.85
2959.53
2856.86
2735.11
2969.51
2840.3
2731.75
2911.51
2862.15
2635.07
2677.29
2633.91
3059.21
2740.88
2898.41
2920.99
2743.56
2698.03
2910.08
2817.73
2894.95
2882.84
3132.92
3234.03
2950.08
3067.8
3213.97
3136.45
3275.86
3056.66
2977.47
3190.28
3402.88
3273.88
3372.82
3609.3
3396.99
3623.5
3469.86
3370.99
3746.59
3812.64
3780.22
3491.33
3764.87
3732.34
3878.95
3858.3
3808.25
4000.84
3862.81
4133.81
3799.13
4075.29
4179.9
3930.63
4208.5
4192.54
4130.23
4118.19
4401.61
4296.79
4449.93
4629.18
4508.75
4495.48
4644.87
4603.06
4496.9
4590.86
4653.77
4685.05
4595.82
4720.49
4941.66
4773.35
4825.65
4723.62
4986.6
4865.4
4874.42
4893.58
4905.47
4704.1
4654.81
4675.36
4601.05
4579.78
4719.54
4631.3
4708.73
4643.42
4632.47
4645.46
4492.59
4513.17
4319.61
4535.64
4702.16
4269.97
4637.94
4445.27
4496.31
4676.87
4502.32
4453.36
4272.89
4169.77
4200.32
3983.27
3927.6
3919.5
3975.23
4052.54
3923.75
3981.9
3773.86
3855.51
3878.12
3658.62
3681.16
3305.94
3382.8
3276.91
3382.26
3398.55
3367.77
3422.82
3421.97
3023.89
3182.58
3111.11
3159.24
3164.49
3130.36
3030.9
2980.62
3088.99
3235.41
3182
3193.61
3160.75
3174.32
3067.55
3067.27
3346.04
3148.65
3365.77
3395.35
3214.02
3278.33
3350.11
3256.17
3440.26
3330.29
3046.67
3176.34
3526.63
3461.17
3140.46
3130.33
3350.71
3329.75
3501.18
3446.48
3329.21
3333.05
3544.48
3633.42
3623.43
3707.64
3504.08
3191.79
3307.27
3661.38
3606.25
3635.79
3557.56
3625.57
3722.52
3652.4
3779.48
3983.93
3492.24
3857
4013.21
4133.91
4197.26
3845.09
4061.42
4168.3
3990.77
4008.48
4019.21
4158.37
4130.16
4141.78
3979.72
4108.96
4143.78
4223.19
4270.51
4166.68
4393.79
4138.6
4238.54
4017.97
4125.55
4145.08
3927.8
3943.05
3681.5
3961.6
3869.39
3658.68
3549.23
3384.79
3418.02
3381.78
3286.91
3279.83
3276.03
3007.42
2813.45
2815.29
2737.54
2713.95
2728.88
2757.09
2758.49
2826.96
2934.77
3201.11
3067.73
3102.93
3013.63
3234.04
3232.45
3275.46
3276.46
3603.73
3667.05
3539.77
3866.25
3589.18
3703.68
3558.75
3722.39
3379.24
3505.98
3535.29
3432.46
3528.05
3435.13
3218.4
3299.36
3061.17
3087.54
2981.87
2769
2539.59
2534.18
2631.59
2527.16
2662.24
2652.1
2884.3
2917.17
3147.68
3196.81
3338.96
3672.99
3719.73
4009.14
4463.5
4837.63
4792.76
4926.5
5446.05
5658.99
5846.27
6110.46
6301.89
6571.05
6695.4
6805.2
6627.29
6833.46
7124.71
7362.6
7688.66
8207.42
9201.18
10196.9
11722.9
13887.4
16309.2
19846.8
24241.6
30008
37712
47684.7
60990.3
78146.8
100828
128211
161246
198243
234193
259713
265517
245549
206629
158718
115381
81677.5
58103.2
42112.9
32121
25439.9
21190
18104.2
16248.5
14591.2
13324.3
12635.9
12077.2
12370.2
12399.4
13264.6
14281.9
15904
18220.6
21244.4
25325
31161.2
38834.9
48873.5
62247.9
80388.8
103201
133362
171769
216060
264776
309334
339724
339694
306480
249315
186363
130486
89823.5
61622
43037.3
31024.7
23432.1
18050.5
14549.6
11912.7
10176.2
8742.28
7505.61
6677.22
5802.09
5079.99
4750.72
4153.29
3807.28
3394.04
3095.03
2731.09
2459.22
2347.97
1983.19
1789.8
1703.01
1522.36
1251.72
1174.82
1120.81
924.277
854.26
793.483
739.47
701.018
590.69
494.859
464.618
457.2
260.695
265.632
276.213
185.704
201.081
123.639
57.2214
20.3186
-50.6338
-21.2345
4.37564
37.6731
-15.6206
-19.4055
-0.125242
-29.2373
90.7133
129.825
-0.713557
-0.681974
-12.3333
0
0
0
0
0
0
0
0
0
0
0
0
0
0
0
0
0
0
0
0
0
0
0
0
0
0
0
2.30555
end of experiment