File: data/Shirley/Cu_test.vms
VAMAS Surface Chemical Analysis Standard Data Transfer Format 1988 May 4
Not Specified
Not Specified
Not Specified
Not Specified
9
Casa Info Follows CasaXPS Version 2.3.20rev1.2G
0
Created by SpecsLab Prodigy, Version 4.63.4-r87993
SourceAnalyserAngle: 56.500000 d
CasaRowLabel:Cu in vacuum
CasaRowLabel:Cu in vacuum, short shirley
CasaRowLabel:Cu in vacuum. long shirley
CasaRowLabel:Cu in vacuum, short shirley, background subtr.
CasaRowLabel:Cu in vacuum. long shirley, background subtr.
NORM
REGULAR
1
1
Exp Variable
d
0
0
0
0
5
Cu2p
Cu in vacuum
2020
3
8
23
38
57
0
14
Casa Info Follows
0
0
0
0
EX340_CEC356_effect of lens modes.sle
Group = Cu in vacuum
First of group = 0
Analyzer lens = LargeArea:1.5kV
Analyzer slit = 4:7x20c\C:mesh
Scan mode = FixedAnalyzerTransmission
Kinetic energy start = 456.61
Sum of 20 spectra in column containing 20 scans
C:\Users\pielsticker\Lukas\MPI-CEC\Projects\Gas phase background\inelasticscattering\data\N2\Au, Ag, Cu in N2.vms
XPS
1
Al
1486.61
0
0
0
54.5
180
FAT
20
1
4.156
0
0
0
0
0
Cu2p

-1
kinetic energy
eV
456.61
0.1
2
counts
d
Transmission
d
pulse counting
3
1
0
0
0
0
2
ESCAPE DEPTH TYPE
d
0
MFP Exponent
d
0
1420.77
3.64711
49871.4
49982.7
50035.1
49899.9
49667.9
50024.1
50455.1
50225.6
50118.8
50213.5
50049
49901.7
50164.6
49865.2
50278.7
50161.8
50177.1
50251.3
50010.9
49955.2
50059.5
50395
50456.6
50442
50430.4
50288.6
50315.1
50534.3
50194.5
50403
50175.4
50232.9
50577
50750.1
50169.7
50497
50617.4
50524.8
50397.6
50408.3
50441.3
50313.3
50414.1
50470.6
50837.2
50530.4
50238.9
50318.1
50471.4
50700.5
50673.4
50869.6
50784.8
50672.4
50492.2
50322.6
50763.2
50762.7
50853.5
50924.3
50625.3
50764.7
51011
50706.6
50797.5
50987
50858.6
50959.7
51051
50821.1
51057.6
50534.8
50732.4
50756.7
50870.5
50824.3
50952.4
50775.6
50592.7
50852.4
50740.3
51098.6
51262.9
51352.3
51119.7
51311.4
51504.4
51301.1
51095.4
51191.7
51047.3
51022
50970.7
50998
51102.7
51342.1
51268.1
51457.9
51192.8
50872
50875.8
51602.6
51610.5
51667.9
51495.6
51221
51604.7
51470.9
51836.2
51678.1
51228.2
51512.8
51828.1
51678.8
51506.7
51714.8
51848.3
51273.7
51597.9
51819.3
51651.5
51697.5
51430.8
51739.4
51632.8
51485.1
51832.8
51878.3
51669.6
51959.1
51687.1
51704.4
51985.1
52094.1
51799.2
51765.8
52086.4
51947.3
51671.4
52117.3
52143.8
51705.3
51976.2
52133.1
52085.1
51913.7
52216.8
51902.1
52020.1
51838.8
51984
52389.5
51986.7
52341
52346
52295.8
52151.6
51912.3
52116.3
52251.5
52231.2
52235.1
52379.3
52347.9
52654.5
52511.5
52230.2
52296.1
52169.6
52272.9
52249.4
52666.4
52576.5
52590.9
52691.8
52688.7
52577.3
52246.5
52837.9
52726.1
52751.8
52682.6
53017.3
52699.7
52669.3
52830.7
52718.4
52952.3
52585.3
52744.2
53022.6
52692.9
52838.8
52739.3
52814.3
53077.2
52766
52601.8
52692.1
52611.7
52827.6
52756.9
53099.2
53340.8
52801
53207.6
53031.8
53102.4
53159.1
53154
53213.6
53409.4
53096.5
52991.7
53216.5
53515.1
53305.9
53289.7
53145.3
53160.7
53257.8
53260.6
53106.6
53545.1
53188.9
53140.9
53300.8
53556.6
53532.6
53589.8
53658.4
53559.9
53514.7
53355
53279
53723.9
53586
53629.4
53482.1
53539.6
53083.2
53552.6
53718.4
53683
53766.8
53466.3
53367
53687.1
53807.2
53829.1
53954.8
53984.8
54016.6
53689.5
53796.3
54231.8
53991
54033.4
54104.5
54096.2
53606.6
53716.3
54006.2
54333
54105.9
54221.8
54298
53925
54312.8
54393.6
54321.9
54449
54296
54567.8
54418.4
54334.5
54548.4
54218.6
54618.7
54592.1
54677.1
54494.2
54349.3
54846.3
54966.4
54783.2
54294.6
54722.1
54910.1
54461
54405.4
54691.3
54723.1
54793.4
54834.5
54854.8
54751.5
55058.5
55000.3
55209.4
55185.5
55114.5
54930.1
54973.4
54948.5
54931.7
54855.5
55127.3
55031.9
55392.7
55177.9
55311.5
55346.4
55612.7
55064.5
55387.8
55496.5
55638.6
55421.1
55190.6
55918.8
55595.8
55484.4
55330.5
55429.6
55596.8
55579.7
55851.2
55749.1
55787
55518.6
55395.3
55388.8
55623.9
55655.5
55596.3
55608.6
55346.8
55920.7
56097.7
56394.6
55821.5
55672.2
55942.9
56028.3
56014.5
56221.6
56364.8
56008.7
56068.3
56180.1
55961.7
56109.3
56264.9
56150.7
55990.1
55973.8
56137.7
55940.9
56221.4
56381
56202.6
56025.9
56266
56379.8
56452.7
56248.4
56604
56252.4
55900.2
56013.8
55979.5
56287.7
56516.5
56562.1
56598.1
56345.9
56298
55956.3
56293.4
56623.6
56311.1
56260
56279.3
56773.8
56511.9
56614.2
56566.7
56942.9
56356.4
56733.2
56627.4
56797.4
56440
56702.6
56698.7
57020.6
56591.3
56841
57141.9
57147.3
56492.9
56519.4
56740
57065.9
56731.9
56705.9
57038.7
56841.7
57285.4
57319.8
56999.7
56911.5
57208.6
57324.7
57168.5
57357.3
56941.6
57215.6
57241
57394.4
57155.2
57417.3
57063.7
57191.2
57247.7
57084.8
57292.8
57173.4
57624.1
57537.3
57682.9
57838.2
57799.1
57718
57570
57642
57910
58048.9
57691.6
58456
57541
57758.4
58123.1
58131.6
57693.3
57963.1
57975.7
58007.3
58210.8
58107.4
57728.3
57985.6
58259.6
57820.5
57683.2
57816.9
58302.7
58328.5
58397.9
58191.3
58162.8
58226.3
58943
58563.2
58433.7
58584.2
58687
58801.5
59178
58980.3
58743.9
58785.1
58779.1
58929.1
58846.4
59303
58589.8
59031.4
59224.1
58982.9
59095.1
58841.6
59481.6
59552.8
59333
59232.5
59381.1
59512.6
59381.3
59578.8
59658.6
59656.5
59672.4
59674.3
60199.9
59657.4
59506.4
59870.3
60032.3
59955
60039
59970.7
60027.4
60036.3
60121.4
60325.7
60354.2
60196.8
60338
60108.1
60122.8
60259.9
60615.1
60482.1
60346.9
60619.5
60481
60597.5
60654.3
60386.7
60221.5
60672.6
61046
60939.5
60598.4
60746.8
60904.6
60343.6
60870.7
61031
61231.2
60674
60922.7
61015.4
61271.4
60986.4
61283.4
61288.4
61035.6
61383.9
61245.3
61404
61370.1
61461.1
61588.3
61651.1
61597.3
61721.3
61897.5
61544.3
61931.4
61782.6
61594.4
61870.2
62295.3
62221.4
61605.4
61729
62179.5
62066.9
62534.2
62397.5
62834
62505.1
62637.6
62008.2
62437
62341.4
62371
62292
62294.1
62490.5
62240.4
62494.4
62482.9
62457
62413.5
62399.1
62203
62229.7
62240
62085.9
62297.6
61981.2
62093.4
62394.5
62124.4
62511.6
62005.5
62248.5
62101.7
61942.8
62267.4
62241.3
62229.9
62053.7
62152.4
62224.1
62106.3
62267.9
62121.5
62334.7
62144.3
62200.3
62185.8
62487.2
61822.6
61778.9
61994.9
62227.2
62292.3
62185
62014.7
61965.4
61970.2
61800.9
61717.9
62077.1
62040.1
61873.6
61582
61726.3
61726.3
61564.6
61514.4
61809
61731.8
61578.7
61376.5
62006.8
61754.9
61849.4
61934.7
61854.6
62223.8
61929.4
62185.1
62039.2
62176.5
61813.2
62238.1
62265.6
62215.5
62284.7
62597.7
62589.7
62443
62785.6
62553.9
62722.3
62618
62583
62537.1
62562.5
62638.9
62398.3
62526
62428.7
62082.6
61917.3
61625.6
61456.9
61508
60908.3
60582.9
60233.4
60799.1
60613.8
60147.2
60227.3
60307.8
60250.2
60138.3
59882.1
59667
59455.9
59233.5
59128.5
59397.4
59179.3
59486.5
59531
59052.1
59060
59036.1
58959.7
59173.1
59460.5
59245.4
59509.2
59172.6
59145.5
59435.5
59148.1
59224.8
59497.8
59411.3
59359.8
60000.8
59423.1
59099.8
59493.4
59613.9
60078.6
59789
60202.3
60146
60149.4
60035.2
59874.8
59958.8
59761.5
59867.9
60071.7
60274.5
59941.4
59729.3
60588.6
60669.8
60972.1
60589.8
60778.9
61079.3
60954.4
61117.7
61178.8
61134.8
61306.5
61660.8
61686.7
61815.5
62225.3
62350.6
62405
63019.7
62461.7
62705.6
63268
63468.3
63314.3
63809.4
64154.3
64395.6
64785
64770
65307.1
65767.7
65936.8
66466.5
67093.9
68108.2
68518.1
69088.5
70245.9
71248.8
72744.5
74002.1
75598.9
77504
79516.1
82299.6
85202
88426.5
92339.5
97553.3
102792
108508
115259
122717
130148
137668
144860
150147
153183
153494
150980
146231
138923
130651
121474
113463
105680
98548.3
92385.2
87271.9
82906
79039.7
76242.8
73065.3
71456.4
69701.6
67880.1
66309.9
64734.3
64071.4
63462.4
62204
61525.2
61242.2
60604.7
59990.7
59186
58813.3
58797.7
58263.9
57604.9
57016.1
56624.4
56493.8
56170.7
55711.5
55539.5
55814.3
55340
55233.9
54897.5
54705.3
54955
54937.3
54655.8
54409.6
54574.1
54171.2
54402
54403.3
53998
53861.3
53976.1
54162.2
54047.3
54104.6
53636.6
53576.6
54073.3
54088.9
53930.7
53661.4
53361
53623.9
53386.1
53175.5
52963.8
52499.5
52206.5
52268.4
52106.8
51467.2
51768.7
51009.6
50834.6
50872.5
50816
51069.4
50597.4
50618.6
50347.4
50216.4
50428.9
50030.5
49862.4
49738.8
49795.5
49490.9
49445.7
49239.4
48843.3
48386.9
48206.4
48216.9
48008.6
48080.5
47471
47362
47612.8
47144.1
46647.2
46412.3
45770.8
45751
45338.9
45032.6
45067.5
44659.1
44137.7
44258.1
43677.5
43762.3
44133.2
43545
43394.4
43680.1
43545.6
43406.7
43531.2
43633.8
43830
43454.5
43621.2
43468.3
43712.5
43670.9
43727.7
43989.9
43966.3
43695.4
43680.2
43798.5
43656.2
43709.2
43432.3
43635.5
43762.3
43673
43809.5
43871.8
43799.2
44060.1
44373.4
44334.6
44597.7
44671.9
44817.6
45000.7
45313.1
45492.8
45975.4
46070.1
45769.2
45954.8
46020.6
46195
46565.6
46571.4
47090.3
47131.2
47153.8
47086.5
46898.8
47533
47412.7
47496.7
47357.4
47707.1
47841.6
48139.2
48404
48706.4
49157.6
49302.5
49546.9
50566.2
51671
52629.8
53807.4
55616.3
57131.9
59289.1
62530.3
66111.6
70715.5
76471.1
83884.6
94200.8
106644
123631
145912
173505
206580
244124
282046
315608
337808
344743
330940
299442
258132
215194
176652
144843
119940
100628
85839.1
75196.7
66940.4
60736.5
55916.9
52067.2
48900.1
46421.4
44750.5
43323.9
41634.9
40553.8
39500.2
38516.7
37520.7
37090.7
36353.1
35773.1
35100.7
34675.2
34420.9
34024.8
33737.2
33427
33276.9
32784.7
32759.7
32420.6
32139.6
32070.9
31836.5
31757.6
31549.9
31500.9
30947.6
31092.4
31307.2
30953.9
30944.5
30603.4
30643.9
30908.5
30572.4
30613.3
30379.9
30373.2
30279
30567.8
30293.2
30488.8
30615.7
30441.2
30020
29943.6
30003.4
30086.8
29932
29885.1
30042.3
29953.7
29937.5
29518.6
29590.6
29712.2
29608.9
29555.3
29982.1
29735.4
29436.8
29806.6
29477.5
29429.3
29609.3
29491.9
29520.7
29536.2
29590.8
29732.6
29679.8
29780.6
29523.7
29572
29596.4
29350.2
29311.8
29396.9
29605.8
29540.1
29423.7
29430.6
29562.8
29290
29121
29415.7
29188.1
29556
29474.3
29423.6
29332.2
29214
29379.6
29456.7
29581.8
29201.7
29259
29349
29125.5
29160.9
29434.7
29468
29370.3
29529.1
29379.2
29289.6
29334.4
29295.3
29098.5
29133.1
29334.8
3.64711
Cu2p
Cu in vacuum, short shirley
2020
3
8
23
38
57
0
17
Casa Info Follows
1
BackgroundSubtract
0
1
CASA region (*Cu 2p*) (*Shirley*) 502.3639 563.8457 25.081921 2 0 0 833.83732 -450 0 0 (*Cu 2p*) 63.549 0 25.39
0
EX340_CEC356_effect of lens modes.sle
Group = Cu in vacuum
First of group = 0
Analyzer lens = LargeArea:1.5kV
Analyzer slit = 4:7x20c\C:mesh
Scan mode = FixedAnalyzerTransmission
Kinetic energy start = 456.61
Sum of 20 spectra in column containing 20 scans
C:\Users\pielsticker\Lukas\MPI-CEC\Projects\Gas phase background\inelasticscattering\data\N2\Au, Ag, Cu in N2.vms
CasaXP4
XPS
1
Al
1486.61
0
0
0
54.5
180
FAT
20
1
4.156
0
0
0
0
0
Cu2p

-1
kinetic energy
eV
456.61
0.1
2
counts
d
Transmission
d
pulse counting
3
1
0
0
0
0
2
ESCAPE DEPTH TYPE
d
0
MFP Exponent
d
0
1420.77
3.64711
49871.4
49982.7
50035.1
49899.9
49667.9
50024.1
50455.1
50225.6
50118.8
50213.5
50049
49901.7
50164.6
49865.2
50278.7
50161.8
50177.1
50251.3
50010.9
49955.2
50059.5
50395
50456.6
50442
50430.4
50288.6
50315.1
50534.3
50194.5
50403
50175.4
50232.9
50577
50750.1
50169.7
50497
50617.4
50524.8
50397.6
50408.3
50441.3
50313.3
50414.1
50470.6
50837.2
50530.4
50238.9
50318.1
50471.4
50700.5
50673.4
50869.6
50784.8
50672.4
50492.2
50322.6
50763.2
50762.7
50853.5
50924.3
50625.3
50764.7
51011
50706.6
50797.5
50987
50858.6
50959.7
51051
50821.1
51057.6
50534.8
50732.4
50756.7
50870.5
50824.3
50952.4
50775.6
50592.7
50852.4
50740.3
51098.6
51262.9
51352.3
51119.7
51311.4
51504.4
51301.1
51095.4
51191.7
51047.3
51022
50970.7
50998
51102.7
51342.1
51268.1
51457.9
51192.8
50872
50875.8
51602.6
51610.5
51667.9
51495.6
51221
51604.7
51470.9
51836.2
51678.1
51228.2
51512.8
51828.1
51678.8
51506.7
51714.8
51848.3
51273.7
51597.9
51819.3
51651.5
51697.5
51430.8
51739.4
51632.8
51485.1
51832.8
51878.3
51669.6
51959.1
51687.1
51704.4
51985.1
52094.1
51799.2
51765.8
52086.4
51947.3
51671.4
52117.3
52143.8
51705.3
51976.2
52133.1
52085.1
51913.7
52216.8
51902.1
52020.1
51838.8
51984
52389.5
51986.7
52341
52346
52295.8
52151.6
51912.3
52116.3
52251.5
52231.2
52235.1
52379.3
52347.9
52654.5
52511.5
52230.2
52296.1
52169.6
52272.9
52249.4
52666.4
52576.5
52590.9
52691.8
52688.7
52577.3
52246.5
52837.9
52726.1
52751.8
52682.6
53017.3
52699.7
52669.3
52830.7
52718.4
52952.3
52585.3
52744.2
53022.6
52692.9
52838.8
52739.3
52814.3
53077.2
52766
52601.8
52692.1
52611.7
52827.6
52756.9
53099.2
53340.8
52801
53207.6
53031.8
53102.4
53159.1
53154
53213.6
53409.4
53096.5
52991.7
53216.5
53515.1
53305.9
53289.7
53145.3
53160.7
53257.8
53260.6
53106.6
53545.1
53188.9
53140.9
53300.8
53556.6
53532.6
53589.8
53658.4
53559.9
53514.7
53355
53279
53723.9
53586
53629.4
53482.1
53539.6
53083.2
53552.6
53718.4
53683
53766.8
53466.3
53367
53687.1
53807.2
53829.1
53954.8
53984.8
54016.6
53689.5
53796.3
54231.8
53991
54033.4
54104.5
54096.2
53606.6
53716.3
54006.2
54333
54105.9
54221.8
54298
53925
54312.8
54393.6
54321.9
54449
54296
54567.8
54418.4
54334.5
54548.4
54218.6
54618.7
54592.1
54677.1
54494.2
54349.3
54846.3
54966.4
54783.2
54294.6
54722.1
54910.1
54461
54405.4
54691.3
54723.1
54793.4
54834.5
54854.8
54751.5
55058.5
55000.3
55209.4
55185.5
55114.5
54930.1
54973.4
54948.5
54931.7
54855.5
55127.3
55031.9
55392.7
55177.9
55311.5
55346.4
55612.7
55064.5
55387.8
55496.5
55638.6
55421.1
55190.6
55918.8
55595.8
55484.4
55330.5
55429.6
55596.8
55579.7
55851.2
55749.1
55787
55518.6
55395.3
55388.8
55623.9
55655.5
55596.3
55608.6
55346.8
55920.7
56097.7
56394.6
55821.5
55672.2
55942.9
56028.3
56014.5
56221.6
56364.8
56008.7
56068.3
56180.1
55961.7
56109.3
56264.9
56150.7
55990.1
55973.8
56137.7
55940.9
56221.4
56381
56202.6
56025.9
56266
56379.8
56452.7
56248.4
56604
56252.4
55900.2
56013.8
55979.5
56287.7
56516.5
56562.1
56598.1
56345.9
56298
55956.3
56293.4
56623.6
56311.1
56260
56279.3
56773.8
56511.9
56614.2
56566.7
56942.9
56356.4
56733.2
56627.4
56797.4
56440
56702.6
56698.7
57020.6
56591.3
56841
57141.9
57147.3
56492.9
56519.4
56740
57065.9
56731.9
56705.9
57038.7
56841.7
57285.4
57319.8
56999.7
56911.5
57208.6
57324.7
57168.5
57357.3
56941.6
57215.6
57241
57394.4
57155.2
57417.3
57063.7
57191.2
57247.7
57084.8
57292.8
57173.4
57624.1
57537.3
57682.9
57838.2
57799.1
57718
57570
57642
57910
58048.9
57691.6
58456
57541
57758.4
58123.1
58131.6
57693.3
57963.1
57975.7
58007.3
58210.8
58107.4
57728.3
57985.6
58259.6
57820.5
57683.2
57816.9
58302.7
58328.5
58397.9
58191.3
58162.8
58226.3
58943
58563.2
58433.7
58584.2
58687
58801.5
59178
58980.3
58743.9
58785.1
58779.1
58929.1
58846.4
59303
58589.8
59031.4
59224.1
58982.9
59095.1
58841.6
59481.6
59552.8
59333
59232.5
59381.1
59512.6
59381.3
59578.8
59658.6
59656.5
59672.4
59674.3
60199.9
59657.4
59506.4
59870.3
60032.3
59955
60039
59970.7
60027.4
60036.3
60121.4
60325.7
60354.2
60196.8
60338
60108.1
60122.8
60259.9
60615.1
60482.1
60346.9
60619.5
60481
60597.5
60654.3
60386.7
60221.5
60672.6
61046
60939.5
60598.4
60746.8
60904.6
60343.6
60870.7
61031
61231.2
60674
60922.7
61015.4
61271.4
60986.4
61283.4
61288.4
61035.6
61383.9
61245.3
61404
61370.1
61461.1
61588.3
61651.1
61597.3
61721.3
61897.5
61544.3
61931.4
61782.6
61594.4
61870.2
62295.3
62221.4
61605.4
61729
62179.5
62066.9
62534.2
62397.5
62834
62505.1
62637.6
62008.2
62437
62341.4
62371
62292
62294.1
62490.5
62240.4
62494.4
62482.9
62457
62413.5
62399.1
62203
62229.7
62240
62085.9
62297.6
61981.2
62093.4
62394.5
62124.4
62511.6
62005.5
62248.5
62101.7
61942.8
62267.4
62241.3
62229.9
62053.7
62152.4
62224.1
62106.3
62267.9
62121.5
62334.7
62144.3
62200.3
62185.8
62487.2
61822.6
61778.9
61994.9
62227.2
62292.3
62185
62014.7
61965.4
61970.2
61800.9
61717.9
62077.1
62040.1
61873.6
61582
61726.3
61726.3
61564.6
61514.4
61809
61731.8
61578.7
61376.5
62006.8
61754.9
61849.4
61934.7
61854.6
62223.8
61929.4
62185.1
62039.2
62176.5
61813.2
62238.1
62265.6
62215.5
62284.7
62597.7
62589.7
62443
62785.6
62553.9
62722.3
62618
62583
62537.1
62562.5
62638.9
62398.3
62526
62428.7
62082.6
61917.3
61625.6
61456.9
61508
60908.3
60582.9
60233.4
60799.1
60613.8
60147.2
60227.3
60307.8
60250.2
60138.3
59882.1
59667
59455.9
59233.5
59128.5
59397.4
59179.3
59486.5
59531
59052.1
59060
59036.1
58959.7
59173.1
59460.5
59245.4
59509.2
59172.6
59145.5
59435.5
59148.1
59224.8
59497.8
59411.3
59359.8
60000.8
59423.1
59099.8
59493.4
59613.9
60078.6
59789
60202.3
60146
60149.4
60035.2
59874.8
59958.8
59761.5
59867.9
60071.7
60274.5
59941.4
59729.3
60588.6
60669.8
60972.1
60589.8
60778.9
61079.3
60954.4
61117.7
61178.8
61134.8
61306.5
61660.8
61686.7
61815.5
62225.3
62350.6
62405
63019.7
62461.7
62705.6
63268
63468.3
63314.3
63809.4
64154.3
64395.6
64785
64770
65307.1
65767.7
65936.8
66466.5
67093.9
68108.2
68518.1
69088.5
70245.9
71248.8
72744.5
74002.1
75598.9
77504
79516.1
82299.6
85202
88426.5
92339.5
97553.3
102792
108508
115259
122717
130148
137668
144860
150147
153183
153494
150980
146231
138923
130651
121474
113463
105680
98548.3
92385.2
87271.9
82906
79039.7
76242.8
73065.3
71456.4
69701.6
67880.1
66309.9
64734.3
64071.4
63462.4
62204
61525.2
61242.2
60604.7
59990.7
59186
58813.3
58797.7
58263.9
57604.9
57016.1
56624.4
56493.8
56170.7
55711.5
55539.5
55814.3
55340
55233.9
54897.5
54705.3
54955
54937.3
54655.8
54409.6
54574.1
54171.2
54402
54403.3
53998
53861.3
53976.1
54162.2
54047.3
54104.6
53636.6
53576.6
54073.3
54088.9
53930.7
53661.4
53361
53623.9
53386.1
53175.5
52963.8
52499.5
52206.5
52268.4
52106.8
51467.2
51768.7
51009.6
50834.6
50872.5
50816
51069.4
50597.4
50618.6
50347.4
50216.4
50428.9
50030.5
49862.4
49738.8
49795.5
49490.9
49445.7
49239.4
48843.3
48386.9
48206.4
48216.9
48008.6
48080.5
47471
47362
47612.8
47144.1
46647.2
46412.3
45770.8
45751
45338.9
45032.6
45067.5
44659.1
44137.7
44258.1
43677.5
43762.3
44133.2
43545
43394.4
43680.1
43545.6
43406.7
43531.2
43633.8
43830
43454.5
43621.2
43468.3
43712.5
43670.9
43727.7
43989.9
43966.3
43695.4
43680.2
43798.5
43656.2
43709.2
43432.3
43635.5
43762.3
43673
43809.5
43871.8
43799.2
44060.1
44373.4
44334.6
44597.7
44671.9
44817.6
45000.7
45313.1
45492.8
45975.4
46070.1
45769.2
45954.8
46020.6
46195
46565.6
46571.4
47090.3
47131.2
47153.8
47086.5
46898.8
47533
47412.7
47496.7
47357.4
47707.1
47841.6
48139.2
48404
48706.4
49157.6
49302.5
49546.9
50566.2
51671
52629.8
53807.4
55616.3
57131.9
59289.1
62530.3
66111.6
70715.5
76471.1
83884.6
94200.8
106644
123631
145912
173505
206580
244124
282046
315608
337808
344743
330940
299442
258132
215194
176652
144843
119940
100628
85839.1
75196.7
66940.4
60736.5
55916.9
52067.2
48900.1
46421.4
44750.5
43323.9
41634.9
40553.8
39500.2
38516.7
37520.7
37090.7
36353.1
35773.1
35100.7
34675.2
34420.9
34024.8
33737.2
33427
33276.9
32784.7
32759.7
32420.6
32139.6
32070.9
31836.5
31757.6
31549.9
31500.9
30947.6
31092.4
31307.2
30953.9
30944.5
30603.4
30643.9
30908.5
30572.4
30613.3
30379.9
30373.2
30279
30567.8
30293.2
30488.8
30615.7
30441.2
30020
29943.6
30003.4
30086.8
29932
29885.1
30042.3
29953.7
29937.5
29518.6
29590.6
29712.2
29608.9
29555.3
29982.1
29735.4
29436.8
29806.6
29477.5
29429.3
29609.3
29491.9
29520.7
29536.2
29590.8
29732.6
29679.8
29780.6
29523.7
29572
29596.4
29350.2
29311.8
29396.9
29605.8
29540.1
29423.7
29430.6
29562.8
29290
29121
29415.7
29188.1
29556
29474.3
29423.6
29332.2
29214
29379.6
29456.7
29581.8
29201.7
29259
29349
29125.5
29160.9
29434.7
29468
29370.3
29529.1
29379.2
29289.6
29334.4
29295.3
29098.5
29133.1
29334.8
3.64711
Cu2p
Cu in vacuum. long shirley
2020
3
8
23
38
57
0
17
Casa Info Follows
1
BackgroundSubtract
0
1
CASA region (*Cu 2p*) (*Shirley*) 461.66199 563.8457 25.081921 2 0 0 833.83732 -450 0 0 (*Cu 2p*) 63.549 0 25.39
0
EX340_CEC356_effect of lens modes.sle
Group = Cu in vacuum
First of group = 0
Analyzer lens = LargeArea:1.5kV
Analyzer slit = 4:7x20c\C:mesh
Scan mode = FixedAnalyzerTransmission
Kinetic energy start = 456.61
Sum of 20 spectra in column containing 20 scans
C:\Users\pielsticker\Lukas\MPI-CEC\Projects\Gas phase background\inelasticscattering\data\N2\Au, Ag, Cu in N2.vms
CasaXP4
XPS
1
Al
1486.61
0
0
0
54.5
180
FAT
20
1
4.156
0
0
0
0
0
Cu2p

-1
kinetic energy
eV
456.61
0.1
2
counts
d
Transmission
d
pulse counting
3
1
0
0
0
0
2
ESCAPE DEPTH TYPE
d
0
MFP Exponent
d
0
1420.77
3.64711
49871.4
49982.7
50035.1
49899.9
49667.9
50024.1
50455.1
50225.6
50118.8
50213.5
50049
49901.7
50164.6
49865.2
50278.7
50161.8
50177.1
50251.3
50010.9
49955.2
50059.5
50395
50456.6
50442
50430.4
50288.6
50315.1
50534.3
50194.5
50403
50175.4
50232.9
50577
50750.1
50169.7
50497
50617.4
50524.8
50397.6
50408.3
50441.3
50313.3
50414.1
50470.6
50837.2
50530.4
50238.9
50318.1
50471.4
50700.5
50673.4
50869.6
50784.8
50672.4
50492.2
50322.6
50763.2
50762.7
50853.5
50924.3
50625.3
50764.7
51011
50706.6
50797.5
50987
50858.6
50959.7
51051
50821.1
51057.6
50534.8
50732.4
50756.7
50870.5
50824.3
50952.4
50775.6
50592.7
50852.4
50740.3
51098.6
51262.9
51352.3
51119.7
51311.4
51504.4
51301.1
51095.4
51191.7
51047.3
51022
50970.7
50998
51102.7
51342.1
51268.1
51457.9
51192.8
50872
50875.8
51602.6
51610.5
51667.9
51495.6
51221
51604.7
51470.9
51836.2
51678.1
51228.2
51512.8
51828.1
51678.8
51506.7
51714.8
51848.3
51273.7
51597.9
51819.3
51651.5
51697.5
51430.8
51739.4
51632.8
51485.1
51832.8
51878.3
51669.6
51959.1
51687.1
51704.4
51985.1
52094.1
51799.2
51765.8
52086.4
51947.3
51671.4
52117.3
52143.8
51705.3
51976.2
52133.1
52085.1
51913.7
52216.8
51902.1
52020.1
51838.8
51984
52389.5
51986.7
52341
52346
52295.8
52151.6
51912.3
52116.3
52251.5
52231.2
52235.1
52379.3
52347.9
52654.5
52511.5
52230.2
52296.1
52169.6
52272.9
52249.4
52666.4
52576.5
52590.9
52691.8
52688.7
52577.3
52246.5
52837.9
52726.1
52751.8
52682.6
53017.3
52699.7
52669.3
52830.7
52718.4
52952.3
52585.3
52744.2
53022.6
52692.9
52838.8
52739.3
52814.3
53077.2
52766
52601.8
52692.1
52611.7
52827.6
52756.9
53099.2
53340.8
52801
53207.6
53031.8
53102.4
53159.1
53154
53213.6
53409.4
53096.5
52991.7
53216.5
53515.1
53305.9
53289.7
53145.3
53160.7
53257.8
53260.6
53106.6
53545.1
53188.9
53140.9
53300.8
53556.6
53532.6
53589.8
53658.4
53559.9
53514.7
53355
53279
53723.9
53586
53629.4
53482.1
53539.6
53083.2
53552.6
53718.4
53683
53766.8
53466.3
53367
53687.1
53807.2
53829.1
53954.8
53984.8
54016.6
53689.5
53796.3
54231.8
53991
54033.4
54104.5
54096.2
53606.6
53716.3
54006.2
54333
54105.9
54221.8
54298
53925
54312.8
54393.6
54321.9
54449
54296
54567.8
54418.4
54334.5
54548.4
54218.6
54618.7
54592.1
54677.1
54494.2
54349.3
54846.3
54966.4
54783.2
54294.6
54722.1
54910.1
54461
54405.4
54691.3
54723.1
54793.4
54834.5
54854.8
54751.5
55058.5
55000.3
55209.4
55185.5
55114.5
54930.1
54973.4
54948.5
54931.7
54855.5
55127.3
55031.9
55392.7
55177.9
55311.5
55346.4
55612.7
55064.5
55387.8
55496.5
55638.6
55421.1
55190.6
55918.8
55595.8
55484.4
55330.5
55429.6
55596.8
55579.7
55851.2
55749.1
55787
55518.6
55395.3
55388.8
55623.9
55655.5
55596.3
55608.6
55346.8
55920.7
56097.7
56394.6
55821.5
55672.2
55942.9
56028.3
56014.5
56221.6
56364.8
56008.7
56068.3
56180.1
55961.7
56109.3
56264.9
56150.7
55990.1
55973.8
56137.7
55940.9
56221.4
56381
56202.6
56025.9
56266
56379.8
56452.7
56248.4
56604
56252.4
55900.2
56013.8
55979.5
56287.7
56516.5
56562.1
56598.1
56345.9
56298
55956.3
56293.4
56623.6
56311.1
56260
56279.3
56773.8
56511.9
56614.2
56566.7
56942.9
56356.4
56733.2
56627.4
56797.4
56440
56702.6
56698.7
57020.6
56591.3
56841
57141.9
57147.3
56492.9
56519.4
56740
57065.9
56731.9
56705.9
57038.7
56841.7
57285.4
57319.8
56999.7
56911.5
57208.6
57324.7
57168.5
57357.3
56941.6
57215.6
57241
57394.4
57155.2
57417.3
57063.7
57191.2
57247.7
57084.8
57292.8
57173.4
57624.1
57537.3
57682.9
57838.2
57799.1
57718
57570
57642
57910
58048.9
57691.6
58456
57541
57758.4
58123.1
58131.6
57693.3
57963.1
57975.7
58007.3
58210.8
58107.4
57728.3
57985.6
58259.6
57820.5
57683.2
57816.9
58302.7
58328.5
58397.9
58191.3
58162.8
58226.3
58943
58563.2
58433.7
58584.2
58687
58801.5
59178
58980.3
58743.9
58785.1
58779.1
58929.1
58846.4
59303
58589.8
59031.4
59224.1
58982.9
59095.1
58841.6
59481.6
59552.8
59333
59232.5
59381.1
59512.6
59381.3
59578.8
59658.6
59656.5
59672.4
59674.3
60199.9
59657.4
59506.4
59870.3
60032.3
59955
60039
59970.7
60027.4
60036.3
60121.4
60325.7
60354.2
60196.8
60338
60108.1
60122.8
60259.9
60615.1
60482.1
60346.9
60619.5
60481
60597.5
60654.3
60386.7
60221.5
60672.6
61046
60939.5
60598.4
60746.8
60904.6
60343.6
60870.7
61031
61231.2
60674
60922.7
61015.4
61271.4
60986.4
61283.4
61288.4
61035.6
61383.9
61245.3
61404
61370.1
61461.1
61588.3
61651.1
61597.3
61721.3
61897.5
61544.3
61931.4
61782.6
61594.4
61870.2
62295.3
62221.4
61605.4
61729
62179.5
62066.9
62534.2
62397.5
62834
62505.1
62637.6
62008.2
62437
62341.4
62371
62292
62294.1
62490.5
62240.4
62494.4
62482.9
62457
62413.5
62399.1
62203
62229.7
62240
62085.9
62297.6
61981.2
62093.4
62394.5
62124.4
62511.6
62005.5
62248.5
62101.7
61942.8
62267.4
62241.3
62229.9
62053.7
62152.4
62224.1
62106.3
62267.9
62121.5
62334.7
62144.3
62200.3
62185.8
62487.2
61822.6
61778.9
61994.9
62227.2
62292.3
62185
62014.7
61965.4
61970.2
61800.9
61717.9
62077.1
62040.1
61873.6
61582
61726.3
61726.3
61564.6
61514.4
61809
61731.8
61578.7
61376.5
62006.8
61754.9
61849.4
61934.7
61854.6
62223.8
61929.4
62185.1
62039.2
62176.5
61813.2
62238.1
62265.6
62215.5
62284.7
62597.7
62589.7
62443
62785.6
62553.9
62722.3
62618
62583
62537.1
62562.5
62638.9
62398.3
62526
62428.7
62082.6
61917.3
61625.6
61456.9
61508
60908.3
60582.9
60233.4
60799.1
60613.8
60147.2
60227.3
60307.8
60250.2
60138.3
59882.1
59667
59455.9
59233.5
59128.5
59397.4
59179.3
59486.5
59531
59052.1
59060
59036.1
58959.7
59173.1
59460.5
59245.4
59509.2
59172.6
59145.5
59435.5
59148.1
59224.8
59497.8
59411.3
59359.8
60000.8
59423.1
59099.8
59493.4
59613.9
60078.6
59789
60202.3
60146
60149.4
60035.2
59874.8
59958.8
59761.5
59867.9
60071.7
60274.5
59941.4
59729.3
60588.6
60669.8
60972.1
60589.8
60778.9
61079.3
60954.4
61117.7
61178.8
61134.8
61306.5
61660.8
61686.7
61815.5
62225.3
62350.6
62405
63019.7
62461.7
62705.6
63268
63468.3
63314.3
63809.4
64154.3
64395.6
64785
64770
65307.1
65767.7
65936.8
66466.5
67093.9
68108.2
68518.1
69088.5
70245.9
71248.8
72744.5
74002.1
75598.9
77504
79516.1
82299.6
85202
88426.5
92339.5
97553.3
102792
108508
115259
122717
130148
137668
144860
150147
153183
153494
150980
146231
138923
130651
121474
113463
105680
98548.3
92385.2
87271.9
82906
79039.7
76242.8
73065.3
71456.4
69701.6
67880.1
66309.9
64734.3
64071.4
63462.4
62204
61525.2
61242.2
60604.7
59990.7
59186
58813.3
58797.7
58263.9
57604.9
57016.1
56624.4
56493.8
56170.7
55711.5
55539.5
55814.3
55340
55233.9
54897.5
54705.3
54955
54937.3
54655.8
54409.6
54574.1
54171.2
54402
54403.3
53998
53861.3
53976.1
54162.2
54047.3
54104.6
53636.6
53576.6
54073.3
54088.9
53930.7
53661.4
53361
53623.9
53386.1
53175.5
52963.8
52499.5
52206.5
52268.4
52106.8
51467.2
51768.7
51009.6
50834.6
50872.5
50816
51069.4
50597.4
50618.6
50347.4
50216.4
50428.9
50030.5
49862.4
49738.8
49795.5
49490.9
49445.7
49239.4
48843.3
48386.9
48206.4
48216.9
48008.6
48080.5
47471
47362
47612.8
47144.1
46647.2
46412.3
45770.8
45751
45338.9
45032.6
45067.5
44659.1
44137.7
44258.1
43677.5
43762.3
44133.2
43545
43394.4
43680.1
43545.6
43406.7
43531.2
43633.8
43830
43454.5
43621.2
43468.3
43712.5
43670.9
43727.7
43989.9
43966.3
43695.4
43680.2
43798.5
43656.2
43709.2
43432.3
43635.5
43762.3
43673
43809.5
43871.8
43799.2
44060.1
44373.4
44334.6
44597.7
44671.9
44817.6
45000.7
45313.1
45492.8
45975.4
46070.1
45769.2
45954.8
46020.6
46195
46565.6
46571.4
47090.3
47131.2
47153.8
47086.5
46898.8
47533
47412.7
47496.7
47357.4
47707.1
47841.6
48139.2
48404
48706.4
49157.6
49302.5
49546.9
50566.2
51671
52629.8
53807.4
55616.3
57131.9
59289.1
62530.3
66111.6
70715.5
76471.1
83884.6
94200.8
106644
123631
145912
173505
206580
244124
282046
315608
337808
344743
330940
299442
258132
215194
176652
144843
119940
100628
85839.1
75196.7
66940.4
60736.5
55916.9
52067.2
48900.1
46421.4
44750.5
43323.9
41634.9
40553.8
39500.2
38516.7
37520.7
37090.7
36353.1
35773.1
35100.7
34675.2
34420.9
34024.8
33737.2
33427
33276.9
32784.7
32759.7
32420.6
32139.6
32070.9
31836.5
31757.6
31549.9
31500.9
30947.6
31092.4
31307.2
30953.9
30944.5
30603.4
30643.9
30908.5
30572.4
30613.3
30379.9
30373.2
30279
30567.8
30293.2
30488.8
30615.7
30441.2
30020
29943.6
30003.4
30086.8
29932
29885.1
30042.3
29953.7
29937.5
29518.6
29590.6
29712.2
29608.9
29555.3
29982.1
29735.4
29436.8
29806.6
29477.5
29429.3
29609.3
29491.9
29520.7
29536.2
29590.8
29732.6
29679.8
29780.6
29523.7
29572
29596.4
29350.2
29311.8
29396.9
29605.8
29540.1
29423.7
29430.6
29562.8
29290
29121
29415.7
29188.1
29556
29474.3
29423.6
29332.2
29214
29379.6
29456.7
29581.8
29201.7
29259
29349
29125.5
29160.9
29434.7
29468
29370.3
29529.1
29379.2
29289.6
29334.4
29295.3
29098.5
29133.1
29334.8
3.64711
Cu2p
Cu in vacuum, short shirley, background subtr.
2020
3
8
23
38
57
0
15
Casa Info Follows
0
0
0
0
EX340_CEC356_effect of lens modes.sle
Group = Cu in vacuum
First of group = 0
Analyzer lens = LargeArea:1.5kV
Analyzer slit = 4:7x20c\C:mesh
Scan mode = FixedAnalyzerTransmission
Kinetic energy start = 456.61
Sum of 20 spectra in column containing 20 scans
C:\Users\pielsticker\Lukas\MPI-CEC\Projects\Gas phase background\inelasticscattering\data\N2\Au, Ag, Cu in N2.vms
CasaXP4
XPS
1e+037
Al
1486.61
0
0
0
54.5
180
FAT
20
1
4.156
0
0
0
0
0
Cu2p

-1
kinetic energy
eV
456.61
0.1
2
counts
d
Transmission
d
pulse counting
3
1
0
0
0
0
2
ESCAPE DEPTH TYPE
d
0
MFP Exponent
d
0
1420.77
3.64711
0
0
0
0
0
0
0
0
0
0
0
0
0
0
0
0
0
0
0
0
0
0
0
0
0
0
0
0
0
0
0
0
0
0
0
0
0
0
0
0
0
0
0
0
0
0
0
0
0
0
0
0
0
0
0
0
0
0
0
0
0
0
0
0
0
0
0
0
0
0
0
0
0
0
0
0
0
0
0
0
0
0
0
0
0
0
0
0
0
0
0
0
0
0
0
0
0
0
0
0
0
0
0
0
0
0
0
0
0
0
0
0
0
0
0
0
0
0
0
0
0
0
0
0
0
0
0
0
0
0
0
0
0
0
0
0
0
0
0
0
0
0
0
0
0
0
0
0
0
0
0
0
0
0
0
0
0
0
0
0
0
0
0
0
0
0
0
0
0
0
0
0
0
0
0
0
0
0
0
0
0
0
0
0
0
0
0
0
0
0
0
0
0
0
0
0
0
0
0
0
0
0
0
0
0
0
0
0
0
0
0
0
0
0
0
0
0
0
0
0
0
0
0
0
0
0
0
0
0
0
0
0
0
0
0
0
0
0
0
0
0
0
0
0
0
0
0
0
0
0
0
0
0
0
0
0
0
0
0
0
0
0
0
0
0
0
0
0
0
0
0
0
0
0
0
0
0
0
0
0
0
0
0
0
0
0
0
0
0
0
0
0
0
0
0
0
0
0
0
0
0
0
0
0
0
0
0
0
0
0
0
0
0
0
0
0
0
0
0
0
0
0
0
0
0
0
0
0
0
0
0
0
0
0
0
0
0
0
0
0
0
0
0
0
0
0
0
0
0
0
0
0
0
0
0
0
0
0
0
0
0
0
0
0
0
0
0
0
0
0
0
0
0
0
0
0
0
0
0
0
0
0
0
0
0
0
0
0
0
0
0
0
0
0
0
0
0
0
0
0
0
0
0
0
0
0
0
0
0
0
0
0
0
0
0
0
0
0
0
0
0
0
0
0
0
0
0
0
0
0
0
0
0
0
0
0
0
0
0
0
0
0
0
0
0
0
0
0
0
0
0
0
0
0
0
0
0
0
-14.4826
55.1106
-150.96
-178.833
-114.93
603.886
224.875
95.7103
247.076
351.107
467.245
846.713
651.296
416.356
459.165
454.759
606.887
526.031
986.088
273.847
717.964
913.868
675.034
790.003
538.391
1182.54
1258.15
1042
944.811
1097.26
1233.08
1105.66
1307.74
1392.42
1395.21
1416.08
1422.96
1955.42
1417.89
1271.35
1641
1809.34
1738.13
1828.54
1766.44
1829.55
1844.92
1936.81
2148.64
2184.8
2034.53
2183.38
1960.35
1982
2126.56
2490.49
2365.78
2238.43
2519.86
2389.74
2515.05
2580.9
2321.44
2163.82
2624.12
3008.07
2911.77
2579.72
2737.71
2905.7
2352.95
2890.18
3061.21
3272.88
2725.23
2984.4
3087.92
3355.68
3081.49
3390.37
3407.31
3165.61
3526.27
3399.59
3570.81
3549.35
3653.16
3793.65
3870.02
3829.64
3967.55
4158.33
3818.51
4220.41
4085.93
3911.44
4201.97
4643.35
4585.52
3983.49
4121.54
4588.12
4491.26
4976.01
4856.33
5311.45
5000.08
5150.63
4537.14
4983.41
4905
4951.96
4890.1
4909.41
5123.77
4890.82
5162.91
5169.54
5161.73
5136.23
5139.85
4961.14
5005.39
5033.33
4896.4
5126.07
4826.59
4956.16
5275.75
5023.26
5429.49
4940.71
5201.95
5072.93
4931.32
5274.41
5266.77
5273.86
5115.59
5232.63
5322.99
5223.5
5404.05
5276.14
5508.65
5336.96
5411.93
5416.42
5737.93
5091.18
5065.23
5299.81
5551.57
5636.43
5548.58
5397.2
5366.71
5390.41
5239.48
5174.61
5553.28
5535.69
5388.07
5114.4
5277.2
5295.77
5152.13
5119.87
5433.52
5375.16
5240.43
5055.96
5706.26
5473.55
5587.63
5692.89
5632.53
6022.85
5748.6
6025.42
5900.2
6058.74
5715.48
6161.98
6211.25
6182.82
6274.02
6610.19
6625.41
6501.5
6868.18
6659.82
6852.25
6771.68
6760.38
6738.1
6787.29
6887.84
6670.62
6822.24
6748.59
6425.02
6281.74
6011.11
5862.96
5934.86
5353.93
5046.22
4713.24
5297.51
5130.2
4680
4776.85
4874.43
4833.78
4738.49
4498.06
4298.02
4101.3
3892.55
3800.87
4084.09
3879.59
4201.51
4260.95
3795.35
3816.63
3806.08
3742.8
3970.11
4272.49
4071.66
4350.71
4028.23
4015.21
4320.35
4047.14
4138.35
4426.87
4355.63
4319.28
4977.72
4415.5
4106.6
4516.03
4652.84
5135.54
4862.99
5294.85
5256.98
5278.88
5182.85
5040.12
5142.14
4962.24
5086.47
5308.88
5531.07
5216.25
5021.76
5901.74
6003.99
6328.47
5967.09
6177.85
6501.04
6398.57
6584.95
6669.43
6648.74
6844.43
7224.05
7275.46
7430.3
7867.68
8021.1
8103.91
8749.28
8220.09
8493.77
9088.02
9321
9199.25
9728.45
10108.8
10386.5
10813.8
10836.8
11413.9
11916.3
12127.9
12702.1
13376.4
14441.3
14903.5
15528.3
16744.4
17809.7
19373.3
20703.5
22378.8
24369.3
26474.2
29360.6
32376.5
35726.2
39778.7
45150.8
50566.7
56480.7
63454.1
71161.6
78869.1
86693
94215.2
99852.3
103250
103925
101768
97360.5
90369.3
82386.1
73466.6
65685.9
58106.6
51154.2
45149.4
40176.9
35937
32183.5
29490
26405
24883.4
23209.9
21463.7
19963.5
18452.5
17852.2
17303.9
16101.9
15477.4
15247.8
14661.7
14097.1
13339.2
13012.1
13042.2
12552.4
11935.3
11386.4
11033.4
10941.1
10655.4
10232
10095.4
10406.7
9967.35
9895.94
9593.16
9434.04
9717.8
9734.22
9485.98
9272.28
9469.98
9098.97
9362.59
9396.83
9023.16
8917.72
9064.3
9282.94
9200.29
9290.15
8853.19
8824.12
9353.61
9402.17
9276.49
9038.87
8769.21
9063.88
8857.13
8676.95
8495.03
8058.98
7793.3
7882.83
7748.39
7133.8
7461.45
6725.93
6573.98
6635.14
6601.78
6879.29
6429.83
6473.73
6224.34
6114.78
6349.54
5972.07
5824.39
5720.84
5797.87
5512.59
5486.62
5298.9
4920.05
4479.35
4313.97
4339.68
4145.92
4232.65
3635.9
3539.31
3803.44
3346.47
2859.59
2633.93
1999.44
1986.6
1580.04
1278.22
1317.74
912.538
392.514
514.718
-65.652
19.2154
391.488
-196.025
-345.414
-59.5057
-193.328
-331.068
-205.846
-102.885
93.643
-280.872
-113.774
-265.742
-21.4669
-62.8466
-6.02547
257.076
234.297
-36.4751
-51.4946
67.0404
-74.9967
-21.9199
-297.776
-94.2457
32.6688
-56.4333
80.3483
143.15
70.7983
332.865
648.438
611.783
877.96
955.51
1105.08
1292.72
1610.76
1796.76
2287.38
2390.46
2096.91
2290.54
2364.63
2547.96
2928.83
2944.95
3476.03
3529.31
3564.4
3509.4
3333.39
3981.54
3874.83
3972.75
3846.94
4211.4
4361.19
4675.18
4957.36
5278.26
5749.61
5915.25
6181.32
7225.95
8360.05
9351.64
10566.3
12418.7
13983.3
16197.3
19506.9
23169.4
27871
33744.9
41303.2
51801
64470.2
81743.7
104391
132448
166105
204366
243140
277675
300930
308948
296183
265617
225096
182798
144764
113352
88760.3
69692.6
55096.9
44610.9
36482.4
30385.1
25655.4
21882.4
18781.1
16359.8
14740.6
13360.8
11712.9
10669.2
9649.38
8696.36
7727.45
7323.12
6608.69
6049.9
5396.41
4988.4
4750.75
4369.97
4096.73
3799.85
3662.59
3181.54
3167.65
2838.5
2566.5
2506.58
2280.17
2209.02
2008.36
1966.25
1417.92
1568.22
1789.29
1441.04
1436.68
1099.43
1143.94
1413.5
1081.19
1126.04
895.775
892.203
800.81
1093.44
821.724
1020.9
1151.84
980.778
561.547
486.853
548.576
634.199
481.086
435.713
594.999
508.18
493.711
75.0741
147.591
270.138
167.425
114.226
542.929
297.271
-1.32437
369.772
40.8149
-7.35928
173.248
56.0445
85.143
100.997
156.144
298.992
247.058
349.082
92.5065
141.302
166.285
-79.6362
-117.624
-32.4102
177.111
111.803
-4.58139
2.32677
135
0
0
0
0
0
0
0
0
0
0
0
0
0
0
0
0
0
0
0
0
0
0
0
0
0
0
0
0
3.64711
Cu2p
Cu in vacuum. long shirley, background subtr.
2020
3
8
23
38
57
0
15
Casa Info Follows
0
0
0
0
EX340_CEC356_effect of lens modes.sle
Group = Cu in vacuum
First of group = 0
Analyzer lens = LargeArea:1.5kV
Analyzer slit = 4:7x20c\C:mesh
Scan mode = FixedAnalyzerTransmission
Kinetic energy start = 456.61
Sum of 20 spectra in column containing 20 scans
C:\Users\pielsticker\Lukas\MPI-CEC\Projects\Gas phase background\inelasticscattering\data\N2\Au, Ag, Cu in N2.vms
CasaXP4
XPS
1e+037
Al
1486.61
0
0
0
54.5
180
FAT
20
1
4.156
0
0
0
0
0
Cu2p

-1
kinetic energy
eV
456.61
0.1
2
counts
d
Transmission
d
pulse counting
3
1
0
0
0
0
2
ESCAPE DEPTH TYPE
d
0
MFP Exponent
d
0
1420.77
3.64711
0
0
0
0
0
0
0
0
0
0
0
0
0
0
0
0
0
0
0
0
0
0
0
0
0
0
0
0
0
0
0
0
0
0
0
0
0
0
0
0
0
0
0
0
0
0
0
0
0
0
0
93.8003
9.01311
-103.24
-283.037
-451.993
-11.3767
-11.8598
79.0528
150.067
-148.722
-9.30832
237.33
-66.9749
23.9593
213.764
85.4855
186.852
278.548
48.7178
285.625
-236.838
-39.1822
-14.861
99.0801
52.9555
181.314
4.52023
-178.126
81.6903
-30.3664
328.401
493.404
583.635
351.536
544.011
738.062
535.525
330.296
427.204
283.208
258.275
207.271
234.905
340.09
580.316
507.038
697.832
433.35
112.71
116.676
844.68
853.796
912.495
741.251
467.317
852.231
719.456
1086.3
929.527
480.311
766.002
1082.84
934.876
763.864
973.351
1108.43
534.591
860.016
1082.96
916.464
963.837
698.131
1008.17
902.853
756.23
1105.51
1152.65
945.293
1236.55
965.931
984.633
1267.14
1378.1
1084.75
1052.85
1375.4
1238.07
963.541
1411.45
1440
1002.93
1275.65
1434.59
1388.57
1218.91
1524.18
1211.2
1331.1
1151.44
1298.49
1706.42
1305.48
1662.14
1669.52
1621.63
1479.54
1242.01
1448.07
1585.53
1567.46
1573.6
1720.25
1691.26
2000.71
1860.36
1581.32
1649.57
1525.24
1630.86
1609.65
2029.54
1942.41
1959.6
2063.44
2063.28
1954.66
1626.18
2220.74
2111.95
2140.7
2074.46
2412.59
2097.98
2070.53
2235.11
2125.84
2363.11
1998.96
2160.93
2442.81
2116.13
2265.25
2168.84
2247.04
2513.52
2205.47
2044.18
2137.52
2060.06
2279.2
2211.65
2557.6
2803.19
2266.62
2677.03
2504.8
2579.07
2639.53
2638.19
2701.64
2901.57
2592.36
2491.11
2719.79
3022.69
2817.5
2805.3
2664.7
2683.92
2784.99
2791.76
2641.52
3084.42
2732.11
2687.94
2851.9
3112.13
3092.54
3154.23
3227.43
3133.39
3092.6
2937.08
2865.16
3314.78
3181.41
3229.41
3086.51
3148.49
2695.93
3169.85
3340.41
3309.72
3398.36
3102.28
3007.27
3332.11
3457.14
3484
3614.85
3650.05
3687.1
3364.79
3476.54
3917.62
3682.07
3729.78
3806.3
3803.42
3318.55
3433.14
3728.35
4060.93
3839.3
3960.84
4042.8
3675.04
4068.63
4155.35
4089.47
4222.59
4075.39
4353.39
4209.99
4131.98
4352.08
4028.01
4434.43
4414.12
4505.53
4328.8
4189.87
4693.55
4820.52
4643.94
4161.26
4595.31
4790.13
4347.22
4297.74
4590.18
4628.58
4705.58
4753.45
4780.56
4683.93
4998.05
4946.9
5163.35
5146.78
5083.02
4905.61
4955.97
4938.1
4928.32
4859.04
5138.16
5049.95
5418.47
5211.1
5352.32
5394.9
5669.28
5128.38
5459.46
5576.1
5726.36
5516.72
5293.76
6030.55
5715.69
5612.28
5466.17
5573.21
5748.6
5739.67
6019.75
5926.09
5972.49
5712.23
5596.9
5598.38
5841.8
5881.78
5830.88
5851.52
5597.69
6180.39
6366.46
6672.86
6108.47
5967.67
6247.26
6341.7
6336.92
6553.36
6706.11
6359.07
6427.82
6548.95
6339.58
6496.44
6661.52
6556.66
6405.19
6398
6571.26
6383.55
6673.56
6842.91
6674.01
6506.58
6756.3
6879.9
6962.72
6768.06
7133.82
6791.9
6448.88
6571.84
6546.87
6864.85
7103.77
7159.56
7205.83
6963.55
6925.51
6593.2
6940.19
7280.76
6978.2
6936.98
6966.2
7471.34
7219.73
7332.47
7295.36
7682.51
7106.13
7493.6
7398.34
7579.13
7232.04
7505.33
7512.13
7845.2
7426.48
7687.13
7999.42
8016.24
7372.34
7409.4
7640.88
7978.14
7655.05
7639.93
7984.1
7798.21
8253.67
8299.89
7991.17
7914.24
8223.06
8351.05
8206.54
8407.32
8003.02
8288.82
8326.08
8491.58
8264.15
8538.41
8196.49
8335.86
8404.33
8253.19
8473.26
8365.77
8829.05
8754.72
8913.01
9081.25
9055.05
8986.75
8851.35
8936.08
9217.21
9369.46
9025.01
9803.38
8901.06
9131.46
9509.71
9531.78
9106.46
9389.63
9415.64
9460.72
9678
9588.26
9222.3
9493.12
9781.05
9355.28
9231.12
9378.18
9878.05
9917.98
10001.6
9809
9794.45
9872.01
10603.8
10238.6
10123.5
10288.7
10406.3
10535.8
10927.9
10745.5
10524.1
10580.3
10589.4
10754.7
10687.3
11159.8
10461.5
10918.6
11127.2
10901.5
11029.4
10791.3
11447.6
11535.2
11331.5
11247.1
11411.9
11559.9
11444.9
11659
11755.5
11770.2
11802.9
11821.7
12364.9
11839.2
11704.9
12086
12265.5
12205.6
12307.1
12256.3
12330.5
12357
12459.9
12682.2
12728.9
12589.4
12748.8
12536.7
12569.3
12724.5
13098.4
12983.9
12867
13158.4
13038.4
13173.7
13249.4
13000.3
12853.4
13323.5
13716.4
13629.3
13307.2
13474.8
13652
13109.7
13656.2
13836.3
14056.5
13518.5
13786.9
13899.4
14175.6
13910.4
14227.6
14252.9
14020.1
14388.9
14270.6
14449.9
14436.6
14548.3
14696.4
14780.3
14747.5
14892.7
15090.4
14758.2
15166.9
15039.6
14872.5
15169.9
15617.3
15565.6
14970.9
15116
15588.7
15498.2
15988.3
15874.2
16333.9
16027.9
16183.4
15576.2
16027.8
15955
16007.4
15951.1
15975.9
16195.4
15968.1
16245.2
16256.9
16254.1
16233.7
16242.5
16069.3
16118.9
16152.2
16020.9
16255.8
15962.1
16097.3
16421.8
16174.7
16585.5
16102.4
16368.7
16245
16109.1
16457.1
16454.4
16466.5
16313.5
16435.6
16530.9
16436.5
16621.8
16498.9
16735.9
16569.1
16648.8
16658
16983.6
16342.3
16321.9
16561.5
16817.7
16906.9
16823.6
16677
16651.4
16680
16534.2
16474.7
16857.9
16844.9
16702.2
16434
16602
16625.6
16487.4
16460.7
16779.2
16725.8
16596.3
16417.5
17072.1
16844.2
16962.9
17072.5
17016.6
17410.6
17140.7
17421.2
17299.9
17462.1
17123.2
17573.1
17625.7
17600.7
17695.1
18033.8
18051.5
17930.3
18299
18093.1
18287.5
18209.2
18200.1
18180.1
18231.4
18334
18119.2
18272.9
18201.5
17880.9
17740.9
17474
17330
17405.9
16830.2
16528.3
16201.9
16791.5
16629.9
16186.4
16289.7
16393.5
16359.2
16270.5
16037.2
15844.6
15655.8
15455.4
15372.3
15663.5
15467.5
15797.2
15864.3
15407.3
15437.2
15435.3
15380.8
15616.4
15926.5
15733.8
16020.5
15706.2
15701.5
16014.3
15749.3
15848.6
16144.6
16081
16052.4
16717.2
16162.5
15861.8
16278.6
16422.5
16911.3
16645.4
17083
17051
17078.7
16988.7
16852.3
16960.5
16787.1
16917.6
17145.8
17373.4
17064.6
16876.5
17761.1
17867.8
18196
17839.1
18053.9
18380.5
18281.6
18471.2
18558.8
18541.2
18739.6
19121.1
19174.3
19330.7
19768.6
19922.3
20005.2
20649.3
20120
20392.9
20985.2
21215.7
21091.8
21617.7
21993.9
22266.9
22688.6
22706
23276.2
23770.7
23973.9
24538.6
25201.9
26253.6
26701.5
27310.8
28508.8
29553.8
31093.8
32397.5
34042.8
35999.2
38065.5
40907.3
43872.2
47163.9
51149.7
56443.9
61770.6
67582.9
74439.9
82014.7
89573.3
97231.8
104573
110016
113214
113687
111331
106734
99568.1
91426.3
82366.6
74461.7
66773.8
59727.2
53640.5
48596.4
44293.6
40485
37741.8
34613.6
33051.8
31341.7
29562.3
28032
26494.1
25868.1
25295.1
24071
23425.6
23175.6
22570.2
21987.5
21213.1
20870.1
20884.2
20379.5
19748.6
19187.1
18822.2
18718.3
18421.4
17987.8
17841.3
18141.9
17692.8
17611.8
17300
17132.2
17406.7
17413.8
17156.8
16934.7
17123.6
16744.5
16999.5
17025.1
16643.5
16530.3
16668.9
16879
16788
16869.4
16424.8
16388.1
16908.9
16948.6
16814.4
16568.7
16291.5
16578
16363.5
16176
15987
15544.9
15273.6
15357.4
15217.5
14598.7
14921.4
14182.5
14027.5
14085.5
14049
14322.8
13870.5
13911.6
13659.8
13548.1
13780.2
13400.9
13251.7
13146.8
13222.4
12936.2
12909.4
12721.2
12342.7
11903.2
11739.5
11766.7
11574.9
11663.4
11069.7
10976.3
11243.1
10789.8
10307.6
10087
9459.02
9452.69
9053.48
8759.66
8807.1
8410.68
7900.54
8032.38
7462.41
7557.97
7940.18
7362.47
7222.16
7518.57
7394.6
7266.05
7401.09
7514.39
7721.59
7356.57
7534
7391.63
7646.72
7615.97
7683.72
7957.25
7944.97
7685.01
7680.75
7810.18
7678.82
7742.84
7476.59
7690.75
7828.7
7750.44
7898.19
7971.84
7910.51
8183.07
8508.49
8481.77
8757.34
8844.14
9002.66
9198.87
9524.83
9718.38
10215.5
10324.9
10038.3
10238.5
10319
10508.4
10894.5
10915.8
11451.1
11508.4
11547.4
11496.5
11324.9
11976.2
11872.8
11973.8
11851.4
12218.5
12370.6
12686.3
12969.6
13290.9
13761.7
13926.5
14191.1
15232.1
16360.2
17343.7
18547.7
20385.6
21932.5
24124
27404.3
31029.8
35684.5
41499.2
48982.5
59383.3
71928.9
89042.7
111483
139274
172595
210439
248715
282679
305314
312695
299318
268202
227216
184541
146207
114561
89785.9
70574.4
55865.1
45287.2
37083.7
30923.9
26141.5
22323.6
19183.8
16728.9
15079.5
13672.4
12000.5
10935
9895.47
8924.68
7939.99
7520.7
6792.78
6221.64
5557.15
5138.97
4891.64
4501.95
4220.36
3915.74
3771.01
3283.49
3263.14
2928.21
2650.99
2585.97
2354.92
2279.27
2074.52
2028.41
1477.22
1624.33
1841.76
1490.58
1483.29
1143.82
1186.01
1452.68
1118.17
1160.72
928.648
923.263
830.245
1120.64
847.248
1044.34
1172.91
999.831
579.456
503.774
564.378
648.702
494.606
448.345
606.408
518.547
503.064
84.2837
156.507
278.503
175.453
122.027
549.61
303.342
4.74876
375.083
46.0486
-2.14832
178.105
60.792
89.7198
105.37
160.198
302.429
249.985
351.285
94.5199
143.024
167.662
-78.4259
-116.66
-31.5148
177.638
112.098
-4.29601
2.60771
135
0
0
0
0
0
0
0
0
0
0
0
0
0
0
0
0
0
0
0
0
0
0
0
0
0
0
0
0
3.64711
end of experiment